Workbook
Name Kabeltype: [1]Kabelmodstand!$AF$4:$AF$8
Name kvadrat: [1]Kabelmodstand!$AR$66:$AR$83
Name Lederantal: [1]Kabelmodstand!$AE$4:$AE$8
Name Parallelleleder: [1]Kabelmodstand!$AC$4:$AC$13

Sheet Transformer
X1: grader | Y1: cos | Z1: sin | AA1: tan | AB1: radianer | AH1: er | AI1: R/X
X2: =IF(B10="R/X",DEGREES(ATAN(1/D10)),DEGREES(ACOS(D10))) -> 14.069868 | Y2: =COS(AB2) -> 0.97 | Z2: =SIN(AB2) -> 0.24310492 | AA2: =TAN(AB2) -> 0.25062362 | AB2: =RADIANS(X2) -> 0.24556552 | AH2: PCU | AI2: cosϕ
X3: =DEGREES(ACOS(D19/D18)) -> #NUM! | Y3: =COS(AB3) -> #NUM! | Z3: =SIN(AB3) -> #NUM! | AA3: =TAN(AB3) -> #NUM! | AB3: =RADIANS(X3) -> #NUM!
B8: Beregning af Z̅N
B9: SKN | D9: 100 | F9: MVA
B10: cosϕ | D10: 0.97
B11: UN | D11: 400 | F11: V
B13: Z̅̅N = | D13: UN² | I13: ⇒ | J13: =D11&"²" -> 400² | Q13: = | R13: ="("&AB14&"°) Ω" -> (0,0016 ∠14,07°) Ω | X13: R | Y13: X | Z13: Z | AA13: Zn | AB13: polar
D14: (SKN | F14: =IF(B10="R/X","∠-tan¯¹(1/RX))","∠-cos¯¹(ϕ))") -> ∠-cos¯¹(ϕ)) | J14: ="(("&D9&"·10⁶)"&IF(B10="R/X","∠-tan¯¹(1/"&D10&"))","∠-cos¯¹("&D10&"))") -> ((100·10⁶)∠-cos¯¹(0,97)) | X14: =Z14*Y2 -> 0.001552 | Y14: =Z14*Z2 -> 0.00038896786 | Z14: =D11^2/(D9*10^6) -> 0.0016 | AA14: =COMPLEX(X14,Y14,) -> 0,001552+0,000388967864996583i | AB14: =ROUND(IMABS(COMPLEX(X14,Y14,"j")),4)&" ∠"&ROUND(DEGREES(IMARGUMENT(COMPLEX(X14,Y14,"j"))),2) -> 0,0016 ∠14,07
B16: Beregning af transformer Z̅T
B17: S1/1 | D17: 500 | F17: kVA
B18: ek | D18: 4 | F18: %
B19: PCU | D19: 5300 | F19: =IF(B19="er","%","W") -> W
B20: UT | D20: 400 | F20: V
B22: Z̅̅T = | D22: ek · UT² | I22: ⇒ | J22: =IF(B19="er",D18&" · "&D20&"²","") | Q22: = | R22: =IF(B19="er","("&AB23&"°) Ω","") | X22: R | Y22: X | Z22: Z | AA22: Zt | AB22: polar
D23: 100 · (S1/1 ∠-cos¯¹(er /ek)) | J23: =IF(B19="er","100 · (("&D17&" · 10³) ∠-cos¯¹("&D19&" /"&D18&"))","") | X23: =IF(D19="","",Z23*Y3) -> #NUM! | Y23: =IF(D19="","",Z23*Z3) -> #NUM! | Z23: =IF(B19="","",D18*D20^2/(100*D17*10^3)) -> 0.0128 | AA23: =IF(B19="","",COMPLEX(X23,Y23,)) -> #NUM! | AB23: =IF(B19="","",ROUND(IMABS(COMPLEX(X23,Y23,"j")),4)&" ∠"&ROUND(DEGREES(IMARGUMENT(COMPLEX(X23,Y23,"j"))),2)) -> #NUM!
B26: ZT = | D26: ek · UT² | I26: ⇒ | J26: =IF(B19="er","",D18&" · "&D20&"²") -> 4 · 400² | Q26: = | R26: =IF(B19="er","",Z27&" Ω") -> 0,0128 Ω | Z26: Z
D27: 100 · S1/1 | J27: =IF(B19="er","","100 · ("&D17&" · 10³)") -> 100 · (500 · 10³) | Z27: =IF(B19="er","",ROUND((D18*D20^2)/(100*(D17*10^3)),6)) -> 0.0128
B30: RT = | D30: Pcu · UT² | I30: ⇒ | J30: =IF(B19="er","",D19&" · "&D20&"²") -> 5300 · 400² | Q30: = | R30: =IF(B19="er","","("&X31&") Ω") -> (0,003392) Ω | X30: R
D31: S1/1² | J31: =IF(B19="er","","("&D17&" · 10³)²") -> (500 · 10³)² | X31: =ROUND((D19*D20^2)/((D17*10^3)^2),6) -> 0.003392
AB32: Vinkel | AC32: Pcu
AB33: =DEGREES(ACOS(AC33)) -> 74.633047 | AC33: =(D19*100)/(D18*(D17*10^3)) -> 0.265
B34: ∠ϕ = | D34: Pcu · 100 | I34: ⇒ | J34: =IF(B19="er","",D19&" · 100") -> 5300 · 100 | Q34: = | R34: =IF(B19="er","","("&ROUND(AB33,2)&"°) ") -> (74,63°) | Y34: X
D35: er · S1/1² | J35: =IF(B19="er","",D18&" · ("&D17&" ·10³)") -> 4 · (500 ·10³) | Y35: =ROUND(SQRT(Z27^2-X31^2),6) -> 0.012342
B38: Z̅̅T = | D38: (ZT ∠ϕ) | I38: ⇒ | J38: =IF(B19="er","","("&AB39&"°)") -> (0,0128 ∠74,63°) | Q38: = | R38: =IF(B19="er","","("&AB39&"°) Ω") -> (0,0128 ∠74,63°) Ω | X38: R | Y38: X | Z38: Z | AA38: ZT | AB38: polar
X39: =X31 -> 0.003392 | Y39: =Y35 -> 0.012342 | Z39: =Z27 -> 0.0128 | AA39: =COMPLEX(X39,Y39,) -> 0,003392+0,012342i | AB39: =ROUND(IMABS(COMPLEX(X39,Y39,"j")),4)&" ∠"&ROUND(DEGREES(IMARGUMENT(COMPLEX(X39,Y39,"j"))),2) -> 0,0128 ∠74,63
B43: ΣZ̅N3f = | D43: Z̅N + Z̅T | I43: ⇒ | J43: =IF(B19="er","("&AB14&") + ("&AB23&")","("&AB14&") + ("&AB39&")") -> (0,0016 ∠14,07) + (0,0128 ∠74,63) | Q43: = | R43: ="("&AB44&"°) Ω" -> (0,0137 ∠68,78°) Ω | AA43: ZN+ZT | AB43: polar | AD43: =SQRT(3) -> 1.7320508
X44: =IF(B19="er",X14+X23,X14+X39) -> 0.004944 | Y44: =IF(B19="er",Y14+Y23,Y14+Y39) -> 0.012730968 | Z44: =SQRT(X44^2+Y44^2) -> 0.013657257 | AA44: =COMPLEX(X44,Y44) -> 0,004944+0,0127309678649966i | AB44: =ROUND(IMABS(COMPLEX(X44,Y44,"j")),4)&" ∠"&ROUND(DEGREES(IMARGUMENT(COMPLEX(X44,Y44,"j"))),2) -> 0,0137 ∠68,78
B46: ΣZ̅N2f = | D46: Z̅N + Z̅T | I46: ⇒ | J46: =IF(B19="er","("&AB14&") + ("&AB23&")","("&AB14&") + ("&AB39&")") -> (0,0016 ∠14,07) + (0,0128 ∠74,63) | Q46: = | R46: ="("&AB46&"°) Ω" -> (0,0158 ∠68,78°) Ω | X46: =X44/(SQRT(3)/2) -> 0.0057088395 | Y46: =Y44/(SQRT(3)/2) -> 0.014700455 | Z46: =SQRT(X46^2+Y46^2) -> 0.015770042 | AA46: =COMPLEX(X46,Y46) -> 0,00570883946174702+0,0147004554478005i | AB46: =ROUND(IMABS(COMPLEX(X46,Y46,"j")),4)&" ∠"&ROUND(DEGREES(IMARGUMENT(COMPLEX(X46,Y46,"j"))),2) -> 0,0158 ∠68,78
D47: √3 / 2 | L47: ( | M47: √3 | N47: )
M48: 2
B50: Kortslutningsniveau på transformers sekundær klemmer
B52: Ikmax3f = | D52: UN | I52: ⇒ | J52: =D11 -> 400 | Q52: = | R52: =ROUND(AB53/1000,2)&"kA" -> 16,91kA
D53: √3 · ΣZ̅N3f | J53: ="√3 · ("&AB44&")" -> √3 · (0,0137 ∠68,78) | AB53: =J52/(SQRT(3)*IMABS(AA44)) -> 16909.699
B56: Ikmax2f = | D56: Ikmax3f · | F56: ( | G56: √3 | H56: ) | I56: ⇒ | J56: =ROUND(AB53,2)&" · (√3/2)" -> 16909,7 · (√3/2) | Q56: = | R56: =ROUND(AB57/1000,2)&"kA" -> 14,64kA
G57: 2 | AB57: =AB53*(SQRT(3)/2) -> 14644.229
B60: Ikmax1f = | D60: Ikmax3f | I60: ⇒ | J60: =ROUND(AB53,2) -> 16909.7 | Q60: = | R60: =ROUND(AB53/1000,2)&"kA" -> 16,91kA
AF62: fra | AG62: til | AH62: maks | AI62: min
AC63: 35000 | AF63: 100 | AG63: 400 | AH63: 1 | AI63: 0.95 | AJ63: =IF(AC63<AG63,AH63,IF(AND(AC63>=AF64,AC63<AG64),AH64,IF(AND(AC63>=AF65,AC63<AG65),AH65,IF(AC63>=AF66,AH66,)))) -> 1.1 | AK63: =IF(AC63<AG63,AI63,IF(AND(AC63>=AF64,AC63<AG64),AI64,IF(AND(AC63>=AF65,AC63<AG65),AI65,IF(AC63>=AF66,AI66,)))) -> 1
AF64: 400 | AG64: 1000 | AH64: 1.05 | AI64: 1
...

Sheet Kabeludskrift
A2: Impedansværdier beregning af Ikmax og spændingsfald | P2: ( Z ∠ ° ) | U2: ( R + Xi )
AA3: R | AB3: X | AC3: Z | AD3: Z̅̅ | AE3: polar | AG3: Længde | AH3: parallelle
A5: Z̅ | D5: = | E5: L · (R+jX) | H5: ⇒ | I5: =IF(B6="","",AG5&" · ("&AA5&"+j"&AB5&")") -> 75 · (0,0787+j0,077) | O5: = | P5: =IF(B6="","","("&AE6&"°) Ω") -> (0,002753 ∠44,37°) Ω | U5: =IF(B6="","","("&AD6&") Ω") -> (0,0019675+0,001925i) Ω | AA5: =Kabeldata!B14 -> 0.0787 | AB5: =Kabeldata!B15 -> 0.077 | AC5: =SQRT(AA5^2+AB5^2) -> 0.11010309 | AD5: =COMPLEX(AA5,AB5,) -> 0,0787+0,077i | AE5: =ROUND(IMABS(COMPLEX(AA5,AB5,"j")),6)&" ∠"&ROUND(DEGREES(IMARGUMENT(COMPLEX(AA5,AB5,"j"))),2) -> 0,110103 ∠44,37 | AG5: =Kabeldata!B9 -> 75 | AH5: =Kabeldata!B10 -> 3
B6: =IF(Kabeldata!$B$4="","",Kabeldata!$B$4) -> W1 | E6: =1000&IF(AH5=1,""," · η") -> 1000 · η | I6: =IF(B6="","",1000&IF(AH5=1,""," · "&AH5)) -> 1000 · 3 | AA6: =(AG5*AA5)/AH6 -> 0.0019675 | AB6: =(AG5*AB5)/AH6 -> 0.001925 | AC6: =SQRT(AA6^2+AB6^2) -> 0.0027525772 | AD6: =COMPLEX(AA6,AB6,) -> 0,0019675+0,001925i | AE6: =ROUND(IMABS(COMPLEX(AA6,AB6,"j")),6)&" ∠"&ROUND(DEGREES(IMARGUMENT(COMPLEX(AA6,AB6,"j"))),2) -> 0,002753 ∠44,37 | AH6: =1000*AH5 -> 3000
A7: ------------------------------------------------------------------------------------------------------------------------------------------------------------------------------------------------
A8: Z̅ | D8: = | E8: L · (R+jX) | H8: ⇒ | I8: =IF(B9="","",AG8&" · ("&AA8&"+j"&AB8&")") -> 20 · (0,641+j0,081) | O8: = | P8: =IF(B9="","","("&AE9&"°) Ω") -> (0,012922 ∠7,2°) Ω | U8: =IF(B9="","","("&AD9&") Ω") -> (0,01282+0,00162i) Ω | AA8: =Kabeldata!F14 -> 0.641 | AB8: =Kabeldata!F15 -> 0.081 | AC8: =SQRT(AA8^2+AB8^2) -> 0.64609752 | AD8: =COMPLEX(AA8,AB8,) -> 0,641+0,081i | AE8: =ROUND(IMABS(COMPLEX(AA8,AB8,"j")),6)&" ∠"&ROUND(DEGREES(IMARGUMENT(COMPLEX(AA8,AB8,"j"))),2) -> 0,646098 ∠7,2 | AG8: =Kabeldata!F9 -> 20 | AH8: =Kabeldata!F10 -> 1
B9: =IF(Kabeldata!$F$4="","",Kabeldata!$F$4) -> W2 | E9: =1000&IF(AH8=1,""," · η") -> 1000 | I9: =IF(B9="","",1000&IF(AH8=1,""," · "&AH8)) -> 1000 | AA9: =(AG8*AA8)/AH9 -> 0.01282 | AB9: =(AG8*AB8)/AH9 -> 0.00162 | AC9: =SQRT(AA9^2+AB9^2) -> 0.01292195 | AD9: =COMPLEX(AA9,AB9,) -> 0,01282+0,00162i | AE9: =ROUND(IMABS(COMPLEX(AA9,AB9,"j")),6)&" ∠"&ROUND(DEGREES(IMARGUMENT(COMPLEX(AA9,AB9,"j"))),2) -> 0,012922 ∠7,2 | AH9: =1000*AH8 -> 1000
A10: ------------------------------------------------------------------------------------------------------------------------------------------------------------------------------------------------
A11: Z̅ | D11: = | E11: L · (R+jX) | H11: ⇒ | I11: =IF(B12="","",AG11&" · ("&AA11&"+j"&AB11&")") -> 30 · (0,444+j0,08) | O11: = | P11: =IF(B12="","","("&AE12&"°) Ω") -> (0,013534 ∠10,21°) Ω | U11: =IF(B12="","","("&AD12&") Ω") -> (0,01332+0,0024i) Ω | AA11: =Kabeldata!J14 -> 0.444 | AB11: =Kabeldata!J15 -> 0.08 | AC11: =SQRT(AA11^2+AB11^2) -> 0.45114964 | AD11: =COMPLEX(AA11,AB11,) -> 0,444+0,08i | AE11: =ROUND(IMABS(COMPLEX(AA11,AB11,"j")),6)&" ∠"&ROUND(DEGREES(IMARGUMENT(COMPLEX(AA11,AB11,"j"))),2) -> 0,45115 ∠10,21 | AG11: =Kabeldata!J9 -> 30 | AH11: =Kabeldata!J10 -> 1
B12: =IF(Kabeldata!$J$4="","",Kabeldata!$J$4) -> W3 | E12: =1000&IF(AH11=1,""," · η") -> 1000 | I12: =IF(B12="","",1000&IF(AH11=1,""," · "&AH11)) -> 1000 | AA12: =(AG11*AA11)/AH12 -> 0.01332 | AB12: =(AG11*AB11)/AH12 -> 0.0024 | AC12: =SQRT(AA12^2+AB12^2) -> 0.013534489 | AD12: =COMPLEX(AA12,AB12,) -> 0,01332+0,0024i | AE12: =ROUND(IMABS(COMPLEX(AA12,AB12,"j")),6)&" ∠"&ROUND(DEGREES(IMARGUMENT(COMPLEX(AA12,AB12,"j"))),2) -> 0,013534 ∠10,21 | AH12: =1000*AH11 -> 1000
A13: ------------------------------------------------------------------------------------------------------------------------------------------------------------------------------------------------
A14: Z̅ | D14: = | E14: L · (R+jX) | H14: ⇒ | I14: =IF(B15="","",AG14&" · ("&AA14&"+j"&AB14&")") -> 8 · (1,2+j0,087) | O14: = | P14: =IF(B15="","","("&AE15&"°) Ω") -> (0,009625 ∠4,15°) Ω | U14: =IF(B15="","","("&AD15&") Ω") -> (0,0096+0,000696i) Ω | AA14: =Kabeldata!N14 -> 1.2 | AB14: =Kabeldata!N15 -> 0.087 | AC14: =SQRT(AA14^2+AB14^2) -> 1.2031496 | AD14: =COMPLEX(AA14,AB14,) -> 1,2+0,087i | AE14: =ROUND(IMABS(COMPLEX(AA14,AB14,"j")),6)&" ∠"&ROUND(DEGREES(IMARGUMENT(COMPLEX(AA14,AB14,"j"))),2) -> 1,20315 ∠4,15 | AG14: =Kabeldata!N9 -> 8 | AH14: =Kabeldata!N10 -> 1
B15: =IF(Kabeldata!$N$4="","",Kabeldata!$N$4) -> W4 | E15: =1000&IF(AH14=1,""," · η") -> 1000 | I15: =IF(B15="","",1000&IF(AH14=1,""," · "&AH14)) -> 1000 | AA15: =(AG14*AA14)/AH15 -> 0.0096 | AB15: =(AG14*AB14)/AH15 -> 0.000696 | AC15: =SQRT(AA15^2+AB15^2) -> 0.0096251969 | AD15: =COMPLEX(AA15,AB15,) -> 0,0096+0,000696i | AE15: =ROUND(IMABS(COMPLEX(AA15,AB15,"j")),6)&" ∠"&ROUND(DEGREES(IMARGUMENT(COMPLEX(AA15,AB15,"j"))),2) -> 0,009625 ∠4,15 | AH15: =1000*AH14 -> 1000
A16: ------------------------------------------------------------------------------------------------------------------------------------------------------------------------------------------------
A17: Z̅ | D17: = | E17: L · (R+jX) | H17: ⇒ | I17: =IF(B18="","",AG17&" · ("&AA17&"+j"&AB17&")") | O17: = | P17: =IF(B18="","","("&AE18&"°) Ω") | U17: =IF(B18="","","("&AD18&") Ω") | AA17: =Kabeldata!R14 -> 0.727 | AB17: =Kabeldata!R15 -> 0.079 | AC17: =SQRT(AA17^2+AB17^2) -> 0.7312797 | AD17: =COMPLEX(AA17,AB17,) -> 0,727+0,079i | AE17: =ROUND(IMABS(COMPLEX(AA17,AB17,"j")),6)&" ∠"&ROUND(DEGREES(IMARGUMENT(COMPLEX(AA17,AB17,"j"))),2) -> 0,73128 ∠6,2 | AG17: =Kabeldata!R9 -> 100 | AH17: =Kabeldata!R10 -> 1
B18: =IF(Kabeldata!$R$4="","",Kabeldata!$R$4) | E18: =1000&IF(AH17=1,""," · η") -> 1000 | I18: =IF(B18="","",1000&IF(AH17=1,""," · "&AH17)) | AA18: =(AG17*AA17)/AH18 -> 0.0727 | AB18: =(AG17*AB17)/AH18 -> 0.0079 | AC18: =SQRT(AA18^2+AB18^2) -> 0.07312797 | AD18: =COMPLEX(AA18,AB18,) -> 0,0727+0,0079i | AE18: =ROUND(IMABS(COMPLEX(AA18,AB18,"j")),6)&" ∠"&ROUND(DEGREES(IMARGUMENT(COMPLEX(AA18,AB18,"j"))),2) -> 0,073128 ∠6,2 | AH18: =1000*AH17 -> 1000
A19: ------------------------------------------------------------------------------------------------------------------------------------------------------------------------------------------------
A20: Z̅ | D20: = | E20: L · (R+jX) | H20: ⇒ | I20: =IF(B21="","",AG20&" · ("&AA20&"+j"&AB20&")") | O20: = | P20: =IF(B21="","","("&AE21&"°) Ω") | U20: =IF(B21="","","("&AD21&") Ω") | AA20: =Kabeldata!B32 -> 7.41 | AB20: =Kabeldata!B33 -> 0.095 | AC20: =SQRT(AA20^2+AB20^2) -> 7.4106089 | AD20: =COMPLEX(AA20,AB20,) -> 7,41+0,095i | AE20: =ROUND(IMABS(COMPLEX(AA20,AB20,"j")),6)&" ∠"&ROUND(DEGREES(IMARGUMENT(COMPLEX(AA20,AB20,"j"))),2) -> 7,410609 ∠0,73 | AG20: =Kabeldata!B27 -> 10.7 | AH20: =Kabeldata!B28 -> 1
B21: =IF(Kabeldata!$B$22="","",Kabeldata!$B$22) | E21: =1000&IF(AH20=1,""," · η") -> 1000 | I21: =IF(B21="","",1000&IF(AH20=1,""," · "&AH20)) | AA21: =(AG20*AA20)/AH21 -> 0.079287 | AB21: =(AG20*AB20)/AH21 -> 0.0010165 | AC21: =SQRT(AA21^2+AB21^2) -> 0.079293516 | AD21: =COMPLEX(AA21,AB21,) -> 0,079287+0,0010165i | AE21: =ROUND(IMABS(COMPLEX(AA21,AB21,"j")),6)&" ∠"&ROUND(DEGREES(IMARGUMENT(COMPLEX(AA21,AB21,"j"))),2) -> 0,079294 ∠0,73 | AH21: =1000*AH20 -> 1000
A22: ------------------------------------------------------------------------------------------------------------------------------------------------------------------------------------------------
A23: Z̅ | D23: = | E23: L · (R+jX) | H23: ⇒ | I23: =IF(B24="","",AG23&" · ("&AA23&"+j"&AB23&")") | O23: = | P23: =IF(B24="","","("&AE24&"°) Ω") | U23: =IF(B24="","","("&AD24&") Ω") | AA23: =Kabeldata!F32 -> 1.15 | AB23: =Kabeldata!F33 -> 0.085 | AC23: =SQRT(AA23^2+AB23^2) -> 1.153137 | AD23: =COMPLEX(AA23,AB23,) -> 1,15+0,085i | AE23: =ROUND(IMABS(COMPLEX(AA23,AB23,"j")),6)&" ∠"&ROUND(DEGREES(IMARGUMENT(COMPLEX(AA23,AB23,"j"))),2) -> 1,153137 ∠4,23 | AG23: =Kabeldata!F27 -> 2 | AH23: =Kabeldata!F28 -> 1
B24: =IF(Kabeldata!$F$22="","",Kabeldata!$F$22) | E24: =1000&IF(AH23=1,""," · η") -> 1000 | I24: =IF(B24="","",1000&IF(AH23=1,""," · "&AH23)) | AA24: =(AG23*AA23)/AH24 -> 0.0023 | AB24: =(AG23*AB23)/AH24 -> 0.00017 | AC24: =SQRT(AA24^2+AB24^2) -> 0.0023062741 | AD24: =COMPLEX(AA24,AB24,) -> 0,0023+0,00017i | AE24: =ROUND(IMABS(COMPLEX(AA24,AB24,"j")),6)&" ∠"&ROUND(DEGREES(IMARGUMENT(COMPLEX(AA24,AB24,"j"))),2) -> 0,002306 ∠4,23 | AH24: =1000*AH23 -> 1000
A25: ------------------------------------------------------------------------------------------------------------------------------------------------------------------------------------------------
A26: Z̅ | D26: = | E26: L · (R+jX) | H26: ⇒ | I26: =IF(B27="","",AG26&" · ("&AA26&"+j"&AB26&")") | O26: = | P26: =IF(B27="","","("&AE27&"°) Ω") | U26: =IF(B27="","","("&AD27&") Ω") | AA26: =Kabeldata!J32 -> 7.41 | AB26: =Kabeldata!J33 -> 0.095 | AC26: =SQRT(AA26^2+AB26^2) -> 7.4106089 | AD26: =COMPLEX(AA26,AB26,) -> 7,41+0,095i | AE26: =ROUND(IMABS(COMPLEX(AA26,AB26,"j")),6)&" ∠"&ROUND(DEGREES(IMARGUMENT(COMPLEX(AA26,AB26,"j"))),2) -> 7,410609 ∠0,73 | AG26: =Kabeldata!J27 -> 38.35 | AH26: =Kabeldata!J28 -> 1
B27: =IF(Kabeldata!$J$22="","",Kabeldata!$J$22) | E27: =1000&IF(AH26=1,""," · η") -> 1000 | I27: =IF(B27="","",1000&IF(AH26=1,""," · "&AH26)) | AA27: =(AG26*AA26)/AH27 -> 0.2841735 | AB27: =(AG26*AB26)/AH27 -> 0.00364325 | AC27: =SQRT(AA27^2+AB27^2) -> 0.28419685 | AD27: =COMPLEX(AA27,AB27,) -> 0,2841735+0,00364325i | AE27: =ROUND(IMABS(COMPLEX(AA27,AB27,"j")),6)&" ∠"&ROUND(DEGREES(IMARGUMENT(COMPLEX(AA27,AB27,"j"))),2) -> 0,284197 ∠0,73 | AH27: =1000*AH26 -> 1000
A28: ------------------------------------------------------------------------------------------------------------------------------------------------------------------------------------------------
A29: Z̅ | D29: = | E29: L · (R+jX) | H29: ⇒ | I29: =IF(B30="","",AG29&" · ("&AA29&"+j"&AB29&")") | O29: = | P29: =IF(B30="","","("&AE30&"°) Ω") | U29: =IF(B30="","","("&AD30&") Ω") | AA29: =Kabeldata!N32 -> 0 | AB29: =Kabeldata!N33 -> 0 | AC29: =SQRT(AA29^2+AB29^2) -> 0 | AD29: =COMPLEX(AA29,AB29,) -> 0 | AE29: =ROUND(IMABS(COMPLEX(AA29,AB29,"j")),6)&" ∠"&ROUND(DEGREES(IMARGUMENT(COMPLEX(AA29,AB29,"j"))),2) -> #DIV/0! | AG29: =Kabeldata!N27 -> 0 | AH29: =Kabeldata!N28 -> 1
B30: =IF(Kabeldata!$N$22="","",Kabeldata!$N$22) | E30: =1000&IF(AH29=1,""," · η") -> 1000 | I30: =IF(B30="","",1000&IF(AH29=1,""," · "&AH29)) | AA30: =(AG29*AA29)/AH30 -> 0 | AB30: =(AG29*AB29)/AH30 -> 0 | AC30: =SQRT(AA30^2+AB30^2) -> 0 | AD30: =COMPLEX(AA30,AB30,) -> 0 | AE30: =ROUND(IMABS(COMPLEX(AA30,AB30,"j")),6)&" ∠"&ROUND(DEGREES(IMARGUMENT(COMPLEX(AA30,AB30,"j"))),2) -> #DIV/0! | AH30: =1000*AH29 -> 1000
A31: ------------------------------------------------------------------------------------------------------------------------------------------------------------------------------------------------
A32: Z̅ | D32: = | E32: L · (R+jX) | H32: ⇒ | I32: =IF(B33="","",AG32&" · ("&AA32&"+j"&AB32&")") | O32: = | P32: =IF(B33="","","("&AE33&"°) Ω") | U32: =IF(B33="","","("&AD33&") Ω") | AA32: =Kabeldata!R32 -> 0 | AB32: =Kabeldata!R33 -> 0 | AC32: =SQRT(AA32^2+AB32^2) -> 0 | AD32: =COMPLEX(AA32,AB32,) -> 0 | AE32: =ROUND(IMABS(COMPLEX(AA32,AB32,"j")),6)&" ∠"&ROUND(DEGREES(IMARGUMENT(COMPLEX(AA32,AB32,"j"))),2) -> #DIV/0! | AG32: =Kabeldata!R27 -> 0 | AH32: =Kabeldata!R28 -> 0
B33: =IF(Kabeldata!$R$22="","",Kabeldata!$R$22) | E33: =1000&IF(AH32=1,""," · η") -> 1000 · η | I33: =IF(B33="","",1000&IF(AH32=1,""," · "&AH32)) | AA33: =(AG32*AA32)/AH33 -> #DIV/0! | AB33: =(AG32*AB32)/AH33 -> #DIV/0! | AC33: =SQRT(AA33^2+AB33^2) -> #DIV/0! | AD33: =COMPLEX(AA33,AB33,) -> #DIV/0! | AE33: =ROUND(IMABS(COMPLEX(AA33,AB33,"j")),6)&" ∠"&ROUND(DEGREES(IMARGUMENT(COMPLEX(AA33,AB33,"j"))),2) -> #DIV/0! | AH33: =1000*AH32 -> 0
A37: Impedansværdier beregning af Ikmin | P37: ( Z ∠ ° ) | U37: ( R + Xi )
AA38: R | AB38: X | AC38: Z | AD38: Z̅̅ | AE38: polar | AG38: Længde | AH38: parallelle | AI38: Separat PE leder
A40: Z̅ | D40: = | E40: ="L · ("&IF(AI40="Ja",1.25,1.5)&" · R+jX)" -> L · (1,5 · R+jX) | H40: ⇒ | I40: =IF(B41="","",AG40&" · ("&(IF(AI40="Ja",1.25,1.5)&" · "&AA40&"+j"&AB40&")")) -> 75 · (1,5 · 0,0787+j0,077) | O40: = | P40: =IF(B41="","","("&AE41&"°) Ω") -> (0,003524 ∠33,12°) Ω | U40: =IF(B41="","","("&AD41&") Ω") -> (0,00295125+0,001925i) Ω | AA40: =AA5 -> 0.0787 | AB40: =AB5 -> 0.077 | AC40: =SQRT(AA40^2+AB40^2) -> 0.11010309 | AD40: =COMPLEX(AA40,AB40,) -> 0,0787+0,077i | AE40: =ROUND(IMABS(COMPLEX(AA40,AB40,"j")),6)&" ∠"&ROUND(DEGREES(IMARGUMENT(COMPLEX(AA40,AB40,"j"))),2) -> 0,110103 ∠44,37 | AG40: =Kabeldata!B9 -> 75 | AH40: =Kabeldata!B10 -> 3 | AI40: =Kabeldata!B3 -> Nej
B41: =IF(Kabeldata!$B$4="","",Kabeldata!$B$4) -> W1 | C41: =IF(Kabeldata!$B$4="","",Kabeldata!$B$4) -> W1 | E41: =1000&IF(AH40=1,""," · η") -> 1000 · η | I41: =IF(B41="","",1000&IF(AH40=1,""," · "&AH40)) -> 1000 · 3 | AA41: =(AG40*(IF(AI40="Ja",1.25,1.5)*AA40))/AH41 -> 0.00295125 | AB41: =(AG40*AB40)/AH41 -> 0.001925 | AC41: =SQRT(AA41^2+AB41^2) -> 0.0035235638 | AD41: =COMPLEX(AA41,AB41,) -> 0,00295125+0,001925i | AE41: =ROUND(IMABS(COMPLEX(AA41,AB41,"j")),6)&" ∠"&ROUND(DEGREES(IMARGUMENT(COMPLEX(AA41,AB41,"j"))),2) -> 0,003524 ∠33,12 | AH41: =1000*AH40 -> 3000
A42: ------------------------------------------------------------------------------------------------------------------------------------------------------------------------------------------------
A43: Z̅ | D43: = | E43: ="L · ("&IF(AI43="Ja",1.25,1.5)&" · R+jX)" -> L · (1,5 · R+jX) | H43: ⇒ | I43: =IF(B44="","",AG43&" · ("&(IF(AI43="Ja",1.25,1.5)&" · "&AA43&"+j"&AB43&")")) -> 20 · (1,5 · 0,641+j0,081) | O43: = | P43: =IF(B44="","","("&AE44&"°) Ω") -> (0,019298 ∠4,82°) Ω | U43: =IF(B44="","","("&AD44&") Ω") -> (0,01923+0,00162i) Ω | AA43: =AA8 -> 0.641 | AB43: =AB8 -> 0.081 | AC43: =SQRT(AA43^2+AB43^2) -> 0.64609752 | AD43: =COMPLEX(AA43,AB43,) -> 0,641+0,081i | AE43: =ROUND(IMABS(COMPLEX(AA43,AB43,"j")),6)&" ∠"&ROUND(DEGREES(IMARGUMENT(COMPLEX(AA43,AB43,"j"))),2) -> 0,646098 ∠7,2 | AG43: =Kabeldata!F9 -> 20 | AH43: =Kabeldata!F10 -> 1 | AI43: =Kabeldata!F3 -> Nej
B44: =IF(Kabeldata!$F$4="","",Kabeldata!$F$4) -> W2 | E44: =1000&IF(AH43=1,""," · η") -> 1000 | I44: =IF(B44="","",1000&IF(AH43=1,""," · "&AH43)) -> 1000 | AA44: =(AG43*(IF(AI43="Ja",1.25,1.5)*AA43))/AH44 -> 0.01923 | AB44: =(AG43*AB43)/AH44 -> 0.00162 | AC44: =SQRT(AA44^2+AB44^2) -> 0.019298116 | AD44: =COMPLEX(AA44,AB44,) -> 0,01923+0,00162i | AE44: =ROUND(IMABS(COMPLEX(AA44,AB44,"j")),6)&" ∠"&ROUND(DEGREES(IMARGUMENT(COMPLEX(AA44,AB44,"j"))),2) -> 0,019298 ∠4,82 | AH44: =1000*AH43 -> 1000
A45: ------------------------------------------------------------------------------------------------------------------------------------------------------------------------------------------------
A46: Z̅ | D46: = | E46: ="L · ("&IF(AI46="Ja",1.25,1.5)&" · R+jX)" -> L · (1,25 · R+jX) | H46: ⇒ | I46: =IF(B47="","",AG46&" · ("&(IF(AI46="Ja",1.25,1.5)&" · "&AA46&"+j"&AB46&")")) -> 30 · (1,25 · 0,444+j0,08) | O46: = | P46: =IF(B47="","","("&AE47&"°) Ω") -> (0,016822 ∠8,2°) Ω | U46: =IF(B47="","","("&AD47&") Ω") -> (0,01665+0,0024i) Ω | AA46: =AA11 -> 0.444 | AB46: =AB11 -> 0.08 | AC46: =SQRT(AA46^2+AB46^2) -> 0.45114964 | AD46: =COMPLEX(AA46,AB46,) -> 0,444+0,08i | AE46: =ROUND(IMABS(COMPLEX(AA46,AB46,"j")),6)&" ∠"&ROUND(DEGREES(IMARGUMENT(COMPLEX(AA46,AB46,"j"))),2) -> 0,45115 ∠10,21 | AG46: =Kabeldata!J9 -> 30 | AH46: =Kabeldata!J10 -> 1 | AI46: =Kabeldata!J3 -> Ja
...

Sheet Kabeldata
A2: Kabel 1 | E2: Kabel 2 | I2: Kabel 3 | M2: Kabel 4 | Q2: Kabel 5
A3: Separat PE leder | B3: Nej | F3: Nej | J3: Ja | N3: Nej | R3: Nej
A4: Navn | B4: W1 | F4: W2 | J4: W3 | N4: W4
A5: Kabeltype | B5: NOIK | F5: NOIK | J5: NOIK | N5: NOIKLX | R5: NOIKLX | AB5: NOIK | AF5: NOIKLX | AJ5: Gummi - og plast | AN5: NOIKLX reduceret PE | AR5: Armeret kabler
A6: Materiale | B6: CU | F6: AL | J6: AL | N6: AL | R6: CU | AB6: NOIK, PVIK, NOIKL, NOIBH-CU-S | AF6: NOIKLX, PVIKX, NOIKX, NOIKX FLEX | AJ6: NOPKA, H05VV-F, H05RR-F, H05RN-F, H07RN-F | AN6: NOIKLX, PVIKX, NOIKX, NOIKX FLEX | AR6: NOAKLX, NOAKX, PAPLX | AZ6: 1 | BA6: CU | BB6: 1x | BC6: NOIK
A7: Antal ledere | B7: 4x | F7: 4x | J7: 4x | N7: 5x | R7: 1x | AZ7: 2 | BA7: AL | BB7: 2x | BC7: NOIKLX
A8: Kvadrat (mm²) | B8: 240 | F8: 50 | J8: 70 | N8: 25 | R8: 25 | AB8: Kobber | AF8: Kobber | AJ8: Kobber | AN8: Kobber | AR8: Kobber | AZ8: 3 | BB8: 3x | BC8: Gummi- og plast
A9: Længde (m) | B9: 75 | E9: m | F9: 20 | I9: m | J9: 30 | M9: m | N9: 8 | Q9: m | R9: 100 | AB9: 1x | AC9: R | AD9: X | AF9: 1x | AG9: R | AH9: X | AJ9: 1x | AK9: R | AL9: X | AN9: 1x | AO9: R | AP9: X | AR9: 1x | AS9: R | AT9: X | AZ9: 4 | BB9: 4x | BC9: NOIKLX reduceret PE
A10: Paralle (n) | B10: 3 | E10: n | F10: 1 | I10: n | J10: 1 | M10: n | N10: 1 | Q10: n | R10: 1 | AB10: 0.75 | AF10: 0.75 | AJ10: 0.75 | AK10: 26 | AL10: 0.111 | AN10: 0.75 | AR10: 0.75 | AZ10: 5 | BB10: 5x | BC10: Armeret
A11: I̅ B | B11: 483.15 | C11: Ð- | D11: 9.79 | F11: 143.1 | G11: Ð- | H11: 25.19 | J11: 215.81 | K11: Ð- | L11: 16.42 | N11: 80 | O11: Ð- | P11: 11.48 | R11: 10 | S11: Ð- | T11: 0 | AB11: 1 | AF11: 1 | AJ11: 1 | AK11: 19.5 | AL11: 0.105 | AN11: 1 | AR11: 1 | AZ11: 6
A12: Z20° | B12: =SQRT(B14^2+B15^2) -> 0.11010309 | E12: Z20° | F12: =SQRT(F14^2+F15^2) -> 0.64609752 | I12: Z20° | J12: =SQRT(J14^2+J15^2) -> 0.45114964 | M12: Z20° | N12: =SQRT(N14^2+N15^2) -> 1.2031496 | Q12: Z20° | R12: =SQRT(R14^2+R15^2) -> 0.7312797 | AB12: 1.5 | AC12: 12.1 | AD12: 0.108 | AF12: 1.5 | AG12: 12.1 | AH12: 0.103 | AJ12: 1.5 | AK12: 13.3 | AL12: 0.107 | AN12: 1.5 | AR12: 1.5 | AZ12: 7
A13: Ð 20° | B13: =DEGREES(IMARGUMENT(COMPLEX(B14,B15,"j"))) -> 44.374445 | E13: Ð 20° | F13: =DEGREES(IMARGUMENT(COMPLEX(F14,F15,"j"))) -> 7.202012 | I13: Ð 20° | J13: =DEGREES(IMARGUMENT(COMPLEX(J14,J15,"j"))) -> 10.213973 | M13: Ð 20° | N13: =DEGREES(IMARGUMENT(COMPLEX(N14,N15,"j"))) -> 4.1466888 | Q13: Ð 20° | R13: =DEGREES(IMARGUMENT(COMPLEX(R14,R15,"j"))) -> 6.2017546 | AB13: 2.5 | AC13: 7.41 | AD13: 0.099 | AF13: 2.5 | AG13: 7.41 | AH13: 0.095 | AJ13: 2.5 | AK13: 7.98 | AL13: 0.103 | AN13: 2.5 | AR13: 2.5 | AZ13: 8
A14: R | B14: =IF(AND(B6="CU",B5=$AB$5,B7="1x"),VLOOKUP(B8,$AB$10:$AD$27,2,FALSE),IF(AND(B6="CU",B5=$AB$5,B7="2x"),VLOOKUP(B8,$AB$29:$AD$46,2,FALSE),IF(AND(B6="CU",B5=$AB$5,B7="3x"),VLOOKUP(B8,$AB$48:$AD$65,2,FALSE),IF(AND(B6="CU",B5=$AB$5,B7="4x"),VLOOKUP(B8,$AB$67:$AD$84,2,FALSE),IF(AND(B6="CU",B5=$AB$5,B7="5x"),VLOOKUP(B8,$AB$86:$AD$103,2,FALSE),IF(AND(B6="CU",B5=$AF$5,B7="1x"),VLOOKUP(B8,$AF$10:$AH$27,2,FALSE),IF(AND(B6="CU",B5=$AF$5,B7="2x"),VLOOKUP(B8,$AF$29:$AH$46,2,FALSE),IF(AND(B6="CU",B5=$AF$5,B7="3x"),VLOOKUP(B8,$AF$48:$AH$65,2,FALSE),IF(AND(B6="CU",B5=$AF$5,B7="4x"),VLOOKUP(B8,$AF$67:$AH$84,2,FALSE),IF(AND(B6="CU",B5=$AF$5,B7="5x"),VLOOKUP(B8,$AF$86:$AH$103,2,FALSE),IF(AND(B6="CU",B5=$AJ$5,B7="1x"),VLOOKUP(B8,$AJ$10:$AL$27,2,FALSE),IF(AND(B6="CU",B5=$AJ$5,B7="2x"),VLOOKUP(B8,$AJ$29:$AL$46,2,FALSE),IF(AND(B6="CU",B5=$AJ$5,B7="3x"),VLOOKUP(B8,$AJ$48:$AL$65,2,FALSE),IF(AND(B6="CU",B5=$AJ$5,B7="4x"),VLOOKUP(B8,$AJ$67:$AL$84,2,FALSE),IF(AND(B6="CU",B5=$AJ$5,B7="5x"),VLOOKUP(B8,$AJ$86:$AL$103,2,FALSE),IF(AND(B6="CU",B5=$AN$5,B7="1x"),VLOOKUP(B8,$AN$10:$AP$27,2,FALSE),IF(AND(B6="CU",B5=$AN$5,B7="2x"),VLOOKUP(B8,$AN$29:$AP$46,2,FALSE),IF(AND(B6="CU",B5=$AN$5,B7="3x"),VLOOKUP(B8,$AN$48:$AP$65,2,FALSE),IF(AND(B6="CU",B5=$AN$5,B7="4x"),VLOOKUP(B8,$AN$67:$AP$84,2,FALSE),IF(AND(B6="CU",B5=$AN$5,B7="5x"),VLOOKUP(B8,$AN$86:$AP$103,2,FALSE),IF(AND(B6="CU",B5=$AR$5,B7="1x"),VLOOKUP(B8,$AR$10:$AT$27,2,FALSE),IF(AND(B6="CU",B5=$AR$5,B7="2x"),VLOOKUP(B8,$AR$29:$AT$46,2,FALSE),IF(AND(B6="CU",B5=$AR$5,B7="3x"),VLOOKUP(B8,$AR$48:$AT$65,2,FALSE),IF(AND(B6="CU",B5=$AR$5,B7="4x"),VLOOKUP(B8,$AR$67:$AT$84,2,FALSE),IF(AND(B6="CU",B5=$AR$5,B7="5x"),VLOOKUP(B8,$AR$86:$AT$103,2,FALSE),IF(AND(B6="AL",B5=$AB$5,B7="4x"),VLOOKUP(B8,$AB$113:$AD$123,2,FALSE),IF(AND(B6="AL",B5=$AB$5,B7="5x"),VLOOKUP(B8,$AB$125:$AD$135,2,FALSE),IF(AND(B6="AL",B5=$AF$5,B7="4x"),VLOOKUP(B8,$AF$113:$AH$123,2,FALSE),IF(AND(B6="AL",B5=$AF$5,B7="5x"),VLOOKUP(B8,$AF$125:$AH$135,2,FALSE),IF(AND(B6="AL",B5=$AJ$5,B7="4x"),VLOOKUP(B8,$AJ$113:$AL$123,2,FALSE),IF(AND(B6="AL",B5=$AJ$5,B7="5x"),VLOOKUP(B8,$AJ$125:$AL$135,2,FALSE),IF(AND(B6="AL",B5=$AN$5,B7="4x"),VLOOKUP(B8,$AN$113:$AP$123,2,FALSE),IF(AND(B6="AL",B5=$AN$5,B7="5x"),VLOOKUP(B8,$AN$125:$AP$135,2,FALSE),IF(AND(B6="AL",B5=$AR$5,B7="4x"),VLOOKUP(B8,$AR$113:$AT$123,2,FALSE),IF(AND(B6="AL",B5=$AR$5,B7="5x"),VLOOKUP(B8,$AR$125:$AT$135,2,FALSE)))))))))))))))))))))))))))))))))))) -> 0.0787 | E14: R | F14: =IF(AND(F6="CU",F5=$AB$5,F7="1x"),VLOOKUP(F8,$AB$10:$AD$27,2,FALSE),IF(AND(F6="CU",F5=$AB$5,F7="2x"),VLOOKUP(F8,$AB$29:$AD$46,2,FALSE),IF(AND(F6="CU",F5=$AB$5,F7="3x"),VLOOKUP(F8,$AB$48:$AD$65,2,FALSE),IF(AND(F6="CU",F5=$AB$5,F7="4x"),VLOOKUP(F8,$AB$67:$AD$84,2,FALSE),IF(AND(F6="CU",F5=$AB$5,F7="5x"),VLOOKUP(F8,$AB$86:$AD$103,2,FALSE),IF(AND(F6="CU",F5=$AF$5,F7="1x"),VLOOKUP(F8,$AF$10:$AH$27,2,FALSE),IF(AND(F6="CU",F5=$AF$5,F7="2x"),VLOOKUP(F8,$AF$29:$AH$46,2,FALSE),IF(AND(F6="CU",F5=$AF$5,F7="3x"),VLOOKUP(F8,$AF$48:$AH$65,2,FALSE),IF(AND(F6="CU",F5=$AF$5,F7="4x"),VLOOKUP(F8,$AF$67:$AH$84,2,FALSE),IF(AND(F6="CU",F5=$AF$5,F7="5x"),VLOOKUP(F8,$AF$86:$AH$103,2,FALSE),IF(AND(F6="CU",F5=$AJ$5,F7="1x"),VLOOKUP(F8,$AJ$10:$AL$27,2,FALSE),IF(AND(F6="CU",F5=$AJ$5,F7="2x"),VLOOKUP(F8,$AJ$29:$AL$46,2,FALSE),IF(AND(F6="CU",F5=$AJ$5,F7="3x"),VLOOKUP(F8,$AJ$48:$AL$65,2,FALSE),IF(AND(F6="CU",F5=$AJ$5,F7="4x"),VLOOKUP(F8,$AJ$67:$AL$84,2,FALSE),IF(AND(F6="CU",F5=$AJ$5,F7="5x"),VLOOKUP(F8,$AJ$86:$AL$103,2,FALSE),IF(AND(F6="CU",F5=$AN$5,F7="1x"),VLOOKUP(F8,$AN$10:$AP$27,2,FALSE),IF(AND(F6="CU",F5=$AN$5,F7="2x"),VLOOKUP(F8,$AN$29:$AP$46,2,FALSE),IF(AND(F6="CU",F5=$AN$5,F7="3x"),VLOOKUP(F8,$AN$48:$AP$65,2,FALSE),IF(AND(F6="CU",F5=$AN$5,F7="4x"),VLOOKUP(F8,$AN$67:$AP$84,2,FALSE),IF(AND(F6="CU",F5=$AN$5,F7="5x"),VLOOKUP(F8,$AN$86:$AP$103,2,FALSE),IF(AND(F6="CU",F5=$AR$5,F7="1x"),VLOOKUP(F8,$AR$10:$AT$27,2,FALSE),IF(AND(F6="CU",F5=$AR$5,F7="2x"),VLOOKUP(F8,$AR$29:$AT$46,2,FALSE),IF(AND(F6="CU",F5=$AR$5,F7="3x"),VLOOKUP(F8,$AR$48:$AT$65,2,FALSE),IF(AND(F6="CU",F5=$AR$5,F7="4x"),VLOOKUP(F8,$AR$67:$AT$84,2,FALSE),IF(AND(F6="CU",F5=$AR$5,F7="5x"),VLOOKUP(F8,$AR$86:$AT$103,2,FALSE),IF(AND(F6="AL",F5=$AB$5,F7="4x"),VLOOKUP(F8,$AB$113:$AD$123,2,FALSE),IF(AND(F6="AL",F5=$AB$5,F7="5x"),VLOOKUP(F8,$AB$125:$AD$135,2,FALSE),IF(AND(F6="AL",F5=$AF$5,F7="4x"),VLOOKUP(F8,$AF$113:$AH$123,2,FALSE),IF(AND(F6="AL",F5=$AF$5,F7="5x"),VLOOKUP(F8,$AF$125:$AH$135,2,FALSE),IF(AND(F6="AL",F5=$AJ$5,F7="4x"),VLOOKUP(F8,$AJ$113:$AL$123,2,FALSE),IF(AND(F6="AL",F5=$AJ$5,F7="5x"),VLOOKUP(F8,$AJ$125:$AL$135,2,FALSE),IF(AND(F6="AL",F5=$AN$5,F7="4x"),VLOOKUP(F8,$AN$113:$AP$123,2,FALSE),IF(AND(F6="AL",F5=$AN$5,F7="5x"),VLOOKUP(F8,$AN$125:$AP$135,2,FALSE),IF(AND(F6="AL",F5=$AR$5,F7="4x"),VLOOKUP(F8,$AR$113:$AT$123,2,FALSE),IF(AND(F6="AL",F5=$AR$5,F7="5x"),VLOOKUP(F8,$AR$125:$AT$135,2,FALSE)))))))))))))))))))))))))))))))))))) -> 0.641 | I14: R | J14: =IF(AND(J6="CU",J5=$AB$5,J7="1x"),VLOOKUP(J8,$AB$10:$AD$27,2,FALSE),IF(AND(J6="CU",J5=$AB$5,J7="2x"),VLOOKUP(J8,$AB$29:$AD$46,2,FALSE),IF(AND(J6="CU",J5=$AB$5,J7="3x"),VLOOKUP(J8,$AB$48:$AD$65,2,FALSE),IF(AND(J6="CU",J5=$AB$5,J7="4x"),VLOOKUP(J8,$AB$67:$AD$84,2,FALSE),IF(AND(J6="CU",J5=$AB$5,J7="5x"),VLOOKUP(J8,$AB$86:$AD$103,2,FALSE),IF(AND(J6="CU",J5=$AF$5,J7="1x"),VLOOKUP(J8,$AF$10:$AH$27,2,FALSE),IF(AND(J6="CU",J5=$AF$5,J7="2x"),VLOOKUP(J8,$AF$29:$AH$46,2,FALSE),IF(AND(J6="CU",J5=$AF$5,J7="3x"),VLOOKUP(J8,$AF$48:$AH$65,2,FALSE),IF(AND(J6="CU",J5=$AF$5,J7="4x"),VLOOKUP(J8,$AF$67:$AH$84,2,FALSE),IF(AND(J6="CU",J5=$AF$5,J7="5x"),VLOOKUP(J8,$AF$86:$AH$103,2,FALSE),IF(AND(J6="CU",J5=$AJ$5,J7="1x"),VLOOKUP(J8,$AJ$10:$AL$27,2,FALSE),IF(AND(J6="CU",J5=$AJ$5,J7="2x"),VLOOKUP(J8,$AJ$29:$AL$46,2,FALSE),IF(AND(J6="CU",J5=$AJ$5,J7="3x"),VLOOKUP(J8,$AJ$48:$AL$65,2,FALSE),IF(AND(J6="CU",J5=$AJ$5,J7="4x"),VLOOKUP(J8,$AJ$67:$AL$84,2,FALSE),IF(AND(J6="CU",J5=$AJ$5,J7="5x"),VLOOKUP(J8,$AJ$86:$AL$103,2,FALSE),IF(AND(J6="CU",J5=$AN$5,J7="1x"),VLOOKUP(J8,$AN$10:$AP$27,2,FALSE),IF(AND(J6="CU",J5=$AN$5,J7="2x"),VLOOKUP(J8,$AN$29:$AP$46,2,FALSE),IF(AND(J6="CU",J5=$AN$5,J7="3x"),VLOOKUP(J8,$AN$48:$AP$65,2,FALSE),IF(AND(J6="CU",J5=$AN$5,J7="4x"),VLOOKUP(J8,$AN$67:$AP$84,2,FALSE),IF(AND(J6="CU",J5=$AN$5,J7="5x"),VLOOKUP(J8,$AN$86:$AP$103,2,FALSE),IF(AND(J6="CU",J5=$AR$5,J7="1x"),VLOOKUP(J8,$AR$10:$AT$27,2,FALSE),IF(AND(J6="CU",J5=$AR$5,J7="2x"),VLOOKUP(J8,$AR$29:$AT$46,2,FALSE),IF(AND(J6="CU",J5=$AR$5,J7="3x"),VLOOKUP(J8,$AR$48:$AT$65,2,FALSE),IF(AND(J6="CU",J5=$AR$5,J7="4x"),VLOOKUP(J8,$AR$67:$AT$84,2,FALSE),IF(AND(J6="CU",J5=$AR$5,J7="5x"),VLOOKUP(J8,$AR$86:$AT$103,2,FALSE),IF(AND(J6="AL",J5=$AB$5,J7="4x"),VLOOKUP(J8,$AB$113:$AD$123,2,FALSE),IF(AND(J6="AL",J5=$AB$5,J7="5x"),VLOOKUP(J8,$AB$125:$AD$135,2,FALSE),IF(AND(J6="AL",J5=$AF$5,J7="4x"),VLOOKUP(J8,$AF$113:$AH$123,2,FALSE),IF(AND(J6="AL",J5=$AF$5,J7="5x"),VLOOKUP(J8,$AF$125:$AH$135,2,FALSE),IF(AND(J6="AL",J5=$AJ$5,J7="4x"),VLOOKUP(J8,$AJ$113:$AL$123,2,FALSE),IF(AND(J6="AL",J5=$AJ$5,J7="5x"),VLOOKUP(J8,$AJ$125:$AL$135,2,FALSE),IF(AND(J6="AL",J5=$AN$5,J7="4x"),VLOOKUP(J8,$AN$113:$AP$123,2,FALSE),IF(AND(J6="AL",J5=$AN$5,J7="5x"),VLOOKUP(J8,$AN$125:$AP$135,2,FALSE),IF(AND(J6="AL",J5=$AR$5,J7="4x"),VLOOKUP(J8,$AR$113:$AT$123,2,FALSE),IF(AND(J6="AL",J5=$AR$5,J7="5x"),VLOOKUP(J8,$AR$125:$AT$135,2,FALSE)))))))))))))))))))))))))))))))))))) -> 0.444 | M14: R | N14: =IF(AND(N6="CU",N5=$AB$5,N7="1x"),VLOOKUP(N8,$AB$10:$AD$27,2,FALSE),IF(AND(N6="CU",N5=$AB$5,N7="2x"),VLOOKUP(N8,$AB$29:$AD$46,2,FALSE),IF(AND(N6="CU",N5=$AB$5,N7="3x"),VLOOKUP(N8,$AB$48:$AD$65,2,FALSE),IF(AND(N6="CU",N5=$AB$5,N7="4x"),VLOOKUP(N8,$AB$67:$AD$84,2,FALSE),IF(AND(N6="CU",N5=$AB$5,N7="5x"),VLOOKUP(N8,$AB$86:$AD$103,2,FALSE),IF(AND(N6="CU",N5=$AF$5,N7="1x"),VLOOKUP(N8,$AF$10:$AH$27,2,FALSE),IF(AND(N6="CU",N5=$AF$5,N7="2x"),VLOOKUP(N8,$AF$29:$AH$46,2,FALSE),IF(AND(N6="CU",N5=$AF$5,N7="3x"),VLOOKUP(N8,$AF$48:$AH$65,2,FALSE),IF(AND(N6="CU",N5=$AF$5,N7="4x"),VLOOKUP(N8,$AF$67:$AH$84,2,FALSE),IF(AND(N6="CU",N5=$AF$5,N7="5x"),VLOOKUP(N8,$AF$86:$AH$103,2,FALSE),IF(AND(N6="CU",N5=$AJ$5,N7="1x"),VLOOKUP(N8,$AJ$10:$AL$27,2,FALSE),IF(AND(N6="CU",N5=$AJ$5,N7="2x"),VLOOKUP(N8,$AJ$29:$AL$46,2,FALSE),IF(AND(N6="CU",N5=$AJ$5,N7="3x"),VLOOKUP(N8,$AJ$48:$AL$65,2,FALSE),IF(AND(N6="CU",N5=$AJ$5,N7="4x"),VLOOKUP(N8,$AJ$67:$AL$84,2,FALSE),IF(AND(N6="CU",N5=$AJ$5,N7="5x"),VLOOKUP(N8,$AJ$86:$AL$103,2,FALSE),IF(AND(N6="CU",N5=$AN$5,N7="1x"),VLOOKUP(N8,$AN$10:$AP$27,2,FALSE),IF(AND(N6="CU",N5=$AN$5,N7="2x"),VLOOKUP(N8,$AN$29:$AP$46,2,FALSE),IF(AND(N6="CU",N5=$AN$5,N7="3x"),VLOOKUP(N8,$AN$48:$AP$65,2,FALSE),IF(AND(N6="CU",N5=$AN$5,N7="4x"),VLOOKUP(N8,$AN$67:$AP$84,2,FALSE),IF(AND(N6="CU",N5=$AN$5,N7="5x"),VLOOKUP(N8,$AN$86:$AP$103,2,FALSE),IF(AND(N6="CU",N5=$AR$5,N7="1x"),VLOOKUP(N8,$AR$10:$AT$27,2,FALSE),IF(AND(N6="CU",N5=$AR$5,N7="2x"),VLOOKUP(N8,$AR$29:$AT$46,2,FALSE),IF(AND(N6="CU",N5=$AR$5,N7="3x"),VLOOKUP(N8,$AR$48:$AT$65,2,FALSE),IF(AND(N6="CU",N5=$AR$5,N7="4x"),VLOOKUP(N8,$AR$67:$AT$84,2,FALSE),IF(AND(N6="CU",N5=$AR$5,N7="5x"),VLOOKUP(N8,$AR$86:$AT$103,2,FALSE),IF(AND(N6="AL",N5=$AB$5,N7="4x"),VLOOKUP(N8,$AB$113:$AD$123,2,FALSE),IF(AND(N6="AL",N5=$AB$5,N7="5x"),VLOOKUP(N8,$AB$125:$AD$135,2,FALSE),IF(AND(N6="AL",N5=$AF$5,N7="4x"),VLOOKUP(N8,$AF$113:$AH$123,2,FALSE),IF(AND(N6="AL",N5=$AF$5,N7="5x"),VLOOKUP(N8,$AF$125:$AH$135,2,FALSE),IF(AND(N6="AL",N5=$AJ$5,N7="4x"),VLOOKUP(N8,$AJ$113:$AL$123,2,FALSE),IF(AND(N6="AL",N5=$AJ$5,N7="5x"),VLOOKUP(N8,$AJ$125:$AL$135,2,FALSE),IF(AND(N6="AL",N5=$AN$5,N7="4x"),VLOOKUP(N8,$AN$113:$AP$123,2,FALSE),IF(AND(N6="AL",N5=$AN$5,N7="5x"),VLOOKUP(N8,$AN$125:$AP$135,2,FALSE),IF(AND(N6="AL",N5=$AR$5,N7="4x"),VLOOKUP(N8,$AR$113:$AT$123,2,FALSE),IF(AND(N6="AL",N5=$AR$5,N7="5x"),VLOOKUP(N8,$AR$125:$AT$135,2,FALSE)))))))))))))))))))))))))))))))))))) -> 1.2 | Q14: R | R14: =IF(AND(R6="CU",R5=$AB$5,R7="1x"),VLOOKUP(R8,$AB$10:$AD$27,2,FALSE),IF(AND(R6="CU",R5=$AB$5,R7="2x"),VLOOKUP(R8,$AB$29:$AD$46,2,FALSE),IF(AND(R6="CU",R5=$AB$5,R7="3x"),VLOOKUP(R8,$AB$48:$AD$65,2,FALSE),IF(AND(R6="CU",R5=$AB$5,R7="4x"),VLOOKUP(R8,$AB$67:$AD$84,2,FALSE),IF(AND(R6="CU",R5=$AB$5,R7="5x"),VLOOKUP(R8,$AB$86:$AD$103,2,FALSE),IF(AND(R6="CU",R5=$AF$5,R7="1x"),VLOOKUP(R8,$AF$10:$AH$27,2,FALSE),IF(AND(R6="CU",R5=$AF$5,R7="2x"),VLOOKUP(R8,$AF$29:$AH$46,2,FALSE),IF(AND(R6="CU",R5=$AF$5,R7="3x"),VLOOKUP(R8,$AF$48:$AH$65,2,FALSE),IF(AND(R6="CU",R5=$AF$5,R7="4x"),VLOOKUP(R8,$AF$67:$AH$84,2,FALSE),IF(AND(R6="CU",R5=$AF$5,R7="5x"),VLOOKUP(R8,$AF$86:$AH$103,2,FALSE),IF(AND(R6="CU",R5=$AJ$5,R7="1x"),VLOOKUP(R8,$AJ$10:$AL$27,2,FALSE),IF(AND(R6="CU",R5=$AJ$5,R7="2x"),VLOOKUP(R8,$AJ$29:$AL$46,2,FALSE),IF(AND(R6="CU",R5=$AJ$5,R7="3x"),VLOOKUP(R8,$AJ$48:$AL$65,2,FALSE),IF(AND(R6="CU",R5=$AJ$5,R7="4x"),VLOOKUP(R8,$AJ$67:$AL$84,2,FALSE),IF(AND(R6="CU",R5=$AJ$5,R7="5x"),VLOOKUP(R8,$AJ$86:$AL$103,2,FALSE),IF(AND(R6="CU",R5=$AN$5,R7="1x"),VLOOKUP(R8,$AN$10:$AP$27,2,FALSE),IF(AND(R6="CU",R5=$AN$5,R7="2x"),VLOOKUP(R8,$AN$29:$AP$46,2,FALSE),IF(AND(R6="CU",R5=$AN$5,R7="3x"),VLOOKUP(R8,$AN$48:$AP$65,2,FALSE),IF(AND(R6="CU",R5=$AN$5,R7="4x"),VLOOKUP(R8,$AN$67:$AP$84,2,FALSE),IF(AND(R6="CU",R5=$AN$5,R7="5x"),VLOOKUP(R8,$AN$86:$AP$103,2,FALSE),IF(AND(R6="CU",R5=$AR$5,R7="1x"),VLOOKUP(R8,$AR$10:$AT$27,2,FALSE),IF(AND(R6="CU",R5=$AR$5,R7="2x"),VLOOKUP(R8,$AR$29:$AT$46,2,FALSE),IF(AND(R6="CU",R5=$AR$5,R7="3x"),VLOOKUP(R8,$AR$48:$AT$65,2,FALSE),IF(AND(R6="CU",R5=$AR$5,R7="4x"),VLOOKUP(R8,$AR$67:$AT$84,2,FALSE),IF(AND(R6="CU",R5=$AR$5,R7="5x"),VLOOKUP(R8,$AR$86:$AT$103,2,FALSE),IF(AND(R6="AL",R5=$AB$5,R7="4x"),VLOOKUP(R8,$AB$113:$AD$123,2,FALSE),IF(AND(R6="AL",R5=$AB$5,R7="5x"),VLOOKUP(R8,$AB$125:$AD$135,2,FALSE),IF(AND(R6="AL",R5=$AF$5,R7="4x"),VLOOKUP(R8,$AF$113:$AH$123,2,FALSE),IF(AND(R6="AL",R5=$AF$5,R7="5x"),VLOOKUP(R8,$AF$125:$AH$135,2,FALSE),IF(AND(R6="AL",R5=$AJ$5,R7="4x"),VLOOKUP(R8,$AJ$113:$AL$123,2,FALSE),IF(AND(R6="AL",R5=$AJ$5,R7="5x"),VLOOKUP(R8,$AJ$125:$AL$135,2,FALSE),IF(AND(R6="AL",R5=$AN$5,R7="4x"),VLOOKUP(R8,$AN$113:$AP$123,2,FALSE),IF(AND(R6="AL",R5=$AN$5,R7="5x"),VLOOKUP(R8,$AN$125:$AP$135,2,FALSE),IF(AND(R6="AL",R5=$AR$5,R7="4x"),VLOOKUP(R8,$AR$113:$AT$123,2,FALSE),IF(AND(R6="AL",R5=$AR$5,R7="5x"),VLOOKUP(R8,$AR$125:$AT$135,2,FALSE)))))))))))))))))))))))))))))))))))) -> 0.727 | AB14: 4 | AC14: 4.61 | AD14: 0.096 | AF14: 4 | AG14: 4.61 | AH14: 0.089 | AJ14: 4 | AN14: 4 | AR14: 4 | AZ14: 9
A15: X | B15: =IF(AND(B6="CU",B5=$AB$5,B7="1x"),VLOOKUP(B8,$AB$10:$AD$27,3,FALSE),IF(AND(B6="CU",B5=$AB$5,B7="2x"),VLOOKUP(B8,$AB$29:$AD$46,3,FALSE),IF(AND(B6="CU",B5=$AB$5,B7="3x"),VLOOKUP(B8,$AB$48:$AD$65,3,FALSE),IF(AND(B6="CU",B5=$AB$5,B7="4x"),VLOOKUP(B8,$AB$67:$AD$84,3,FALSE),IF(AND(B6="CU",B5=$AB$5,B7="5x"),VLOOKUP(B8,$AB$86:$AD$103,3,FALSE),IF(AND(B6="CU",B5=$AF$5,B7="1x"),VLOOKUP(B8,$AF$10:$AH$27,3,FALSE),IF(AND(B6="CU",B5=$AF$5,B7="2x"),VLOOKUP(B8,$AF$29:$AH$46,3,FALSE),IF(AND(B6="CU",B5=$AF$5,B7="3x"),VLOOKUP(B8,$AF$48:$AH$65,3,FALSE),IF(AND(B6="CU",B5=$AF$5,B7="4x"),VLOOKUP(B8,$AF$67:$AH$84,3,FALSE),IF(AND(B6="CU",B5=$AF$5,B7="5x"),VLOOKUP(B8,$AF$86:$AH$103,3,FALSE),IF(AND(B6="CU",B5=$AJ$5,B7="1x"),VLOOKUP(B8,$AJ$10:$AL$27,3,FALSE),IF(AND(B6="CU",B5=$AJ$5,B7="2x"),VLOOKUP(B8,$AJ$29:$AL$46,3,FALSE),IF(AND(B6="CU",B5=$AJ$5,B7="3x"),VLOOKUP(B8,$AJ$48:$AL$65,3,FALSE),IF(AND(B6="CU",B5=$AJ$5,B7="4x"),VLOOKUP(B8,$AJ$67:$AL$84,3,FALSE),IF(AND(B6="CU",B5=$AJ$5,B7="5x"),VLOOKUP(B8,$AJ$86:$AL$103,3,FALSE),IF(AND(B6="CU",B5=$AN$5,B7="1x"),VLOOKUP(B8,$AN$10:$AP$27,3,FALSE),IF(AND(B6="CU",B5=$AN$5,B7="2x"),VLOOKUP(B8,$AN$29:$AP$46,3,FALSE),IF(AND(B6="CU",B5=$AN$5,B7="3x"),VLOOKUP(B8,$AN$48:$AP$65,3,FALSE),IF(AND(B6="CU",B5=$AN$5,B7="4x"),VLOOKUP(B8,$AN$67:$AP$84,3,FALSE),IF(AND(B6="CU",B5=$AN$5,B7="5x"),VLOOKUP(B8,$AN$86:$AP$103,3,FALSE),IF(AND(B6="CU",B5=$AR$5,B7="1x"),VLOOKUP(B8,$AR$10:$AT$27,3,FALSE),IF(AND(B6="CU",B5=$AR$5,B7="2x"),VLOOKUP(B8,$AR$29:$AT$46,3,FALSE),IF(AND(B6="CU",B5=$AR$5,B7="3x"),VLOOKUP(B8,$AR$48:$AT$65,3,FALSE),IF(AND(B6="CU",B5=$AR$5,B7="4x"),VLOOKUP(B8,$AR$67:$AT$84,3,FALSE),IF(AND(B6="CU",B5=$AR$5,B7="5x"),VLOOKUP(B8,$AR$86:$AT$103,3,FALSE),IF(AND(B6="AL",B5=$AB$5,B7="4x"),VLOOKUP(B8,$AB$113:$AD$123,3,FALSE),IF(AND(B6="AL",B5=$AB$5,B7="5x"),VLOOKUP(B8,$AB$125:$AD$135,3,FALSE),IF(AND(B6="AL",B5=$AF$5,B7="4x"),VLOOKUP(B8,$AF$113:$AH$123,3,FALSE),IF(AND(B6="AL",B5=$AF$5,B7="5x"),VLOOKUP(B8,$AF$125:$AH$135,3,FALSE),IF(AND(B6="AL",B5=$AJ$5,B7="4x"),VLOOKUP(B8,$AJ$113:$AL$123,3,FALSE),IF(AND(B6="AL",B5=$AJ$5,B7="5x"),VLOOKUP(B8,$AJ$125:$AL$135,3,FALSE),IF(AND(B6="AL",B5=$AN$5,B7="4x"),VLOOKUP(B8,$AN$113:$AP$123,3,FALSE),IF(AND(B6="AL",B5=$AN$5,B7="5x"),VLOOKUP(B8,$AN$125:$AP$135,3,FALSE),IF(AND(B6="AL",B5=$AR$5,B7="4x"),VLOOKUP(B8,$AR$113:$AT$123,3,FALSE),IF(AND(B6="AL",B5=$AR$5,B7="5x"),VLOOKUP(B8,$AR$125:$AT$135,3,FALSE)))))))))))))))))))))))))))))))))))) -> 0.077 | E15: X | F15: =IF(AND(F6="CU",F5=$AB$5,F7="1x"),VLOOKUP(F8,$AB$10:$AD$27,3,FALSE),IF(AND(F6="CU",F5=$AB$5,F7="2x"),VLOOKUP(F8,$AB$29:$AD$46,3,FALSE),IF(AND(F6="CU",F5=$AB$5,F7="3x"),VLOOKUP(F8,$AB$48:$AD$65,3,FALSE),IF(AND(F6="CU",F5=$AB$5,F7="4x"),VLOOKUP(F8,$AB$67:$AD$84,3,FALSE),IF(AND(F6="CU",F5=$AB$5,F7="5x"),VLOOKUP(F8,$AB$86:$AD$103,3,FALSE),IF(AND(F6="CU",F5=$AF$5,F7="1x"),VLOOKUP(F8,$AF$10:$AH$27,3,FALSE),IF(AND(F6="CU",F5=$AF$5,F7="2x"),VLOOKUP(F8,$AF$29:$AH$46,3,FALSE),IF(AND(F6="CU",F5=$AF$5,F7="3x"),VLOOKUP(F8,$AF$48:$AH$65,3,FALSE),IF(AND(F6="CU",F5=$AF$5,F7="4x"),VLOOKUP(F8,$AF$67:$AH$84,3,FALSE),IF(AND(F6="CU",F5=$AF$5,F7="5x"),VLOOKUP(F8,$AF$86:$AH$103,3,FALSE),IF(AND(F6="CU",F5=$AJ$5,F7="1x"),VLOOKUP(F8,$AJ$10:$AL$27,3,FALSE),IF(AND(F6="CU",F5=$AJ$5,F7="2x"),VLOOKUP(F8,$AJ$29:$AL$46,3,FALSE),IF(AND(F6="CU",F5=$AJ$5,F7="3x"),VLOOKUP(F8,$AJ$48:$AL$65,3,FALSE),IF(AND(F6="CU",F5=$AJ$5,F7="4x"),VLOOKUP(F8,$AJ$67:$AL$84,3,FALSE),IF(AND(F6="CU",F5=$AJ$5,F7="5x"),VLOOKUP(F8,$AJ$86:$AL$103,3,FALSE),IF(AND(F6="CU",F5=$AN$5,F7="1x"),VLOOKUP(F8,$AN$10:$AP$27,3,FALSE),IF(AND(F6="CU",F5=$AN$5,F7="2x"),VLOOKUP(F8,$AN$29:$AP$46,3,FALSE),IF(AND(F6="CU",F5=$AN$5,F7="3x"),VLOOKUP(F8,$AN$48:$AP$65,3,FALSE),IF(AND(F6="CU",F5=$AN$5,F7="4x"),VLOOKUP(F8,$AN$67:$AP$84,3,FALSE),IF(AND(F6="CU",F5=$AN$5,F7="5x"),VLOOKUP(F8,$AN$86:$AP$103,3,FALSE),IF(AND(F6="CU",F5=$AR$5,F7="1x"),VLOOKUP(F8,$AR$10:$AT$27,3,FALSE),IF(AND(F6="CU",F5=$AR$5,F7="2x"),VLOOKUP(F8,$AR$29:$AT$46,3,FALSE),IF(AND(F6="CU",F5=$AR$5,F7="3x"),VLOOKUP(F8,$AR$48:$AT$65,3,FALSE),IF(AND(F6="CU",F5=$AR$5,F7="4x"),VLOOKUP(F8,$AR$67:$AT$84,3,FALSE),IF(AND(F6="CU",F5=$AR$5,F7="5x"),VLOOKUP(F8,$AR$86:$AT$103,3,FALSE),IF(AND(F6="AL",F5=$AB$5,F7="4x"),VLOOKUP(F8,$AB$113:$AD$123,3,FALSE),IF(AND(F6="AL",F5=$AB$5,F7="5x"),VLOOKUP(F8,$AB$125:$AD$135,3,FALSE),IF(AND(F6="AL",F5=$AF$5,F7="4x"),VLOOKUP(F8,$AF$113:$AH$123,3,FALSE),IF(AND(F6="AL",F5=$AF$5,F7="5x"),VLOOKUP(F8,$AF$125:$AH$135,3,FALSE),IF(AND(F6="AL",F5=$AJ$5,F7="4x"),VLOOKUP(F8,$AJ$113:$AL$123,3,FALSE),IF(AND(F6="AL",F5=$AJ$5,F7="5x"),VLOOKUP(F8,$AJ$125:$AL$135,3,FALSE),IF(AND(F6="AL",F5=$AN$5,F7="4x"),VLOOKUP(F8,$AN$113:$AP$123,3,FALSE),IF(AND(F6="AL",F5=$AN$5,F7="5x"),VLOOKUP(F8,$AN$125:$AP$135,3,FALSE),IF(AND(F6="AL",F5=$AR$5,F7="4x"),VLOOKUP(F8,$AR$113:$AT$123,3,FALSE),IF(AND(F6="AL",F5=$AR$5,F7="5x"),VLOOKUP(F8,$AR$125:$AT$135,3,FALSE)))))))))))))))))))))))))))))))))))) -> 0.081 | I15: X | J15: =IF(AND(J6="CU",J5=$AB$5,J7="1x"),VLOOKUP(J8,$AB$10:$AD$27,3,FALSE),IF(AND(J6="CU",J5=$AB$5,J7="2x"),VLOOKUP(J8,$AB$29:$AD$46,3,FALSE),IF(AND(J6="CU",J5=$AB$5,J7="3x"),VLOOKUP(J8,$AB$48:$AD$65,3,FALSE),IF(AND(J6="CU",J5=$AB$5,J7="4x"),VLOOKUP(J8,$AB$67:$AD$84,3,FALSE),IF(AND(J6="CU",J5=$AB$5,J7="5x"),VLOOKUP(J8,$AB$86:$AD$103,3,FALSE),IF(AND(J6="CU",J5=$AF$5,J7="1x"),VLOOKUP(J8,$AF$10:$AH$27,3,FALSE),IF(AND(J6="CU",J5=$AF$5,J7="2x"),VLOOKUP(J8,$AF$29:$AH$46,3,FALSE),IF(AND(J6="CU",J5=$AF$5,J7="3x"),VLOOKUP(J8,$AF$48:$AH$65,3,FALSE),IF(AND(J6="CU",J5=$AF$5,J7="4x"),VLOOKUP(J8,$AF$67:$AH$84,3,FALSE),IF(AND(J6="CU",J5=$AF$5,J7="5x"),VLOOKUP(J8,$AF$86:$AH$103,3,FALSE),IF(AND(J6="CU",J5=$AJ$5,J7="1x"),VLOOKUP(J8,$AJ$10:$AL$27,3,FALSE),IF(AND(J6="CU",J5=$AJ$5,J7="2x"),VLOOKUP(J8,$AJ$29:$AL$46,3,FALSE),IF(AND(J6="CU",J5=$AJ$5,J7="3x"),VLOOKUP(J8,$AJ$48:$AL$65,3,FALSE),IF(AND(J6="CU",J5=$AJ$5,J7="4x"),VLOOKUP(J8,$AJ$67:$AL$84,3,FALSE),IF(AND(J6="CU",J5=$AJ$5,J7="5x"),VLOOKUP(J8,$AJ$86:$AL$103,3,FALSE),IF(AND(J6="CU",J5=$AN$5,J7="1x"),VLOOKUP(J8,$AN$10:$AP$27,3,FALSE),IF(AND(J6="CU",J5=$AN$5,J7="2x"),VLOOKUP(J8,$AN$29:$AP$46,3,FALSE),IF(AND(J6="CU",J5=$AN$5,J7="3x"),VLOOKUP(J8,$AN$48:$AP$65,3,FALSE),IF(AND(J6="CU",J5=$AN$5,J7="4x"),VLOOKUP(J8,$AN$67:$AP$84,3,FALSE),IF(AND(J6="CU",J5=$AN$5,J7="5x"),VLOOKUP(J8,$AN$86:$AP$103,3,FALSE),IF(AND(J6="CU",J5=$AR$5,J7="1x"),VLOOKUP(J8,$AR$10:$AT$27,3,FALSE),IF(AND(J6="CU",J5=$AR$5,J7="2x"),VLOOKUP(J8,$AR$29:$AT$46,3,FALSE),IF(AND(J6="CU",J5=$AR$5,J7="3x"),VLOOKUP(J8,$AR$48:$AT$65,3,FALSE),IF(AND(J6="CU",J5=$AR$5,J7="4x"),VLOOKUP(J8,$AR$67:$AT$84,3,FALSE),IF(AND(J6="CU",J5=$AR$5,J7="5x"),VLOOKUP(J8,$AR$86:$AT$103,3,FALSE),IF(AND(J6="AL",J5=$AB$5,J7="4x"),VLOOKUP(J8,$AB$113:$AD$123,3,FALSE),IF(AND(J6="AL",J5=$AB$5,J7="5x"),VLOOKUP(J8,$AB$125:$AD$135,3,FALSE),IF(AND(J6="AL",J5=$AF$5,J7="4x"),VLOOKUP(J8,$AF$113:$AH$123,3,FALSE),IF(AND(J6="AL",J5=$AF$5,J7="5x"),VLOOKUP(J8,$AF$125:$AH$135,3,FALSE),IF(AND(J6="AL",J5=$AJ$5,J7="4x"),VLOOKUP(J8,$AJ$113:$AL$123,3,FALSE),IF(AND(J6="AL",J5=$AJ$5,J7="5x"),VLOOKUP(J8,$AJ$125:$AL$135,3,FALSE),IF(AND(J6="AL",J5=$AN$5,J7="4x"),VLOOKUP(J8,$AN$113:$AP$123,3,FALSE),IF(AND(J6="AL",J5=$AN$5,J7="5x"),VLOOKUP(J8,$AN$125:$AP$135,3,FALSE),IF(AND(J6="AL",J5=$AR$5,J7="4x"),VLOOKUP(J8,$AR$113:$AT$123,3,FALSE),IF(AND(J6="AL",J5=$AR$5,J7="5x"),VLOOKUP(J8,$AR$125:$AT$135,3,FALSE)))))))))))))))))))))))))))))))))))) -> 0.08 | M15: X | N15: =IF(AND(N6="CU",N5=$AB$5,N7="1x"),VLOOKUP(N8,$AB$10:$AD$27,3,FALSE),IF(AND(N6="CU",N5=$AB$5,N7="2x"),VLOOKUP(N8,$AB$29:$AD$46,3,FALSE),IF(AND(N6="CU",N5=$AB$5,N7="3x"),VLOOKUP(N8,$AB$48:$AD$65,3,FALSE),IF(AND(N6="CU",N5=$AB$5,N7="4x"),VLOOKUP(N8,$AB$67:$AD$84,3,FALSE),IF(AND(N6="CU",N5=$AB$5,N7="5x"),VLOOKUP(N8,$AB$86:$AD$103,3,FALSE),IF(AND(N6="CU",N5=$AF$5,N7="1x"),VLOOKUP(N8,$AF$10:$AH$27,3,FALSE),IF(AND(N6="CU",N5=$AF$5,N7="2x"),VLOOKUP(N8,$AF$29:$AH$46,3,FALSE),IF(AND(N6="CU",N5=$AF$5,N7="3x"),VLOOKUP(N8,$AF$48:$AH$65,3,FALSE),IF(AND(N6="CU",N5=$AF$5,N7="4x"),VLOOKUP(N8,$AF$67:$AH$84,3,FALSE),IF(AND(N6="CU",N5=$AF$5,N7="5x"),VLOOKUP(N8,$AF$86:$AH$103,3,FALSE),IF(AND(N6="CU",N5=$AJ$5,N7="1x"),VLOOKUP(N8,$AJ$10:$AL$27,3,FALSE),IF(AND(N6="CU",N5=$AJ$5,N7="2x"),VLOOKUP(N8,$AJ$29:$AL$46,3,FALSE),IF(AND(N6="CU",N5=$AJ$5,N7="3x"),VLOOKUP(N8,$AJ$48:$AL$65,3,FALSE),IF(AND(N6="CU",N5=$AJ$5,N7="4x"),VLOOKUP(N8,$AJ$67:$AL$84,3,FALSE),IF(AND(N6="CU",N5=$AJ$5,N7="5x"),VLOOKUP(N8,$AJ$86:$AL$103,3,FALSE),IF(AND(N6="CU",N5=$AN$5,N7="1x"),VLOOKUP(N8,$AN$10:$AP$27,3,FALSE),IF(AND(N6="CU",N5=$AN$5,N7="2x"),VLOOKUP(N8,$AN$29:$AP$46,3,FALSE),IF(AND(N6="CU",N5=$AN$5,N7="3x"),VLOOKUP(N8,$AN$48:$AP$65,3,FALSE),IF(AND(N6="CU",N5=$AN$5,N7="4x"),VLOOKUP(N8,$AN$67:$AP$84,3,FALSE),IF(AND(N6="CU",N5=$AN$5,N7="5x"),VLOOKUP(N8,$AN$86:$AP$103,3,FALSE),IF(AND(N6="CU",N5=$AR$5,N7="1x"),VLOOKUP(N8,$AR$10:$AT$27,3,FALSE),IF(AND(N6="CU",N5=$AR$5,N7="2x"),VLOOKUP(N8,$AR$29:$AT$46,3,FALSE),IF(AND(N6="CU",N5=$AR$5,N7="3x"),VLOOKUP(N8,$AR$48:$AT$65,3,FALSE),IF(AND(N6="CU",N5=$AR$5,N7="4x"),VLOOKUP(N8,$AR$67:$AT$84,3,FALSE),IF(AND(N6="CU",N5=$AR$5,N7="5x"),VLOOKUP(N8,$AR$86:$AT$103,3,FALSE),IF(AND(N6="AL",N5=$AB$5,N7="4x"),VLOOKUP(N8,$AB$113:$AD$123,3,FALSE),IF(AND(N6="AL",N5=$AB$5,N7="5x"),VLOOKUP(N8,$AB$125:$AD$135,3,FALSE),IF(AND(N6="AL",N5=$AF$5,N7="4x"),VLOOKUP(N8,$AF$113:$AH$123,3,FALSE),IF(AND(N6="AL",N5=$AF$5,N7="5x"),VLOOKUP(N8,$AF$125:$AH$135,3,FALSE),IF(AND(N6="AL",N5=$AJ$5,N7="4x"),VLOOKUP(N8,$AJ$113:$AL$123,3,FALSE),IF(AND(N6="AL",N5=$AJ$5,N7="5x"),VLOOKUP(N8,$AJ$125:$AL$135,3,FALSE),IF(AND(N6="AL",N5=$AN$5,N7="4x"),VLOOKUP(N8,$AN$113:$AP$123,3,FALSE),IF(AND(N6="AL",N5=$AN$5,N7="5x"),VLOOKUP(N8,$AN$125:$AP$135,3,FALSE),IF(AND(N6="AL",N5=$AR$5,N7="4x"),VLOOKUP(N8,$AR$113:$AT$123,3,FALSE),IF(AND(N6="AL",N5=$AR$5,N7="5x"),VLOOKUP(N8,$AR$125:$AT$135,3,FALSE)))))))))))))))))))))))))))))))))))) -> 0.087 | Q15: X | R15: =IF(AND(R6="CU",R5=$AB$5,R7="1x"),VLOOKUP(R8,$AB$10:$AD$27,3,FALSE),IF(AND(R6="CU",R5=$AB$5,R7="2x"),VLOOKUP(R8,$AB$29:$AD$46,3,FALSE),IF(AND(R6="CU",R5=$AB$5,R7="3x"),VLOOKUP(R8,$AB$48:$AD$65,3,FALSE),IF(AND(R6="CU",R5=$AB$5,R7="4x"),VLOOKUP(R8,$AB$67:$AD$84,3,FALSE),IF(AND(R6="CU",R5=$AB$5,R7="5x"),VLOOKUP(R8,$AB$86:$AD$103,3,FALSE),IF(AND(R6="CU",R5=$AF$5,R7="1x"),VLOOKUP(R8,$AF$10:$AH$27,3,FALSE),IF(AND(R6="CU",R5=$AF$5,R7="2x"),VLOOKUP(R8,$AF$29:$AH$46,3,FALSE),IF(AND(R6="CU",R5=$AF$5,R7="3x"),VLOOKUP(R8,$AF$48:$AH$65,3,FALSE),IF(AND(R6="CU",R5=$AF$5,R7="4x"),VLOOKUP(R8,$AF$67:$AH$84,3,FALSE),IF(AND(R6="CU",R5=$AF$5,R7="5x"),VLOOKUP(R8,$AF$86:$AH$103,3,FALSE),IF(AND(R6="CU",R5=$AJ$5,R7="1x"),VLOOKUP(R8,$AJ$10:$AL$27,3,FALSE),IF(AND(R6="CU",R5=$AJ$5,R7="2x"),VLOOKUP(R8,$AJ$29:$AL$46,3,FALSE),IF(AND(R6="CU",R5=$AJ$5,R7="3x"),VLOOKUP(R8,$AJ$48:$AL$65,3,FALSE),IF(AND(R6="CU",R5=$AJ$5,R7="4x"),VLOOKUP(R8,$AJ$67:$AL$84,3,FALSE),IF(AND(R6="CU",R5=$AJ$5,R7="5x"),VLOOKUP(R8,$AJ$86:$AL$103,3,FALSE),IF(AND(R6="CU",R5=$AN$5,R7="1x"),VLOOKUP(R8,$AN$10:$AP$27,3,FALSE),IF(AND(R6="CU",R5=$AN$5,R7="2x"),VLOOKUP(R8,$AN$29:$AP$46,3,FALSE),IF(AND(R6="CU",R5=$AN$5,R7="3x"),VLOOKUP(R8,$AN$48:$AP$65,3,FALSE),IF(AND(R6="CU",R5=$AN$5,R7="4x"),VLOOKUP(R8,$AN$67:$AP$84,3,FALSE),IF(AND(R6="CU",R5=$AN$5,R7="5x"),VLOOKUP(R8,$AN$86:$AP$103,3,FALSE),IF(AND(R6="CU",R5=$AR$5,R7="1x"),VLOOKUP(R8,$AR$10:$AT$27,3,FALSE),IF(AND(R6="CU",R5=$AR$5,R7="2x"),VLOOKUP(R8,$AR$29:$AT$46,3,FALSE),IF(AND(R6="CU",R5=$AR$5,R7="3x"),VLOOKUP(R8,$AR$48:$AT$65,3,FALSE),IF(AND(R6="CU",R5=$AR$5,R7="4x"),VLOOKUP(R8,$AR$67:$AT$84,3,FALSE),IF(AND(R6="CU",R5=$AR$5,R7="5x"),VLOOKUP(R8,$AR$86:$AT$103,3,FALSE),IF(AND(R6="AL",R5=$AB$5,R7="4x"),VLOOKUP(R8,$AB$113:$AD$123,3,FALSE),IF(AND(R6="AL",R5=$AB$5,R7="5x"),VLOOKUP(R8,$AB$125:$AD$135,3,FALSE),IF(AND(R6="AL",R5=$AF$5,R7="4x"),VLOOKUP(R8,$AF$113:$AH$123,3,FALSE),IF(AND(R6="AL",R5=$AF$5,R7="5x"),VLOOKUP(R8,$AF$125:$AH$135,3,FALSE),IF(AND(R6="AL",R5=$AJ$5,R7="4x"),VLOOKUP(R8,$AJ$113:$AL$123,3,FALSE),IF(AND(R6="AL",R5=$AJ$5,R7="5x"),VLOOKUP(R8,$AJ$125:$AL$135,3,FALSE),IF(AND(R6="AL",R5=$AN$5,R7="4x"),VLOOKUP(R8,$AN$113:$AP$123,3,FALSE),IF(AND(R6="AL",R5=$AN$5,R7="5x"),VLOOKUP(R8,$AN$125:$AP$135,3,FALSE),IF(AND(R6="AL",R5=$AR$5,R7="4x"),VLOOKUP(R8,$AR$113:$AT$123,3,FALSE),IF(AND(R6="AL",R5=$AR$5,R7="5x"),VLOOKUP(R8,$AR$125:$AT$135,3,FALSE)))))))))))))))))))))))))))))))))))) -> 0.079 | AB15: 6 | AC15: 3.08 | AD15: 0.093 | AF15: 6 | AG15: 3.08 | AH15: 0.087 | AJ15: 6 | AN15: 6 | AR15: 6 | AZ15: 10
A16: Z70° | B16: =SQRT(((1.5*B14)^2)+(B15^2)) -> 0.14094255 | E16: Z70° | F16: =SQRT(((1.5*F14)^2)+(F15^2)) -> 0.96490582 | I16: Z70° | J16: =SQRT(((1.5*J14)^2)+(J15^2)) -> 0.6707876 | M16: Z70° | N16: =SQRT(((1.5*N14)^2)+(N15^2)) -> 1.8021013 | Q16: Z70° | R16: =SQRT(((1.5*R14)^2)+(R15^2)) -> 1.0933578 | AB16: 10 | AC16: 1.83 | AD16: 0.083 | AF16: 10 | AG16: 1.83 | AH16: 0.082 | AJ16: 10 | AN16: 10 | AR16: 10
A17: Ð 70° | B17: =DEGREES(IMARGUMENT(COMPLEX(1.5*B14,B15,"j"))) -> 33.115043 | E17: Ð 70° | F17: =DEGREES(IMARGUMENT(COMPLEX(1.5*F14,F15,"j"))) -> 4.8154194 | I17: Ð 70° | J17: =DEGREES(IMARGUMENT(COMPLEX(1.5*J14,J15,"j"))) -> 6.849558 | M17: Ð 70° | N17: =DEGREES(IMARGUMENT(COMPLEX(1.5*N14,N15,"j"))) -> 2.7671426 | Q17: Ð 70° | R17: =DEGREES(IMARGUMENT(COMPLEX(1.5*R14,R15,"j"))) -> 4.1434875 | AB17: 16 | AC17: 1.15 | AD17: 0.086 | AF17: 16 | AG17: 1.15 | AH17: 0.078 | AJ17: 16 | AN17: 16 | AR17: 16
A18: Indtastning | B18: =IF(B14+B15>0.0000000001,"OK","Fejl") -> OK | F18: =IF(F14+F15>0.0000000001,"OK","Fejl") -> OK | J18: =IF(J14+J15>0.0000000001,"OK","Fejl") -> OK | N18: =IF(N14+N15>0.0000000001,"OK","Fejl") -> OK | R18: =IF(R14+R15>0.0000000001,"OK","Fejl") -> OK | AB18: 25 | AC18: 0.727 | AD18: 0.085 | AF18: 25 | AG18: 0.727 | AH18: 0.079 | AJ18: 25 | AN18: 25 | AR18: 25
AB19: 35 | AC19: 0.525 | AD19: 0.073 | AF19: 35 | AG19: 0.525 | AH19: 0.074 | AJ19: 35 | AN19: 35 | AR19: 35
A20: Kabel 6 | E20: Kabel 7 | I20: Kabel 8 | M20: Hvis man får R og X værdi | Q20: Hvis man får R og X værdi | AB20: 50 | AC20: 0.388 | AD20: 0.073 | AF20: 50 | AJ20: 50 | AN20: 50 | AR20: 50
A21: Separat PE leder | B21: Nej | F21: Ja | J21: Nej | N21: Nej | R21: Nej | AB21: 70 | AC21: 0.269 | AD21: 0.072 | AF21: 70 | AJ21: 70 | AN21: 70 | AR21: 70
A22: Navn | AB22: 95 | AC22: 0.194 | AD22: 0.07 | AF22: 95 | AJ22: 95 | AN22: 95 | AR22: 95
A23: Kabeltype | B23: NOIKLX | F23: NOIKLX | J23: NOIKLX | AB23: 120 | AC23: 0.155 | AD23: 0.07 | AF23: 120 | AJ23: 120 | AN23: 120 | AR23: 120
A24: Materiale | B24: CU | F24: CU | J24: CU | AB24: 150 | AC24: 0.126 | AD24: 0.07 | AF24: 150 | AJ24: 150 | AN24: 150 | AR24: 150
A25: Antal ledere | B25: 3x | F25: 4x | J25: 3x | M25: R 20˚ | Q25: R 20˚ | AB25: 185 | AC25: 0.1017 | AD25: 0.07 | AF25: 185 | AJ25: 185 | AN25: 185 | AR25: 185
A26: Kvadrat (mm²) | B26: 2.5 | F26: 16 | J26: 2.5 | M26: X | Q26: X | AB26: 240 | AC26: 0.0787 | AD26: 0.07 | AF26: 240 | AJ26: 240 | AN26: 240 | AR26: 240
A27: Længde (m) | B27: 10.7 | E27: m | F27: 2 | I27: m | J27: 38.35 | M27: m | Q27: m | AB27: 300 | AF27: 300 | AJ27: 300 | AN27: 300 | AR27: 300
A28: Paralle (n) | B28: 1 | E28: n | F28: 1 | I28: n | J28: 1 | M28: n | N28: 1 | Q28: n | AB28: 2x | AC28: R | AD28: X | AF28: 2x | AG28: R | AH28: X | AJ28: 2x | AK28: R | AL28: X | AN28: 2x | AO28: R | AP28: X | AR28: 2x | AS28: R | AT28: X
A29: I̅ B | B29: 6 | C29: Ð- | D29: 0 | F29: 63 | G29: Ð- | H29: 0 | J29: 10 | K29: Ð- | L29: 0 | N29: 250 | O29: Ð- | P29: 23 | R29: 250 | S29: Ð- | T29: 23 | AB29: 0.75 | AF29: 0.75 | AJ29: 0.75 | AK29: 26 | AL29: 0.111 | AN29: 0.75 | AR29: 0.75
A30: Z20° | B30: =SQRT(B32^2+B33^2) -> 7.4106089 | E30: Z20° | F30: =SQRT(F32^2+F33^2) -> 1.153137 | I30: Z20° | J30: =SQRT(J32^2+J33^2) -> 7.4106089 | M30: Z20° | N30: =IF(N25="","",IMABS(COMPLEX(N25,N26,"i"))) | Q30: Z20° | R30: =IF(R25="","",IMABS(COMPLEX(R25,R26,"i"))) | AB30: 1 | AF30: 1 | AJ30: 1 | AK30: 19.5 | AL30: 0.105 | AN30: 1 | AR30: 1
A31: Ð 20° | B31: =DEGREES(IMARGUMENT(COMPLEX(B32,B33,"j"))) -> 0.73452103 | E31: Ð 20° | F31: =DEGREES(IMARGUMENT(COMPLEX(F32,F33,"j"))) -> 4.2272187 | I31: Ð 20° | J31: =DEGREES(IMARGUMENT(COMPLEX(J32,J33,"j"))) -> 0.73452103 | M31: Ð 20° | N31: =IF(N26="","",DEGREES(ACOS((N25/N30)))) | Q31: Ð 20° | R31: =IF(R26="","",DEGREES(ACOS((R25/R30)))) | AB31: 1.5 | AC31: 12.1 | AD31: 0.108 | AF31: 1.5 | AG31: 12.1 | AH31: 0.103 | AJ31: 1.5 | AK31: 13.3 | AL31: 0.107 | AN31: 1.5 | AR31: 1.5
