Workbook
Name antal.kabler: [1]Ark2!$M$40:$M$60
Name antalkabelbakke: [1]Ark2!$M$71:$M$76
Name Drifttemperatur: [1]Ark2!$A$98:$A$101
Name Installationsmetode: [1]Ark2!$A$2:$A$91
Name Kabel.ledning: [1]Ark2!$C$41:$C$43
Name kabelafstandjord: [1]Ark2!$U$29:$U$35
Name Omgivelsestemperatur: [1]Ark2!$E$38:$E$55
Name Termiskmodstand: [1]Ark2!$E$76:$E$82

Sheet Ark1
B2: Enleder/flerleder | E2: Flerleder
B3: Antal Ledere | E3: AL 3 belastede leder
B4: Kablets Drifttemp. | E4: 90°C XLPE & EPR
B5: Sikring/IB | E5: 80
B6: Antal kabler parallel | E6: 1
B7: Maks strøm i kabel | E7: =E5/IF(E6="",1,E6) -> 80
E11: Oplægning 1 | M11: Oplægning 2 | U11: Oplægning 3 | AC11: Oplægning 4 | AK11: Oplægning 5
B12: Installationmetode | E12: Billede nr.: | H12: 73 | M12: Billede nr.: | P12: 5 | U12: Billede nr.: | X12: 3 | AC12: Billede nr.: | AK12: Billede nr.:
B13: Reference | E13: Reference: | H13: =IF($E$2="Flerleder",VLOOKUP(H12,'kt,ks,kj'!$A$3:$B$84,2,FALSE),IF($E$2="Enleder",VLOOKUP(H12,'kt,ks,kj'!$A$96:$B$177,2,FALSE),)) -> D2 | M13: Reference: | P13: =IF($E$2="Flerleder",VLOOKUP(P12,'kt,ks,kj'!$A$3:$B$84,2,FALSE),IF($E$2="Enleder",VLOOKUP(P12,'kt,ks,kj'!$A$96:$B$177,2,FALSE),)) -> B2 | U13: Reference: | X13: =IF($E$2="Flerleder",VLOOKUP(X12,'kt,ks,kj'!$A$3:$B$84,2,FALSE),IF($E$2="Enleder",VLOOKUP(X12,'kt,ks,kj'!$A$96:$B$177,2,FALSE),)) -> A1 | AC13: Reference: | AF13: =IF($E$2="Flerleder",VLOOKUP(AF12,'kt,ks,kj'!$A$3:$B$84,2,FALSE),IF($E$2="Enleder",VLOOKUP(AF12,'kt,ks,kj'!$A$96:$B$177,2,FALSE),)) -> #N/A | AK13: Reference: | AN13: =IF($E$2="Flerleder",VLOOKUP(AN12,'kt,ks,kj'!$A$3:$B$84,2,FALSE),IF($E$2="Enleder",VLOOKUP(AN12,'kt,ks,kj'!$A$96:$B$177,2,FALSE),)) -> #N/A
E14: Korritionfaktor for temperatur (kt) | M14: Korritionfaktor for temperatur (kt) | U14: Korritionfaktor for temperatur (kt) | AC14: Korritionfaktor for temperatur (kt) | AK14: Korritionfaktor for temperatur (kt)
B15: Korritionfaktor for temperatur (kt) | E15: Temperatur: | H15: 35°C | M15: Temperatur: | P15: 35°C | U15: Temperatur: | X15: 20°C | AC15: Temperatur: | AK15: Temperatur:
E16: Tabel: | H16: =IF(OR(H13="D1",H13="D2"),'kt,ks,kj'!$D$34,'kt,ks,kj'!$D$13) -> B.52.15 | M16: Tabel: | P16: =IF(OR(P13="D1",P13="D2"),'kt,ks,kj'!$D$34,'kt,ks,kj'!$D$13) -> B.52.14 | U16: Tabel: | X16: =IF(OR(X13="D1",X13="D2"),'kt,ks,kj'!$D$34,'kt,ks,kj'!$D$13) -> B.52.14 | AC16: Tabel: | AF16: =IF(OR(AF13="D1",AF13="D2"),'kt,ks,kj'!$D$34,'kt,ks,kj'!$D$13) -> #N/A | AK16: Tabel: | AN16: =IF(OR(AN13="D1",AN13="D2"),'kt,ks,kj'!$D$34,'kt,ks,kj'!$D$13) -> #N/A
E17: Faktor: | H17: =IF(OR(H13="D1",H13="D2"),INDEX('kt,ks,kj'!$E$35:$F$49,MATCH('Ark1'!H15,'kt,ks,kj'!$D$35:$D$49,0),MATCH('Ark1'!$E$4,'kt,ks,kj'!$E$34:$F$34,0)),IF(OR(H13="A1",H13="A2",H13="B1",H13="B2",H13="C",H13="E",H13="F",H13="G"),INDEX('kt,ks,kj'!$E$14:$H$31,MATCH('Ark1'!H15,'kt,ks,kj'!$D$14:$D$31,0),MATCH('Ark1'!$E$4,'kt,ks,kj'!$E$13:$H$13,0)))) -> 0.89 | M17: Faktor: | P17: =IF(OR(P13="D1",P13="D2"),INDEX('kt,ks,kj'!$E$35:$F$49,MATCH('Ark1'!P15,'kt,ks,kj'!$D$35:$D$49,0),MATCH('Ark1'!$E$4,'kt,ks,kj'!$E$34:$F$34,0)),IF(OR(P13="A1",P13="A2",P13="B1",P13="B2",P13="C",P13="E",P13="F",P13="G"),INDEX('kt,ks,kj'!$E$14:$H$31,MATCH('Ark1'!P15,'kt,ks,kj'!$D$14:$D$31,0),MATCH('Ark1'!$E$4,'kt,ks,kj'!$E$13:$H$13,0)))) -> 0.96 | U17: Faktor: | X17: =IF(OR(X13="D1",X13="D2"),INDEX('kt,ks,kj'!$E$35:$F$49,MATCH('Ark1'!X15,'kt,ks,kj'!$D$35:$D$49,0),MATCH('Ark1'!$E$4,'kt,ks,kj'!$E$34:$F$34,0)),IF(OR(X13="A1",X13="A2",X13="B1",X13="B2",X13="C",X13="E",X13="F",X13="G"),INDEX('kt,ks,kj'!$E$14:$H$31,MATCH('Ark1'!X15,'kt,ks,kj'!$D$14:$D$31,0),MATCH('Ark1'!$E$4,'kt,ks,kj'!$E$13:$H$13,0)))) -> 1.08 | AC17: Faktor: | AF17: =IF(OR(AF13="D1",AF13="D2"),INDEX('kt,ks,kj'!$E$35:$F$49,MATCH('Ark1'!AF15,'kt,ks,kj'!$D$35:$D$49,0),MATCH('Ark1'!$E$4,'kt,ks,kj'!$E$34:$F$34,0)),IF(OR(AF13="A1",AF13="A2",AF13="B1",AF13="B2",AF13="C",AF13="E",AF13="F",AF13="G"),INDEX('kt,ks,kj'!$E$14:$H$31,MATCH('Ark1'!AF15,'kt,ks,kj'!$D$14:$D$31,0),MATCH('Ark1'!$E$4,'kt,ks,kj'!$E$13:$H$13,0)))) -> #N/A | AK17: Faktor: | AN17: =IF(OR(AN13="D1",AN13="D2"),INDEX('kt,ks,kj'!$E$35:$F$49,MATCH('Ark1'!AN15,'kt,ks,kj'!$D$35:$D$49,0),MATCH('Ark1'!$E$4,'kt,ks,kj'!$E$34:$F$34,0)),IF(OR(AN13="A1",AN13="A2",AN13="B1",AN13="B2",AN13="C",AN13="E",AN13="F",AN13="G"),INDEX('kt,ks,kj'!$E$14:$H$31,MATCH('Ark1'!AN15,'kt,ks,kj'!$D$14:$D$31,0),MATCH('Ark1'!$E$4,'kt,ks,kj'!$E$13:$H$13,0)))) -> #N/A
E18: Korritionsfaktor for sideløb (ks) | M18: Korritionsfaktor for sideløb (ks) | U18: Korritionsfaktor for sideløb (ks) | AC18: Korritionsfaktor for sideløb (ks) | AK18: Korritionsfaktor for sideløb (ks)
B19: Korritionsfaktor for sideløb (ks) | E19: Antal kabler: | H19: 1 | M19: Antal kabler: | P19: 1 | U19: Antal kabler: | X19: 1 | AC19: Antal kabler: | AF19: 9 | AK19: Antal kabler: | AN19: 9
E20: Afstand: | H20: Ingen | M20: Afstand: | P20: Ingen | U20: Afstand: | X20: Ingen | AC20: Afstand: | AF20: Ingen | AK20: Afstand: | AN20: Ingen
E21: Bakker/Stiger: | H21: 1 vandret | M21: Bakker/Stiger: | P21: 1 vandret | U21: Bakker/Stiger: | X21: 1 vandret | AC21: Bakker/Stiger: | AK21: Bakker/Stiger:
E22: Tabel: | H22: =IF(OR(H13="A1",H13="A2",H13="B1",H13="B2",H13="C"),'kt,ks,kj'!$K$13,IF(H13="D1",'kt,ks,kj'!$Y$12,IF(H13="D2",'kt,ks,kj'!$R$12,IF(H13="E",'kt,ks,kj'!$K$39,IF(H13="F",'kt,ks,kj'!$K$67))))) -> B.52.18 | M22: Tabel: | P22: =IF(OR(P13="A1",P13="A2",P13="B1",P13="B2",P13="C"),'kt,ks,kj'!$K$13,IF(P13="D1",'kt,ks,kj'!$Y$12,IF(P13="D2",'kt,ks,kj'!$R$12,IF(P13="E",'kt,ks,kj'!$K$39,IF(P13="F",'kt,ks,kj'!$K$67))))) -> B.52.17 | U22: Tabel: | X22: =IF(OR(X13="A1",X13="A2",X13="B1",X13="B2",X13="C"),'kt,ks,kj'!$K$13,IF(X13="D1",'kt,ks,kj'!$Y$12,IF(X13="D2",'kt,ks,kj'!$R$12,IF(X13="E",'kt,ks,kj'!$K$39,IF(X13="F",'kt,ks,kj'!$K$67))))) -> B.52.17 | AC22: Tabel: | AF22: =IF(OR(AF13="A1",AF13="A2",AF13="B1",AF13="B2",AF13="C"),'kt,ks,kj'!$K$13,IF(AF13="D1",'kt,ks,kj'!$Y$12,IF(AF13="D2",'kt,ks,kj'!$R$12,IF(AF13="E",'kt,ks,kj'!$K$39,IF(AF13="F",'kt,ks,kj'!$K$67))))) -> #N/A | AK22: Tabel: | AN22: =IF(OR(AN13="A1",AN13="A2",AN13="B1",AN13="B2",AN13="C"),'kt,ks,kj'!$K$13,IF(AN13="D1",'kt,ks,kj'!$Y$12,IF(AN13="D2",'kt,ks,kj'!$R$12,IF(AN13="E",'kt,ks,kj'!$K$39,IF(AN13="F",'kt,ks,kj'!$K$67))))) -> #N/A
E23: Faktor: | H23: =IF(AND(OR(H12=21,H12=23),H13="C"),VLOOKUP(H19,'kt,ks,kj'!$K$15:$N$35,4,FALSE),IF(H13="C",VLOOKUP(H19,'kt,ks,kj'!$K$15:$N$35,3,FALSE),IF(OR(H13="A1",H13="A2",H13="B1",H13="B2"),VLOOKUP(H19,'kt,ks,kj'!$K$15:$L$35,2,FALSE),IF(H13="D1",INDEX('kt,ks,kj'!$Y$15:$AC$35,MATCH('Ark1'!H19,'kt,ks,kj'!$X$15:$X$35,0),MATCH('Ark1'!H20,'kt,ks,kj'!$Y$14:$AC$14,0)),IF('Ark1'!H13="D2",INDEX('kt,ks,kj'!$R$15:$W$35,MATCH('Ark1'!H19,'kt,ks,kj'!$Q$15:$Q$35,0),MATCH('Ark1'!H20,'kt,ks,kj'!$R$14:$W$14,0)),IF(AND(H13="E",H12=31,H20="Ingen"),INDEX('kt,ks,kj'!$L$43:$Q$63,MATCH('Ark1'!H19,'kt,ks,kj'!$K$43:$K$63,0),MATCH('Ark1'!H21,'kt,ks,kj'!$L$42:$Q$42,0)),IF(AND(H13="E",H12=31,H20="En kabeldiameter"),INDEX('kt,ks,kj'!$R$43:$W$63,MATCH('Ark1'!H19,'kt,ks,kj'!$K$43:$K$63,0),MATCH('Ark1'!H21,'kt,ks,kj'!$R$42:$W$42,0)),IF(AND(H13="E",H12=30,H20="Ingen"),INDEX('kt,ks,kj'!$X$43:$AC$63,MATCH('Ark1'!H19,'kt,ks,kj'!$K$43:$K$63,0),MATCH('Ark1'!H21,'kt,ks,kj'!$X$42:$AC$42,0)),IF(AND(H13="E",OR(H12=32,H12=33,H12=34),H20="Ingen"),INDEX('kt,ks,kj'!$AD$43:$AI$63,MATCH('Ark1'!H19,'kt,ks,kj'!$K$43:$K$63,0),MATCH('Ark1'!H21,'kt,ks,kj'!$AD$42:$AI$42,0)),IF(AND(H13="E",OR(H12=32,H12=33,H12=34),H20="En kabeldiameter"),INDEX('kt,ks,kj'!$AJ$43:$AO$63,MATCH('Ark1'!H19,'kt,ks,kj'!$K$43:$K$63,0),MATCH('Ark1'!H21,'kt,ks,kj'!$AJ$42:$AO$42,0)),IF(AND(H13="F",H12=31,H20="Ingen"),INDEX('kt,ks,kj'!$L$71:$Q$91,MATCH('Ark1'!H19,'kt,ks,kj'!$K$71:$K$91,0),MATCH('Ark1'!H21,'kt,ks,kj'!$L$70:$Q$70,0)),IF(AND(H13="F",H12=31,H20="En kabeldiameter"),INDEX('kt,ks,kj'!$R$71:$W$91,MATCH('Ark1'!H19,'kt,ks,kj'!$K$71:$K$91,0),MATCH('Ark1'!H21,'kt,ks,kj'!$R$70:$W$70,0)),IF(AND(H13="F",OR(H12=32,H12=33,H12=34),H20="Ingen"),INDEX('kt,ks,kj'!$X$71:$AA$91,MATCH('Ark1'!H19,'kt,ks,kj'!$K$71:$K$91,0),MATCH('Ark1'!H21,'kt,ks,kj'!$X$70:$AC$70,0)),IF(AND(H13="F",H12=31,H20="To kabeldiameter"),INDEX('kt,ks,kj'!$AL$71:$AQ$91,MATCH('Ark1'!H19,'kt,ks,kj'!$K$71:$K$91,0),MATCH('Ark1'!H21,'kt,ks,kj'!$AL$70:$AQ$70,0)),IF(AND(H13="F",OR(H12=32,H12=33,H12=34),H20="To kabeldiameter"),INDEX('kt,ks,kj'!$AR$71:$AU$91,MATCH('Ark1'!H19,'kt,ks,kj'!$K$71:$K$91,0),MATCH('Ark1'!H21,'kt,ks,kj'!$AR$70:$AW$70,0)),"FALSK"))))))))))))))) -> 1 | M23: Faktor: | P23: =IF(AND(OR(P12=21,P12=23),P13="C"),VLOOKUP(P19,'kt,ks,kj'!$K$15:$N$35,4,FALSE),IF(P13="C",VLOOKUP(P19,'kt,ks,kj'!$K$15:$N$35,3,FALSE),IF(OR(P13="A1",P13="A2",P13="B1",P13="B2"),VLOOKUP(P19,'kt,ks,kj'!$K$15:$L$35,2,FALSE),IF(P13="D1",INDEX('kt,ks,kj'!$Y$15:$AC$35,MATCH('Ark1'!P19,'kt,ks,kj'!$X$15:$X$35,0),MATCH('Ark1'!P20,'kt,ks,kj'!$Y$14:$AC$14,0)),IF('Ark1'!P13="D2",INDEX('kt,ks,kj'!$R$15:$W$35,MATCH('Ark1'!P19,'kt,ks,kj'!$Q$15:$Q$35,0),MATCH('Ark1'!P20,'kt,ks,kj'!$R$14:$W$14,0)),IF(AND(P13="E",P12=31,P20="Ingen"),INDEX('kt,ks,kj'!$L$43:$Q$63,MATCH('Ark1'!P19,'kt,ks,kj'!$K$43:$K$63,0),MATCH('Ark1'!P21,'kt,ks,kj'!$L$42:$Q$42,0)),IF(AND(P13="E",P12=31,P20="En kabeldiameter"),INDEX('kt,ks,kj'!$R$43:$W$63,MATCH('Ark1'!P19,'kt,ks,kj'!$K$43:$K$63,0),MATCH('Ark1'!P21,'kt,ks,kj'!$R$42:$W$42,0)),IF(AND(P13="E",P12=30,P20="Ingen"),INDEX('kt,ks,kj'!$X$43:$AC$63,MATCH('Ark1'!P19,'kt,ks,kj'!$K$43:$K$63,0),MATCH('Ark1'!P21,'kt,ks,kj'!$X$42:$AC$42,0)),IF(AND(P13="E",OR(P12=32,P12=33,P12=34),P20="Ingen"),INDEX('kt,ks,kj'!$AD$43:$AI$63,MATCH('Ark1'!P19,'kt,ks,kj'!$K$43:$K$63,0),MATCH('Ark1'!P21,'kt,ks,kj'!$AD$42:$AI$42,0)),IF(AND(P13="E",OR(P12=32,P12=33,P12=34),P20="En kabeldiameter"),INDEX('kt,ks,kj'!$AJ$43:$AO$63,MATCH('Ark1'!P19,'kt,ks,kj'!$K$43:$K$63,0),MATCH('Ark1'!P21,'kt,ks,kj'!$AJ$42:$AO$42,0)),IF(AND(P13="F",P12=31,P20="Ingen"),INDEX('kt,ks,kj'!$L$71:$Q$91,MATCH('Ark1'!P19,'kt,ks,kj'!$K$71:$K$91,0),MATCH('Ark1'!P21,'kt,ks,kj'!$L$70:$Q$70,0)),IF(AND(P13="F",P12=31,P20="En kabeldiameter"),INDEX('kt,ks,kj'!$R$71:$W$91,MATCH('Ark1'!P19,'kt,ks,kj'!$K$71:$K$91,0),MATCH('Ark1'!P21,'kt,ks,kj'!$R$70:$W$70,0)),IF(AND(P13="F",OR(P12=32,P12=33,P12=34),P20="Ingen"),INDEX('kt,ks,kj'!$X$71:$AA$91,MATCH('Ark1'!P19,'kt,ks,kj'!$K$71:$K$91,0),MATCH('Ark1'!P21,'kt,ks,kj'!$X$70:$AC$70,0)),IF(AND(P13="F",P12=31,P20="To kabeldiameter"),INDEX('kt,ks,kj'!$AL$71:$AQ$91,MATCH('Ark1'!P19,'kt,ks,kj'!$K$71:$K$91,0),MATCH('Ark1'!P21,'kt,ks,kj'!$AL$70:$AQ$70,0)),IF(AND(P13="F",OR(P12=32,P12=33,P12=34),P20="To kabeldiameter"),INDEX('kt,ks,kj'!$AR$71:$AU$91,MATCH('Ark1'!P19,'kt,ks,kj'!$K$71:$K$91,0),MATCH('Ark1'!P21,'kt,ks,kj'!$AR$70:$AW$70,0)),"FALSK"))))))))))))))) -> 1 | U23: Faktor: | X23: =IF(AND(OR(X12=21,X12=23),X13="C"),VLOOKUP(X19,'kt,ks,kj'!$K$15:$N$35,4,FALSE),IF(X13="C",VLOOKUP(X19,'kt,ks,kj'!$K$15:$N$35,3,FALSE),IF(OR(X13="A1",X13="A2",X13="B1",X13="B2"),VLOOKUP(X19,'kt,ks,kj'!$K$15:$L$35,2,FALSE),IF(X13="D1",INDEX('kt,ks,kj'!$Y$15:$AC$35,MATCH('Ark1'!X19,'kt,ks,kj'!$X$15:$X$35,0),MATCH('Ark1'!X20,'kt,ks,kj'!$Y$14:$AC$14,0)),IF('Ark1'!X13="D2",INDEX('kt,ks,kj'!$R$15:$W$35,MATCH('Ark1'!X19,'kt,ks,kj'!$Q$15:$Q$35,0),MATCH('Ark1'!X20,'kt,ks,kj'!$R$14:$W$14,0)),IF(AND(X13="E",X12=31,X20="Ingen"),INDEX('kt,ks,kj'!$L$43:$Q$63,MATCH('Ark1'!X19,'kt,ks,kj'!$K$43:$K$63,0),MATCH('Ark1'!X21,'kt,ks,kj'!$L$42:$Q$42,0)),IF(AND(X13="E",X12=31,X20="En kabeldiameter"),INDEX('kt,ks,kj'!$R$43:$W$63,MATCH('Ark1'!X19,'kt,ks,kj'!$K$43:$K$63,0),MATCH('Ark1'!X21,'kt,ks,kj'!$R$42:$W$42,0)),IF(AND(X13="E",X12=30,X20="Ingen"),INDEX('kt,ks,kj'!$X$43:$AC$63,MATCH('Ark1'!X19,'kt,ks,kj'!$K$43:$K$63,0),MATCH('Ark1'!X21,'kt,ks,kj'!$X$42:$AC$42,0)),IF(AND(X13="E",OR(X12=32,X12=33,X12=34),X20="Ingen"),INDEX('kt,ks,kj'!$AD$43:$AI$63,MATCH('Ark1'!X19,'kt,ks,kj'!$K$43:$K$63,0),MATCH('Ark1'!X21,'kt,ks,kj'!$AD$42:$AI$42,0)),IF(AND(X13="E",OR(X12=32,X12=33,X12=34),X20="En kabeldiameter"),INDEX('kt,ks,kj'!$AJ$43:$AO$63,MATCH('Ark1'!X19,'kt,ks,kj'!$K$43:$K$63,0),MATCH('Ark1'!X21,'kt,ks,kj'!$AJ$42:$AO$42,0)),IF(AND(X13="F",X12=31,X20="Ingen"),INDEX('kt,ks,kj'!$L$71:$Q$91,MATCH('Ark1'!X19,'kt,ks,kj'!$K$71:$K$91,0),MATCH('Ark1'!X21,'kt,ks,kj'!$L$70:$Q$70,0)),IF(AND(X13="F",X12=31,X20="En kabeldiameter"),INDEX('kt,ks,kj'!$R$71:$W$91,MATCH('Ark1'!X19,'kt,ks,kj'!$K$71:$K$91,0),MATCH('Ark1'!X21,'kt,ks,kj'!$R$70:$W$70,0)),IF(AND(X13="F",OR(X12=32,X12=33,X12=34),X20="Ingen"),INDEX('kt,ks,kj'!$X$71:$AA$91,MATCH('Ark1'!X19,'kt,ks,kj'!$K$71:$K$91,0),MATCH('Ark1'!X21,'kt,ks,kj'!$X$70:$AC$70,0)),IF(AND(X13="F",X12=31,X20="To kabeldiameter"),INDEX('kt,ks,kj'!$AL$71:$AQ$91,MATCH('Ark1'!X19,'kt,ks,kj'!$K$71:$K$91,0),MATCH('Ark1'!X21,'kt,ks,kj'!$AL$70:$AQ$70,0)),IF(AND(X13="F",OR(X12=32,X12=33,X12=34),X20="To kabeldiameter"),INDEX('kt,ks,kj'!$AR$71:$AU$91,MATCH('Ark1'!X19,'kt,ks,kj'!$K$71:$K$91,0),MATCH('Ark1'!X21,'kt,ks,kj'!$AR$70:$AW$70,0)),"FALSK"))))))))))))))) -> 1 | AC23: Faktor: | AF23: =IF(AND(OR(AF12=21,AF12=23),AF13="C"),VLOOKUP(AF19,'kt,ks,kj'!$K$15:$N$35,4,FALSE),IF(AF13="C",VLOOKUP(AF19,'kt,ks,kj'!$K$15:$N$35,3,FALSE),IF(OR(AF13="A1",AF13="A2",AF13="B1",AF13="B2"),VLOOKUP(AF19,'kt,ks,kj'!$K$15:$L$35,2,FALSE),IF(AF13="D1",INDEX('kt,ks,kj'!$Y$15:$AC$35,MATCH('Ark1'!AF19,'kt,ks,kj'!$X$15:$X$35,0),MATCH('Ark1'!AF20,'kt,ks,kj'!$Y$14:$AC$14,0)),IF('Ark1'!AF13="D2",INDEX('kt,ks,kj'!$R$15:$W$35,MATCH('Ark1'!AF19,'kt,ks,kj'!$Q$15:$Q$35,0),MATCH('Ark1'!AF20,'kt,ks,kj'!$R$14:$W$14,0)),IF(AND(AF13="E",AF12=31,AF20="Ingen"),INDEX('kt,ks,kj'!$L$43:$Q$63,MATCH('Ark1'!AF19,'kt,ks,kj'!$K$43:$K$63,0),MATCH('Ark1'!AF21,'kt,ks,kj'!$L$42:$Q$42,0)),IF(AND(AF13="E",AF12=31,AF20="En kabeldiameter"),INDEX('kt,ks,kj'!$R$43:$W$63,MATCH('Ark1'!AF19,'kt,ks,kj'!$K$43:$K$63,0),MATCH('Ark1'!AF21,'kt,ks,kj'!$R$42:$W$42,0)),IF(AND(AF13="E",AF12=30,AF20="Ingen"),INDEX('kt,ks,kj'!$X$43:$AC$63,MATCH('Ark1'!AF19,'kt,ks,kj'!$K$43:$K$63,0),MATCH('Ark1'!AF21,'kt,ks,kj'!$X$42:$AC$42,0)),IF(AND(AF13="E",OR(AF12=32,AF12=33,AF12=34),AF20="Ingen"),INDEX('kt,ks,kj'!$AD$43:$AI$63,MATCH('Ark1'!AF19,'kt,ks,kj'!$K$43:$K$63,0),MATCH('Ark1'!AF21,'kt,ks,kj'!$AD$42:$AI$42,0)),IF(AND(AF13="E",OR(AF12=32,AF12=33,AF12=34),AF20="En kabeldiameter"),INDEX('kt,ks,kj'!$AJ$43:$AO$63,MATCH('Ark1'!AF19,'kt,ks,kj'!$K$43:$K$63,0),MATCH('Ark1'!AF21,'kt,ks,kj'!$AJ$42:$AO$42,0)),IF(AND(AF13="F",AF12=31,AF20="Ingen"),INDEX('kt,ks,kj'!$L$71:$Q$91,MATCH('Ark1'!AF19,'kt,ks,kj'!$K$71:$K$91,0),MATCH('Ark1'!AF21,'kt,ks,kj'!$L$70:$Q$70,0)),IF(AND(AF13="F",AF12=31,AF20="En kabeldiameter"),INDEX('kt,ks,kj'!$R$71:$W$91,MATCH('Ark1'!AF19,'kt,ks,kj'!$K$71:$K$91,0),MATCH('Ark1'!AF21,'kt,ks,kj'!$R$70:$W$70,0)),IF(AND(AF13="F",OR(AF12=32,AF12=33,AF12=34),AF20="Ingen"),INDEX('kt,ks,kj'!$X$71:$AA$91,MATCH('Ark1'!AF19,'kt,ks,kj'!$K$71:$K$91,0),MATCH('Ark1'!AF21,'kt,ks,kj'!$X$70:$AC$70,0)),IF(AND(AF13="F",AF12=31,AF20="To kabeldiameter"),INDEX('kt,ks,kj'!$AL$71:$AQ$91,MATCH('Ark1'!AF19,'kt,ks,kj'!$K$71:$K$91,0),MATCH('Ark1'!AF21,'kt,ks,kj'!$AL$70:$AQ$70,0)),IF(AND(AF13="F",OR(AF12=32,AF12=33,AF12=34),AF20="To kabeldiameter"),INDEX('kt,ks,kj'!$AR$71:$AU$91,MATCH('Ark1'!AF19,'kt,ks,kj'!$K$71:$K$91,0),MATCH('Ark1'!AF21,'kt,ks,kj'!$AR$70:$AW$70,0)),"FALSK"))))))))))))))) -> #N/A | AK23: Faktor: | AN23: =IF(AND(OR(AN12=21,AN12=23),AN13="C"),VLOOKUP(AN19,'kt,ks,kj'!$K$15:$N$35,4,FALSE),IF(AN13="C",VLOOKUP(AN19,'kt,ks,kj'!$K$15:$N$35,3,FALSE),IF(OR(AN13="A1",AN13="A2",AN13="B1",AN13="B2"),VLOOKUP(AN19,'kt,ks,kj'!$K$15:$L$35,2,FALSE),IF(AN13="D1",INDEX('kt,ks,kj'!$Y$15:$AC$35,MATCH('Ark1'!AN19,'kt,ks,kj'!$X$15:$X$35,0),MATCH('Ark1'!AN20,'kt,ks,kj'!$Y$14:$AC$14,0)),IF('Ark1'!AN13="D2",INDEX('kt,ks,kj'!$R$15:$W$35,MATCH('Ark1'!AN19,'kt,ks,kj'!$Q$15:$Q$35,0),MATCH('Ark1'!AN20,'kt,ks,kj'!$R$14:$W$14,0)),IF(AND(AN13="E",AN12=31,AN20="Ingen"),INDEX('kt,ks,kj'!$L$43:$Q$63,MATCH('Ark1'!AN19,'kt,ks,kj'!$K$43:$K$63,0),MATCH('Ark1'!AN21,'kt,ks,kj'!$L$42:$Q$42,0)),IF(AND(AN13="E",AN12=31,AN20="En kabeldiameter"),INDEX('kt,ks,kj'!$R$43:$W$63,MATCH('Ark1'!AN19,'kt,ks,kj'!$K$43:$K$63,0),MATCH('Ark1'!AN21,'kt,ks,kj'!$R$42:$W$42,0)),IF(AND(AN13="E",AN12=30,AN20="Ingen"),INDEX('kt,ks,kj'!$X$43:$AC$63,MATCH('Ark1'!AN19,'kt,ks,kj'!$K$43:$K$63,0),MATCH('Ark1'!AN21,'kt,ks,kj'!$X$42:$AC$42,0)),IF(AND(AN13="E",OR(AN12=32,AN12=33,AN12=34),AN20="Ingen"),INDEX('kt,ks,kj'!$AD$43:$AI$63,MATCH('Ark1'!AN19,'kt,ks,kj'!$K$43:$K$63,0),MATCH('Ark1'!AN21,'kt,ks,kj'!$AD$42:$AI$42,0)),IF(AND(AN13="E",OR(AN12=32,AN12=33,AN12=34),AN20="En kabeldiameter"),INDEX('kt,ks,kj'!$AJ$43:$AO$63,MATCH('Ark1'!AN19,'kt,ks,kj'!$K$43:$K$63,0),MATCH('Ark1'!AN21,'kt,ks,kj'!$AJ$42:$AO$42,0)),IF(AND(AN13="F",AN12=31,AN20="Ingen"),INDEX('kt,ks,kj'!$L$71:$Q$91,MATCH('Ark1'!AN19,'kt,ks,kj'!$K$71:$K$91,0),MATCH('Ark1'!AN21,'kt,ks,kj'!$L$70:$Q$70,0)),IF(AND(AN13="F",AN12=31,AN20="En kabeldiameter"),INDEX('kt,ks,kj'!$R$71:$W$91,MATCH('Ark1'!AN19,'kt,ks,kj'!$K$71:$K$91,0),MATCH('Ark1'!AN21,'kt,ks,kj'!$R$70:$W$70,0)),IF(AND(AN13="F",OR(AN12=32,AN12=33,AN12=34),AN20="Ingen"),INDEX('kt,ks,kj'!$X$71:$AA$91,MATCH('Ark1'!AN19,'kt,ks,kj'!$K$71:$K$91,0),MATCH('Ark1'!AN21,'kt,ks,kj'!$X$70:$AC$70,0)),IF(AND(AN13="F",AN12=31,AN20="To kabeldiameter"),INDEX('kt,ks,kj'!$AL$71:$AQ$91,MATCH('Ark1'!AN19,'kt,ks,kj'!$K$71:$K$91,0),MATCH('Ark1'!AN21,'kt,ks,kj'!$AL$70:$AQ$70,0)),IF(AND(AN13="F",OR(AN12=32,AN12=33,AN12=34),AN20="To kabeldiameter"),INDEX('kt,ks,kj'!$AR$71:$AU$91,MATCH('Ark1'!AN19,'kt,ks,kj'!$K$71:$K$91,0),MATCH('Ark1'!AN21,'kt,ks,kj'!$AR$70:$AW$70,0)),"FALSK"))))))))))))))) -> #N/A
E24: Termisk modstand i jord (kj) | M24: Termisk modstand i jord (kj) | U24: Termisk modstand i jord (kj) | AC24: Termisk modstand i jord (kj) | AK24: Termisk modstand i jord (kj)
B25: Termisk modstand i jord (kj) | E25: Modstand | H25: 2,5K · m/W | M25: Modstand | P25: 1,5K · m/W | U25: Modstand | AC25: Modstand | AK25: Modstand
E26: Tabel: | H26: =IF(OR(H13="D1",H13="D2"),'kt,ks,kj'!$D$52,"") -> B.52.16 | M26: Tabel: | P26: =IF(OR(P13="D1",P13="D2"),'kt,ks,kj'!$D$52,"") | U26: Tabel: | X26: =IF(OR(X13="D1",X13="D2"),'kt,ks,kj'!$D$52,"") | AC26: Tabel: | AF26: =IF(OR(AF13="D1",AF13="D2"),'kt,ks,kj'!$D$52,"") -> #N/A | AK26: Tabel: | AN26: =IF(OR(AN13="D1",AN13="D2"),'kt,ks,kj'!$D$52,"") -> #N/A
E27: Faktor: | H27: =IF(H13="D1",VLOOKUP(H25,'kt,ks,kj'!$D$55:$F$61,2,FALSE),IF(H13="D2",VLOOKUP('Ark1'!H25,'kt,ks,kj'!$D$55:$F$61,3,FALSE),"")) -> 1 | M27: Faktor: | P27: =IF(P13="D1",VLOOKUP(P25,'kt,ks,kj'!$D$55:$F$61,2,FALSE),IF(P13="D2",VLOOKUP('Ark1'!P25,'kt,ks,kj'!$D$55:$F$61,3,FALSE),"")) | U27: Faktor: | X27: =IF(X13="D1",VLOOKUP(X25,'kt,ks,kj'!$D$55:$F$61,2,FALSE),IF(X13="D2",VLOOKUP('Ark1'!X25,'kt,ks,kj'!$D$55:$F$61,3,FALSE),"")) | AC27: Faktor: | AF27: =IF(AF13="D1",VLOOKUP(AF25,'kt,ks,kj'!$D$55:$F$61,2,FALSE),IF(AF13="D2",VLOOKUP('Ark1'!AF25,'kt,ks,kj'!$D$55:$F$61,3,FALSE),"")) -> #N/A | AK27: Faktor: | AN27: =IF(AN13="D1",VLOOKUP(AN25,'kt,ks,kj'!$D$55:$F$61,2,FALSE),IF(AN13="D2",VLOOKUP('Ark1'!AN25,'kt,ks,kj'!$D$55:$F$61,3,FALSE),"")) -> #N/A
E28: Strømværdi nødvendig (Iz) | M28: Strømværdi nødvendig (Iz) | U28: Strømværdi nødvendig (Iz) | AC28: Strømværdi nødvendig (Iz) | AK28: Strømværdi nødvendig (Iz)
B29: Strømværdi nødvendig (Iz) | C29: IN | F29: =$E$7 -> 80 | G29: = | H29: =$E$7/(H17*H23*IF(H27="",1,H27)) -> 89.88764 | N29: =$E$7 -> 80 | O29: = | P29: =$E$7/(P17*P23*IF(P27="",1,P27)) -> 83.333333 | V29: =$E$7 -> 80 | W29: = | X29: =$E$7/(X17*X23*IF(X27="",1,X27)) -> 74.074074 | AD29: =$E$7 -> 80 | AE29: = | AF29: =$E$7/(AF17*AF23*IF(AF27="",1,AF27)) -> #N/A | AL29: =$E$7 -> 80 | AM29: = | AN29: =$E$7/(AN17*AN23*IF(AN27="",1,AN27)) -> #N/A
C30: kt · ks · kj | F30: =H17&" · "&H23&IF(H27="",""," · "&H27) -> 0,89 · 1 · 1 | N30: =P17&" · "&P23&IF(P27="",""," · "&P27) -> 0,96 · 1 | V30: =X17&" · "&X23&IF(X27="",""," · "&X27) -> 1,08 · 1 | AD30: =AF17&" · "&AF23&IF(AF27="",""," · "&AF27) -> #N/A | AL30: =AN17&" · "&AN23&IF(AN27="",""," · "&AN27) -> #N/A
E31: Kabel valg | M31: Kabel valg | U31: Kabel valg | AC31: Kabel valg | AK31: Kabel valg
B32: Tabel for strømværdi | E32: Tabel: | H32: =IF(AND(OR($E$3="AL 2 belastede leder",$E$3="CU 2 belastede leder"),$E$4="70°C PVC",OR(H13="A1",H13="A2",H13="B1",H13="B2",H13="C",H13="D1",H13="D2")),'Ark4'!$A$1,IF(AND(OR($E$3="AL 3 belastede leder",$E$3="CU 3 belastede leder"),$E$4="70°C PVC",OR(H13="A1",H13="A2",H13="B1",H13="B2",H13="C",H13="D1",H13="D2")),'Ark4'!$R$1,IF(AND(OR($E$3="AL 2 belastede leder",$E$3="CU 2 belastede leder"),$E$4="90°C XLPE & EPR",OR(H13="A1",H13="A2",H13="B1",H13="B2",H13="C",H13="D1",H13="D2")),'Ark4'!$J$1,IF(AND(OR($E$3="AL 3 belastede leder",$E$3="CU 3 belastede leder"),$E$4="90°C XLPE & EPR",OR(H13="A1",H13="A2",H13="B1",H13="B2",H13="C",H13="D1",H13="D2")),'Ark4'!$Z$1,IF(AND(OR($E$3="CU 2 belastede leder",$E$3="CU 3 belastede leder"),$E$4="70°C PVC",OR(H13="E",H13="F")),'Ark4'!$B$44,IF(AND(OR($E$3="AL 2 belastede leder",$E$3="AL 3 belastede leder"),$E$4="70°C PVC",OR(H13="E",H13="F")),'Ark4'!$B$66,IF(AND(OR($E$3="CU 2 belastede leder",$E$3="CU 3 belastede leder"),$E$4="90°C XLPE & EPR",OR(H13="E",H13="F")),'Ark4'!$K$44,IF(AND(OR($E$3="AL 2 belastede leder",$E$3="AL 3 belastede leder"),$E$4="90°C XLPE & EPR",OR(H13="E",H13="F")),'Ark4'!$K$66)))))))) -> B.52.5 | M32: Tabel: | P32: =IF(AND(OR($E$3="AL 2 belastede leder",$E$3="CU 2 belastede leder"),$E$4="70°C PVC",OR(P13="A1",P13="A2",P13="B1",P13="B2",P13="C",P13="D1",P13="D2")),'Ark4'!$A$1,IF(AND(OR($E$3="AL 3 belastede leder",$E$3="CU 3 belastede leder"),$E$4="70°C PVC",OR(P13="A1",P13="A2",P13="B1",P13="B2",P13="C",P13="D1",P13="D2")),'Ark4'!$R$1,IF(AND(OR($E$3="AL 2 belastede leder",$E$3="CU 2 belastede leder"),$E$4="90°C XLPE & EPR",OR(P13="A1",P13="A2",P13="B1",P13="B2",P13="C",P13="D1",P13="D2")),'Ark4'!$J$1,IF(AND(OR($E$3="AL 3 belastede leder",$E$3="CU 3 belastede leder"),$E$4="90°C XLPE & EPR",OR(P13="A1",P13="A2",P13="B1",P13="B2",P13="C",P13="D1",P13="D2")),'Ark4'!$Z$1,IF(AND(OR($E$3="CU 2 belastede leder",$E$3="CU 3 belastede leder"),$E$4="70°C PVC",OR(P13="E",P13="F")),'Ark4'!$B$44,IF(AND(OR($E$3="AL 2 belastede leder",$E$3="AL 3 belastede leder"),$E$4="70°C PVC",OR(P13="E",P13="F")),'Ark4'!$B$66,IF(AND(OR($E$3="CU 2 belastede leder",$E$3="CU 3 belastede leder"),$E$4="90°C XLPE & EPR",OR(P13="E",P13="F")),'Ark4'!$K$44,IF(AND(OR($E$3="AL 2 belastede leder",$E$3="AL 3 belastede leder"),$E$4="90°C XLPE & EPR",OR(P13="E",P13="F")),'Ark4'!$K$66)))))))) -> B.52.5 | U32: Tabel: | X32: =IF(AND(OR($E$3="AL 2 belastede leder",$E$3="CU 2 belastede leder"),$E$4="70°C PVC",OR(X13="A1",X13="A2",X13="B1",X13="B2",X13="C",X13="D1",X13="D2")),'Ark4'!$A$1,IF(AND(OR($E$3="AL 3 belastede leder",$E$3="CU 3 belastede leder"),$E$4="70°C PVC",OR(X13="A1",X13="A2",X13="B1",X13="B2",X13="C",X13="D1",X13="D2")),'Ark4'!$R$1,IF(AND(OR($E$3="AL 2 belastede leder",$E$3="CU 2 belastede leder"),$E$4="90°C XLPE & EPR",OR(X13="A1",X13="A2",X13="B1",X13="B2",X13="C",X13="D1",X13="D2")),'Ark4'!$J$1,IF(AND(OR($E$3="AL 3 belastede leder",$E$3="CU 3 belastede leder"),$E$4="90°C XLPE & EPR",OR(X13="A1",X13="A2",X13="B1",X13="B2",X13="C",X13="D1",X13="D2")),'Ark4'!$Z$1,IF(AND(OR($E$3="CU 2 belastede leder",$E$3="CU 3 belastede leder"),$E$4="70°C PVC",OR(X13="E",X13="F")),'Ark4'!$B$44,IF(AND(OR($E$3="AL 2 belastede leder",$E$3="AL 3 belastede leder"),$E$4="70°C PVC",OR(X13="E",X13="F")),'Ark4'!$B$66,IF(AND(OR($E$3="CU 2 belastede leder",$E$3="CU 3 belastede leder"),$E$4="90°C XLPE & EPR",OR(X13="E",X13="F")),'Ark4'!$K$44,IF(AND(OR($E$3="AL 2 belastede leder",$E$3="AL 3 belastede leder"),$E$4="90°C XLPE & EPR",OR(X13="E",X13="F")),'Ark4'!$K$66)))))))) -> B.52.5 | AC32: Tabel: | AF32: =IF(AND(OR($E$3="AL 2 belastede leder",$E$3="CU 2 belastede leder"),$E$4="70°C PVC",OR(AF13="A1",AF13="A2",AF13="B1",AF13="B2",AF13="C",AF13="D1",AF13="D2")),'Ark4'!$A$1,IF(AND(OR($E$3="AL 3 belastede leder",$E$3="CU 3 belastede leder"),$E$4="70°C PVC",OR(AF13="A1",AF13="A2",AF13="B1",AF13="B2",AF13="C",AF13="D1",AF13="D2")),'Ark4'!$R$1,IF(AND(OR($E$3="AL 2 belastede leder",$E$3="CU 2 belastede leder"),$E$4="90°C XLPE & EPR",OR(AF13="A1",AF13="A2",AF13="B1",AF13="B2",AF13="C",AF13="D1",AF13="D2")),'Ark4'!$J$1,IF(AND(OR($E$3="AL 3 belastede leder",$E$3="CU 3 belastede leder"),$E$4="90°C XLPE & EPR",OR(AF13="A1",AF13="A2",AF13="B1",AF13="B2",AF13="C",AF13="D1",AF13="D2")),'Ark4'!$Z$1,IF(AND(OR($E$3="CU 2 belastede leder",$E$3="CU 3 belastede leder"),$E$4="70°C PVC",OR(AF13="E",AF13="F")),'Ark4'!$B$44,IF(AND(OR($E$3="AL 2 belastede leder",$E$3="AL 3 belastede leder"),$E$4="70°C PVC",OR(AF13="E",AF13="F")),'Ark4'!$B$66,IF(AND(OR($E$3="CU 2 belastede leder",$E$3="CU 3 belastede leder"),$E$4="90°C XLPE & EPR",OR(AF13="E",AF13="F")),'Ark4'!$K$44,IF(AND(OR($E$3="AL 2 belastede leder",$E$3="AL 3 belastede leder"),$E$4="90°C XLPE & EPR",OR(AF13="E",AF13="F")),'Ark4'!$K$66)))))))) -> #N/A | AK32: Tabel: | AN32: =IF(AND(OR($E$3="AL 2 belastede leder",$E$3="CU 2 belastede leder"),$E$4="70°C PVC",OR(AN13="A1",AN13="A2",AN13="B1",AN13="B2",AN13="C",AN13="D1",AN13="D2")),'Ark4'!$A$1,IF(AND(OR($E$3="AL 3 belastede leder",$E$3="CU 3 belastede leder"),$E$4="70°C PVC",OR(AN13="A1",AN13="A2",AN13="B1",AN13="B2",AN13="C",AN13="D1",AN13="D2")),'Ark4'!$R$1,IF(AND(OR($E$3="AL 2 belastede leder",$E$3="CU 2 belastede leder"),$E$4="90°C XLPE & EPR",OR(AN13="A1",AN13="A2",AN13="B1",AN13="B2",AN13="C",AN13="D1",AN13="D2")),'Ark4'!$J$1,IF(AND(OR($E$3="AL 3 belastede leder",$E$3="CU 3 belastede leder"),$E$4="90°C XLPE & EPR",OR(AN13="A1",AN13="A2",AN13="B1",AN13="B2",AN13="C",AN13="D1",AN13="D2")),'Ark4'!$Z$1,IF(AND(OR($E$3="CU 2 belastede leder",$E$3="CU 3 belastede leder"),$E$4="70°C PVC",OR(AN13="E",AN13="F")),'Ark4'!$B$44,IF(AND(OR($E$3="AL 2 belastede leder",$E$3="AL 3 belastede leder"),$E$4="70°C PVC",OR(AN13="E",AN13="F")),'Ark4'!$B$66,IF(AND(OR($E$3="CU 2 belastede leder",$E$3="CU 3 belastede leder"),$E$4="90°C XLPE & EPR",OR(AN13="E",AN13="F")),'Ark4'!$K$44,IF(AND(OR($E$3="AL 2 belastede leder",$E$3="AL 3 belastede leder"),$E$4="90°C XLPE & EPR",OR(AN13="E",AN13="F")),'Ark4'!$K$66)))))))) -> #N/A
B33: Kabelvalg: | E33: (mm²):(A) | H33: =IF(H39<H40,H39,H40) -> 35 | I33: mm² | J33: =IF(J39<J40,J39,J40) -> 98 | K33: A | M33: (mm²):(A) | P33: =IF(P39<P40,P39,P40) -> 25 | Q33: mm² | R33: =IF(R39<R40,R39,R40) -> 84 | S33: A | U33: (mm²):(A) | X33: =IF(X39<X40,X39,X40) -> 25 | Y33: mm² | Z33: =IF(Z39<Z40,Z39,Z40) -> 76 | AA33: A | AC33: (mm²):(A) | AF33: =IF(AF39<AF40,AF39,AF40) -> #N/A | AG33: mm² | AH33: =IF(AH39<AH40,AH39,AH40) -> #N/A | AI33: A | AK33: (mm²):(A) | AN33: =IF(AN39<AN40,AN39,AN40) -> #N/A | AO33: mm² | AP33: =IF(AP39<AP40,AP39,AP40) -> #N/A | AQ33: A
E34: Strømværdi (Izkorr) | M34: Strømværdi (Izkorr) | U34: Strømværdi (Izkorr) | AC34: Strømværdi (Izkorr) | AK34: Strømværdi (Izkorr)
B35: Strømværdi (Izkorr) | C35: Iz · kt · ks · kj | E35: =J33&" · "&H17&" · "&H23&IF(H27="",""," · "&H27) -> 98 · 0,89 · 1 · 1 | G35: = | H35: =J33*(H17*H23*IF(H27="",1,H27)) -> 87.22 | M35: =R33&" · "&P17&" · "&P23&IF(P27="",""," · "&P27) -> 84 · 0,96 · 1 | O35: = | P35: =R33*(P17*P23*IF(P27="",1,P27)) -> 80.64 | U35: =Z33&" · "&X17&" · "&X23&IF(X27="",""," · "&X27) -> 76 · 1,08 · 1 | W35: = | X35: =Z33*(X17*X23*IF(X27="",1,X27)) -> 82.08 | AC35: =AH33&" · "&AF17&" · "&AF23&IF(AF27="",""," · "&AF27) -> #N/A | AE35: = | AF35: =AH33*(AF17*AF23*IF(AF27="",1,AF27)) -> #N/A | AK35: =AP33&" · "&AN17&" · "&AN23&IF(AN27="",""," · "&AN27) -> #N/A | AM35: = | AN35: =AP33*(AN17*AN23*IF(AN27="",1,AN27)) -> #N/A
B38: Lavet af: Mikkel Vive, 2018
