Workbook
Name kabel: Kabel!$C$5:$C$74
Name kabeltilledning: 'Kabel gummi'!$C$5:$C$53
Name kabelvalg: Transformer!#REF!
Name kabelvalg: Transformer!#REF!
Name kabelvalg: Transformer!#REF!
Name kabelvalg2: 'udregning 2'!$A$2:$A$21
Name kabelvalg3: 'udregning 2'!$A$2:$A$21

Sheet LX
A1: NOIKLX

Sheet Transformer
A7: Beregning af Z̅N
A8: SKN | D8: 150 | F8: MVA
A9: R/X | D9: 0.3
A10: UN | D10: 400 | F10: V
A11: ZN | B11: = | D11: UN² | G11: => | K11: =D10 -> 400 | M11: ² | T11: = | U11: =IF(D8="","",IF(D8>0,ROUND(D10^2/(D8*10^6),4))) -> 0.0011
D12: SKN | K12: =IF(D8="","",D8) -> 150 | L12: * | M12: 10 | N12: 6
A13: ϕN | B13: = | D13: =IF(A9=AE14,"tan-1",IF(A9=AE15,"cos-1")) -> tan-1 | E13: ( | F13: =IF(A9=AE14,1,IF(A9=AE15,"cosϕ")) -> 1 | G13: ) | I13: => | K13: =IF($A$9=$AE$14,"tan-1",IF($A$9=$AE$15,"cos-1")) -> tan-1 | M13: ( | O13: =IF($A$9=$AE$14,1,IF($A$9=$AE$15,D9)) -> 1 | P13: ) | T13: = | U13: =IF(D9="","",IF(D9>0,(IF(A9=AE14,(DEGREES(ATAN((1/D9)))),IF(A9=AE15,(DEGREES(ACOS(D9)))))))) -> 73.300756
F14: =IF(A9=AE14,"R/X",IF(A9=AE15,1)) -> R/X | O14: =IF(D9="","",IF(A9=AE14,D9,IF(A9=AE15,1))) -> 0.3 | AE14: R/X
A15: Z̅N | O15: =IF(D8="","",IF(D8>0,U11,)) -> 0.0011 | T15: Ð | U15: =U13 -> 73.300756 | AE15: cosϕ
A17: Beregning af transformer Z̅T
A18: S1/1 | D18: 630 | F18: kVA | AD18: =(IF($A$20="PCU",1)+IF($A$20="er",2)) -> 2 | AE18: =(IF($A$20="PCU",1)+IF($A$20="er",2)) -> 2 | AG18: RT | AH18: ZT
A19: ek | D19: 5 | F19: % | AD19: 1 | AE19: PCU | AF19: 23 | AG19: er | AH19: ek
A20: er | D20: 4 | F20: =IF(A20="PCU","W",IF(A20="er","%",)) -> % | AD20: 2 | AE20: er | AF20: 224
A21: UT | D21: 420 | F21: V
A22: ZT | B22: = | D22: ek * U²T | I22: => | K22: =IF(D19="","",D19) -> 5 | M22: * | O22: =IF(D21="","",D21) -> 420 | P22: ² | T22: = | U22: =IF(D18="","",ROUND((D19*D21^2)/(100*D18*10^3),4)) -> 0.014
D23: 100 * S1/1 | K23: 100 | M23: * | N23: ( | O23: =IF(D18="","",D18) -> 630 | P23: *103 )
A24: RT | B24: = | D24: PCU * U²T | I24: => | K24: =IF(D20="","",D20) -> 4 | M24: * | O24: =IF(D21="","",D21) -> 420 | P24: ² | T24: = | U24: =IF(D18="","",ROUND((D20*D21^2)/(D18*10^3)^2,4)) -> 0
D25: S²1/1 | J25: ( | K25: =IF(D18="","",IF(D18>0,D18)) -> 630 | M25: *103 )2
A26: ϕT | B26: = | D26: cos-1 | E26: ( | F26: =IF(A20="PCU","RT",IF(A20="er","er",)) -> er | G26: ) | I26: cos-1 | K26: ( | L26: =IF(D19="","",IF(F26=A24,U24,IF(F26=A20,D20,))) -> 4 | P26: ) | T26: = | U26: =IF(D20="","",ROUND(DEGREES(ACOS(L26/L27)),2)) -> 36.87
F27: =IF(A20="PCU","ZT",IF(A20="er","ek",)) -> ek | L27: =IF(D19="","",IF(F27=A22,U22,IF(F27=A19,D19,))) -> 5
A28: Z̅T | M28: = | O28: =U22 -> 0.014 | T28: Ð | U28: =U26 -> 36.87
A30: Kortslutningsstrøm på transformers sekundær klemmer
A32: IKmax3F | B32: = | E32: UN
D33: √3 | E33: * | F33: ( Z̅N + Z̅T)
A35: IKmax3F | B35: = | D35: =D10 -> 400 | V35: = | W35: =IF(O15="","",IF(O15>0,ROUND((D35/(SQRT(3)*A81))*10^-3,2))) -> 15.5
D36: √3 | E36: * | F36: =O15 -> 0.0011 | H36: Ð | I36: =U15 -> 73.300756 | L36: + | M36: =O28 -> 0.014 | P36: Ð | Q36: =U28 -> 36.87
A38: IKFPE(N) | B38: = | C38: IKmax3F
A40: IK2F | B40: = | D40: √3 | E40: * | F40: IKmax3F | G40: <=> | I40: √3 | K40: * | L40: =W35 -> 15.5 | V40: = | W40: =IF(W35="","",IF(W35>0,(SQRT(3)/2)*W35)) -> 13.423394
D41: 2 | I41: 2
A45: Hvis der ikke er nogen transformerdata kan der bruges disse værdier IKmax 16kA cosϕ 0,3 Ikmin = 5 gange stikledningenssikringens mærkestrøm
A49: Beregning af Z̅Nmax ved oplyst IKmax
A50: IKmax | D50: 16 | E50: kA
A51: UN | D51: 400 | E51: V
A52: cosϕ | D52: 0.3
A54: Z̅max | B54: = | D54: UN | G54: Ð | H54: cos-1ϕ
D55: √3 * IKmax * 103
D57: 400 | I57: Ð cos-1 | K57: =IF(D52="","",D52) -> 0.3 | L57: =
D58: √3 x | E58: =D50 -> 16 | G58: x 103
A59: Z̅Nmax | C59: =(IF(D50="","",(D51/(D50*10^3*SQRT(3))))) -> 0.014433757 | E59: =IF(D50="","",IF(D50>0,AJ66,)) -> Ð | F59: =IF(D52="","",ROUND(DEGREES(ACOS(D52)),4)) -> 72.5424
A62: Beregning af Z̅Nmin ved oplyst IKmin
...

Sheet KabelData
U1: CU 1
A2: Kabel 1 | E2: Kabel 2 | I2: Kabel 3 | M2: Kabel 4 | Q2: Kabel 5 | U2: 0.75 | V2: 1 | W2: 1 | X2: 2
A3: Navn | B3: -W1 | F3: -W2 | J3: -W3 | N3: -W4 | R3: -E5 | U3: 1 | V3: 3 | W3: 4 | X3: 3
A4: Materiale | B4: CU | F4: CU | J4: CU | N4: CU | R4: CU | U4: 1.5 | V4: 4 | W4: 5 | X4: 4
A5: Antal ledere | B5: 4 | F5: 4 | J5: 5 | N5: 3 | U5: 2.5 | V5: 5 | X5: 5
A6: Kvadrat (mm²) | B6: 50 | F6: 16 | J6: 6 | N6: 1.5 | U6: 4
A7: Længde (m) | B7: 15 | E7: m | F7: 20 | I7: m | J7: 20 | M7: m | N7: 18 | Q7: m | U7: 6
A8: Paralle (n) | B8: 1 | E8: n | F8: 1 | I8: n | J8: 1 | M8: n | N8: 1 | Q8: n | R8: 1 | U8: 10
A9: I̅ B | B9: 121 | C9: Ð- | D9: 90 | F9: 50 | G9: Ð- | H9: 90 | J9: 26 | K9: Ð- | L9: 90 | N9: 10 | O9: Ð- | P9: 90 | S9: Ð- | U9: 16
A10: Z20° | B10: =IF(B6="","",IF(B6>0,IF(KabelData!$B$4="CU",(IF(KabelData!$B$5=1,VLOOKUP(KabelData!$B$6,Kabel!$C$49:$G$63,4,FALSE))+IF(KabelData!$B$5=3,VLOOKUP(KabelData!$B$6,Kabel!$C$5:$G$12,4,FALSE))+IF(KabelData!$B$5=4,VLOOKUP(KabelData!$B$6,Kabel!$C$13:$G$27,4,FALSE))+IF(KabelData!B5=5,VLOOKUP(KabelData!$B$6,Kabel!$C$28:$G$35,4,FALSE))))+IF(KabelData!$B$4="AL",(IF(KabelData!$B$5=1,VLOOKUP(KabelData!$B$6,Kabel!$C$64:$G$74,4,FALSE))+IF(KabelData!$B$5=4,VLOOKUP(KabelData!$B$6,Kabel!$C$36:$G$46,4,FALSE))+IF(KabelData!$B$5=5,VLOOKUP(KabelData!$B$6,Kabel!$C$47:$G$48,4,FALSE))))+IF(KabelData!$B$4="Tilledning",(IF(KabelData!$B$5=2,VLOOKUP(KabelData!$B$6,Kabel!$C$83:$G$86,4,FALSE))+IF(KabelData!$B$5=3,VLOOKUP(KabelData!$B$6,Kabel!$C$87:$G$96,4,FALSE))+IF(KabelData!$B$5=4,VLOOKUP(KabelData!$B$6,Kabel!$C$97:$G$114,4,FALSE))+IF(KabelData!$B$5=5,VLOOKUP(KabelData!$B$6,Kabel!$C$115:$G$123,4,FALSE)))))) -> 0.39698866 | E10: Z20° | F10: =IF(F6="","",IF(KabelData!F4="CU",(IF(KabelData!F5=1,VLOOKUP(KabelData!F6,Kabel!$C$49:$G$63,4,FALSE))+IF(KabelData!F5=3,VLOOKUP(KabelData!F6,Kabel!$C$5:$G$12,4,FALSE))+IF(KabelData!F5=4,VLOOKUP(KabelData!F6,Kabel!$C$13:$G$27,4,FALSE))+IF(KabelData!F5=5,VLOOKUP(KabelData!F6,Kabel!$C$28:$G$35,4,FALSE))))+IF(KabelData!F4="AL",(IF(KabelData!F5=1,VLOOKUP(KabelData!F6,Kabel!$C$64:$G$74,4,FALSE))+IF(KabelData!F5=4,VLOOKUP(KabelData!F6,Kabel!$C$36:$G$46,4,FALSE))+IF(KabelData!F5=5,VLOOKUP(KabelData!F6,Kabel!$C$47:$G$48,4,FALSE))))+IF(KabelData!F4="Tilledning",(IF(KabelData!F5=2,VLOOKUP(KabelData!F6,Kabel!$C$83:$G$86,4,FALSE))+IF(KabelData!F5=3,VLOOKUP(KabelData!F6,Kabel!$C$87:$G$96,4,FALSE))+IF(KabelData!F5=4,VLOOKUP(KabelData!F6,Kabel!$C$97:$G$114,4,FALSE))+IF(KabelData!F5=5,VLOOKUP(KabelData!F6,Kabel!$C$115:$G$123,4,FALSE))))) -> 1.153137 | I10: Z20° | J10: =IF(J6="","",IF(KabelData!J4="CU",(IF(KabelData!J5=1,VLOOKUP(KabelData!J6,Kabel!$C$49:$G$63,4,FALSE))+IF(KabelData!J5=3,VLOOKUP(KabelData!J6,Kabel!$C$5:$G$12,4,FALSE))+IF(KabelData!J5=4,VLOOKUP(KabelData!J6,Kabel!$C$13:$G$27,4,FALSE))+IF(KabelData!J5=5,VLOOKUP(KabelData!J6,Kabel!$C$28:$G$35,4,FALSE))))+IF(KabelData!J4="AL",(IF(KabelData!J5=1,VLOOKUP(KabelData!J6,Kabel!$C$64:$G$74,4,FALSE))+IF(KabelData!J5=4,VLOOKUP(KabelData!J6,Kabel!$C$36:$G$46,4,FALSE))+IF(KabelData!J5=5,VLOOKUP(KabelData!J6,Kabel!$C$47:$G$48,4,FALSE))))+IF(KabelData!J4="Tilledning",(IF(KabelData!J5=2,VLOOKUP(KabelData!J6,Kabel!$C$83:$G$86,4,FALSE))+IF(KabelData!J5=3,VLOOKUP(KabelData!J6,Kabel!$C$87:$G$96,4,FALSE))+IF(KabelData!J5=4,VLOOKUP(KabelData!J6,Kabel!$C$97:$G$114,4,FALSE))+IF(KabelData!J5=5,VLOOKUP(KabelData!J6,Kabel!$C$115:$G$123,4,FALSE))))) -> 3.0815271 | M10: Z20° | N10: =IF(N6="","",IF(KabelData!N4="CU",(IF(KabelData!N5=1,VLOOKUP(KabelData!N6,Kabel!$C$49:$G$63,4,FALSE))+IF(KabelData!N5=3,VLOOKUP(KabelData!N6,Kabel!$C$5:$G$12,4,FALSE))+IF(KabelData!N5=4,VLOOKUP(KabelData!N6,Kabel!$C$13:$G$27,4,FALSE))+IF(KabelData!N5=5,VLOOKUP(KabelData!N6,Kabel!$C$28:$G$35,4,FALSE))))+IF(KabelData!N4="AL",(IF(KabelData!N5=1,VLOOKUP(KabelData!N6,Kabel!$C$64:$G$74,4,FALSE))+IF(KabelData!N5=4,VLOOKUP(KabelData!N6,Kabel!$C$36:$G$46,4,FALSE))+IF(KabelData!N5=5,VLOOKUP(KabelData!N6,Kabel!$C$47:$G$48,4,FALSE))))+IF(KabelData!N4="Tilledning",(IF(KabelData!N5=2,VLOOKUP(KabelData!N6,Kabel!$C$83:$G$86,4,FALSE))+IF(KabelData!N5=3,VLOOKUP(KabelData!N6,Kabel!$C$87:$G$96,4,FALSE))+IF(KabelData!N5=4,VLOOKUP(KabelData!N6,Kabel!$C$97:$G$114,4,FALSE))+IF(KabelData!N5=5,VLOOKUP(KabelData!N6,Kabel!$C$115:$G$123,4,FALSE))))) -> 12.100438 | Q10: Z20° | R10: =IF(R6="","",IF(KabelData!R4="CU",(IF(KabelData!R5=1,VLOOKUP(KabelData!R6,Kabel!$C$49:$G$63,4,FALSE))+IF(KabelData!R5=3,VLOOKUP(KabelData!R6,Kabel!$C$5:$G$12,4,FALSE))+IF(KabelData!R5=4,VLOOKUP(KabelData!R6,Kabel!$C$13:$G$27,4,FALSE))+IF(KabelData!R5=5,VLOOKUP(KabelData!R6,Kabel!$C$28:$G$35,4,FALSE))))+IF(KabelData!R4="AL",(IF(KabelData!R5=1,VLOOKUP(KabelData!R6,Kabel!$C$64:$G$74,4,FALSE))+IF(KabelData!R5=4,VLOOKUP(KabelData!R6,Kabel!$C$36:$G$46,4,FALSE))+IF(KabelData!R5=5,VLOOKUP(KabelData!R6,Kabel!$C$47:$G$48,4,FALSE))))+IF(KabelData!R4="Tilledning",(IF(KabelData!R5=2,VLOOKUP(KabelData!R6,Kabel!$C$83:$G$86,4,FALSE))+IF(KabelData!R5=3,VLOOKUP(KabelData!R6,Kabel!$C$87:$G$96,4,FALSE))+IF(KabelData!R5=4,VLOOKUP(KabelData!R6,Kabel!$C$97:$G$114,4,FALSE))+IF(KabelData!R5=5,VLOOKUP(KabelData!R6,Kabel!$C$115:$G$123,4,FALSE))))) | U10: 25
A11: Ð 20° | B11: =IF(B6="","",IF(KabelData!B4="CU",(IF(KabelData!B5=1,VLOOKUP(KabelData!B6,Kabel!$C$49:$G$63,5,FALSE))+IF(KabelData!B5=3,VLOOKUP(KabelData!B6,Kabel!$C$5:$G$12,5,FALSE))+IF(KabelData!B5=4,VLOOKUP(KabelData!B6,Kabel!$C$13:$G$27,5,FALSE))+IF(KabelData!B5=5,VLOOKUP(KabelData!B6,Kabel!$C$28:$G$35,5,FALSE))))+IF(KabelData!B4="AL",(IF(KabelData!B5=1,VLOOKUP(KabelData!B6,Kabel!$C$64:$G$74,5,FALSE))+IF(KabelData!B5=4,VLOOKUP(KabelData!B6,Kabel!$C$36:$G$46,5,FALSE))+IF(KabelData!B5=5,VLOOKUP(KabelData!B6,Kabel!$C$47:$G$48,5,FALSE))))+IF(KabelData!B4="Tilledning",(IF(KabelData!B5=2,VLOOKUP(KabelData!B6,Kabel!$C$83:$G$86,5,FALSE))+IF(KabelData!B5=3,VLOOKUP(KabelData!B6,Kabel!$C$87:$G$96,5,FALSE))+IF(KabelData!B5=4,VLOOKUP(KabelData!B6,Kabel!$C$97:$G$114,5,FALSE))+IF(KabelData!B5=5,VLOOKUP(KabelData!B6,Kabel!$C$115:$G$123,5,FALSE))))) -> 12.215719 | E11: Ð 20° | F11: =IF(F6="","",IF(KabelData!F4="CU",(IF(KabelData!F5=1,VLOOKUP(KabelData!F6,Kabel!$C$49:$G$63,5,FALSE))+IF(KabelData!F5=3,VLOOKUP(KabelData!F6,Kabel!$C$5:$G$12,5,FALSE))+IF(KabelData!F5=4,VLOOKUP(KabelData!F6,Kabel!$C$13:$G$27,5,FALSE))+IF(KabelData!F5=5,VLOOKUP(KabelData!F6,Kabel!$C$28:$G$35,5,FALSE))))+IF(KabelData!F4="AL",(IF(KabelData!F5=1,VLOOKUP(KabelData!F6,Kabel!$C$64:$G$74,5,FALSE))+IF(KabelData!F5=4,VLOOKUP(KabelData!F6,Kabel!$C$36:$G$46,5,FALSE))+IF(KabelData!F5=5,VLOOKUP(KabelData!F6,Kabel!$C$47:$G$48,5,FALSE))))+IF(KabelData!F4="Tilledning",(IF(KabelData!F5=2,VLOOKUP(KabelData!F6,Kabel!$C$83:$G$86,5,FALSE))+IF(KabelData!F5=3,VLOOKUP(KabelData!F6,Kabel!$C$87:$G$96,5,FALSE))+IF(KabelData!F5=4,VLOOKUP(KabelData!F6,Kabel!$C$97:$G$114,5,FALSE))+IF(KabelData!F5=5,VLOOKUP(KabelData!F6,Kabel!$C$115:$G$123,5,FALSE))))) -> 4.2272187 | I11: Ð 20° | J11: =IF(J6="","",IF(KabelData!J4="CU",(IF(KabelData!J5=1,VLOOKUP(KabelData!J6,Kabel!$C$49:$G$63,5,FALSE))+IF(KabelData!J5=3,VLOOKUP(KabelData!J6,Kabel!$C$5:$G$12,5,FALSE))+IF(KabelData!J5=4,VLOOKUP(KabelData!J6,Kabel!$C$13:$G$27,5,FALSE))+IF(KabelData!J5=5,VLOOKUP(KabelData!J6,Kabel!$C$28:$G$35,5,FALSE))))+IF(KabelData!J4="AL",(IF(KabelData!J5=1,VLOOKUP(KabelData!J6,Kabel!$C$64:$G$74,5,FALSE))+IF(KabelData!J5=4,VLOOKUP(KabelData!J6,Kabel!$C$36:$G$46,5,FALSE))+IF(KabelData!J5=5,VLOOKUP(KabelData!J6,Kabel!$C$47:$G$48,5,FALSE))))+IF(KabelData!J4="Tilledning",(IF(KabelData!J5=2,VLOOKUP(KabelData!J6,Kabel!$C$83:$G$86,5,FALSE))+IF(KabelData!J5=3,VLOOKUP(KabelData!J6,Kabel!$C$87:$G$96,5,FALSE))+IF(KabelData!J5=4,VLOOKUP(KabelData!J6,Kabel!$C$97:$G$114,5,FALSE))+IF(KabelData!J5=5,VLOOKUP(KabelData!J6,Kabel!$C$115:$G$123,5,FALSE))))) -> 1.8038488 | M11: Ð 20° | N11: =IF(N6="","",IF(KabelData!N4="CU",(IF(KabelData!N5=1,VLOOKUP(KabelData!N6,Kabel!$C$49:$G$63,5,FALSE))+IF(KabelData!N5=3,VLOOKUP(KabelData!N6,Kabel!$C$5:$G$12,5,FALSE))+IF(KabelData!N5=4,VLOOKUP(KabelData!N6,Kabel!$C$13:$G$27,5,FALSE))+IF(KabelData!N5=5,VLOOKUP(KabelData!N6,Kabel!$C$28:$G$35,5,FALSE))))+IF(KabelData!N4="AL",(IF(KabelData!N5=1,VLOOKUP(KabelData!N6,Kabel!$C$64:$G$74,5,FALSE))+IF(KabelData!N5=4,VLOOKUP(KabelData!N6,Kabel!$C$36:$G$46,5,FALSE))+IF(KabelData!N5=5,VLOOKUP(KabelData!N6,Kabel!$C$47:$G$48,5,FALSE))))+IF(KabelData!N4="Tilledning",(IF(KabelData!N5=2,VLOOKUP(KabelData!N6,Kabel!$C$83:$G$86,5,FALSE))+IF(KabelData!N5=3,VLOOKUP(KabelData!N6,Kabel!$C$87:$G$96,5,FALSE))+IF(KabelData!N5=4,VLOOKUP(KabelData!N6,Kabel!$C$97:$G$114,5,FALSE))+IF(KabelData!N5=5,VLOOKUP(KabelData!N6,Kabel!$C$115:$G$123,5,FALSE))))) -> 0.48771262 | Q11: Ð 20° | R11: =IF(R6="","",IF(KabelData!R4="CU",(IF(KabelData!R5=1,VLOOKUP(KabelData!R6,Kabel!$C$49:$G$63,5,FALSE))+IF(KabelData!R5=3,VLOOKUP(KabelData!R6,Kabel!$C$5:$G$12,5,FALSE))+IF(KabelData!R5=4,VLOOKUP(KabelData!R6,Kabel!$C$13:$G$27,5,FALSE))+IF(KabelData!R5=5,VLOOKUP(KabelData!R6,Kabel!$C$28:$G$35,5,FALSE))))+IF(KabelData!R4="AL",(IF(KabelData!R5=1,VLOOKUP(KabelData!R6,Kabel!$C$64:$G$74,5,FALSE))+IF(KabelData!R5=4,VLOOKUP(KabelData!R6,Kabel!$C$36:$G$46,5,FALSE))+IF(KabelData!R5=5,VLOOKUP(KabelData!R6,Kabel!$C$47:$G$48,5,FALSE))))+IF(KabelData!R4="Tilledning",(IF(KabelData!R5=2,VLOOKUP(KabelData!R6,Kabel!$C$83:$G$86,5,FALSE))+IF(KabelData!R5=3,VLOOKUP(KabelData!R6,Kabel!$C$87:$G$96,5,FALSE))+IF(KabelData!R5=4,VLOOKUP(KabelData!R6,Kabel!$C$97:$G$114,5,FALSE))+IF(KabelData!R5=5,VLOOKUP(KabelData!R6,Kabel!$C$115:$G$123,5,FALSE))))) | U11: 35
A12: R | B12: =IF(B6="","",IF(KabelData!B4="CU",(IF(KabelData!B5=1,VLOOKUP(KabelData!B6,Kabel!$C$49:$G$63,2,FALSE))+IF(KabelData!B5=3,VLOOKUP(KabelData!B6,Kabel!$C$5:$G$12,2,FALSE))+IF(KabelData!B5=4,VLOOKUP(KabelData!B6,Kabel!$C$13:$G$27,2,FALSE))+IF(KabelData!B5=5,VLOOKUP(KabelData!B6,Kabel!$C$28:$G$35,2,FALSE))))+IF(KabelData!B4="AL",(IF(KabelData!B5=1,VLOOKUP(KabelData!B6,Kabel!$C$64:$G$74,2,FALSE))+IF(KabelData!B5=4,VLOOKUP(KabelData!B6,Kabel!$C$36:$G$46,2,FALSE))+IF(KabelData!B5=5,VLOOKUP(KabelData!B6,Kabel!$C$47:$G$48,2,FALSE))))+IF(KabelData!B4="Tilledning",(IF(KabelData!B5=2,VLOOKUP(KabelData!B6,Kabel!$C$83:$G$86,2,FALSE))+IF(KabelData!B5=3,VLOOKUP(KabelData!B6,Kabel!$C$87:$G$96,2,FALSE))+IF(KabelData!B5=4,VLOOKUP(KabelData!B6,Kabel!$C$97:$G$114,2,FALSE))+IF(KabelData!B5=5,VLOOKUP(KabelData!B6,Kabel!$C$115:$G$123,2,FALSE))))) -> 0.388 | E12: R | F12: =IF(F6="","",IF(KabelData!F4="CU",(IF(KabelData!F5=1,VLOOKUP(KabelData!F6,Kabel!$C$49:$G$63,2,FALSE))+IF(KabelData!F5=3,VLOOKUP(KabelData!F6,Kabel!$C$5:$G$12,2,FALSE))+IF(KabelData!F5=4,VLOOKUP(KabelData!F6,Kabel!$C$13:$G$27,2,FALSE))+IF(KabelData!F5=5,VLOOKUP(KabelData!F6,Kabel!$C$28:$G$35,2,FALSE))))+IF(KabelData!F4="AL",(IF(KabelData!F5=1,VLOOKUP(KabelData!F6,Kabel!$C$64:$G$74,2,FALSE))+IF(KabelData!F5=4,VLOOKUP(KabelData!F6,Kabel!$C$36:$G$46,2,FALSE))+IF(KabelData!F5=5,VLOOKUP(KabelData!F6,Kabel!$C$47:$G$48,2,FALSE))))+IF(KabelData!F4="Tilledning",(IF(KabelData!F5=2,VLOOKUP(KabelData!F6,Kabel!$C$83:$G$86,2,FALSE))+IF(KabelData!F5=3,VLOOKUP(KabelData!F6,Kabel!$C$87:$G$96,2,FALSE))+IF(KabelData!F5=4,VLOOKUP(KabelData!F6,Kabel!$C$97:$G$114,2,FALSE))+IF(KabelData!F5=5,VLOOKUP(KabelData!F6,Kabel!$C$115:$G$123,2,FALSE))))) -> 1.15 | I12: R | J12: =IF(J6="","",IF(KabelData!J4="CU",(IF(KabelData!J5=1,VLOOKUP(KabelData!J6,Kabel!$C$49:$G$63,2,FALSE))+IF(KabelData!J5=3,VLOOKUP(KabelData!J6,Kabel!$C$5:$G$12,2,FALSE))+IF(KabelData!J5=4,VLOOKUP(KabelData!J6,Kabel!$C$13:$G$27,2,FALSE))+IF(KabelData!J5=5,VLOOKUP(KabelData!J6,Kabel!$C$28:$G$35,2,FALSE))))+IF(KabelData!J4="AL",(IF(KabelData!J5=1,VLOOKUP(KabelData!J6,Kabel!$C$64:$G$74,2,FALSE))+IF(KabelData!J5=4,VLOOKUP(KabelData!J6,Kabel!$C$36:$G$46,2,FALSE))+IF(KabelData!J5=5,VLOOKUP(KabelData!J6,Kabel!$C$47:$G$48,2,FALSE))))+IF(KabelData!J4="Tilledning",(IF(KabelData!J5=2,VLOOKUP(KabelData!J6,Kabel!$C$83:$G$86,2,FALSE))+IF(KabelData!J5=3,VLOOKUP(KabelData!J6,Kabel!$C$87:$G$96,2,FALSE))+IF(KabelData!J5=4,VLOOKUP(KabelData!J6,Kabel!$C$97:$G$114,2,FALSE))+IF(KabelData!J5=5,VLOOKUP(KabelData!J6,Kabel!$C$115:$G$123,2,FALSE))))) -> 3.08 | M12: R | N12: =IF(N6="","",IF(KabelData!N4="CU",(IF(KabelData!N5=1,VLOOKUP(KabelData!N6,Kabel!$C$49:$G$63,2,FALSE))+IF(KabelData!N5=3,VLOOKUP(KabelData!N6,Kabel!$C$5:$G$12,2,FALSE))+IF(KabelData!N5=4,VLOOKUP(KabelData!N6,Kabel!$C$13:$G$27,2,FALSE))+IF(KabelData!N5=5,VLOOKUP(KabelData!N6,Kabel!$C$28:$G$35,2,FALSE))))+IF(KabelData!N4="AL",(IF(KabelData!N5=1,VLOOKUP(KabelData!N6,Kabel!$C$64:$G$74,2,FALSE))+IF(KabelData!N5=4,VLOOKUP(KabelData!N6,Kabel!$C$36:$G$46,2,FALSE))+IF(KabelData!N5=5,VLOOKUP(KabelData!N6,Kabel!$C$47:$G$48,2,FALSE))))+IF(KabelData!N4="Tilledning",(IF(KabelData!N5=2,VLOOKUP(KabelData!N6,Kabel!$C$83:$G$86,2,FALSE))+IF(KabelData!N5=3,VLOOKUP(KabelData!N6,Kabel!$C$87:$G$96,2,FALSE))+IF(KabelData!N5=4,VLOOKUP(KabelData!N6,Kabel!$C$97:$G$114,2,FALSE))+IF(KabelData!N5=5,VLOOKUP(KabelData!N6,Kabel!$C$115:$G$123,2,FALSE))))) -> 12.1 | Q12: R | R12: =IF(R6="","",IF(KabelData!R4="CU",(IF(KabelData!R5=1,VLOOKUP(KabelData!R6,Kabel!$C$49:$G$63,2,FALSE))+IF(KabelData!R5=3,VLOOKUP(KabelData!R6,Kabel!$C$5:$G$12,2,FALSE))+IF(KabelData!R5=4,VLOOKUP(KabelData!R6,Kabel!$C$13:$G$27,2,FALSE))+IF(KabelData!R5=5,VLOOKUP(KabelData!R6,Kabel!$C$28:$G$35,2,FALSE))))+IF(KabelData!R4="AL",(IF(KabelData!R5=1,VLOOKUP(KabelData!R6,Kabel!$C$64:$G$74,2,FALSE))+IF(KabelData!R5=4,VLOOKUP(KabelData!R6,Kabel!$C$36:$G$46,2,FALSE))+IF(KabelData!R5=5,VLOOKUP(KabelData!R6,Kabel!$C$47:$G$48,2,FALSE))))+IF(KabelData!R4="Tilledning",(IF(KabelData!R5=2,VLOOKUP(KabelData!R6,Kabel!$C$83:$G$86,2,FALSE))+IF(KabelData!R5=3,VLOOKUP(KabelData!R6,Kabel!$C$87:$G$96,2,FALSE))+IF(KabelData!R5=4,VLOOKUP(KabelData!R6,Kabel!$C$97:$G$114,2,FALSE))+IF(KabelData!R5=5,VLOOKUP(KabelData!R6,Kabel!$C$115:$G$123,2,FALSE))))) | U12: 50
A13: X | B13: =IF(B6="","",IF(KabelData!B4="CU",(IF(KabelData!B5=1,VLOOKUP(KabelData!B6,Kabel!$C$49:$G$63,3,FALSE))+IF(KabelData!B5=3,VLOOKUP(KabelData!B6,Kabel!$C$5:$G$12,3,FALSE))+IF(KabelData!B5=4,VLOOKUP(KabelData!B6,Kabel!$C$13:$G$27,3,FALSE))+IF(KabelData!B5=5,VLOOKUP(KabelData!B6,Kabel!$C$28:$G$35,3,FALSE))))+IF(KabelData!B4="AL",(IF(KabelData!B5=1,VLOOKUP(KabelData!B6,Kabel!$C$64:$G$74,3,FALSE))+IF(KabelData!B5=4,VLOOKUP(KabelData!B6,Kabel!$C$36:$G$46,3,FALSE))+IF(KabelData!B5=5,VLOOKUP(KabelData!B6,Kabel!$C$47:$G$48,3,FALSE))))+IF(KabelData!B4="Tilledning",(IF(KabelData!B5=2,VLOOKUP(KabelData!B6,Kabel!$C$83:$G$86,3,FALSE))+IF(KabelData!B5=3,VLOOKUP(KabelData!B6,Kabel!$C$87:$G$96,3,FALSE))+IF(KabelData!B5=4,VLOOKUP(KabelData!B6,Kabel!$C$97:$G$114,3,FALSE))+IF(KabelData!B5=5,VLOOKUP(KabelData!B6,Kabel!$C$115:$G$123,3,FALSE))))) -> 0.084 | E13: X | F13: =IF(F6="","",IF(KabelData!F4="CU",(IF(KabelData!F5=1,VLOOKUP(KabelData!F6,Kabel!$C$49:$G$63,3,FALSE))+IF(KabelData!F5=3,VLOOKUP(KabelData!F6,Kabel!$C$5:$G$12,3,FALSE))+IF(KabelData!F5=4,VLOOKUP(KabelData!F6,Kabel!$C$13:$G$27,3,FALSE))+IF(KabelData!F5=5,VLOOKUP(KabelData!F6,Kabel!$C$28:$G$35,3,FALSE))))+IF(KabelData!F4="AL",(IF(KabelData!F5=1,VLOOKUP(KabelData!F6,Kabel!$C$64:$G$74,3,FALSE))+IF(KabelData!F5=4,VLOOKUP(KabelData!F6,Kabel!$C$36:$G$46,3,FALSE))+IF(KabelData!F5=5,VLOOKUP(KabelData!F6,Kabel!$C$47:$G$48,3,FALSE))))+IF(KabelData!F4="Tilledning",(IF(KabelData!F5=2,VLOOKUP(KabelData!F6,Kabel!$C$83:$G$86,3,FALSE))+IF(KabelData!F5=3,VLOOKUP(KabelData!F6,Kabel!$C$87:$G$96,3,FALSE))+IF(KabelData!F5=4,VLOOKUP(KabelData!F6,Kabel!$C$97:$G$114,3,FALSE))+IF(KabelData!F5=5,VLOOKUP(KabelData!F6,Kabel!$C$115:$G$123,3,FALSE))))) -> 0.085 | I13: X | J13: =IF(J6="","",IF(KabelData!J4="CU",(IF(KabelData!J5=1,VLOOKUP(KabelData!J6,Kabel!$C$49:$G$63,3,FALSE))+IF(KabelData!J5=3,VLOOKUP(KabelData!J6,Kabel!$C$5:$G$12,3,FALSE))+IF(KabelData!J5=4,VLOOKUP(KabelData!J6,Kabel!$C$13:$G$27,3,FALSE))+IF(KabelData!J5=5,VLOOKUP(KabelData!J6,Kabel!$C$28:$G$35,3,FALSE))))+IF(KabelData!J4="AL",(IF(KabelData!J5=1,VLOOKUP(KabelData!J6,Kabel!$C$64:$G$74,3,FALSE))+IF(KabelData!J5=4,VLOOKUP(KabelData!J6,Kabel!$C$36:$G$46,3,FALSE))+IF(KabelData!J5=5,VLOOKUP(KabelData!J6,Kabel!$C$47:$G$48,3,FALSE))))+IF(KabelData!J4="Tilledning",(IF(KabelData!J5=2,VLOOKUP(KabelData!J6,Kabel!$C$83:$G$86,3,FALSE))+IF(KabelData!J5=3,VLOOKUP(KabelData!J6,Kabel!$C$87:$G$96,3,FALSE))+IF(KabelData!J5=4,VLOOKUP(KabelData!J6,Kabel!$C$97:$G$114,3,FALSE))+IF(KabelData!J5=5,VLOOKUP(KabelData!J6,Kabel!$C$115:$G$123,3,FALSE))))) -> 0.097 | M13: X | N13: =IF(N6="","",IF(KabelData!N4="CU",(IF(KabelData!N5=1,VLOOKUP(KabelData!N6,Kabel!$C$49:$G$63,3,FALSE))+IF(KabelData!N5=3,VLOOKUP(KabelData!N6,Kabel!$C$5:$G$12,3,FALSE))+IF(KabelData!N5=4,VLOOKUP(KabelData!N6,Kabel!$C$13:$G$27,3,FALSE))+IF(KabelData!N5=5,VLOOKUP(KabelData!N6,Kabel!$C$28:$G$35,3,FALSE))))+IF(KabelData!N4="AL",(IF(KabelData!N5=1,VLOOKUP(KabelData!N6,Kabel!$C$64:$G$74,3,FALSE))+IF(KabelData!N5=4,VLOOKUP(KabelData!N6,Kabel!$C$36:$G$46,3,FALSE))+IF(KabelData!N5=5,VLOOKUP(KabelData!N6,Kabel!$C$47:$G$48,3,FALSE))))+IF(KabelData!N4="Tilledning",(IF(KabelData!N5=2,VLOOKUP(KabelData!N6,Kabel!$C$83:$G$86,3,FALSE))+IF(KabelData!N5=3,VLOOKUP(KabelData!N6,Kabel!$C$87:$G$96,3,FALSE))+IF(KabelData!N5=4,VLOOKUP(KabelData!N6,Kabel!$C$97:$G$114,3,FALSE))+IF(KabelData!N5=5,VLOOKUP(KabelData!N6,Kabel!$C$115:$G$123,3,FALSE))))) -> 0.103 | Q13: X | R13: =IF(R6="","",IF(KabelData!R4="CU",(IF(KabelData!R5=1,VLOOKUP(KabelData!R6,Kabel!$C$49:$G$63,3,FALSE))+IF(KabelData!R5=3,VLOOKUP(KabelData!R6,Kabel!$C$5:$G$12,3,FALSE))+IF(KabelData!R5=4,VLOOKUP(KabelData!R6,Kabel!$C$13:$G$27,3,FALSE))+IF(KabelData!R5=5,VLOOKUP(KabelData!R6,Kabel!$C$28:$G$35,3,FALSE))))+IF(KabelData!R4="AL",(IF(KabelData!R5=1,VLOOKUP(KabelData!R6,Kabel!$C$64:$G$74,3,FALSE))+IF(KabelData!R5=4,VLOOKUP(KabelData!R6,Kabel!$C$36:$G$46,3,FALSE))+IF(KabelData!R5=5,VLOOKUP(KabelData!R6,Kabel!$C$47:$G$48,3,FALSE))))+IF(KabelData!R4="Tilledning",(IF(KabelData!R5=2,VLOOKUP(KabelData!R6,Kabel!$C$83:$G$86,3,FALSE))+IF(KabelData!R5=3,VLOOKUP(KabelData!R6,Kabel!$C$87:$G$96,3,FALSE))+IF(KabelData!R5=4,VLOOKUP(KabelData!R6,Kabel!$C$97:$G$114,3,FALSE))+IF(KabelData!R5=5,VLOOKUP(KabelData!R6,Kabel!$C$115:$G$123,3,FALSE))))) | U13: 70
A14: Z70° | B14: =IF(B6="","",IF(KabelData!B4="CU",(IF(KabelData!B5=1,VLOOKUP(KabelData!B6,Kabel!$C$49:$K$63,6,FALSE))+IF(KabelData!B5=3,VLOOKUP(KabelData!B6,Kabel!$C$5:$K$12,6,FALSE))+IF(KabelData!B5=4,VLOOKUP(KabelData!B6,Kabel!$C$13:$K$27,6,FALSE))+IF(KabelData!B5=5,VLOOKUP(KabelData!B6,Kabel!$C$28:$K$35,6,FALSE))))+IF(KabelData!B4="AL",(IF(KabelData!B5=1,VLOOKUP(KabelData!B6,Kabel!$C$64:$K$74,6,FALSE))+IF(KabelData!B5=4,VLOOKUP(KabelData!B6,Kabel!$C$36:$K$46,6,FALSE))+IF(KabelData!B5=5,VLOOKUP(KabelData!B6,Kabel!$C$47:$K$48,6,FALSE))))+IF(KabelData!B4="Tilledning",(IF(KabelData!B5=2,VLOOKUP(KabelData!B6,Kabel!$C$83:$K$86,6,FALSE))+IF(KabelData!B5=3,VLOOKUP(KabelData!B6,Kabel!$C$87:$K$96,6,FALSE))+IF(KabelData!B5=4,VLOOKUP(KabelData!B6,Kabel!$C$97:$K$114,6,FALSE))+IF(KabelData!B5=5,VLOOKUP(KabelData!B6,Kabel!$C$115:$K$123,6,FALSE))))) -> 0.58803061 | E14: Z70° | F14: =IF(F6="","",IF(KabelData!F4="CU",(IF(KabelData!F5=1,VLOOKUP(KabelData!F6,Kabel!$C$49:$K$63,6,FALSE))+IF(KabelData!F5=3,VLOOKUP(KabelData!F6,Kabel!$C$5:$K$12,6,FALSE))+IF(KabelData!F5=4,VLOOKUP(KabelData!F6,Kabel!$C$13:$K$27,6,FALSE))+IF(KabelData!F5=5,VLOOKUP(KabelData!F6,Kabel!$C$28:$K$35,6,FALSE))))+IF(KabelData!F4="AL",(IF(KabelData!F5=1,VLOOKUP(KabelData!F6,Kabel!$C$64:$K$74,6,FALSE))+IF(KabelData!F5=4,VLOOKUP(KabelData!F6,Kabel!$C$36:$K$46,6,FALSE))+IF(KabelData!F5=5,VLOOKUP(KabelData!F6,Kabel!$C$47:$K$48,6,FALSE))))+IF(KabelData!F4="Tilledning",(IF(KabelData!F5=2,VLOOKUP(KabelData!F6,Kabel!$C$83:$K$86,6,FALSE))+IF(KabelData!F5=3,VLOOKUP(KabelData!F6,Kabel!$C$87:$K$96,6,FALSE))+IF(KabelData!F5=4,VLOOKUP(KabelData!F6,Kabel!$C$97:$K$114,6,FALSE))+IF(KabelData!F5=5,VLOOKUP(KabelData!F6,Kabel!$C$115:$K$123,6,FALSE))))) -> 1.7270929 | I14: Z70° | J14: =IF(J6="","",IF(KabelData!J4="CU",(IF(KabelData!J5=1,VLOOKUP(KabelData!J6,Kabel!$C$49:$K$63,6,FALSE))+IF(KabelData!J5=3,VLOOKUP(KabelData!J6,Kabel!$C$5:$K$12,6,FALSE))+IF(KabelData!J5=4,VLOOKUP(KabelData!J6,Kabel!$C$13:$K$27,6,FALSE))+IF(KabelData!J5=5,VLOOKUP(KabelData!J6,Kabel!$C$28:$K$35,6,FALSE))))+IF(KabelData!J4="AL",(IF(KabelData!J5=1,VLOOKUP(KabelData!J6,Kabel!$C$64:$K$74,6,FALSE))+IF(KabelData!J5=4,VLOOKUP(KabelData!J6,Kabel!$C$36:$K$46,6,FALSE))+IF(KabelData!J5=5,VLOOKUP(KabelData!J6,Kabel!$C$47:$K$48,6,FALSE))))+IF(KabelData!J4="Tilledning",(IF(KabelData!J5=2,VLOOKUP(KabelData!J6,Kabel!$C$83:$K$86,6,FALSE))+IF(KabelData!J5=3,VLOOKUP(KabelData!J6,Kabel!$C$87:$K$96,6,FALSE))+IF(KabelData!J5=4,VLOOKUP(KabelData!J6,Kabel!$C$97:$K$114,6,FALSE))+IF(KabelData!J5=5,VLOOKUP(KabelData!J6,Kabel!$C$115:$K$123,6,FALSE))))) -> 4.6210182 | M14: Z70° | N14: =IF(N6="","",IF(KabelData!N4="CU",(IF(KabelData!N5=1,VLOOKUP(KabelData!N6,Kabel!$C$49:$K$63,6,FALSE))+IF(KabelData!N5=3,VLOOKUP(KabelData!N6,Kabel!$C$5:$K$12,6,FALSE))+IF(KabelData!N5=4,VLOOKUP(KabelData!N6,Kabel!$C$13:$K$27,6,FALSE))+IF(KabelData!N5=5,VLOOKUP(KabelData!N6,Kabel!$C$28:$K$35,6,FALSE))))+IF(KabelData!N4="AL",(IF(KabelData!N5=1,VLOOKUP(KabelData!N6,Kabel!$C$64:$K$74,6,FALSE))+IF(KabelData!N5=4,VLOOKUP(KabelData!N6,Kabel!$C$36:$K$46,6,FALSE))+IF(KabelData!N5=5,VLOOKUP(KabelData!N6,Kabel!$C$47:$K$48,6,FALSE))))+IF(KabelData!N4="Tilledning",(IF(KabelData!N5=2,VLOOKUP(KabelData!N6,Kabel!$C$83:$K$86,6,FALSE))+IF(KabelData!N5=3,VLOOKUP(KabelData!N6,Kabel!$C$87:$K$96,6,FALSE))+IF(KabelData!N5=4,VLOOKUP(KabelData!N6,Kabel!$C$97:$K$114,6,FALSE))+IF(KabelData!N5=5,VLOOKUP(KabelData!N6,Kabel!$C$115:$K$123,6,FALSE))))) -> 18.150292 | Q14: Z70° | R14: =IF(R6="","",IF(KabelData!R4="CU",(IF(KabelData!R5=1,VLOOKUP(KabelData!R6,Kabel!$C$49:$K$63,6,FALSE))+IF(KabelData!R5=3,VLOOKUP(KabelData!R6,Kabel!$C$5:$K$12,6,FALSE))+IF(KabelData!R5=4,VLOOKUP(KabelData!R6,Kabel!$C$13:$K$27,6,FALSE))+IF(KabelData!R5=5,VLOOKUP(KabelData!R6,Kabel!$C$28:$K$35,6,FALSE))))+IF(KabelData!R4="AL",(IF(KabelData!R5=1,VLOOKUP(KabelData!R6,Kabel!$C$64:$K$74,6,FALSE))+IF(KabelData!R5=4,VLOOKUP(KabelData!R6,Kabel!$C$36:$K$46,6,FALSE))+IF(KabelData!R5=5,VLOOKUP(KabelData!R6,Kabel!$C$47:$K$48,6,FALSE))))+IF(KabelData!R4="Tilledning",(IF(KabelData!R5=2,VLOOKUP(KabelData!R6,Kabel!$C$83:$K$86,6,FALSE))+IF(KabelData!R5=3,VLOOKUP(KabelData!R6,Kabel!$C$87:$K$96,6,FALSE))+IF(KabelData!R5=4,VLOOKUP(KabelData!R6,Kabel!$C$97:$K$114,6,FALSE))+IF(KabelData!R5=5,VLOOKUP(KabelData!R6,Kabel!$C$115:$K$123,6,FALSE))))) | U14: 95
A15: Ð 70° | B15: =IF(B6="","",IF(KabelData!B4="CU",(IF(KabelData!B5=1,VLOOKUP(KabelData!B6,Kabel!$C$49:$K$63,7,FALSE))+IF(KabelData!B5=3,VLOOKUP(KabelData!B6,Kabel!$C$5:$K$12,7,FALSE))+IF(KabelData!B5=4,VLOOKUP(KabelData!B6,Kabel!$C$13:$K$27,7,FALSE))+IF(KabelData!B5=5,VLOOKUP(KabelData!B6,Kabel!$C$28:$K$35,7,FALSE))))+IF(KabelData!B4="AL",(IF(KabelData!B5=1,VLOOKUP(KabelData!B6,Kabel!$C$64:$K$74,7,FALSE))+IF(KabelData!B5=4,VLOOKUP(KabelData!B6,Kabel!$C$36:$K$46,7,FALSE))+IF(KabelData!B5=5,VLOOKUP(KabelData!B6,Kabel!$C$47:$K$48,7,FALSE))))+IF(KabelData!B4="Tilledning",(IF(KabelData!B5=2,VLOOKUP(KabelData!B6,Kabel!$C$83:$K$86,7,FALSE))+IF(KabelData!B5=3,VLOOKUP(KabelData!B6,Kabel!$C$87:$K$96,7,FALSE))+IF(KabelData!B5=4,VLOOKUP(KabelData!B6,Kabel!$C$97:$K$114,7,FALSE))+IF(KabelData!B5=5,VLOOKUP(KabelData!B6,Kabel!$C$115:$K$123,7,FALSE))))) -> 8.2127802 | E15: Ð 70° | F15: =IF(F6="","",IF(KabelData!F4="CU",(IF(KabelData!F5=1,VLOOKUP(KabelData!F6,Kabel!$C$49:$K$63,7,FALSE))+IF(KabelData!F5=3,VLOOKUP(KabelData!F6,Kabel!$C$5:$K$12,7,FALSE))+IF(KabelData!F5=4,VLOOKUP(KabelData!F6,Kabel!$C$13:$K$27,7,FALSE))+IF(KabelData!F5=5,VLOOKUP(KabelData!F6,Kabel!$C$28:$K$35,7,FALSE))))+IF(KabelData!F4="AL",(IF(KabelData!F5=1,VLOOKUP(KabelData!F6,Kabel!$C$64:$K$74,7,FALSE))+IF(KabelData!F5=4,VLOOKUP(KabelData!F6,Kabel!$C$36:$K$46,7,FALSE))+IF(KabelData!F5=5,VLOOKUP(KabelData!F6,Kabel!$C$47:$K$48,7,FALSE))))+IF(KabelData!F4="Tilledning",(IF(KabelData!F5=2,VLOOKUP(KabelData!F6,Kabel!$C$83:$K$86,7,FALSE))+IF(KabelData!F5=3,VLOOKUP(KabelData!F6,Kabel!$C$87:$K$96,7,FALSE))+IF(KabelData!F5=4,VLOOKUP(KabelData!F6,Kabel!$C$97:$K$114,7,FALSE))+IF(KabelData!F5=5,VLOOKUP(KabelData!F6,Kabel!$C$115:$K$123,7,FALSE))))) -> 2.8209886 | I15: Ð 70° | J15: =IF(J6="","",IF(KabelData!J4="CU",(IF(KabelData!J5=1,VLOOKUP(KabelData!J6,Kabel!$C$49:$K$63,7,FALSE))+IF(KabelData!J5=3,VLOOKUP(KabelData!J6,Kabel!$C$5:$K$12,7,FALSE))+IF(KabelData!J5=4,VLOOKUP(KabelData!J6,Kabel!$C$13:$K$27,7,FALSE))+IF(KabelData!J5=5,VLOOKUP(KabelData!J6,Kabel!$C$28:$K$35,7,FALSE))))+IF(KabelData!J4="AL",(IF(KabelData!J5=1,VLOOKUP(KabelData!J6,Kabel!$C$64:$K$74,7,FALSE))+IF(KabelData!J5=4,VLOOKUP(KabelData!J6,Kabel!$C$36:$K$46,7,FALSE))+IF(KabelData!J5=5,VLOOKUP(KabelData!J6,Kabel!$C$47:$K$48,7,FALSE))))+IF(KabelData!J4="Tilledning",(IF(KabelData!J5=2,VLOOKUP(KabelData!J6,Kabel!$C$83:$K$86,7,FALSE))+IF(KabelData!J5=3,VLOOKUP(KabelData!J6,Kabel!$C$87:$K$96,7,FALSE))+IF(KabelData!J5=4,VLOOKUP(KabelData!J6,Kabel!$C$97:$K$114,7,FALSE))+IF(KabelData!J5=5,VLOOKUP(KabelData!J6,Kabel!$C$115:$K$123,7,FALSE))))) -> 1.2027866 | M15: Ð 70° | N15: =IF(N6="","",IF(KabelData!N4="CU",(IF(KabelData!N5=1,VLOOKUP(KabelData!N6,Kabel!$C$49:$K$63,7,FALSE))+IF(KabelData!N5=3,VLOOKUP(KabelData!N6,Kabel!$C$5:$K$12,7,FALSE))+IF(KabelData!N5=4,VLOOKUP(KabelData!N6,Kabel!$C$13:$K$27,7,FALSE))+IF(KabelData!N5=5,VLOOKUP(KabelData!N6,Kabel!$C$28:$K$35,7,FALSE))))+IF(KabelData!N4="AL",(IF(KabelData!N5=1,VLOOKUP(KabelData!N6,Kabel!$C$64:$K$74,7,FALSE))+IF(KabelData!N5=4,VLOOKUP(KabelData!N6,Kabel!$C$36:$K$46,7,FALSE))+IF(KabelData!N5=5,VLOOKUP(KabelData!N6,Kabel!$C$47:$K$48,7,FALSE))))+IF(KabelData!N4="Tilledning",(IF(KabelData!N5=2,VLOOKUP(KabelData!N6,Kabel!$C$83:$K$86,7,FALSE))+IF(KabelData!N5=3,VLOOKUP(KabelData!N6,Kabel!$C$87:$K$96,7,FALSE))+IF(KabelData!N5=4,VLOOKUP(KabelData!N6,Kabel!$C$97:$K$114,7,FALSE))+IF(KabelData!N5=5,VLOOKUP(KabelData!N6,Kabel!$C$115:$K$123,7,FALSE))))) -> 0.32514611 | Q15: Ð 70° | R15: =IF(R6="","",IF(KabelData!R4="CU",(IF(KabelData!R5=1,VLOOKUP(KabelData!R6,Kabel!$C$49:$K$63,7,FALSE))+IF(KabelData!R5=3,VLOOKUP(KabelData!R6,Kabel!$C$5:$K$12,7,FALSE))+IF(KabelData!R5=4,VLOOKUP(KabelData!R6,Kabel!$C$13:$K$27,7,FALSE))+IF(KabelData!R5=5,VLOOKUP(KabelData!R6,Kabel!$C$28:$K$35,7,FALSE))))+IF(KabelData!R4="AL",(IF(KabelData!R5=1,VLOOKUP(KabelData!R6,Kabel!$C$64:$K$74,7,FALSE))+IF(KabelData!R5=4,VLOOKUP(KabelData!R6,Kabel!$C$36:$K$46,7,FALSE))+IF(KabelData!R5=5,VLOOKUP(KabelData!R6,Kabel!$C$47:$K$48,7,FALSE))))+IF(KabelData!R4="Tilledning",(IF(KabelData!R5=2,VLOOKUP(KabelData!R6,Kabel!$C$83:$K$86,7,FALSE))+IF(KabelData!R5=3,VLOOKUP(KabelData!R6,Kabel!$C$87:$K$96,7,FALSE))+IF(KabelData!R5=4,VLOOKUP(KabelData!R6,Kabel!$C$97:$K$114,7,FALSE))+IF(KabelData!R5=5,VLOOKUP(KabelData!R6,Kabel!$C$115:$K$123,7,FALSE))))) | U15: 120
U16: 150
A17: Kabel 6 | E17: Kabel 7 | I17: Kabel 8 | M17: Hvis man får R og X værdi | Q17: Hvis man får R og X værdi | U17: 185
A18: Navn | R18: -W10 | U18: 240
A19: Materiale | B19: CU | F19: CU | J19: CU | N19: CU | R19: CU | U19: 300
A20: Antal ledere | M20: R 20˚ | Q20: R 20˚
A21: Kvadrat (mm²) | M21: X | Q21: X | U21: =IF(AND(B4="CU",B5=1),$U$4:$U$18,IF(AND(B4="CU",B5=3),$U$4:$U$11,IF(AND(B4="CU",B5=4),$U$4:$U$18,IF(AND(B4="CU",B5=5),$U$4:$U$11,IF(AND(B4="AL",B5=1),$U$9:$U$19,IF(AND(B4="AL",B5=4),$U$9:$U$19,IF(AND(B4="AL",B5=5),$U$9:$U$10,IF(AND(B4="Tilledning",B5=2),$U$2:$U$5,IF(AND(B4="Tilledning",B5=3),$U$2:$U$11,IF(AND(B4="Tilledning",B5=4),$U$2:$U$19,IF(AND(B4="Tilledning",B5=5),$U$2:$U$519))))))))))) -> #VALUE! | W21: =IF(AND(B4="CU",B5=1),$U$4:$U$18,IF(AND(B4="CU",B5=3),$U$4:$U$11)) -> FALSE
A22: Længde (m) | E22: m | I22: m | M22: m | Q22: m
A23: Paralle (n) | B23: 1 | E23: n | F23: 1 | I23: n | J23: 1 | M23: n | N23: 1 | Q23: n | R23: 1
A24: IB | C24: Ð- | G24: Ð- | K24: Ð- | O24: Ð- | S24: Ð-
A25: Z20° | B25: =IF(B21="","",IF(KabelData!B19="CU",(IF(KabelData!B20=1,VLOOKUP(KabelData!B21,Kabel!$C$49:$G$63,4,FALSE))+IF(KabelData!B20=3,VLOOKUP(KabelData!B21,Kabel!$C$5:$G$12,4,FALSE))+IF(KabelData!B20=4,VLOOKUP(KabelData!B21,Kabel!$C$13:$G$27,4,FALSE))+IF(KabelData!B20=5,VLOOKUP(KabelData!B21,Kabel!$C$28:$G$35,4,FALSE))))+IF(KabelData!B19="AL",(IF(KabelData!B20=1,VLOOKUP(KabelData!B21,Kabel!$C$64:$G$74,4,FALSE))+IF(KabelData!B20=4,VLOOKUP(KabelData!B21,Kabel!$C$36:$G$46,4,FALSE))+IF(KabelData!B20=5,VLOOKUP(KabelData!B21,Kabel!$C$47:$G$48,4,FALSE))))+IF(KabelData!B19="Tilledning",(IF(KabelData!B20=2,VLOOKUP(KabelData!B21,Kabel!$C$83:$G$86,4,FALSE))+IF(KabelData!B20=3,VLOOKUP(KabelData!B21,Kabel!$C$87:$G$96,4,FALSE))+IF(KabelData!B20=4,VLOOKUP(KabelData!B21,Kabel!$C$97:$G$114,4,FALSE))+IF(KabelData!B20=5,VLOOKUP(KabelData!B21,Kabel!$C$115:$G$123,4,FALSE))))) | E25: Z20° | F25: =IF(F21="","",IF(KabelData!F19="CU",(IF(KabelData!F20=1,VLOOKUP(KabelData!F21,Kabel!$C$49:$G$63,4,FALSE))+IF(KabelData!F20=3,VLOOKUP(KabelData!F21,Kabel!$C$5:$G$12,4,FALSE))+IF(KabelData!F20=4,VLOOKUP(KabelData!F21,Kabel!$C$13:$G$27,4,FALSE))+IF(KabelData!F20=5,VLOOKUP(KabelData!F21,Kabel!$C$28:$G$35,4,FALSE))))+IF(KabelData!F19="AL",(IF(KabelData!F20=1,VLOOKUP(KabelData!F21,Kabel!$C$64:$G$74,4,FALSE))+IF(KabelData!F20=4,VLOOKUP(KabelData!F21,Kabel!$C$36:$G$46,4,FALSE))+IF(KabelData!F20=5,VLOOKUP(KabelData!F21,Kabel!$C$47:$G$48,4,FALSE))))+IF(KabelData!F19="Tilledning",(IF(KabelData!F20=2,VLOOKUP(KabelData!F21,Kabel!$C$83:$G$86,4,FALSE))+IF(KabelData!F20=3,VLOOKUP(KabelData!F21,Kabel!$C$87:$G$96,4,FALSE))+IF(KabelData!F20=4,VLOOKUP(KabelData!F21,Kabel!$C$97:$G$114,4,FALSE))+IF(KabelData!F20=5,VLOOKUP(KabelData!F21,Kabel!$C$115:$G$123,4,FALSE))))) | I25: Z20° | J25: =IF(J21="","",IF(KabelData!J19="CU",(IF(KabelData!J20=1,VLOOKUP(KabelData!J21,Kabel!$C$49:$G$63,4,FALSE))+IF(KabelData!J20=3,VLOOKUP(KabelData!J21,Kabel!$C$5:$G$12,4,FALSE))+IF(KabelData!J20=4,VLOOKUP(KabelData!J21,Kabel!$C$13:$G$27,4,FALSE))+IF(KabelData!J20=5,VLOOKUP(KabelData!J21,Kabel!$C$28:$G$35,4,FALSE))))+IF(KabelData!J19="AL",(IF(KabelData!J20=1,VLOOKUP(KabelData!J21,Kabel!$C$64:$G$74,4,FALSE))+IF(KabelData!J20=4,VLOOKUP(KabelData!J21,Kabel!$C$36:$G$46,4,FALSE))+IF(KabelData!J20=5,VLOOKUP(KabelData!J21,Kabel!$C$47:$G$48,4,FALSE))))+IF(KabelData!J19="Tilledning",(IF(KabelData!J20=2,VLOOKUP(KabelData!J21,Kabel!$C$83:$G$86,4,FALSE))+IF(KabelData!J20=3,VLOOKUP(KabelData!J21,Kabel!$C$87:$G$96,4,FALSE))+IF(KabelData!J20=4,VLOOKUP(KabelData!J21,Kabel!$C$97:$G$114,4,FALSE))+IF(KabelData!J20=5,VLOOKUP(KabelData!J21,Kabel!$C$115:$G$123,4,FALSE))))) | M25: Z20° | N25: =IF(N20="","",IMABS(COMPLEX(N20,N21,"i"))) | Q25: Z20° | R25: =IF(R20="","",IMABS(COMPLEX(R20,R21,"i")))
A26: Ð 20° | B26: =IF(B21="","",IF(KabelData!B19="CU",(IF(KabelData!B20=1,VLOOKUP(KabelData!B21,Kabel!$C$49:$G$63,5,FALSE))+IF(KabelData!B20=3,VLOOKUP(KabelData!B21,Kabel!$C$5:$G$12,5,FALSE))+IF(KabelData!B20=4,VLOOKUP(KabelData!B21,Kabel!$C$13:$G$27,5,FALSE))+IF(KabelData!B20=5,VLOOKUP(KabelData!B21,Kabel!$C$28:$G$35,5,FALSE))))+IF(KabelData!B19="AL",(IF(KabelData!B20=1,VLOOKUP(KabelData!B21,Kabel!$C$64:$G$74,5,FALSE))+IF(KabelData!B20=4,VLOOKUP(KabelData!B21,Kabel!$C$36:$G$46,5,FALSE))+IF(KabelData!B20=5,VLOOKUP(KabelData!B21,Kabel!$C$47:$G$48,5,FALSE))))+IF(KabelData!B19="Tilledning",(IF(KabelData!B20=2,VLOOKUP(KabelData!B21,Kabel!$C$83:$G$86,5,FALSE))+IF(KabelData!B20=3,VLOOKUP(KabelData!B21,Kabel!$C$87:$G$96,5,FALSE))+IF(KabelData!B20=4,VLOOKUP(KabelData!B21,Kabel!$C$97:$G$114,5,FALSE))+IF(KabelData!B20=5,VLOOKUP(KabelData!B21,Kabel!$C$115:$G$123,5,FALSE))))) | E26: Ð 20° | F26: =IF(F21="","",IF(KabelData!F19="CU",(IF(KabelData!F20=1,VLOOKUP(KabelData!F21,Kabel!$C$49:$G$63,5,FALSE))+IF(KabelData!F20=3,VLOOKUP(KabelData!F21,Kabel!$C$5:$G$12,5,FALSE))+IF(KabelData!F20=4,VLOOKUP(KabelData!F21,Kabel!$C$13:$G$27,5,FALSE))+IF(KabelData!F20=5,VLOOKUP(KabelData!F21,Kabel!$C$28:$G$35,5,FALSE))))+IF(KabelData!F19="AL",(IF(KabelData!F20=1,VLOOKUP(KabelData!F21,Kabel!$C$64:$G$74,5,FALSE))+IF(KabelData!F20=4,VLOOKUP(KabelData!F21,Kabel!$C$36:$G$46,5,FALSE))+IF(KabelData!F20=5,VLOOKUP(KabelData!F21,Kabel!$C$47:$G$48,5,FALSE))))+IF(KabelData!F19="Tilledning",(IF(KabelData!F20=2,VLOOKUP(KabelData!F21,Kabel!$C$83:$G$86,5,FALSE))+IF(KabelData!F20=3,VLOOKUP(KabelData!F21,Kabel!$C$87:$G$96,5,FALSE))+IF(KabelData!F20=4,VLOOKUP(KabelData!F21,Kabel!$C$97:$G$114,5,FALSE))+IF(KabelData!F20=5,VLOOKUP(KabelData!F21,Kabel!$C$115:$G$123,5,FALSE))))) | I26: Ð 20° | J26: =IF(J21="","",IF(KabelData!J19="CU",(IF(KabelData!J20=1,VLOOKUP(KabelData!J21,Kabel!$C$49:$G$63,5,FALSE))+IF(KabelData!J20=3,VLOOKUP(KabelData!J21,Kabel!$C$5:$G$12,5,FALSE))+IF(KabelData!J20=4,VLOOKUP(KabelData!J21,Kabel!$C$13:$G$27,5,FALSE))+IF(KabelData!J20=5,VLOOKUP(KabelData!J21,Kabel!$C$28:$G$35,5,FALSE))))+IF(KabelData!J19="AL",(IF(KabelData!J20=1,VLOOKUP(KabelData!J21,Kabel!$C$64:$G$74,5,FALSE))+IF(KabelData!J20=4,VLOOKUP(KabelData!J21,Kabel!$C$36:$G$46,5,FALSE))+IF(KabelData!J20=5,VLOOKUP(KabelData!J21,Kabel!$C$47:$G$48,5,FALSE))))+IF(KabelData!J19="Tilledning",(IF(KabelData!J20=2,VLOOKUP(KabelData!J21,Kabel!$C$83:$G$86,5,FALSE))+IF(KabelData!J20=3,VLOOKUP(KabelData!J21,Kabel!$C$87:$G$96,5,FALSE))+IF(KabelData!J20=4,VLOOKUP(KabelData!J21,Kabel!$C$97:$G$114,5,FALSE))+IF(KabelData!J20=5,VLOOKUP(KabelData!J21,Kabel!$C$115:$G$123,5,FALSE))))) | M26: Ð 20° | N26: =IF(N21="","",DEGREES(ACOS((N20/N25)))) | Q26: Ð 20° | R26: =IF(R21="","",DEGREES(ACOS((R20/R25))))
A27: R | B27: =IF(B21="","",IF(KabelData!B19="CU",(IF(KabelData!B20=1,VLOOKUP(KabelData!B21,Kabel!$C$49:$G$63,2,FALSE))+IF(KabelData!B20=3,VLOOKUP(KabelData!B21,Kabel!$C$5:$G$12,2,FALSE))+IF(KabelData!B20=4,VLOOKUP(KabelData!B21,Kabel!$C$13:$G$27,2,FALSE))+IF(KabelData!B20=5,VLOOKUP(KabelData!B21,Kabel!$C$28:$G$35,2,FALSE))))+IF(KabelData!B19="AL",(IF(KabelData!B20=1,VLOOKUP(KabelData!B21,Kabel!$C$64:$G$74,2,FALSE))+IF(KabelData!B20=4,VLOOKUP(KabelData!B21,Kabel!$C$36:$G$46,2,FALSE))+IF(KabelData!B20=5,VLOOKUP(KabelData!B21,Kabel!$C$47:$G$48,2,FALSE))))+IF(KabelData!B19="Tilledning",(IF(KabelData!B20=2,VLOOKUP(KabelData!B21,Kabel!$C$83:$G$86,2,FALSE))+IF(KabelData!B20=3,VLOOKUP(KabelData!B21,Kabel!$C$87:$G$96,2,FALSE))+IF(KabelData!B20=4,VLOOKUP(KabelData!B21,Kabel!$C$97:$G$114,2,FALSE))+IF(KabelData!B20=5,VLOOKUP(KabelData!B21,Kabel!$C$115:$G$123,2,FALSE))))) | E27: R | F27: =IF(F21="","",IF(KabelData!F19="CU",(IF(KabelData!F20=1,VLOOKUP(KabelData!F21,Kabel!$C$49:$G$63,2,FALSE))+IF(KabelData!F20=3,VLOOKUP(KabelData!F21,Kabel!$C$5:$G$12,2,FALSE))+IF(KabelData!F20=4,VLOOKUP(KabelData!F21,Kabel!$C$13:$G$27,2,FALSE))+IF(KabelData!F20=5,VLOOKUP(KabelData!F21,Kabel!$C$28:$G$35,2,FALSE))))+IF(KabelData!F19="AL",(IF(KabelData!F20=1,VLOOKUP(KabelData!F21,Kabel!$C$64:$G$74,2,FALSE))+IF(KabelData!F20=4,VLOOKUP(KabelData!F21,Kabel!$C$36:$G$46,2,FALSE))+IF(KabelData!F20=5,VLOOKUP(KabelData!F21,Kabel!$C$47:$G$48,2,FALSE))))+IF(KabelData!F19="Tilledning",(IF(KabelData!F20=2,VLOOKUP(KabelData!F21,Kabel!$C$83:$G$86,2,FALSE))+IF(KabelData!F20=3,VLOOKUP(KabelData!F21,Kabel!$C$87:$G$96,2,FALSE))+IF(KabelData!F20=4,VLOOKUP(KabelData!F21,Kabel!$C$97:$G$114,2,FALSE))+IF(KabelData!F20=5,VLOOKUP(KabelData!F21,Kabel!$C$115:$G$123,2,FALSE))))) | I27: R | J27: =IF(J21="","",IF(KabelData!J19="CU",(IF(KabelData!J20=1,VLOOKUP(KabelData!J21,Kabel!$C$49:$G$63,2,FALSE))+IF(KabelData!J20=3,VLOOKUP(KabelData!J21,Kabel!$C$5:$G$12,2,FALSE))+IF(KabelData!J20=4,VLOOKUP(KabelData!J21,Kabel!$C$13:$G$27,2,FALSE))+IF(KabelData!J20=5,VLOOKUP(KabelData!J21,Kabel!$C$28:$G$35,2,FALSE))))+IF(KabelData!J19="AL",(IF(KabelData!J20=1,VLOOKUP(KabelData!J21,Kabel!$C$64:$G$74,2,FALSE))+IF(KabelData!J20=4,VLOOKUP(KabelData!J21,Kabel!$C$36:$G$46,2,FALSE))+IF(KabelData!J20=5,VLOOKUP(KabelData!J21,Kabel!$C$47:$G$48,2,FALSE))))+IF(KabelData!J19="Tilledning",(IF(KabelData!J20=2,VLOOKUP(KabelData!J21,Kabel!$C$83:$G$86,2,FALSE))+IF(KabelData!J20=3,VLOOKUP(KabelData!J21,Kabel!$C$87:$G$96,2,FALSE))+IF(KabelData!J20=4,VLOOKUP(KabelData!J21,Kabel!$C$97:$G$114,2,FALSE))+IF(KabelData!J20=5,VLOOKUP(KabelData!J21,Kabel!$C$115:$G$123,2,FALSE))))) | M27: R | Q27: R
A28: X | B28: =IF(B21="","",IF(KabelData!B19="CU",(IF(KabelData!B20=1,VLOOKUP(KabelData!B21,Kabel!$C$49:$G$63,3,FALSE))+IF(KabelData!B20=3,VLOOKUP(KabelData!B21,Kabel!$C$5:$G$12,3,FALSE))+IF(KabelData!B20=4,VLOOKUP(KabelData!B21,Kabel!$C$13:$G$27,3,FALSE))+IF(KabelData!B20=5,VLOOKUP(KabelData!B21,Kabel!$C$28:$G$35,3,FALSE))))+IF(KabelData!B19="AL",(IF(KabelData!B20=1,VLOOKUP(KabelData!B21,Kabel!$C$64:$G$74,3,FALSE))+IF(KabelData!B20=4,VLOOKUP(KabelData!B21,Kabel!$C$36:$G$46,3,FALSE))+IF(KabelData!B20=5,VLOOKUP(KabelData!B21,Kabel!$C$47:$G$48,3,FALSE))))+IF(KabelData!B19="Tilledning",(IF(KabelData!B20=2,VLOOKUP(KabelData!B21,Kabel!$C$83:$G$86,3,FALSE))+IF(KabelData!B20=3,VLOOKUP(KabelData!B21,Kabel!$C$87:$G$96,3,FALSE))+IF(KabelData!B20=4,VLOOKUP(KabelData!B21,Kabel!$C$97:$G$114,3,FALSE))+IF(KabelData!B20=5,VLOOKUP(KabelData!B21,Kabel!$C$115:$G$123,3,FALSE))))) | E28: X | F28: =IF(F21="","",IF(KabelData!F19="CU",(IF(KabelData!F20=1,VLOOKUP(KabelData!F21,Kabel!$C$49:$G$63,3,FALSE))+IF(KabelData!F20=3,VLOOKUP(KabelData!F21,Kabel!$C$5:$G$12,3,FALSE))+IF(KabelData!F20=4,VLOOKUP(KabelData!F21,Kabel!$C$13:$G$27,3,FALSE))+IF(KabelData!F20=5,VLOOKUP(KabelData!F21,Kabel!$C$28:$G$35,3,FALSE))))+IF(KabelData!F19="AL",(IF(KabelData!F20=1,VLOOKUP(KabelData!F21,Kabel!$C$64:$G$74,3,FALSE))+IF(KabelData!F20=4,VLOOKUP(KabelData!F21,Kabel!$C$36:$G$46,3,FALSE))+IF(KabelData!F20=5,VLOOKUP(KabelData!F21,Kabel!$C$47:$G$48,3,FALSE))))+IF(KabelData!F19="Tilledning",(IF(KabelData!F20=2,VLOOKUP(KabelData!F21,Kabel!$C$83:$G$86,3,FALSE))+IF(KabelData!F20=3,VLOOKUP(KabelData!F21,Kabel!$C$87:$G$96,3,FALSE))+IF(KabelData!F20=4,VLOOKUP(KabelData!F21,Kabel!$C$97:$G$114,3,FALSE))+IF(KabelData!F20=5,VLOOKUP(KabelData!F21,Kabel!$C$115:$G$123,3,FALSE))))) | I28: X | J28: =IF(J21="","",IF(KabelData!J19="CU",(IF(KabelData!J20=1,VLOOKUP(KabelData!J21,Kabel!$C$49:$G$63,3,FALSE))+IF(KabelData!J20=3,VLOOKUP(KabelData!J21,Kabel!$C$5:$G$12,3,FALSE))+IF(KabelData!J20=4,VLOOKUP(KabelData!J21,Kabel!$C$13:$G$27,3,FALSE))+IF(KabelData!J20=5,VLOOKUP(KabelData!J21,Kabel!$C$28:$G$35,3,FALSE))))+IF(KabelData!J19="AL",(IF(KabelData!J20=1,VLOOKUP(KabelData!J21,Kabel!$C$64:$G$74,3,FALSE))+IF(KabelData!J20=4,VLOOKUP(KabelData!J21,Kabel!$C$36:$G$46,3,FALSE))+IF(KabelData!J20=5,VLOOKUP(KabelData!J21,Kabel!$C$47:$G$48,3,FALSE))))+IF(KabelData!J19="Tilledning",(IF(KabelData!J20=2,VLOOKUP(KabelData!J21,Kabel!$C$83:$G$86,3,FALSE))+IF(KabelData!J20=3,VLOOKUP(KabelData!J21,Kabel!$C$87:$G$96,3,FALSE))+IF(KabelData!J20=4,VLOOKUP(KabelData!J21,Kabel!$C$97:$G$114,3,FALSE))+IF(KabelData!J20=5,VLOOKUP(KabelData!J21,Kabel!$C$115:$G$123,3,FALSE))))) | M28: X | Q28: X
A29: Z70° | B29: =IF(B21="","",IF(KabelData!B19="CU",(IF(KabelData!B20=1,VLOOKUP(KabelData!B21,Kabel!$C$49:$K$63,6,FALSE))+IF(KabelData!B20=3,VLOOKUP(KabelData!B21,Kabel!$C$5:$K$12,6,FALSE))+IF(KabelData!B20=4,VLOOKUP(KabelData!B21,Kabel!$C$13:$K$27,6,FALSE))+IF(KabelData!B20=5,VLOOKUP(KabelData!B21,Kabel!$C$28:$K$35,6,FALSE))))+IF(KabelData!B19="AL",(IF(KabelData!B20=1,VLOOKUP(KabelData!B21,Kabel!$C$64:$K$74,6,FALSE))+IF(KabelData!B20=4,VLOOKUP(KabelData!B21,Kabel!$C$36:$K$46,6,FALSE))+IF(KabelData!B20=5,VLOOKUP(KabelData!B21,Kabel!$C$47:$K$48,6,FALSE))))+IF(KabelData!B19="Tilledning",(IF(KabelData!B20=2,VLOOKUP(KabelData!B21,Kabel!$C$83:$K$86,6,FALSE))+IF(KabelData!B20=3,VLOOKUP(KabelData!B21,Kabel!$C$87:$K$96,6,FALSE))+IF(KabelData!B20=4,VLOOKUP(KabelData!B21,Kabel!$C$97:$K$114,6,FALSE))+IF(KabelData!B20=5,VLOOKUP(KabelData!B21,Kabel!$C$115:$K$123,6,FALSE))))) | E29: Z70° | F29: =IF(F21="","",IF(KabelData!F19="CU",(IF(KabelData!F20=1,VLOOKUP(KabelData!F21,Kabel!$C$49:$K$63,6,FALSE))+IF(KabelData!F20=3,VLOOKUP(KabelData!F21,Kabel!$C$5:$K$12,6,FALSE))+IF(KabelData!F20=4,VLOOKUP(KabelData!F21,Kabel!$C$13:$K$27,6,FALSE))+IF(KabelData!F20=5,VLOOKUP(KabelData!F21,Kabel!$C$28:$K$35,6,FALSE))))+IF(KabelData!F19="AL",(IF(KabelData!F20=1,VLOOKUP(KabelData!F21,Kabel!$C$64:$K$74,6,FALSE))+IF(KabelData!F20=4,VLOOKUP(KabelData!F21,Kabel!$C$36:$K$46,6,FALSE))+IF(KabelData!F20=5,VLOOKUP(KabelData!F21,Kabel!$C$47:$K$48,6,FALSE))))+IF(KabelData!F19="Tilledning",(IF(KabelData!F20=2,VLOOKUP(KabelData!F21,Kabel!$C$83:$K$86,6,FALSE))+IF(KabelData!F20=3,VLOOKUP(KabelData!F21,Kabel!$C$87:$K$96,6,FALSE))+IF(KabelData!F20=4,VLOOKUP(KabelData!F21,Kabel!$C$97:$K$114,6,FALSE))+IF(KabelData!F20=5,VLOOKUP(KabelData!F21,Kabel!$C$115:$K$123,6,FALSE))))) | I29: Z70° | J29: =IF(J21="","",IF(KabelData!J19="CU",(IF(KabelData!J20=1,VLOOKUP(KabelData!J21,Kabel!$C$49:$K$63,6,FALSE))+IF(KabelData!J20=3,VLOOKUP(KabelData!J21,Kabel!$C$5:$K$12,6,FALSE))+IF(KabelData!J20=4,VLOOKUP(KabelData!J21,Kabel!$C$13:$K$27,6,FALSE))+IF(KabelData!J20=5,VLOOKUP(KabelData!J21,Kabel!$C$28:$K$35,6,FALSE))))+IF(KabelData!J19="AL",(IF(KabelData!J20=1,VLOOKUP(KabelData!J21,Kabel!$C$64:$K$74,6,FALSE))+IF(KabelData!J20=4,VLOOKUP(KabelData!J21,Kabel!$C$36:$K$46,6,FALSE))+IF(KabelData!J20=5,VLOOKUP(KabelData!J21,Kabel!$C$47:$K$48,6,FALSE))))+IF(KabelData!J19="Tilledning",(IF(KabelData!J20=2,VLOOKUP(KabelData!J21,Kabel!$C$83:$K$86,6,FALSE))+IF(KabelData!J20=3,VLOOKUP(KabelData!J21,Kabel!$C$87:$K$96,6,FALSE))+IF(KabelData!J20=4,VLOOKUP(KabelData!J21,Kabel!$C$97:$K$114,6,FALSE))+IF(KabelData!J20=5,VLOOKUP(KabelData!J21,Kabel!$C$115:$K$123,6,FALSE))))) | M29: Z70° | N29: =IF(N20="","",IMABS(COMPLEX((1.5*N20),N21,"i"))) | Q29: Z70° | R29: =IF(R20="","",IMABS(COMPLEX((1.5*R20),R21,"i")))
A30: Ð 70° | B30: =IF(B21="","",IF(KabelData!B19="CU",(IF(KabelData!B20=1,VLOOKUP(KabelData!B21,Kabel!$C$49:$K$63,7,FALSE))+IF(KabelData!B20=3,VLOOKUP(KabelData!B21,Kabel!$C$5:$K$12,7,FALSE))+IF(KabelData!B20=4,VLOOKUP(KabelData!B21,Kabel!$C$13:$K$27,7,FALSE))+IF(KabelData!B20=5,VLOOKUP(KabelData!B21,Kabel!$C$28:$K$35,7,FALSE))))+IF(KabelData!B19="AL",(IF(KabelData!B20=1,VLOOKUP(KabelData!B21,Kabel!$C$64:$K$74,7,FALSE))+IF(KabelData!B20=4,VLOOKUP(KabelData!B21,Kabel!$C$36:$K$46,7,FALSE))+IF(KabelData!B20=5,VLOOKUP(KabelData!B21,Kabel!$C$47:$K$48,7,FALSE))))+IF(KabelData!B19="Tilledning",(IF(KabelData!B20=2,VLOOKUP(KabelData!B21,Kabel!$C$83:$K$86,7,FALSE))+IF(KabelData!B20=3,VLOOKUP(KabelData!B21,Kabel!$C$87:$K$96,7,FALSE))+IF(KabelData!B20=4,VLOOKUP(KabelData!B21,Kabel!$C$97:$K$114,7,FALSE))+IF(KabelData!B20=5,VLOOKUP(KabelData!B21,Kabel!$C$115:$K$123,7,FALSE))))) | E30: Ð 70° | F30: =IF(F21="","",IF(KabelData!F19="CU",(IF(KabelData!F20=1,VLOOKUP(KabelData!F21,Kabel!$C$49:$K$63,7,FALSE))+IF(KabelData!F20=3,VLOOKUP(KabelData!F21,Kabel!$C$5:$K$12,7,FALSE))+IF(KabelData!F20=4,VLOOKUP(KabelData!F21,Kabel!$C$13:$K$27,7,FALSE))+IF(KabelData!F20=5,VLOOKUP(KabelData!F21,Kabel!$C$28:$K$35,7,FALSE))))+IF(KabelData!F19="AL",(IF(KabelData!F20=1,VLOOKUP(KabelData!F21,Kabel!$C$64:$K$74,7,FALSE))+IF(KabelData!F20=4,VLOOKUP(KabelData!F21,Kabel!$C$36:$K$46,7,FALSE))+IF(KabelData!F20=5,VLOOKUP(KabelData!F21,Kabel!$C$47:$K$48,7,FALSE))))+IF(KabelData!F19="Tilledning",(IF(KabelData!F20=2,VLOOKUP(KabelData!F21,Kabel!$C$83:$K$86,7,FALSE))+IF(KabelData!F20=3,VLOOKUP(KabelData!F21,Kabel!$C$87:$K$96,7,FALSE))+IF(KabelData!F20=4,VLOOKUP(KabelData!F21,Kabel!$C$97:$K$114,7,FALSE))+IF(KabelData!F20=5,VLOOKUP(KabelData!F21,Kabel!$C$115:$K$123,7,FALSE))))) | I30: Ð 70° | J30: =IF(J21="","",IF(KabelData!J19="CU",(IF(KabelData!J20=1,VLOOKUP(KabelData!J21,Kabel!$C$49:$K$63,7,FALSE))+IF(KabelData!J20=3,VLOOKUP(KabelData!J21,Kabel!$C$5:$K$12,7,FALSE))+IF(KabelData!J20=4,VLOOKUP(KabelData!J21,Kabel!$C$13:$K$27,7,FALSE))+IF(KabelData!J20=5,VLOOKUP(KabelData!J21,Kabel!$C$28:$K$35,7,FALSE))))+IF(KabelData!J19="AL",(IF(KabelData!J20=1,VLOOKUP(KabelData!J21,Kabel!$C$64:$K$74,7,FALSE))+IF(KabelData!J20=4,VLOOKUP(KabelData!J21,Kabel!$C$36:$K$46,7,FALSE))+IF(KabelData!J20=5,VLOOKUP(KabelData!J21,Kabel!$C$47:$K$48,7,FALSE))))+IF(KabelData!J19="Tilledning",(IF(KabelData!J20=2,VLOOKUP(KabelData!J21,Kabel!$C$83:$K$86,7,FALSE))+IF(KabelData!J20=3,VLOOKUP(KabelData!J21,Kabel!$C$87:$K$96,7,FALSE))+IF(KabelData!J20=4,VLOOKUP(KabelData!J21,Kabel!$C$97:$K$114,7,FALSE))+IF(KabelData!J20=5,VLOOKUP(KabelData!J21,Kabel!$C$115:$K$123,7,FALSE))))) | M30: Ð 70° | N30: =IF(N21="","",DEGREES(ACOS(((1.5*N20)/N29)))) | Q30: Ð 70° | R30: =IF(R21="","",DEGREES(ACOS(((1.5*R20)/R29))))

Sheet IKmax IKmin
A1: Husk overskrift, tegning og forklaring (overskriv dette)
AO2: =Transformer!U15 -> 73.300756
AN3: Transformer | AO3: =Transformer!U28 -> 36.87 | AQ3: + Z̅ | AR3: + | AS3: * | AT3: Ð
AN4: Beregnet | AO4: =Transformer!F59 -> 72.5424 | AS4: Beregning | AT4: Beregning | AU4: Beregning | AV4: Beregning | AW4: Beregning | AX4: Beregning | AY4: Beregning | AZ4: Beregning | BA4: Beregning | BB4: Beregning | BC4: Tranformer
AO5: Kabel værdier | AS5: 20 grader | AX5: 70 grader | BC5: ZT | BE5: ZN
AO6: Z | AP6: fi | AS6: Z | AT6: fi | AU6: radianer | AV6: cos | AW6: sin | AX6: Z | AY6: fi | AZ6: radianer | BA6: cos | BB6: sin | BC6: Z | BD6: fi | BE6: Z | BF6: fi
AN7: =IF(KabelData!B3="","",KabelData!B3) -> -W1 | AO7: =Kabeludskrif!K5 -> 0.006 | AP7: =IF(KabelData!B11="","",ROUND(KabelData!B11,4)) -> 12.2157 | AQ7: =ROUND(Kabeludskrif!K52,4) -> 0.0088 | AR7: =ROUND(KabelData!B15,4) -> 8.2128 | AS7: =IF(E29="",0,IF(E29>0,E29,)) -> 0 | AT7: =IF(G29="",0,IF(G29>0,G29,)) -> 0 | AU7: =RADIANS(180+AT7) -> 3.1415927 | AV7: =AS7*COS(AU7) -> 0 | AW7: =AS7*SIN(AU7) -> 0 | AX7: =IF(V41="",0,IF(V41>0,V41,)) -> 0.0176 | AY7: =IF(N41="",0,IF(N41>0,N41,)) -> 8.2128 | AZ7: =RADIANS(180+AY7) -> 3.2849331 | BA7: =AX7*COS(AZ7) -> -0.0174195 | BB7: =AX7*SIN(AZ7) -> -0.0025141608 | BC7: =Transformer!O15 -> 0.0011 | BD7: =Transformer!U15 -> 73.300756 | BE7: =Transformer!O28 -> 0.014 | BF7: =Transformer!U28 -> 36.87
AN8: =IF(KabelData!F3="","",KabelData!F3) -> -W2 | AO8: =Kabeludskrif!K9 -> 0.0231 | AP8: =IF(KabelData!F11="","",ROUND(KabelData!F11,4)) -> 4.2272 | AQ8: =Kabeludskrif!K56 -> 0.034541859 | AR8: =KabelData!F15 -> 2.8209886 | AS8: =IF(J29="",0,IF(J29>0,J29,)) -> 0.014433757 | AT8: =IF(N29="",0,IF(N29>0,N29,)) -> 72.5424 | AU8: =RADIANS(180+AT8) -> 4.4076964 | AV8: =AS8*COS(AU8) -> -0.0043301263 | AW8: =AS8*SIN(AU8) -> -0.013768927 | AX8: =IF(V42="",0,IF(V42>0,V42,)) -> 0.069083717 | AY8: =IF(N42="",0,IF(N42>0,N42,)) -> 2.8209886 | AZ8: =RADIANS(180+AY8) -> 3.1908282 | BA8: =AX8*COS(AZ8) -> -0.069 | BB8: =AX8*SIN(AZ8) -> -0.0034 | BC8: Beregnet max | BE8: Beregnet min
AN9: =IF(KabelData!J3="","",KabelData!J3) -> -W3 | AO9: =Kabeludskrif!K13 -> 0.0616 | AP9: =IF(KabelData!J11="","",ROUND(KabelData!J11,4)) -> 1.8038 | AQ9: =Kabeludskrif!K60 -> 0.092420364 | AR9: =KabelData!J15 -> 1.2027866 | AS9: =IF(P29="",0,IF(P29>0,P29,)) -> 0.006 | AT9: =IF(T29="",0,IF(T29>0,T29,)) -> 12.2157 | AU9: =RADIANS(180+AT9) -> 3.3547968 | AV9: =AS9*COS(AU9) -> -0.0058641477 | AW9: =AS9*SIN(AU9) -> -0.0012695557 | AX9: =IF(V43="",0,IF(V43>0,V43,)) -> 0.18484073 | AY9: =IF(N43="",0,IF(N43>0,N43,)) -> 1.2027866 | AZ9: =RADIANS(180+AY9) -> 3.1625852 | BA9: =AX9*COS(AZ9) -> -0.1848 | BB9: =AX9*SIN(AZ9) -> -0.00388 | BC9: Z | BD9: fi | BE9: Z | BF9: fi
AN10: =IF(KabelData!N3="","",KabelData!N3) -> -W4 | AO10: =Kabeludskrif!K17 -> 0.2178 | AP10: =IF(KabelData!N11="","",ROUND(KabelData!N11,4)) -> 0.4877 | AQ10: =Kabeludskrif!K64 -> 0.32670526 | AR10: =KabelData!N15 -> 0.32514611 | AS10: =IF(V29="",0,IF(V29>0,V29,)) -> 0 | AT10: =IF(Z29="",0,IF(Z29>0,Z29,)) -> 0 | AU10: =RADIANS(180+AT10) -> 3.1415927 | AV10: =AS10*COS(AU10) -> 0 | AW10: =AS10*SIN(AU10) -> 0 | AX10: =IF(V44="",0,IF(V44>0,V44,)) -> 0 | AY10: =IF(N44="",0,IF(N44>0,N44,)) -> 0 | AZ10: =RADIANS(180+AY10) -> 3.1415927 | BA10: =AX10*COS(AZ10) -> 0 | BB10: =AX10*SIN(AZ10) -> 0 | BC10: =Transformer!C59 -> 0.014433757 | BD10: =Transformer!F59 -> 72.5424 | BE10: =Transformer!C73 -> 0.1848 | BF10: =Transformer!F73 -> 25.8419
AN11: =IF(KabelData!R3="","",KabelData!R3) -> -E5 | AO11: =Kabeludskrif!K21 | AP11: =IF(KabelData!R11="","",ROUND(KabelData!R11,4)) | AQ11: =Kabeludskrif!K68 | AR11: =KabelData!R15 | AS11: =IF(AD29="",0,IF(AD29>0,AD29,)) -> 0 | AT11: =IF(AH29="",0,IF(AH29>0,AH29,)) -> 0 | AU11: =RADIANS(180+AT11) -> 3.1415927 | AV11: =AS11*COS(AU11) -> 0 | AW11: =AS11*SIN(AU11) -> 0 | AX11: =IF(V45="",0,IF(V45>0,V45,)) -> 0 | AY11: =IF(N45="",0,IF(N45>0,N45,)) -> 0 | AZ11: =RADIANS(180+AY11) -> 3.1415927 | BA11: =AX11*COS(AZ11) -> 0 | BB11: =AX11*SIN(AZ11) -> 0
AN12: =IF(KabelData!B18="","",KabelData!B18) | AO12: =Kabeludskrif!K25 | AP12: =IF(KabelData!B26="","",ROUND(KabelData!B26,4)) | AQ12: =Kabeludskrif!K72 | AR12: =KabelData!B30 | AS12: =SQRT(SUM(AV7:AV11)^2+SUM(AW7:AW11)^2) -> 0.018168081 | AT12: =DEGREES(ATAN(SUM(AW7:AW11)/SUM(AV7:AV11))) -> 55.867472 | AX12: =IF(V46="",0,IF(V46>0,V46,)) -> 0 | AY12: =IF(N46="",0,IF(N46>0,N46,)) -> 0 | AZ12: =RADIANS(180+AY12) -> 3.1415927 | BA12: =AX12*COS(AZ12) -> 0 | BB12: =AX12*SIN(AZ12) -> 0
AN13: =IF(KabelData!F18="","",KabelData!F18) | AO13: =Kabeludskrif!K29 | AP13: =IF(KabelData!F26="","",ROUND(KabelData!F26,4)) | AQ13: =Kabeludskrif!K76 | AR13: =KabelData!F30 | AS13: =IF(E60="",0,E60) -> 0 | AT13: =IF(H60="",0,H60) -> 0 | AU13: =RADIANS(180+AT13) -> 3.1415927 | AV13: =AS13*COS(AU13) -> 0 | AW13: =AS13*SIN(AU13) -> 0 | AX13: =IF(V47="",0,IF(V47>0,V47,)) -> 0 | AY13: =IF(N47="",0,IF(N47>0,N47,)) -> 0 | AZ13: =RADIANS(180+AY13) -> 3.1415927 | BA13: =AX13*COS(AZ13) -> 0 | BB13: =AX13*SIN(AZ13) -> 0
AN14: =IF(KabelData!J18="","",KabelData!J18) | AO14: =Kabeludskrif!K33 | AP14: =IF(KabelData!J26="","",ROUND(KabelData!J26,4)) | AQ14: =Kabeludskrif!K80 | AR14: =KabelData!J30 | AS14: =IF(M60="",0,IF(M60>0,M60,)) -> 0.1848 | AT14: =IF(Q60="",0,IF(Q60>0,Q60,)) -> 25.8419 | AU14: =RADIANS(180+AT14) -> 3.5926189 | AV14: =AS14*COS(AU14) -> -0.16632005 | AW14: =AS14*SIN(AU14) -> -0.080552357 | AX14: =IF(V48="",0,IF(V48>0,V48,)) -> 0 | AY14: =IF(N48="",0,IF(N48>0,N48,)) -> 0 | AZ14: =RADIANS(180+AY14) -> 3.1415927 | BA14: =AX14*COS(AZ14) -> 0 | BB14: =AX14*SIN(AZ14) -> 0
AN15: =IF(KabelData!N18="","",KabelData!N18) | AO15: =Kabeludskrif!K39 | AP15: =IF(KabelData!N26="","",ROUND(KabelData!N26,4)) | AQ15: =Kabeludskrif!K86 | AR15: =KabelData!N30 | AS15: =IF(U60="",0,U60) -> 0.27139628 | AT15: =IF(Y60="",0,Y60) -> 2.0681416 | AU15: =RADIANS(180+AT15) -> 3.1776885 | AV15: =AS15*COS(AU15) -> -0.2712195 | AW15: =AS15*SIN(AU15) -> -0.0097941608 | AX15: =IF(V49="",0,IF(V49>0,V49,)) -> 0 | AY15: =IF(N49="",0,IF(N49>0,N49,)) -> 0 | AZ15: =RADIANS(180+AY15) -> 3.1415927 | BA15: =AX15*COS(AZ15) -> 0 | BB15: =AX15*SIN(AZ15) -> 0
AN16: =IF(KabelData!R18="","",KabelData!R18) -> -W10 | AO16: =Kabeludskrif!K43 | AP16: =IF(KabelData!R26="","",ROUND(KabelData!R26,4)) | AQ16: =Kabeludskrif!K90 | AR16: =KabelData!R30 | AS16: =SQRT(SUM(AV13:AV15)^2+SUM(AW13:AW15)^2) -> 0.44676991 | AT16: =DEGREES(ATAN(SUM(AW13:AW15)/SUM(AV13:AV15))) -> 11.666901 | AX16: =IF(V50="",0,IF(V50>0,V50,)) -> 0 | AY16: =IF(N50="",0,IF(N50>0,N50,)) -> 0 | AZ16: =RADIANS(180+AY16) -> 3.1415927 | BA16: =AX16*COS(AZ16) -> 0 | BB16: =AX16*SIN(AZ16) -> 0
A18: Første fordeling | H18: Beregnet
B20: IKmax3F | F20: kabelværdier er 20˚C
B22: UN
B23: √3 * | D23: ( | E23: =IF(H18="Transformer", "Z̅T",IF(H18="Beregnet","", )) | F23: =IF(H18="Transformer", "+",IF(H18="Beregnet","", )) | G23: Z̅N | J23: =IF(L23="","",$AQ$3) -> + Z̅ | L23: -W1 | O23: =IF(Q23="","",AQ3) | T23: =IF(V23="","",AQ3) | Y23: )
A26: <=>
B28: 400
B29: √3 * | D29: ( | E29: =IF($H$18="Transformer",BC7,IF(H18="Beregnet","",)) | F29: =IF(E29="","",$AT$3) | G29: =IF($H$18="Transformer",BD7,IF(H18="Beregnet","",)) | J29: =(IF($H$18="Transformer",BE7,IF($H$18="beregnet",BC10))) -> 0.014433757 | M29: =IF(J29="","",$AT$3) -> Ð | N29: =(IF($H$18="Transformer",BF7,IF($H$18="beregnet",BD10))) -> 72.5424 | P29: =(IF($L$23="","",IF($L$23=AN7,AO7,IF($L$23=AN8,AO8,IF($L$23=AN9,AO9,IF($L$23=AN10,AO10,IF($L$23=AN11,AO11,IF($L$23=AN12,AO12,IF($L$23=AN13,AO13,IF($L$23=AN14,AO14,IF($L$23=AN15,AO15,IF($L$23=AN16,AO16)))))))))))) -> 0.006 | S29: =IF(P29="","",$AT$3) -> Ð | T29: =(IF($L$23="","",IF($L$23=AN7,AP7,IF($L$23=AN8,AP8,IF($L$23=AN9,AP9,IF($L$23=AN10,AP10,IF($L$23=AN11,AP11,IF($L$23=AN12,AP12,IF($L$23=AN13,AP13,IF($L$23=AN14,AP14,IF($L$23=AN15,AP15,IF($L$23=AN16,AP16)))))))))))) -> 12.2157 | V29: =(IF($Q$23="","",IF($Q$23=AN7,AO7,IF($Q$23=AN8,AO8,IF($Q$23=AN9,AO9,IF($Q$23=AN10,AO10,IF($Q$23=AN11,AO11,IF($Q$23=AN12,AO12,IF($Q$23=AN13,AO13,IF($Q$23=AN14,AO14,IF($Q$23=AN15,AO15,IF($Q$23=AN16,AO16)))))))))))) | Y29: =IF(V29="","",$AT$3) | Z29: =(IF($Q$23="","",IF($Q$23=AN7,AP7,IF($Q$23=AN8,AP8,IF($Q$23=AN9,AP9,IF($Q$23=AN10,AP10,IF($Q$23=AN11,AP11,IF($Q$23=AN12,AP12,IF($Q$23=AN13,AP13,IF($Q$23=AN14,AP14,IF($Q$23=AN15,AP15,IF($Q$23=AN16,AP16)))))))))))) | AD29: =(IF($V$23="","",IF($V$23=AN7,AO7,IF($V$23=AN8,AO8,IF($V$23=AN9,AO9,IF($V$23=AN10,AO10,IF($V$23=AN11,AO11,IF($V$23=AN12,AO12,IF($V$23=AN13,AO13,IF($V$23=AN14,AO14,IF($V$23=AN15,AO15,IF($V$23=AN16,AO16)))))))))))) | AG29: =IF(AD29="","",$AT$3) | AH29: =(IF($V$23="","",IF($V$23=AN7,AP7,IF($V$23=AN8,AP8,IF($V$23=AN9,AP9,IF($V$23=AN10,AP10,IF($V$23=AN11,AP11,IF($V$23=AN12,AP12,IF($V$23=AN13,AP13,IF($V$23=AN14,AP14,IF($V$23=AN15,AP15,IF($V$23=AN16,AP16)))))))))))) | AK29: )
B32: = | C32: =IF(J29="","",ROUND((B28/(SQRT(3)*AS12))*10^-3,2)) -> 12.71 | F32: kA
A34: Første fordeling | H34: Beregnet
A35: Husk overskrift, tegning og forklaring (overskriv dette)
B36: IKminFN(PE) | F36: kabelværdi er 70˚ C
A37: Kabelimpedanser Z̅ er regnet på bilag
B38: n* er antal gange impedansen indgår i fejlkredsen
B40: Kabelimpedans id | I40: Z̅ | R40: n* | V40: Z̅ * n
B41: Z̅ | D41: -W1 | I41: =(IF(D41="","",IF(D41=$AN$7,$AQ$7,IF(D41=$AN$8,$AQ$8,IF(D41=$AN$9,$AQ$9,IF(D41=$AN$10,$AQ$10,IF(D41=$AN$11,$AQ$11,IF(D41=$AN$12,$AQ$12,IF(D41=$AN$13,$AQ$13,IF(D41=$AN$14,$AQ$14,IF(D41=$AN$15,$AQ$15,IF(D41=$AN$16,$AQ$16,)))))))))))) -> 0.0088 | M41: Ð | N41: =(IF(D41="","",IF(D41=$AN$7,$AR$7,IF(D41=$AN$8,$AR$8,IF(D41=$AN$9,$AR$9,IF(D41=$AN$10,$AR$10,IF(D41=$AN$11,$AR$11,IF(D41=$AN$12,$AR$12,IF(D41=$AN$13,$AR$616,IF(D41=$AN$14,$AR$14,IF(D41=$AN$15,$AR$15,IF(D41=$AN$16,$AR$16,)))))))))))) -> 8.2128 | Q41: * | R41: 2 | U41: = | V41: =IF(D41="","",IF(D41>0,R41*I41)) -> 0.0176 | Y41: Ð | Z41: =N41 -> 8.2128
B42: Z̅ | D42: -W2 | I42: =(IF(D42="","",IF(D42=$AN$7,$AQ$7,IF(D42=$AN$8,$AQ$8,IF(D42=$AN$9,$AQ$9,IF(D42=$AN$10,$AQ$10,IF(D42=$AN$11,$AQ$11,IF(D42=$AN$12,$AQ$12,IF(D42=$AN$13,$AQ$13,IF(D42=$AN$14,$AQ$14,IF(D42=$AN$15,$AQ$15,IF(D42=$AN$16,$AQ$16,)))))))))))) -> 0.034541859 | M42: Ð | N42: =(IF(D42="","",IF(D42=$AN$7,$AR$7,IF(D42=$AN$8,$AR$8,IF(D42=$AN$9,$AR$9,IF(D42=$AN$10,$AR$10,IF(D42=$AN$11,$AR$11,IF(D42=$AN$12,$AR$12,IF(D42=$AN$13,$AR$616,IF(D42=$AN$14,$AR$14,IF(D42=$AN$15,$AR$15,IF(D42=$AN$16,$AR$16,)))))))))))) -> 2.8209886 | Q42: * | R42: 2 | U42: = | V42: =IF(D42="","",IF(D42>0,R42*I42)) -> 0.069083717 | Y42: Ð | Z42: =N42 -> 2.8209886
B43: Z̅ | D43: -W3 | I43: =(IF(D43="","",IF(D43=$AN$7,$AQ$7,IF(D43=$AN$8,$AQ$8,IF(D43=$AN$9,$AQ$9,IF(D43=$AN$10,$AQ$10,IF(D43=$AN$11,$AQ$11,IF(D43=$AN$12,$AQ$12,IF(D43=$AN$13,$AQ$13,IF(D43=$AN$14,$AQ$14,IF(D43=$AN$15,$AQ$15,IF(D43=$AN$16,$AQ$16,)))))))))))) -> 0.092420364 | M43: Ð | N43: =(IF(D43="","",IF(D43=$AN$7,$AR$7,IF(D43=$AN$8,$AR$8,IF(D43=$AN$9,$AR$9,IF(D43=$AN$10,$AR$10,IF(D43=$AN$11,$AR$11,IF(D43=$AN$12,$AR$12,IF(D43=$AN$13,$AR$616,IF(D43=$AN$14,$AR$14,IF(D43=$AN$15,$AR$15,IF(D43=$AN$16,$AR$16,)))))))))))) -> 1.2027866 | Q43: * | R43: 2 | U43: = | V43: =IF(D43="","",IF(D43>0,R43*I43)) -> 0.18484073 | Y43: Ð | Z43: =N43 -> 1.2027866
B44: Z̅ | I44: =(IF(D44="","",IF(D44=$AN$7,$AQ$7,IF(D44=$AN$8,$AQ$8,IF(D44=$AN$9,$AQ$9,IF(D44=$AN$10,$AQ$10,IF(D44=$AN$11,$AQ$11,IF(D44=$AN$12,$AQ$12,IF(D44=$AN$13,$AQ$13,IF(D44=$AN$14,$AQ$14,IF(D44=$AN$15,$AQ$15,IF(D44=$AN$16,$AQ$16,)))))))))))) | M44: Ð | N44: =(IF(D44="","",IF(D44=$AN$7,$AR$7,IF(D44=$AN$8,$AR$8,IF(D44=$AN$9,$AR$9,IF(D44=$AN$10,$AR$10,IF(D44=$AN$11,$AR$11,IF(D44=$AN$12,$AR$12,IF(D44=$AN$13,$AR$616,IF(D44=$AN$14,$AR$14,IF(D44=$AN$15,$AR$15,IF(D44=$AN$16,$AR$16,)))))))))))) | Q44: * | U44: = | V44: =IF(D44="","",IF(D44>0,R44*I44)) | Y44: Ð | Z44: =N44
