Workbook

Sheet Tavle +A11
C2: Eftersiddende tavle | H2: 11
P3: sf | Q3: 1 | S3: uf | T3: 1
N4: Selv skriv tavlenavn
C5: UL-L | D5: 400 | E5: [V] | F5: 3. harmoniske strømme | I5: 0 | J5: [A]
N6: Tavle +A11
F7: Værdi | H7: IB [A] | I7: cos ϕ | J7: Tilsluttet | K7: Ðj i Grader | L7: Ind./Kap. | N7: Belastning | P7: IL1 [A] | S7: IL2 [A] | V7: IL3 [A] | Y7: IN [A]
C8: Belastning 1 | F8: 0 | G8: =VLOOKUP(E51,B44:D46,3) -> [kW] | H8: =VLOOKUP(E51,M50:U53,J51+2) -> 0 | I8: 1 | K8: =IF(L51=1,-DEGREES(ACOS(I8)),DEGREES(ACOS(I8))) -> 0 | N8: =C8 -> Belastning 1 | O8: =HLOOKUP($J$51,$AA$49:$AG$54,3) -> 0 | P8: Ð | Q8: =HLOOKUP($J$51,$AJ$49:$AP$54,3) -> 0 | R8: =HLOOKUP($J$51,$AA$49:$AG$54,4) -> 0 | S8: Ð | T8: =HLOOKUP($J$51,$AJ$49:$AP$54,4) -> -120 | U8: =HLOOKUP($J$51,$AA$49:$AG$54,5) -> 0 | V8: Ð | W8: =HLOOKUP($J$51,$AJ$49:$AP$54,5) -> 120 | X8: =HLOOKUP($J$51,$AA$49:$AG$54,6) -> 0 | Y8: Ð | Z8: =HLOOKUP($J$51,$AJ$49:$AP$54,6) -> 0
C9: Belastning 2 | F9: 0 | G9: =VLOOKUP(E55,B44:D46,3) -> [kW] | H9: =VLOOKUP(E55,M55:U57,J55+2) -> 0 | I9: 1 | K9: =IF(L55=1,-DEGREES(ACOS(I9)),DEGREES(ACOS(I9))) -> 0 | L9: ½ | N9: =C9 -> Belastning 2 | O9: =HLOOKUP($J$55,$AA$56:$AG$61,3) -> 0 | P9: Ð | Q9: =HLOOKUP($J$55,$AJ$56:$AP$61,3) -> 0 | R9: =HLOOKUP($J$55,$AA$56:$AG$61,4) -> 0 | S9: Ð | T9: =HLOOKUP($J$55,$AJ$56:$AP$61,4) -> -120 | U9: =HLOOKUP($J$55,$AA$56:$AG$61,5) -> 0 | V9: Ð | W9: =HLOOKUP($J$55,$AJ$56:$AP$61,5) -> 120 | X9: =HLOOKUP($J$55,$AA$56:$AG$61,6) -> 0 | Y9: Ð | Z9: =HLOOKUP($J$55,$AJ$56:$AP$61,6) -> 0
C10: Belastning 3 | F10: 0 | G10: =VLOOKUP(E59,B44:D46,3) -> [kW] | H10: =VLOOKUP(E59,M59:U61,J59+2) -> 0 | I10: 1 | K10: =IF(L59=1,-DEGREES(ACOS(I10)),DEGREES(ACOS(I10))) -> 0 | N10: =C10 -> Belastning 3 | O10: =HLOOKUP($J$59,$AA$63:$AG468,3) -> 0 | P10: Ð | Q10: =HLOOKUP($J$59,$AJ$63:$AP$68,3) -> 0 | R10: =HLOOKUP($J$59,$AA$63:$AG468,4) -> 0 | S10: Ð | T10: =HLOOKUP($J$59,$AJ$63:$AP$68,4) -> -120 | U10: =HLOOKUP($J$59,$AA$63:$AG468,5) -> 0 | V10: Ð | W10: =HLOOKUP($J$59,$AJ$63:$AP$68,5) -> 120 | X10: =HLOOKUP($J$59,$AA$63:$AG468,6) -> 0 | Y10: Ð | Z10: =HLOOKUP($J$59,$AJ$63:$AP$68,6) -> 0
C11: Belastning 4 | F11: 0 | G11: =VLOOKUP(E63,B44:D46,3) -> [kW] | H11: =VLOOKUP(E63,M63:U65,J63+2) -> 0 | I11: 1 | K11: =IF(L63=1,-DEGREES(ACOS(I11)),DEGREES(ACOS(I11))) -> 0 | N11: =C11 -> Belastning 4 | O11: =HLOOKUP($J$63,$AA$70:$AG$75,3) -> 0 | P11: Ð | Q11: =HLOOKUP($J$63,$AJ$70:$AP$75,3) -> 0 | R11: =HLOOKUP($J$63,$AA$70:$AG$75,4) -> 0 | S11: Ð | T11: =HLOOKUP($J$63,$AJ$70:$AP$75,4) -> -120 | U11: =HLOOKUP($J$63,$AA$70:$AG$75,5) -> 0 | V11: Ð | W11: =HLOOKUP($J$63,$AJ$70:$AP$75,5) -> 120 | X11: =HLOOKUP($J$63,$AA$70:$AG$75,6) -> 0 | Y11: Ð | Z11: =HLOOKUP($J$63,$AJ$70:$AP$75,6) -> 0
C12: Belastning 5 | F12: 0 | G12: =VLOOKUP(E67,B44:D46,3) -> [kW] | H12: =VLOOKUP(E67,M67:U69,J67+2) -> 0 | I12: 1 | K12: =IF(L67=1,-DEGREES(ACOS(I12)),DEGREES(ACOS(I12))) -> 0 | N12: =C12 -> Belastning 5 | O12: =HLOOKUP($J$67,$AA$77:$AG$82,3) -> 0 | P12: Ð | Q12: =HLOOKUP($J$67,$AJ$77:$AP$82,3) -> 0 | R12: =HLOOKUP($J$67,$AA$77:$AG$82,4) -> 0 | S12: Ð | T12: =HLOOKUP($J$67,$AJ$77:$AP$82,4) -> -120 | U12: =HLOOKUP($J$67,$AA$77:$AG$82,5) -> 0 | V12: Ð | W12: =HLOOKUP($J$67,$AJ$77:$AP$82,5) -> 120 | X12: =HLOOKUP($J$67,$AA$77:$AG$82,6) -> 0 | Y12: Ð | Z12: =HLOOKUP($J$67,$AJ$77:$AP$82,6) -> 0
C13: Belastning 6 | F13: 0 | G13: =VLOOKUP(E71,B44:D46,3) -> [kW] | H13: =VLOOKUP(E71,M71:U73,J71+2) -> 0 | I13: 1 | K13: =IF(L71=1,-DEGREES(ACOS(I13)),DEGREES(ACOS(I13))) -> 0 | N13: =C13 -> Belastning 6 | O13: =HLOOKUP($J$71,$AA$84:$AG$89,3) -> 0 | P13: Ð | Q13: =HLOOKUP($J$71,$AJ$84:$AP$89,3) -> 0 | R13: =HLOOKUP($J$71,$AA$84:$AG$89,4) -> 0 | S13: Ð | T13: =HLOOKUP($J$71,$AJ$84:$AP$89,4) -> -120 | U13: =HLOOKUP($J$71,$AA$84:$AG$89,5) -> 0 | V13: Ð | W13: =HLOOKUP($J$71,$AJ$84:$AP$89,5) -> 120 | X13: =HLOOKUP($J$71,$AA$84:$AG$89,6) -> 0 | Y13: Ð | Z13: =HLOOKUP($J$71,$AJ$84:$AP$89,6) -> 0
C14: Belastning 7 | F14: 0 | G14: =VLOOKUP(E75,B44:D46,3) -> [kW] | H14: =VLOOKUP(E75,M75:U77,J75+2) -> 0 | I14: 1 | K14: =IF(L75=1,-DEGREES(ACOS(I14)),DEGREES(ACOS(I14))) -> 0 | N14: =C14 -> Belastning 7 | O14: =HLOOKUP($J$75,$AA$91:$AG$96,3) -> 0 | P14: Ð | Q14: =HLOOKUP($J$75,$AJ$91:$AP$96,3) -> 0 | R14: =HLOOKUP($J$75,$AA$91:$AG$96,4) -> 0 | S14: Ð | T14: =HLOOKUP($J$75,$AJ$91:$AP$96,4) -> -120 | U14: =HLOOKUP($J$75,$AA$91:$AG$96,5) -> 0 | V14: Ð | W14: =HLOOKUP($J$75,$AJ$91:$AP$96,5) -> 120 | X14: =HLOOKUP($J$75,$AA$91:$AG$96,6) -> 0 | Y14: Ð | Z14: =HLOOKUP($J$75,$AJ$91:$AP$96,6) -> 0
C15: Belastning 8 | F15: 0 | G15: =VLOOKUP(E79,B44:D46,3) -> [kW] | H15: =VLOOKUP(E79,M79:U81,J79+2) -> 0 | I15: 1 | K15: =IF(L79=1,-DEGREES(ACOS(I15)),DEGREES(ACOS(I15))) -> 0 | N15: =C15 -> Belastning 8 | O15: =HLOOKUP($J$79,$AA$98:$AG$103,3) -> 0 | P15: Ð | Q15: =HLOOKUP($J$79,$AJ$98:$AP$103,3) -> 0 | R15: =HLOOKUP($J$79,$AA$98:$AG$103,4) -> 0 | S15: Ð | T15: =HLOOKUP($J$79,$AJ$98:$AP$103,4) -> -120 | U15: =HLOOKUP($J$79,$AA$98:$AG$103,5) -> 0 | V15: Ð | W15: =HLOOKUP($J$79,$AJ$98:$AP$103,5) -> 120 | X15: =HLOOKUP($J$79,$AA$98:$AG$103,6) -> 0 | Y15: Ð | Z15: =HLOOKUP($J$79,$AJ$98:$AP$103,6) -> 0
C16: Belastning 9 | F16: 0 | G16: =VLOOKUP(E83,B44:D46,3) -> [kW] | H16: =VLOOKUP(E83,M83:U85,J83+2) -> 0 | I16: 1 | K16: =IF(L83=1,-DEGREES(ACOS(I16)),DEGREES(ACOS(I16))) -> 0 | N16: =C16 -> Belastning 9 | O16: =HLOOKUP($J$83,$AA$105:$AG$110,3) -> 0 | P16: Ð | Q16: =HLOOKUP($J$83,$AJ$105:$AP$110,3) -> 0 | R16: =HLOOKUP($J$83,$AA$105:$AG$110,4) -> 0 | S16: Ð | T16: =HLOOKUP($J$83,$AJ$105:$AP$110,4) -> -120 | U16: =HLOOKUP($J$83,$AA$105:$AG$110,5) -> 0 | V16: Ð | W16: =HLOOKUP($J$83,$AJ$105:$AP$110,5) -> 120 | X16: =HLOOKUP($J$83,$AA$105:$AG$110,6) -> 0 | Y16: Ð | Z16: =HLOOKUP($J$83,$AJ$105:$AP$110,6) -> 0
C17: Belastning 10 | F17: 0 | G17: =VLOOKUP(E87,B44:D46,3) -> [kW] | H17: =VLOOKUP(E87,M87:U89,J87+2) -> 0 | I17: 1 | K17: =IF(L87=1,-DEGREES(ACOS(I17)),DEGREES(ACOS(I17))) -> 0 | N17: =C17 -> Belastning 10 | O17: =HLOOKUP($J$87,$AA$112:$AG$117,3) -> 0 | P17: Ð | Q17: =HLOOKUP($J$87,$AJ$112:$AP$117,3) -> 0 | R17: =HLOOKUP($J$87,$AA$112:$AG$117,4) -> 0 | S17: Ð | T17: =HLOOKUP($J$87,$AJ$112:$AP$117,4) -> -120 | U17: =HLOOKUP($J$87,$AA$112:$AG$117,5) -> 0 | V17: Ð | W17: =HLOOKUP($J$87,$AJ$112:$AP$117,5) -> 120 | X17: =HLOOKUP($J$87,$AA$112:$AG$117,6) -> 0 | Y17: Ð | Z17: =HLOOKUP($J$87,$AJ$112:$AP$117,6) -> 0
C18: Belastning 11 | F18: 0 | G18: =VLOOKUP(E91,B44:D46,3) -> [kW] | H18: =VLOOKUP(E91,M91:U93,J91+2) -> 0 | I18: 1 | K18: =IF(L91=1,-DEGREES(ACOS(I18)),DEGREES(ACOS(I18))) -> 0 | N18: =C18 -> Belastning 11 | O18: =HLOOKUP($J$91,$AA$119:$AG$124,3) -> 0 | P18: Ð | Q18: =HLOOKUP($J$91,$AJ$119:$AP$124,3) -> 0 | R18: =HLOOKUP($J$91,$AA$119:$AG$124,4) -> 0 | S18: Ð | T18: =HLOOKUP($J$91,$AJ$119:$AP$124,4) -> -120 | U18: =HLOOKUP($J$91,$AA$119:$AG$124,5) -> 0 | V18: Ð | W18: =HLOOKUP($J$91,$AJ$119:$AP$124,5) -> 120 | X18: =HLOOKUP($J$91,$AA$119:$AG$124,6) -> 0 | Y18: Ð | Z18: =HLOOKUP($J$91,$AJ$119:$AP$124,6) -> 0
C19: Belastning 12 | F19: 0 | G19: =VLOOKUP(E95,B44:D46,3) -> [kW] | H19: =VLOOKUP(E95,M95:U97,J95+2) -> 0 | I19: 1 | K19: =IF(L95=1,-DEGREES(ACOS(I19)),DEGREES(ACOS(I19))) -> 0 | N19: =C19 -> Belastning 12 | O19: =HLOOKUP($J$95,$AA$126:$AG$131,3) -> 0 | P19: Ð | Q19: =HLOOKUP($J$95,$AJ$126:$AP$131,3) -> 0 | R19: =HLOOKUP($J$95,$AA$126:$AG$131,4) -> 0 | S19: Ð | T19: =HLOOKUP($J$95,$AJ$126:$AP$131,4) -> -120 | U19: =HLOOKUP($J$95,$AA$126:$AG$131,5) -> 0 | V19: Ð | W19: =HLOOKUP($J$95,$AJ$126:$AP$131,5) -> 120 | X19: =HLOOKUP($J$95,$AA$126:$AG$131,6) -> 0 | Y19: Ð | Z19: =HLOOKUP($J$95,$AJ$126:$AP$131,6) -> 0
C20: Belastning 13 | F20: 0 | G20: =VLOOKUP(E99,B44:D46,3) -> [kW] | H20: =VLOOKUP(E99,M99:U101,J99+2) -> 0 | I20: 1 | K20: =IF(L99=1,-DEGREES(ACOS(I20)),DEGREES(ACOS(I20))) -> 0 | N20: =C20 -> Belastning 13 | O20: =HLOOKUP($J$99,$AA$133:$AG$138,3) -> 0 | P20: Ð | Q20: =HLOOKUP($J$99,$AJ$133:$AP$138,3) -> 0 | R20: =HLOOKUP($J$99,$AA$133:$AG$138,4) -> 0 | S20: Ð | T20: =HLOOKUP($J$99,$AJ$133:$AP$138,4) -> -120 | U20: =HLOOKUP($J$99,$AA$133:$AG$138,5) -> 0 | V20: Ð | W20: =HLOOKUP($J$99,$AJ$133:$AP$138,5) -> 120 | X20: =HLOOKUP($J$99,$AA$133:$AG$138,6) -> 0 | Y20: Ð | Z20: =HLOOKUP($J$99,$AJ$133:$AP$138,6) -> 0
C21: Belastning 14 | F21: 0 | G21: =VLOOKUP(E103,B44:D46,3) -> [kW] | H21: =VLOOKUP(E103,M103:U105,J103+2) -> 0 | I21: 1 | K21: =IF(L103=1,-DEGREES(ACOS(I21)),DEGREES(ACOS(I21))) -> 0 | N21: =C21 -> Belastning 14 | O21: =HLOOKUP($J$103,$AA$140:$AG$145,3) -> 0 | P21: Ð | Q21: =HLOOKUP($J$103,$AJ$140:$AP$145,3) -> 0 | R21: =HLOOKUP($J$103,$AA$140:$AG$145,4) -> 0 | S21: Ð | T21: =HLOOKUP($J$103,$AJ$140:$AP$145,4) -> -120 | U21: =HLOOKUP($J$103,$AA$140:$AG$145,5) -> 0 | V21: Ð | W21: =HLOOKUP($J$103,$AJ$140:$AP$145,5) -> 120 | X21: =HLOOKUP($J$103,$AA$140:$AG$145,6) -> 0 | Y21: Ð | Z21: =HLOOKUP($J$103,$AJ$140:$AP$145,6) -> 0
C22: Belastning 15 | F22: 0 | G22: =VLOOKUP(E107,B44:D46,3) -> [kW] | H22: =VLOOKUP(E107,M107:U109,J107+2) -> 0 | I22: 1 | K22: =IF(L107=1,-DEGREES(ACOS(I22)),DEGREES(ACOS(I22))) -> 0 | N22: =C22 -> Belastning 15 | O22: =HLOOKUP($J$107,$AA$147:$AG$152,3) -> 0 | P22: Ð | Q22: =HLOOKUP($J$107,$AJ$147:$AP$152,3) -> 0 | R22: =HLOOKUP($J$107,$AA$147:$AG$152,4) -> 0 | S22: Ð | T22: =HLOOKUP($J$107,$AJ$147:$AP$152,4) -> -120 | U22: =HLOOKUP($J$107,$AA$147:$AG$152,5) -> 0 | V22: Ð | W22: =HLOOKUP($J$107,$AJ$147:$AP$152,5) -> 120 | X22: =HLOOKUP($J$107,$AA$147:$AG$152,6) -> 0 | Y22: Ð | Z22: =HLOOKUP($J$107,$AJ$147:$AP$152,6) -> 0
N23: ∑Itil - Global | O23: =SQRT(E128^2+F128^2) -> 0 | P23: Ð | Q23: =IFERROR(DEGREES(ATAN(F128/E128)),0) -> 0 | R23: =SQRT(G128^2+H128^2) -> 0 | S23: Ð | T23: =IFERROR(-DEGREES(ATAN(G128/H128))-90,0) -> 0 | U23: =SQRT(I128^2+J128^2) -> 0 | V23: Ð | W23: =IFERROR(-DEGREES(ATAN(I128/J128))+90,0) -> 0 | X23: =IMABS(COMPLEX(C134+F134+I134,C135+F135+I135)) -> 0 | Y23: Ð | Z23: =IFERROR(DEGREES(IMARGUMENT(IMSUM(L135)))+180,0) -> 0
N24: ∑IB - Global | O24: =O23*Q3*T3 -> 0 | P24: Ð | Q24: =Q23 -> 0 | R24: =R23*Q3*T3 -> 0 | S24: Ð | T24: =T23 -> 0 | U24: =U23*Q3*T3 -> 0 | V24: Ð | W24: =W23 -> 0 | X24: =(X23)*Q3*T3 -> 0 | Y24: Ð | Z24: =Z23 -> 0
N25: ∑IB - Lokal | O25: =O24 -> 0 | P25: Ð | Q25: =Q23 -> 0 | R25: =R24 -> 0 | S25: Ð | T25: =T24+120 -> 120 | U25: =U24 -> 0 | V25: Ð | W25: =W24-120 -> -120 | X25: =(X24) -> 0 | Y25: Ð | Z25: =Z24 -> 0
N26: 3. harmoniske | O26: =IFERROR(((I5/3)/O24)*100,0) -> 0 | P26: % | R26: =IFERROR(((I5/3)/R24)*100,0) -> 0 | S26: % | U26: =IFERROR(((I5/3)/U24)*100,0) -> 0 | V26: %
K27: Tjek SB side 193
I39: 1 | J39: 3 - faser
I40: 2 | J40: L1 - N
I41: 3 | J41: L2 - N
I42: 4 | J42: L3 - N
I43: 5 | J43: L1 - L2 | AA43: 3-harmoniske
B44: 1 | C44: P [kW] | D44: [kW] | I44: 6 | J44: L2 - L3 | L44: Induktiv | Y44: 1 | Z44: IL1 | AB44: %
B45: 2 | C45: S [kVA] | D45: [kVA] | I45: 7 | J45: L1 - L3 | L45: Kapasativ | Y45: 2 | Z45: IL2 | AB45: %
B46: 3 | C46: I [A] | D46: [A] | Y46: 3 | Z46: IL3 | AB46: %
Y47: 4 | Z47: IN
E49: Output | AA49: 1 | AB49: 2 | AC49: 3 | AD49: 4 | AE49: 5 | AF49: 6 | AG49: 7 | AJ49: 1 | AK49: 2 | AL49: 3 | AM49: 4 | AN49: 5 | AO49: 6 | AP49: 7
O50: 3-faset | P50: L1-N | Q50: L2-N | R50: L3-N | S50: L1-L2 | T50: L2-L3 | U50: L1-L3 | AA50: 3-faset | AB50: L1-N | AC50: L2-N | AD50: L3-N | AE50: L1-L2 | AF50: L2-L3 | AG50: L1-L3 | AI50: Ðj Grader | AJ50: 3-faset | AK50: L1-N | AL50: L2-N | AM50: L3-N | AN50: L1-L2 | AO50: L2-L3 | AP50: L1-L3
C51: Belastning 1 | E51: 1 | J51: 1 | L51: 1 | M51: 1 | N51: P | O51: =(F8*1000)/($D$5*SQRT(3)*I8) -> 0 | P51: =($F$8*1000)/(($D$5/SQRT(3))*$I$8) -> 0 | Q51: =P51 -> 0 | R51: =P51 -> 0 | S51: =($F$8*1000)/($D$5*$I$8) -> 0 | T51: =S51 -> 0 | U51: =S51 -> 0 | Z51: IL1 | AA51: =H8 -> 0 | AB51: =AA51 -> 0 | AC51: 0 | AD51: 0 | AE51: =AA51 -> 0 | AF51: 0 | AG51: =AA51 -> 0 | AI51: IL1 | AJ51: =K8 -> 0 | AK51: =AJ51 -> 0 | AL51: 0 | AM51: 0 | AN51: =AJ51+30 -> 30 | AO51: 0 | AP51: =AJ51-30 -> -30
M52: 2 | N52: S | O52: =(F8*1000)/($D$5*SQRT(3)) -> 0 | P52: =($F$8*1000)/(($D$5/SQRT(3))) -> 0 | Q52: =P52 -> 0 | R52: =P52 -> 0 | S52: =($F$8*1000)/($D$5) -> 0 | T52: =S52 -> 0 | U52: =S52 -> 0 | Y52: 1 | Z52: IL2 | AA52: =AA51 -> 0 | AB52: 0 | AC52: =AA51 -> 0 | AD52: 0 | AE52: =AA51 -> 0 | AF52: =AA51 -> 0 | AG52: 0 | AI52: IL2 | AJ52: =AJ51-120 -> -120 | AK52: 0 | AL52: =AJ51-120 -> -120 | AM52: 0 | AN52: =AJ51-150 -> -150 | AO52: =AJ51-90 -> -90 | AP52: 0
M53: 3 | N53: I | O53: =F8 -> 0 | P53: =$F$8 -> 0 | Q53: =$F$8 -> 0 | R53: =$F$8 -> 0 | S53: =$F$8 -> 0 | T53: =$F$8 -> 0 | U53: =$F$8 -> 0 | Z53: IL3 | AA53: =AA51 -> 0 | AB53: 0 | AC53: 0 | AD53: =AA51 -> 0 | AE53: 0 | AF53: =AA51 -> 0 | AG53: =AA51 -> 0 | AI53: IL3 | AJ53: =AJ51+120 -> 120 | AK53: 0 | AL53: 0 | AM53: =AJ51+120 -> 120 | AN53: 0 | AO53: =AJ51+90 -> 90 | AP53: =AJ51+150 -> 150
...

Sheet Tavle +A12
C2: Eftersiddende tavle | H2: 12
P3: sf | Q3: 1 | S3: uf | T3: 1
N4: Selv skriv tavlenavn
C5: UL-L | D5: 400 | E5: [V] | F5: 3. harmoniske strømme | I5: 0 | J5: [A]
N6: Tavle +A12
F7: Værdi | H7: IB [A] | I7: cos ϕ | J7: Tilsluttet | K7: Ðj i Grader | L7: Ind./Kap. | N7: Belastning | P7: IL1 [A] | S7: IL2 [A] | V7: IL3 [A] | Y7: IN [A]
C8: Belastning 1 | F8: 0 | G8: =VLOOKUP(E51,B44:D46,3) -> [kW] | H8: =VLOOKUP(E51,M50:U53,J51+2) -> 0 | I8: 1 | K8: =IF(L51=1,-DEGREES(ACOS(I8)),DEGREES(ACOS(I8))) -> 0 | N8: =C8 -> Belastning 1 | O8: =HLOOKUP($J$51,$AA$49:$AG$54,3) -> 0 | P8: Ð | Q8: =HLOOKUP($J$51,$AJ$49:$AP$54,3) -> 0 | R8: =HLOOKUP($J$51,$AA$49:$AG$54,4) -> 0 | S8: Ð | T8: =HLOOKUP($J$51,$AJ$49:$AP$54,4) -> -120 | U8: =HLOOKUP($J$51,$AA$49:$AG$54,5) -> 0 | V8: Ð | W8: =HLOOKUP($J$51,$AJ$49:$AP$54,5) -> 120 | X8: =HLOOKUP($J$51,$AA$49:$AG$54,6) -> 0 | Y8: Ð | Z8: =HLOOKUP($J$51,$AJ$49:$AP$54,6) -> 0
C9: Belastning 2 | F9: 0 | G9: =VLOOKUP(E55,B44:D46,3) -> [kW] | H9: =VLOOKUP(E55,M55:U57,J55+2) -> 0 | I9: 1 | K9: =IF(L55=1,-DEGREES(ACOS(I9)),DEGREES(ACOS(I9))) -> 0 | L9: ½ | N9: =C9 -> Belastning 2 | O9: =HLOOKUP($J$55,$AA$56:$AG$61,3) -> 0 | P9: Ð | Q9: =HLOOKUP($J$55,$AJ$56:$AP$61,3) -> 0 | R9: =HLOOKUP($J$55,$AA$56:$AG$61,4) -> 0 | S9: Ð | T9: =HLOOKUP($J$55,$AJ$56:$AP$61,4) -> -120 | U9: =HLOOKUP($J$55,$AA$56:$AG$61,5) -> 0 | V9: Ð | W9: =HLOOKUP($J$55,$AJ$56:$AP$61,5) -> 120 | X9: =HLOOKUP($J$55,$AA$56:$AG$61,6) -> 0 | Y9: Ð | Z9: =HLOOKUP($J$55,$AJ$56:$AP$61,6) -> 0
C10: Belastning 3 | F10: 0 | G10: =VLOOKUP(E59,B44:D46,3) -> [kW] | H10: =VLOOKUP(E59,M59:U61,J59+2) -> 0 | I10: 1 | K10: =IF(L59=1,-DEGREES(ACOS(I10)),DEGREES(ACOS(I10))) -> 0 | N10: =C10 -> Belastning 3 | O10: =HLOOKUP($J$59,$AA$63:$AG468,3) -> 0 | P10: Ð | Q10: =HLOOKUP($J$59,$AJ$63:$AP$68,3) -> 0 | R10: =HLOOKUP($J$59,$AA$63:$AG468,4) -> 0 | S10: Ð | T10: =HLOOKUP($J$59,$AJ$63:$AP$68,4) -> -120 | U10: =HLOOKUP($J$59,$AA$63:$AG468,5) -> 0 | V10: Ð | W10: =HLOOKUP($J$59,$AJ$63:$AP$68,5) -> 120 | X10: =HLOOKUP($J$59,$AA$63:$AG468,6) -> 0 | Y10: Ð | Z10: =HLOOKUP($J$59,$AJ$63:$AP$68,6) -> 0
C11: Belastning 4 | F11: 0 | G11: =VLOOKUP(E63,B44:D46,3) -> [kW] | H11: =VLOOKUP(E63,M63:U65,J63+2) -> 0 | I11: 1 | K11: =IF(L63=1,-DEGREES(ACOS(I11)),DEGREES(ACOS(I11))) -> 0 | N11: =C11 -> Belastning 4 | O11: =HLOOKUP($J$63,$AA$70:$AG$75,3) -> 0 | P11: Ð | Q11: =HLOOKUP($J$63,$AJ$70:$AP$75,3) -> 0 | R11: =HLOOKUP($J$63,$AA$70:$AG$75,4) -> 0 | S11: Ð | T11: =HLOOKUP($J$63,$AJ$70:$AP$75,4) -> -120 | U11: =HLOOKUP($J$63,$AA$70:$AG$75,5) -> 0 | V11: Ð | W11: =HLOOKUP($J$63,$AJ$70:$AP$75,5) -> 120 | X11: =HLOOKUP($J$63,$AA$70:$AG$75,6) -> 0 | Y11: Ð | Z11: =HLOOKUP($J$63,$AJ$70:$AP$75,6) -> 0
C12: Belastning 5 | F12: 0 | G12: =VLOOKUP(E67,B44:D46,3) -> [kW] | H12: =VLOOKUP(E67,M67:U69,J67+2) -> 0 | I12: 1 | K12: =IF(L67=1,-DEGREES(ACOS(I12)),DEGREES(ACOS(I12))) -> 0 | N12: =C12 -> Belastning 5 | O12: =HLOOKUP($J$67,$AA$77:$AG$82,3) -> 0 | P12: Ð | Q12: =HLOOKUP($J$67,$AJ$77:$AP$82,3) -> 0 | R12: =HLOOKUP($J$67,$AA$77:$AG$82,4) -> 0 | S12: Ð | T12: =HLOOKUP($J$67,$AJ$77:$AP$82,4) -> -120 | U12: =HLOOKUP($J$67,$AA$77:$AG$82,5) -> 0 | V12: Ð | W12: =HLOOKUP($J$67,$AJ$77:$AP$82,5) -> 120 | X12: =HLOOKUP($J$67,$AA$77:$AG$82,6) -> 0 | Y12: Ð | Z12: =HLOOKUP($J$67,$AJ$77:$AP$82,6) -> 0
C13: Belastning 6 | F13: 0 | G13: =VLOOKUP(E71,B44:D46,3) -> [kW] | H13: =VLOOKUP(E71,M71:U73,J71+2) -> 0 | I13: 1 | K13: =IF(L71=1,-DEGREES(ACOS(I13)),DEGREES(ACOS(I13))) -> 0 | N13: =C13 -> Belastning 6 | O13: =HLOOKUP($J$71,$AA$84:$AG$89,3) -> 0 | P13: Ð | Q13: =HLOOKUP($J$71,$AJ$84:$AP$89,3) -> 0 | R13: =HLOOKUP($J$71,$AA$84:$AG$89,4) -> 0 | S13: Ð | T13: =HLOOKUP($J$71,$AJ$84:$AP$89,4) -> -120 | U13: =HLOOKUP($J$71,$AA$84:$AG$89,5) -> 0 | V13: Ð | W13: =HLOOKUP($J$71,$AJ$84:$AP$89,5) -> 120 | X13: =HLOOKUP($J$71,$AA$84:$AG$89,6) -> 0 | Y13: Ð | Z13: =HLOOKUP($J$71,$AJ$84:$AP$89,6) -> 0
C14: Belastning 7 | F14: 0 | G14: =VLOOKUP(E75,B44:D46,3) -> [kW] | H14: =VLOOKUP(E75,M75:U77,J75+2) -> 0 | I14: 1 | K14: =IF(L75=1,-DEGREES(ACOS(I14)),DEGREES(ACOS(I14))) -> 0 | N14: =C14 -> Belastning 7 | O14: =HLOOKUP($J$75,$AA$91:$AG$96,3) -> 0 | P14: Ð | Q14: =HLOOKUP($J$75,$AJ$91:$AP$96,3) -> 0 | R14: =HLOOKUP($J$75,$AA$91:$AG$96,4) -> 0 | S14: Ð | T14: =HLOOKUP($J$75,$AJ$91:$AP$96,4) -> -120 | U14: =HLOOKUP($J$75,$AA$91:$AG$96,5) -> 0 | V14: Ð | W14: =HLOOKUP($J$75,$AJ$91:$AP$96,5) -> 120 | X14: =HLOOKUP($J$75,$AA$91:$AG$96,6) -> 0 | Y14: Ð | Z14: =HLOOKUP($J$75,$AJ$91:$AP$96,6) -> 0
C15: Belastning 8 | F15: 0 | G15: =VLOOKUP(E79,B44:D46,3) -> [kW] | H15: =VLOOKUP(E79,M79:U81,J79+2) -> 0 | I15: 1 | K15: =IF(L79=1,-DEGREES(ACOS(I15)),DEGREES(ACOS(I15))) -> 0 | N15: =C15 -> Belastning 8 | O15: =HLOOKUP($J$79,$AA$98:$AG$103,3) -> 0 | P15: Ð | Q15: =HLOOKUP($J$79,$AJ$98:$AP$103,3) -> 0 | R15: =HLOOKUP($J$79,$AA$98:$AG$103,4) -> 0 | S15: Ð | T15: =HLOOKUP($J$79,$AJ$98:$AP$103,4) -> -120 | U15: =HLOOKUP($J$79,$AA$98:$AG$103,5) -> 0 | V15: Ð | W15: =HLOOKUP($J$79,$AJ$98:$AP$103,5) -> 120 | X15: =HLOOKUP($J$79,$AA$98:$AG$103,6) -> 0 | Y15: Ð | Z15: =HLOOKUP($J$79,$AJ$98:$AP$103,6) -> 0
C16: Belastning 9 | F16: 0 | G16: =VLOOKUP(E83,B44:D46,3) -> [kW] | H16: =VLOOKUP(E83,M83:U85,J83+2) -> 0 | I16: 1 | K16: =IF(L83=1,-DEGREES(ACOS(I16)),DEGREES(ACOS(I16))) -> 0 | N16: =C16 -> Belastning 9 | O16: =HLOOKUP($J$83,$AA$105:$AG$110,3) -> 0 | P16: Ð | Q16: =HLOOKUP($J$83,$AJ$105:$AP$110,3) -> 0 | R16: =HLOOKUP($J$83,$AA$105:$AG$110,4) -> 0 | S16: Ð | T16: =HLOOKUP($J$83,$AJ$105:$AP$110,4) -> -120 | U16: =HLOOKUP($J$83,$AA$105:$AG$110,5) -> 0 | V16: Ð | W16: =HLOOKUP($J$83,$AJ$105:$AP$110,5) -> 120 | X16: =HLOOKUP($J$83,$AA$105:$AG$110,6) -> 0 | Y16: Ð | Z16: =HLOOKUP($J$83,$AJ$105:$AP$110,6) -> 0
C17: Belastning 10 | F17: 0 | G17: =VLOOKUP(E87,B44:D46,3) -> [kW] | H17: =VLOOKUP(E87,M87:U89,J87+2) -> 0 | I17: 1 | K17: =IF(L87=1,-DEGREES(ACOS(I17)),DEGREES(ACOS(I17))) -> 0 | N17: =C17 -> Belastning 10 | O17: =HLOOKUP($J$87,$AA$112:$AG$117,3) -> 0 | P17: Ð | Q17: =HLOOKUP($J$87,$AJ$112:$AP$117,3) -> 0 | R17: =HLOOKUP($J$87,$AA$112:$AG$117,4) -> 0 | S17: Ð | T17: =HLOOKUP($J$87,$AJ$112:$AP$117,4) -> -120 | U17: =HLOOKUP($J$87,$AA$112:$AG$117,5) -> 0 | V17: Ð | W17: =HLOOKUP($J$87,$AJ$112:$AP$117,5) -> 120 | X17: =HLOOKUP($J$87,$AA$112:$AG$117,6) -> 0 | Y17: Ð | Z17: =HLOOKUP($J$87,$AJ$112:$AP$117,6) -> 0
C18: Belastning 11 | F18: 0 | G18: =VLOOKUP(E91,B44:D46,3) -> [kW] | H18: =VLOOKUP(E91,M91:U93,J91+2) -> 0 | I18: 1 | K18: =IF(L91=1,-DEGREES(ACOS(I18)),DEGREES(ACOS(I18))) -> 0 | N18: =C18 -> Belastning 11 | O18: =HLOOKUP($J$91,$AA$119:$AG$124,3) -> 0 | P18: Ð | Q18: =HLOOKUP($J$91,$AJ$119:$AP$124,3) -> 0 | R18: =HLOOKUP($J$91,$AA$119:$AG$124,4) -> 0 | S18: Ð | T18: =HLOOKUP($J$91,$AJ$119:$AP$124,4) -> -120 | U18: =HLOOKUP($J$91,$AA$119:$AG$124,5) -> 0 | V18: Ð | W18: =HLOOKUP($J$91,$AJ$119:$AP$124,5) -> 120 | X18: =HLOOKUP($J$91,$AA$119:$AG$124,6) -> 0 | Y18: Ð | Z18: =HLOOKUP($J$91,$AJ$119:$AP$124,6) -> 0
C19: Belastning 12 | F19: 0 | G19: =VLOOKUP(E95,B44:D46,3) -> [kW] | H19: =VLOOKUP(E95,M95:U97,J95+2) -> 0 | I19: 1 | K19: =IF(L95=1,-DEGREES(ACOS(I19)),DEGREES(ACOS(I19))) -> 0 | N19: =C19 -> Belastning 12 | O19: =HLOOKUP($J$95,$AA$126:$AG$131,3) -> 0 | P19: Ð | Q19: =HLOOKUP($J$95,$AJ$126:$AP$131,3) -> 0 | R19: =HLOOKUP($J$95,$AA$126:$AG$131,4) -> 0 | S19: Ð | T19: =HLOOKUP($J$95,$AJ$126:$AP$131,4) -> -120 | U19: =HLOOKUP($J$95,$AA$126:$AG$131,5) -> 0 | V19: Ð | W19: =HLOOKUP($J$95,$AJ$126:$AP$131,5) -> 120 | X19: =HLOOKUP($J$95,$AA$126:$AG$131,6) -> 0 | Y19: Ð | Z19: =HLOOKUP($J$95,$AJ$126:$AP$131,6) -> 0
C20: Belastning 13 | F20: 0 | G20: =VLOOKUP(E99,B44:D46,3) -> [kW] | H20: =VLOOKUP(E99,M99:U101,J99+2) -> 0 | I20: 1 | K20: =IF(L99=1,-DEGREES(ACOS(I20)),DEGREES(ACOS(I20))) -> 0 | N20: =C20 -> Belastning 13 | O20: =HLOOKUP($J$99,$AA$133:$AG$138,3) -> 0 | P20: Ð | Q20: =HLOOKUP($J$99,$AJ$133:$AP$138,3) -> 0 | R20: =HLOOKUP($J$99,$AA$133:$AG$138,4) -> 0 | S20: Ð | T20: =HLOOKUP($J$99,$AJ$133:$AP$138,4) -> -120 | U20: =HLOOKUP($J$99,$AA$133:$AG$138,5) -> 0 | V20: Ð | W20: =HLOOKUP($J$99,$AJ$133:$AP$138,5) -> 120 | X20: =HLOOKUP($J$99,$AA$133:$AG$138,6) -> 0 | Y20: Ð | Z20: =HLOOKUP($J$99,$AJ$133:$AP$138,6) -> 0
C21: Belastning 14 | F21: 0 | G21: =VLOOKUP(E103,B44:D46,3) -> [kW] | H21: =VLOOKUP(E103,M103:U105,J103+2) -> 0 | I21: 1 | K21: =IF(L103=1,-DEGREES(ACOS(I21)),DEGREES(ACOS(I21))) -> 0 | N21: =C21 -> Belastning 14 | O21: =HLOOKUP($J$103,$AA$140:$AG$145,3) -> 0 | P21: Ð | Q21: =HLOOKUP($J$103,$AJ$140:$AP$145,3) -> 0 | R21: =HLOOKUP($J$103,$AA$140:$AG$145,4) -> 0 | S21: Ð | T21: =HLOOKUP($J$103,$AJ$140:$AP$145,4) -> -120 | U21: =HLOOKUP($J$103,$AA$140:$AG$145,5) -> 0 | V21: Ð | W21: =HLOOKUP($J$103,$AJ$140:$AP$145,5) -> 120 | X21: =HLOOKUP($J$103,$AA$140:$AG$145,6) -> 0 | Y21: Ð | Z21: =HLOOKUP($J$103,$AJ$140:$AP$145,6) -> 0
C22: Belastning 15 | F22: 0 | G22: =VLOOKUP(E107,B44:D46,3) -> [kW] | H22: =VLOOKUP(E107,M107:U109,J107+2) -> 0 | I22: 1 | K22: =IF(L107=1,-DEGREES(ACOS(I22)),DEGREES(ACOS(I22))) -> 0 | N22: =C22 -> Belastning 15 | O22: =HLOOKUP($J$107,$AA$147:$AG$152,3) -> 0 | P22: Ð | Q22: =HLOOKUP($J$107,$AJ$147:$AP$152,3) -> 0 | R22: =HLOOKUP($J$107,$AA$147:$AG$152,4) -> 0 | S22: Ð | T22: =HLOOKUP($J$107,$AJ$147:$AP$152,4) -> -120 | U22: =HLOOKUP($J$107,$AA$147:$AG$152,5) -> 0 | V22: Ð | W22: =HLOOKUP($J$107,$AJ$147:$AP$152,5) -> 120 | X22: =HLOOKUP($J$107,$AA$147:$AG$152,6) -> 0 | Y22: Ð | Z22: =HLOOKUP($J$107,$AJ$147:$AP$152,6) -> 0
N23: ∑Itil - Global | O23: =SQRT(E128^2+F128^2) -> 0 | P23: Ð | Q23: =IFERROR(DEGREES(ATAN(F128/E128)),0) -> 0 | R23: =SQRT(G128^2+H128^2) -> 0 | S23: Ð | T23: =IFERROR(-DEGREES(ATAN(G128/H128))-90,0) -> 0 | U23: =SQRT(I128^2+J128^2) -> 0 | V23: Ð | W23: =IFERROR(-DEGREES(ATAN(I128/J128))+90,0) -> 0 | X23: =IMABS(COMPLEX(C134+F134+I134,C135+F135+I135)) -> 0 | Y23: Ð | Z23: =IFERROR(DEGREES(IMARGUMENT(IMSUM(L135)))+180,0) -> 0
N24: ∑IB - Global | O24: =O23*Q3*T3 -> 0 | P24: Ð | Q24: =Q23 -> 0 | R24: =R23*Q3*T3 -> 0 | S24: Ð | T24: =T23 -> 0 | U24: =U23*Q3*T3 -> 0 | V24: Ð | W24: =W23 -> 0 | X24: =(X23)*Q3*T3 -> 0 | Y24: Ð | Z24: =Z23 -> 0
N25: ∑IB - Lokal | O25: =O24 -> 0 | P25: Ð | Q25: =Q23 -> 0 | R25: =R24 -> 0 | S25: Ð | T25: =T24+120 -> 120 | U25: =U24 -> 0 | V25: Ð | W25: =W24-120 -> -120 | X25: =(X24) -> 0 | Y25: Ð | Z25: =Z24 -> 0
N26: 3. harmoniske | O26: =IFERROR(((I5/3)/O24)*100,0) -> 0 | P26: % | R26: =IFERROR(((I5/3)/R24)*100,0) -> 0 | S26: % | U26: =IFERROR(((I5/3)/U24)*100,0) -> 0 | V26: %
K27: Tjek SB side 193
I39: 1 | J39: 3 - faser
I40: 2 | J40: L1 - N
I41: 3 | J41: L2 - N
I42: 4 | J42: L3 - N
I43: 5 | J43: L1 - L2 | AA43: 3-harmoniske
B44: 1 | C44: P [kW] | D44: [kW] | I44: 6 | J44: L2 - L3 | L44: Induktiv | Y44: 1 | Z44: IL1 | AB44: %
B45: 2 | C45: S [kVA] | D45: [kVA] | I45: 7 | J45: L1 - L3 | L45: Kapasativ | Y45: 2 | Z45: IL2 | AB45: %
B46: 3 | C46: I [A] | D46: [A] | Y46: 3 | Z46: IL3 | AB46: %
Y47: 4 | Z47: IN
E49: Output | AA49: 1 | AB49: 2 | AC49: 3 | AD49: 4 | AE49: 5 | AF49: 6 | AG49: 7 | AJ49: 1 | AK49: 2 | AL49: 3 | AM49: 4 | AN49: 5 | AO49: 6 | AP49: 7
O50: 3-faset | P50: L1-N | Q50: L2-N | R50: L3-N | S50: L1-L2 | T50: L2-L3 | U50: L1-L3 | AA50: 3-faset | AB50: L1-N | AC50: L2-N | AD50: L3-N | AE50: L1-L2 | AF50: L2-L3 | AG50: L1-L3 | AI50: Ðj Grader | AJ50: 3-faset | AK50: L1-N | AL50: L2-N | AM50: L3-N | AN50: L1-L2 | AO50: L2-L3 | AP50: L1-L3
C51: Belastning 1 | E51: 1 | J51: 1 | L51: 1 | M51: 1 | N51: P | O51: =(F8*1000)/($D$5*SQRT(3)*I8) -> 0 | P51: =($F$8*1000)/(($D$5/SQRT(3))*$I$8) -> 0 | Q51: =P51 -> 0 | R51: =P51 -> 0 | S51: =($F$8*1000)/($D$5*$I$8) -> 0 | T51: =S51 -> 0 | U51: =S51 -> 0 | Z51: IL1 | AA51: =H8 -> 0 | AB51: =AA51 -> 0 | AC51: 0 | AD51: 0 | AE51: =AA51 -> 0 | AF51: 0 | AG51: =AA51 -> 0 | AI51: IL1 | AJ51: =K8 -> 0 | AK51: =AJ51 -> 0 | AL51: 0 | AM51: 0 | AN51: =AJ51+30 -> 30 | AO51: 0 | AP51: =AJ51-30 -> -30
M52: 2 | N52: S | O52: =(F8*1000)/($D$5*SQRT(3)) -> 0 | P52: =($F$8*1000)/(($D$5/SQRT(3))) -> 0 | Q52: =P52 -> 0 | R52: =P52 -> 0 | S52: =($F$8*1000)/($D$5) -> 0 | T52: =S52 -> 0 | U52: =S52 -> 0 | Y52: 1 | Z52: IL2 | AA52: =AA51 -> 0 | AB52: 0 | AC52: =AA51 -> 0 | AD52: 0 | AE52: =AA51 -> 0 | AF52: =AA51 -> 0 | AG52: 0 | AI52: IL2 | AJ52: =AJ51-120 -> -120 | AK52: 0 | AL52: =AJ51-120 -> -120 | AM52: 0 | AN52: =AJ51-150 -> -150 | AO52: =AJ51-90 -> -90 | AP52: 0
M53: 3 | N53: I | O53: =F8 -> 0 | P53: =$F$8 -> 0 | Q53: =$F$8 -> 0 | R53: =$F$8 -> 0 | S53: =$F$8 -> 0 | T53: =$F$8 -> 0 | U53: =$F$8 -> 0 | Z53: IL3 | AA53: =AA51 -> 0 | AB53: 0 | AC53: 0 | AD53: =AA51 -> 0 | AE53: 0 | AF53: =AA51 -> 0 | AG53: =AA51 -> 0 | AI53: IL3 | AJ53: =AJ51+120 -> 120 | AK53: 0 | AL53: 0 | AM53: =AJ51+120 -> 120 | AN53: 0 | AO53: =AJ51+90 -> 90 | AP53: =AJ51+150 -> 150
...

Sheet Tavle +A13
C2: Eftersiddende tavle | H2: 13
P3: sf | Q3: 1 | S3: uf | T3: 1
N4: Selv skriv tavlenavn
C5: UL-L | D5: 400 | E5: [V] | F5: 3. harmoniske strømme | I5: 0 | J5: [A]
N6: Tavle +A13
F7: Værdi | H7: IB [A] | I7: cos ϕ | J7: Tilsluttet | K7: Ðj i Grader | L7: Ind./Kap. | N7: Belastning | P7: IL1 [A] | S7: IL2 [A] | V7: IL3 [A] | Y7: IN [A]
C8: Belastning 1 | F8: 0 | G8: =VLOOKUP(E51,B44:D46,3) -> [kW] | H8: =VLOOKUP(E51,M50:U53,J51+2) -> 0 | I8: 1 | K8: =IF(L51=1,-DEGREES(ACOS(I8)),DEGREES(ACOS(I8))) -> 0 | N8: =C8 -> Belastning 1 | O8: =HLOOKUP($J$51,$AA$49:$AG$54,3) -> 0 | P8: Ð | Q8: =HLOOKUP($J$51,$AJ$49:$AP$54,3) -> 0 | R8: =HLOOKUP($J$51,$AA$49:$AG$54,4) -> 0 | S8: Ð | T8: =HLOOKUP($J$51,$AJ$49:$AP$54,4) -> -120 | U8: =HLOOKUP($J$51,$AA$49:$AG$54,5) -> 0 | V8: Ð | W8: =HLOOKUP($J$51,$AJ$49:$AP$54,5) -> 120 | X8: =HLOOKUP($J$51,$AA$49:$AG$54,6) -> 0 | Y8: Ð | Z8: =HLOOKUP($J$51,$AJ$49:$AP$54,6) -> 0
C9: Belastning 2 | F9: 0 | G9: =VLOOKUP(E55,B44:D46,3) -> [kW] | H9: =VLOOKUP(E55,M55:U57,J55+2) -> 0 | I9: 1 | K9: =IF(L55=1,-DEGREES(ACOS(I9)),DEGREES(ACOS(I9))) -> 0 | L9: ½ | N9: =C9 -> Belastning 2 | O9: =HLOOKUP($J$55,$AA$56:$AG$61,3) -> 0 | P9: Ð | Q9: =HLOOKUP($J$55,$AJ$56:$AP$61,3) -> 0 | R9: =HLOOKUP($J$55,$AA$56:$AG$61,4) -> 0 | S9: Ð | T9: =HLOOKUP($J$55,$AJ$56:$AP$61,4) -> -120 | U9: =HLOOKUP($J$55,$AA$56:$AG$61,5) -> 0 | V9: Ð | W9: =HLOOKUP($J$55,$AJ$56:$AP$61,5) -> 120 | X9: =HLOOKUP($J$55,$AA$56:$AG$61,6) -> 0 | Y9: Ð | Z9: =HLOOKUP($J$55,$AJ$56:$AP$61,6) -> 0
C10: Belastning 3 | F10: 0 | G10: =VLOOKUP(E59,B44:D46,3) -> [kW] | H10: =VLOOKUP(E59,M59:U61,J59+2) -> 0 | I10: 1 | K10: =IF(L59=1,-DEGREES(ACOS(I10)),DEGREES(ACOS(I10))) -> 0 | N10: =C10 -> Belastning 3 | O10: =HLOOKUP($J$59,$AA$63:$AG468,3) -> 0 | P10: Ð | Q10: =HLOOKUP($J$59,$AJ$63:$AP$68,3) -> 0 | R10: =HLOOKUP($J$59,$AA$63:$AG468,4) -> 0 | S10: Ð | T10: =HLOOKUP($J$59,$AJ$63:$AP$68,4) -> -120 | U10: =HLOOKUP($J$59,$AA$63:$AG468,5) -> 0 | V10: Ð | W10: =HLOOKUP($J$59,$AJ$63:$AP$68,5) -> 120 | X10: =HLOOKUP($J$59,$AA$63:$AG468,6) -> 0 | Y10: Ð | Z10: =HLOOKUP($J$59,$AJ$63:$AP$68,6) -> 0
C11: Belastning 4 | F11: 0 | G11: =VLOOKUP(E63,B44:D46,3) -> [kW] | H11: =VLOOKUP(E63,M63:U65,J63+2) -> 0 | I11: 1 | K11: =IF(L63=1,-DEGREES(ACOS(I11)),DEGREES(ACOS(I11))) -> 0 | N11: =C11 -> Belastning 4 | O11: =HLOOKUP($J$63,$AA$70:$AG$75,3) -> 0 | P11: Ð | Q11: =HLOOKUP($J$63,$AJ$70:$AP$75,3) -> 0 | R11: =HLOOKUP($J$63,$AA$70:$AG$75,4) -> 0 | S11: Ð | T11: =HLOOKUP($J$63,$AJ$70:$AP$75,4) -> -120 | U11: =HLOOKUP($J$63,$AA$70:$AG$75,5) -> 0 | V11: Ð | W11: =HLOOKUP($J$63,$AJ$70:$AP$75,5) -> 120 | X11: =HLOOKUP($J$63,$AA$70:$AG$75,6) -> 0 | Y11: Ð | Z11: =HLOOKUP($J$63,$AJ$70:$AP$75,6) -> 0
C12: Belastning 5 | F12: 0 | G12: =VLOOKUP(E67,B44:D46,3) -> [kW] | H12: =VLOOKUP(E67,M67:U69,J67+2) -> 0 | I12: 1 | K12: =IF(L67=1,-DEGREES(ACOS(I12)),DEGREES(ACOS(I12))) -> 0 | N12: =C12 -> Belastning 5 | O12: =HLOOKUP($J$67,$AA$77:$AG$82,3) -> 0 | P12: Ð | Q12: =HLOOKUP($J$67,$AJ$77:$AP$82,3) -> 0 | R12: =HLOOKUP($J$67,$AA$77:$AG$82,4) -> 0 | S12: Ð | T12: =HLOOKUP($J$67,$AJ$77:$AP$82,4) -> -120 | U12: =HLOOKUP($J$67,$AA$77:$AG$82,5) -> 0 | V12: Ð | W12: =HLOOKUP($J$67,$AJ$77:$AP$82,5) -> 120 | X12: =HLOOKUP($J$67,$AA$77:$AG$82,6) -> 0 | Y12: Ð | Z12: =HLOOKUP($J$67,$AJ$77:$AP$82,6) -> 0
C13: Belastning 6 | F13: 0 | G13: =VLOOKUP(E71,B44:D46,3) -> [kW] | H13: =VLOOKUP(E71,M71:U73,J71+2) -> 0 | I13: 1 | K13: =IF(L71=1,-DEGREES(ACOS(I13)),DEGREES(ACOS(I13))) -> 0 | N13: =C13 -> Belastning 6 | O13: =HLOOKUP($J$71,$AA$84:$AG$89,3) -> 0 | P13: Ð | Q13: =HLOOKUP($J$71,$AJ$84:$AP$89,3) -> 0 | R13: =HLOOKUP($J$71,$AA$84:$AG$89,4) -> 0 | S13: Ð | T13: =HLOOKUP($J$71,$AJ$84:$AP$89,4) -> -120 | U13: =HLOOKUP($J$71,$AA$84:$AG$89,5) -> 0 | V13: Ð | W13: =HLOOKUP($J$71,$AJ$84:$AP$89,5) -> 120 | X13: =HLOOKUP($J$71,$AA$84:$AG$89,6) -> 0 | Y13: Ð | Z13: =HLOOKUP($J$71,$AJ$84:$AP$89,6) -> 0
C14: Belastning 7 | F14: 0 | G14: =VLOOKUP(E75,B44:D46,3) -> [kW] | H14: =VLOOKUP(E75,M75:U77,J75+2) -> 0 | I14: 1 | K14: =IF(L75=1,-DEGREES(ACOS(I14)),DEGREES(ACOS(I14))) -> 0 | N14: =C14 -> Belastning 7 | O14: =HLOOKUP($J$75,$AA$91:$AG$96,3) -> 0 | P14: Ð | Q14: =HLOOKUP($J$75,$AJ$91:$AP$96,3) -> 0 | R14: =HLOOKUP($J$75,$AA$91:$AG$96,4) -> 0 | S14: Ð | T14: =HLOOKUP($J$75,$AJ$91:$AP$96,4) -> -120 | U14: =HLOOKUP($J$75,$AA$91:$AG$96,5) -> 0 | V14: Ð | W14: =HLOOKUP($J$75,$AJ$91:$AP$96,5) -> 120 | X14: =HLOOKUP($J$75,$AA$91:$AG$96,6) -> 0 | Y14: Ð | Z14: =HLOOKUP($J$75,$AJ$91:$AP$96,6) -> 0
C15: Belastning 8 | F15: 0 | G15: =VLOOKUP(E79,B44:D46,3) -> [kW] | H15: =VLOOKUP(E79,M79:U81,J79+2) -> 0 | I15: 1 | K15: =IF(L79=1,-DEGREES(ACOS(I15)),DEGREES(ACOS(I15))) -> 0 | N15: =C15 -> Belastning 8 | O15: =HLOOKUP($J$79,$AA$98:$AG$103,3) -> 0 | P15: Ð | Q15: =HLOOKUP($J$79,$AJ$98:$AP$103,3) -> 0 | R15: =HLOOKUP($J$79,$AA$98:$AG$103,4) -> 0 | S15: Ð | T15: =HLOOKUP($J$79,$AJ$98:$AP$103,4) -> -120 | U15: =HLOOKUP($J$79,$AA$98:$AG$103,5) -> 0 | V15: Ð | W15: =HLOOKUP($J$79,$AJ$98:$AP$103,5) -> 120 | X15: =HLOOKUP($J$79,$AA$98:$AG$103,6) -> 0 | Y15: Ð | Z15: =HLOOKUP($J$79,$AJ$98:$AP$103,6) -> 0
C16: Belastning 9 | F16: 0 | G16: =VLOOKUP(E83,B44:D46,3) -> [kW] | H16: =VLOOKUP(E83,M83:U85,J83+2) -> 0 | I16: 1 | K16: =IF(L83=1,-DEGREES(ACOS(I16)),DEGREES(ACOS(I16))) -> 0 | N16: =C16 -> Belastning 9 | O16: =HLOOKUP($J$83,$AA$105:$AG$110,3) -> 0 | P16: Ð | Q16: =HLOOKUP($J$83,$AJ$105:$AP$110,3) -> 0 | R16: =HLOOKUP($J$83,$AA$105:$AG$110,4) -> 0 | S16: Ð | T16: =HLOOKUP($J$83,$AJ$105:$AP$110,4) -> -120 | U16: =HLOOKUP($J$83,$AA$105:$AG$110,5) -> 0 | V16: Ð | W16: =HLOOKUP($J$83,$AJ$105:$AP$110,5) -> 120 | X16: =HLOOKUP($J$83,$AA$105:$AG$110,6) -> 0 | Y16: Ð | Z16: =HLOOKUP($J$83,$AJ$105:$AP$110,6) -> 0
C17: Belastning 10 | F17: 0 | G17: =VLOOKUP(E87,B44:D46,3) -> [kW] | H17: =VLOOKUP(E87,M87:U89,J87+2) -> 0 | I17: 1 | K17: =IF(L87=1,-DEGREES(ACOS(I17)),DEGREES(ACOS(I17))) -> 0 | N17: =C17 -> Belastning 10 | O17: =HLOOKUP($J$87,$AA$112:$AG$117,3) -> 0 | P17: Ð | Q17: =HLOOKUP($J$87,$AJ$112:$AP$117,3) -> 0 | R17: =HLOOKUP($J$87,$AA$112:$AG$117,4) -> 0 | S17: Ð | T17: =HLOOKUP($J$87,$AJ$112:$AP$117,4) -> -120 | U17: =HLOOKUP($J$87,$AA$112:$AG$117,5) -> 0 | V17: Ð | W17: =HLOOKUP($J$87,$AJ$112:$AP$117,5) -> 120 | X17: =HLOOKUP($J$87,$AA$112:$AG$117,6) -> 0 | Y17: Ð | Z17: =HLOOKUP($J$87,$AJ$112:$AP$117,6) -> 0
C18: Belastning 11 | F18: 0 | G18: =VLOOKUP(E91,B44:D46,3) -> [kW] | H18: =VLOOKUP(E91,M91:U93,J91+2) -> 0 | I18: 1 | K18: =IF(L91=1,-DEGREES(ACOS(I18)),DEGREES(ACOS(I18))) -> 0 | N18: =C18 -> Belastning 11 | O18: =HLOOKUP($J$91,$AA$119:$AG$124,3) -> 0 | P18: Ð | Q18: =HLOOKUP($J$91,$AJ$119:$AP$124,3) -> 0 | R18: =HLOOKUP($J$91,$AA$119:$AG$124,4) -> 0 | S18: Ð | T18: =HLOOKUP($J$91,$AJ$119:$AP$124,4) -> -120 | U18: =HLOOKUP($J$91,$AA$119:$AG$124,5) -> 0 | V18: Ð | W18: =HLOOKUP($J$91,$AJ$119:$AP$124,5) -> 120 | X18: =HLOOKUP($J$91,$AA$119:$AG$124,6) -> 0 | Y18: Ð | Z18: =HLOOKUP($J$91,$AJ$119:$AP$124,6) -> 0
C19: Belastning 12 | F19: 0 | G19: =VLOOKUP(E95,B44:D46,3) -> [kW] | H19: =VLOOKUP(E95,M95:U97,J95+2) -> 0 | I19: 1 | K19: =IF(L95=1,-DEGREES(ACOS(I19)),DEGREES(ACOS(I19))) -> 0 | N19: =C19 -> Belastning 12 | O19: =HLOOKUP($J$95,$AA$126:$AG$131,3) -> 0 | P19: Ð | Q19: =HLOOKUP($J$95,$AJ$126:$AP$131,3) -> 0 | R19: =HLOOKUP($J$95,$AA$126:$AG$131,4) -> 0 | S19: Ð | T19: =HLOOKUP($J$95,$AJ$126:$AP$131,4) -> -120 | U19: =HLOOKUP($J$95,$AA$126:$AG$131,5) -> 0 | V19: Ð | W19: =HLOOKUP($J$95,$AJ$126:$AP$131,5) -> 120 | X19: =HLOOKUP($J$95,$AA$126:$AG$131,6) -> 0 | Y19: Ð | Z19: =HLOOKUP($J$95,$AJ$126:$AP$131,6) -> 0
C20: Belastning 13 | F20: 0 | G20: =VLOOKUP(E99,B44:D46,3) -> [kW] | H20: =VLOOKUP(E99,M99:U101,J99+2) -> 0 | I20: 1 | K20: =IF(L99=1,-DEGREES(ACOS(I20)),DEGREES(ACOS(I20))) -> 0 | N20: =C20 -> Belastning 13 | O20: =HLOOKUP($J$99,$AA$133:$AG$138,3) -> 0 | P20: Ð | Q20: =HLOOKUP($J$99,$AJ$133:$AP$138,3) -> 0 | R20: =HLOOKUP($J$99,$AA$133:$AG$138,4) -> 0 | S20: Ð | T20: =HLOOKUP($J$99,$AJ$133:$AP$138,4) -> -120 | U20: =HLOOKUP($J$99,$AA$133:$AG$138,5) -> 0 | V20: Ð | W20: =HLOOKUP($J$99,$AJ$133:$AP$138,5) -> 120 | X20: =HLOOKUP($J$99,$AA$133:$AG$138,6) -> 0 | Y20: Ð | Z20: =HLOOKUP($J$99,$AJ$133:$AP$138,6) -> 0
C21: Belastning 14 | F21: 0 | G21: =VLOOKUP(E103,B44:D46,3) -> [kW] | H21: =VLOOKUP(E103,M103:U105,J103+2) -> 0 | I21: 1 | K21: =IF(L103=1,-DEGREES(ACOS(I21)),DEGREES(ACOS(I21))) -> 0 | N21: =C21 -> Belastning 14 | O21: =HLOOKUP($J$103,$AA$140:$AG$145,3) -> 0 | P21: Ð | Q21: =HLOOKUP($J$103,$AJ$140:$AP$145,3) -> 0 | R21: =HLOOKUP($J$103,$AA$140:$AG$145,4) -> 0 | S21: Ð | T21: =HLOOKUP($J$103,$AJ$140:$AP$145,4) -> -120 | U21: =HLOOKUP($J$103,$AA$140:$AG$145,5) -> 0 | V21: Ð | W21: =HLOOKUP($J$103,$AJ$140:$AP$145,5) -> 120 | X21: =HLOOKUP($J$103,$AA$140:$AG$145,6) -> 0 | Y21: Ð | Z21: =HLOOKUP($J$103,$AJ$140:$AP$145,6) -> 0
C22: Belastning 15 | F22: 0 | G22: =VLOOKUP(E107,B44:D46,3) -> [kW] | H22: =VLOOKUP(E107,M107:U109,J107+2) -> 0 | I22: 1 | K22: =IF(L107=1,-DEGREES(ACOS(I22)),DEGREES(ACOS(I22))) -> 0 | N22: =C22 -> Belastning 15 | O22: =HLOOKUP($J$107,$AA$147:$AG$152,3) -> 0 | P22: Ð | Q22: =HLOOKUP($J$107,$AJ$147:$AP$152,3) -> 0 | R22: =HLOOKUP($J$107,$AA$147:$AG$152,4) -> 0 | S22: Ð | T22: =HLOOKUP($J$107,$AJ$147:$AP$152,4) -> -120 | U22: =HLOOKUP($J$107,$AA$147:$AG$152,5) -> 0 | V22: Ð | W22: =HLOOKUP($J$107,$AJ$147:$AP$152,5) -> 120 | X22: =HLOOKUP($J$107,$AA$147:$AG$152,6) -> 0 | Y22: Ð | Z22: =HLOOKUP($J$107,$AJ$147:$AP$152,6) -> 0
N23: ∑Itil - Global | O23: =SQRT(E128^2+F128^2) -> 0 | P23: Ð | Q23: =IFERROR(DEGREES(ATAN(F128/E128)),0) -> 0 | R23: =SQRT(G128^2+H128^2) -> 0 | S23: Ð | T23: =IFERROR(-DEGREES(ATAN(G128/H128))-90,0) -> 0 | U23: =SQRT(I128^2+J128^2) -> 0 | V23: Ð | W23: =IFERROR(-DEGREES(ATAN(I128/J128))+90,0) -> 0 | X23: =IMABS(COMPLEX(C134+F134+I134,C135+F135+I135)) -> 0 | Y23: Ð | Z23: =IFERROR(DEGREES(IMARGUMENT(IMSUM(L135)))+180,0) -> 0
N24: ∑IB - Global | O24: =O23*Q3*T3 -> 0 | P24: Ð | Q24: =Q23 -> 0 | R24: =R23*Q3*T3 -> 0 | S24: Ð | T24: =T23 -> 0 | U24: =U23*Q3*T3 -> 0 | V24: Ð | W24: =W23 -> 0 | X24: =(X23)*Q3*T3 -> 0 | Y24: Ð | Z24: =Z23 -> 0
N25: ∑IB - Lokal | O25: =O24 -> 0 | P25: Ð | Q25: =Q23 -> 0 | R25: =R24 -> 0 | S25: Ð | T25: =T24+120 -> 120 | U25: =U24 -> 0 | V25: Ð | W25: =W24-120 -> -120 | X25: =(X24) -> 0 | Y25: Ð | Z25: =Z24 -> 0
N26: 3. harmoniske | O26: =IFERROR(((I5/3)/O24)*100,0) -> 0 | P26: % | R26: =IFERROR(((I5/3)/R24)*100,0) -> 0 | S26: % | U26: =IFERROR(((I5/3)/U24)*100,0) -> 0 | V26: %
K27: Tjek SB side 193
I39: 1 | J39: 3 - faser
I40: 2 | J40: L1 - N
I41: 3 | J41: L2 - N
I42: 4 | J42: L3 - N
I43: 5 | J43: L1 - L2 | AA43: 3-harmoniske
B44: 1 | C44: P [kW] | D44: [kW] | I44: 6 | J44: L2 - L3 | L44: Induktiv | Y44: 1 | Z44: IL1 | AB44: %
B45: 2 | C45: S [kVA] | D45: [kVA] | I45: 7 | J45: L1 - L3 | L45: Kapasativ | Y45: 2 | Z45: IL2 | AB45: %
B46: 3 | C46: I [A] | D46: [A] | Y46: 3 | Z46: IL3 | AB46: %
Y47: 4 | Z47: IN
E49: Output | AA49: 1 | AB49: 2 | AC49: 3 | AD49: 4 | AE49: 5 | AF49: 6 | AG49: 7 | AJ49: 1 | AK49: 2 | AL49: 3 | AM49: 4 | AN49: 5 | AO49: 6 | AP49: 7
O50: 3-faset | P50: L1-N | Q50: L2-N | R50: L3-N | S50: L1-L2 | T50: L2-L3 | U50: L1-L3 | AA50: 3-faset | AB50: L1-N | AC50: L2-N | AD50: L3-N | AE50: L1-L2 | AF50: L2-L3 | AG50: L1-L3 | AI50: Ðj Grader | AJ50: 3-faset | AK50: L1-N | AL50: L2-N | AM50: L3-N | AN50: L1-L2 | AO50: L2-L3 | AP50: L1-L3
C51: Belastning 1 | E51: 1 | J51: 1 | L51: 1 | M51: 1 | N51: P | O51: =(F8*1000)/($D$5*SQRT(3)*I8) -> 0 | P51: =($F$8*1000)/(($D$5/SQRT(3))*$I$8) -> 0 | Q51: =P51 -> 0 | R51: =P51 -> 0 | S51: =($F$8*1000)/($D$5*$I$8) -> 0 | T51: =S51 -> 0 | U51: =S51 -> 0 | Z51: IL1 | AA51: =H8 -> 0 | AB51: =AA51 -> 0 | AC51: 0 | AD51: 0 | AE51: =AA51 -> 0 | AF51: 0 | AG51: =AA51 -> 0 | AI51: IL1 | AJ51: =K8 -> 0 | AK51: =AJ51 -> 0 | AL51: 0 | AM51: 0 | AN51: =AJ51+30 -> 30 | AO51: 0 | AP51: =AJ51-30 -> -30
M52: 2 | N52: S | O52: =(F8*1000)/($D$5*SQRT(3)) -> 0 | P52: =($F$8*1000)/(($D$5/SQRT(3))) -> 0 | Q52: =P52 -> 0 | R52: =P52 -> 0 | S52: =($F$8*1000)/($D$5) -> 0 | T52: =S52 -> 0 | U52: =S52 -> 0 | Y52: 1 | Z52: IL2 | AA52: =AA51 -> 0 | AB52: 0 | AC52: =AA51 -> 0 | AD52: 0 | AE52: =AA51 -> 0 | AF52: =AA51 -> 0 | AG52: 0 | AI52: IL2 | AJ52: =AJ51-120 -> -120 | AK52: 0 | AL52: =AJ51-120 -> -120 | AM52: 0 | AN52: =AJ51-150 -> -150 | AO52: =AJ51-90 -> -90 | AP52: 0
M53: 3 | N53: I | O53: =F8 -> 0 | P53: =$F$8 -> 0 | Q53: =$F$8 -> 0 | R53: =$F$8 -> 0 | S53: =$F$8 -> 0 | T53: =$F$8 -> 0 | U53: =$F$8 -> 0 | Z53: IL3 | AA53: =AA51 -> 0 | AB53: 0 | AC53: 0 | AD53: =AA51 -> 0 | AE53: 0 | AF53: =AA51 -> 0 | AG53: =AA51 -> 0 | AI53: IL3 | AJ53: =AJ51+120 -> 120 | AK53: 0 | AL53: 0 | AM53: =AJ51+120 -> 120 | AN53: 0 | AO53: =AJ51+90 -> 90 | AP53: =AJ51+150 -> 150
...

Sheet Tavle +A14
C2: Eftersiddende tavle | H2: 14
P3: sf | Q3: 1 | S3: uf | T3: 1
N4: Selv skriv tavlenavn
C5: UL-L | D5: 400 | E5: [V] | F5: 3. harmoniske strømme | I5: 0 | J5: [A]
N6: Tavle +A14
F7: Værdi | H7: IB [A] | I7: cos ϕ | J7: Tilsluttet | K7: Ðj i Grader | L7: Ind./Kap. | N7: Belastning | P7: IL1 [A] | S7: IL2 [A] | V7: IL3 [A] | Y7: IN [A]
C8: Belastning 1 | F8: 0 | G8: =VLOOKUP(E51,B44:D46,3) -> [kW] | H8: =VLOOKUP(E51,M50:U53,J51+2) -> 0 | I8: 1 | K8: =IF(L51=1,-DEGREES(ACOS(I8)),DEGREES(ACOS(I8))) -> 0 | N8: =C8 -> Belastning 1 | O8: =HLOOKUP($J$51,$AA$49:$AG$54,3) -> 0 | P8: Ð | Q8: =HLOOKUP($J$51,$AJ$49:$AP$54,3) -> 0 | R8: =HLOOKUP($J$51,$AA$49:$AG$54,4) -> 0 | S8: Ð | T8: =HLOOKUP($J$51,$AJ$49:$AP$54,4) -> -120 | U8: =HLOOKUP($J$51,$AA$49:$AG$54,5) -> 0 | V8: Ð | W8: =HLOOKUP($J$51,$AJ$49:$AP$54,5) -> 120 | X8: =HLOOKUP($J$51,$AA$49:$AG$54,6) -> 0 | Y8: Ð | Z8: =HLOOKUP($J$51,$AJ$49:$AP$54,6) -> 0
C9: Belastning 2 | F9: 0 | G9: =VLOOKUP(E55,B44:D46,3) -> [kW] | H9: =VLOOKUP(E55,M55:U57,J55+2) -> 0 | I9: 1 | K9: =IF(L55=1,-DEGREES(ACOS(I9)),DEGREES(ACOS(I9))) -> 0 | L9: ½ | N9: =C9 -> Belastning 2 | O9: =HLOOKUP($J$55,$AA$56:$AG$61,3) -> 0 | P9: Ð | Q9: =HLOOKUP($J$55,$AJ$56:$AP$61,3) -> 0 | R9: =HLOOKUP($J$55,$AA$56:$AG$61,4) -> 0 | S9: Ð | T9: =HLOOKUP($J$55,$AJ$56:$AP$61,4) -> -120 | U9: =HLOOKUP($J$55,$AA$56:$AG$61,5) -> 0 | V9: Ð | W9: =HLOOKUP($J$55,$AJ$56:$AP$61,5) -> 120 | X9: =HLOOKUP($J$55,$AA$56:$AG$61,6) -> 0 | Y9: Ð | Z9: =HLOOKUP($J$55,$AJ$56:$AP$61,6) -> 0
C10: Belastning 3 | F10: 0 | G10: =VLOOKUP(E59,B44:D46,3) -> [kW] | H10: =VLOOKUP(E59,M59:U61,J59+2) -> 0 | I10: 1 | K10: =IF(L59=1,-DEGREES(ACOS(I10)),DEGREES(ACOS(I10))) -> 0 | N10: =C10 -> Belastning 3 | O10: =HLOOKUP($J$59,$AA$63:$AG468,3) -> 0 | P10: Ð | Q10: =HLOOKUP($J$59,$AJ$63:$AP$68,3) -> 0 | R10: =HLOOKUP($J$59,$AA$63:$AG468,4) -> 0 | S10: Ð | T10: =HLOOKUP($J$59,$AJ$63:$AP$68,4) -> -120 | U10: =HLOOKUP($J$59,$AA$63:$AG468,5) -> 0 | V10: Ð | W10: =HLOOKUP($J$59,$AJ$63:$AP$68,5) -> 120 | X10: =HLOOKUP($J$59,$AA$63:$AG468,6) -> 0 | Y10: Ð | Z10: =HLOOKUP($J$59,$AJ$63:$AP$68,6) -> 0
C11: Belastning 4 | F11: 0 | G11: =VLOOKUP(E63,B44:D46,3) -> [kW] | H11: =VLOOKUP(E63,M63:U65,J63+2) -> 0 | I11: 1 | K11: =IF(L63=1,-DEGREES(ACOS(I11)),DEGREES(ACOS(I11))) -> 0 | N11: =C11 -> Belastning 4 | O11: =HLOOKUP($J$63,$AA$70:$AG$75,3) -> 0 | P11: Ð | Q11: =HLOOKUP($J$63,$AJ$70:$AP$75,3) -> 0 | R11: =HLOOKUP($J$63,$AA$70:$AG$75,4) -> 0 | S11: Ð | T11: =HLOOKUP($J$63,$AJ$70:$AP$75,4) -> -120 | U11: =HLOOKUP($J$63,$AA$70:$AG$75,5) -> 0 | V11: Ð | W11: =HLOOKUP($J$63,$AJ$70:$AP$75,5) -> 120 | X11: =HLOOKUP($J$63,$AA$70:$AG$75,6) -> 0 | Y11: Ð | Z11: =HLOOKUP($J$63,$AJ$70:$AP$75,6) -> 0
C12: Belastning 5 | F12: 0 | G12: =VLOOKUP(E67,B44:D46,3) -> [kW] | H12: =VLOOKUP(E67,M67:U69,J67+2) -> 0 | I12: 1 | K12: =IF(L67=1,-DEGREES(ACOS(I12)),DEGREES(ACOS(I12))) -> 0 | N12: =C12 -> Belastning 5 | O12: =HLOOKUP($J$67,$AA$77:$AG$82,3) -> 0 | P12: Ð | Q12: =HLOOKUP($J$67,$AJ$77:$AP$82,3) -> 0 | R12: =HLOOKUP($J$67,$AA$77:$AG$82,4) -> 0 | S12: Ð | T12: =HLOOKUP($J$67,$AJ$77:$AP$82,4) -> -120 | U12: =HLOOKUP($J$67,$AA$77:$AG$82,5) -> 0 | V12: Ð | W12: =HLOOKUP($J$67,$AJ$77:$AP$82,5) -> 120 | X12: =HLOOKUP($J$67,$AA$77:$AG$82,6) -> 0 | Y12: Ð | Z12: =HLOOKUP($J$67,$AJ$77:$AP$82,6) -> 0
C13: Belastning 6 | F13: 0 | G13: =VLOOKUP(E71,B44:D46,3) -> [kW] | H13: =VLOOKUP(E71,M71:U73,J71+2) -> 0 | I13: 1 | K13: =IF(L71=1,-DEGREES(ACOS(I13)),DEGREES(ACOS(I13))) -> 0 | N13: =C13 -> Belastning 6 | O13: =HLOOKUP($J$71,$AA$84:$AG$89,3) -> 0 | P13: Ð | Q13: =HLOOKUP($J$71,$AJ$84:$AP$89,3) -> 0 | R13: =HLOOKUP($J$71,$AA$84:$AG$89,4) -> 0 | S13: Ð | T13: =HLOOKUP($J$71,$AJ$84:$AP$89,4) -> -120 | U13: =HLOOKUP($J$71,$AA$84:$AG$89,5) -> 0 | V13: Ð | W13: =HLOOKUP($J$71,$AJ$84:$AP$89,5) -> 120 | X13: =HLOOKUP($J$71,$AA$84:$AG$89,6) -> 0 | Y13: Ð | Z13: =HLOOKUP($J$71,$AJ$84:$AP$89,6) -> 0
C14: Belastning 7 | F14: 0 | G14: =VLOOKUP(E75,B44:D46,3) -> [kW] | H14: =VLOOKUP(E75,M75:U77,J75+2) -> 0 | I14: 1 | K14: =IF(L75=1,-DEGREES(ACOS(I14)),DEGREES(ACOS(I14))) -> 0 | N14: =C14 -> Belastning 7 | O14: =HLOOKUP($J$75,$AA$91:$AG$96,3) -> 0 | P14: Ð | Q14: =HLOOKUP($J$75,$AJ$91:$AP$96,3) -> 0 | R14: =HLOOKUP($J$75,$AA$91:$AG$96,4) -> 0 | S14: Ð | T14: =HLOOKUP($J$75,$AJ$91:$AP$96,4) -> -120 | U14: =HLOOKUP($J$75,$AA$91:$AG$96,5) -> 0 | V14: Ð | W14: =HLOOKUP($J$75,$AJ$91:$AP$96,5) -> 120 | X14: =HLOOKUP($J$75,$AA$91:$AG$96,6) -> 0 | Y14: Ð | Z14: =HLOOKUP($J$75,$AJ$91:$AP$96,6) -> 0
C15: Belastning 8 | F15: 0 | G15: =VLOOKUP(E79,B44:D46,3) -> [kW] | H15: =VLOOKUP(E79,M79:U81,J79+2) -> 0 | I15: 1 | K15: =IF(L79=1,-DEGREES(ACOS(I15)),DEGREES(ACOS(I15))) -> 0 | N15: =C15 -> Belastning 8 | O15: =HLOOKUP($J$79,$AA$98:$AG$103,3) -> 0 | P15: Ð | Q15: =HLOOKUP($J$79,$AJ$98:$AP$103,3) -> 0 | R15: =HLOOKUP($J$79,$AA$98:$AG$103,4) -> 0 | S15: Ð | T15: =HLOOKUP($J$79,$AJ$98:$AP$103,4) -> -120 | U15: =HLOOKUP($J$79,$AA$98:$AG$103,5) -> 0 | V15: Ð | W15: =HLOOKUP($J$79,$AJ$98:$AP$103,5) -> 120 | X15: =HLOOKUP($J$79,$AA$98:$AG$103,6) -> 0 | Y15: Ð | Z15: =HLOOKUP($J$79,$AJ$98:$AP$103,6) -> 0
C16: Belastning 9 | F16: 0 | G16: =VLOOKUP(E83,B44:D46,3) -> [kW] | H16: =VLOOKUP(E83,M83:U85,J83+2) -> 0 | I16: 1 | K16: =IF(L83=1,-DEGREES(ACOS(I16)),DEGREES(ACOS(I16))) -> 0 | N16: =C16 -> Belastning 9 | O16: =HLOOKUP($J$83,$AA$105:$AG$110,3) -> 0 | P16: Ð | Q16: =HLOOKUP($J$83,$AJ$105:$AP$110,3) -> 0 | R16: =HLOOKUP($J$83,$AA$105:$AG$110,4) -> 0 | S16: Ð | T16: =HLOOKUP($J$83,$AJ$105:$AP$110,4) -> -120 | U16: =HLOOKUP($J$83,$AA$105:$AG$110,5) -> 0 | V16: Ð | W16: =HLOOKUP($J$83,$AJ$105:$AP$110,5) -> 120 | X16: =HLOOKUP($J$83,$AA$105:$AG$110,6) -> 0 | Y16: Ð | Z16: =HLOOKUP($J$83,$AJ$105:$AP$110,6) -> 0
C17: Belastning 10 | F17: 0 | G17: =VLOOKUP(E87,B44:D46,3) -> [kW] | H17: =VLOOKUP(E87,M87:U89,J87+2) -> 0 | I17: 1 | K17: =IF(L87=1,-DEGREES(ACOS(I17)),DEGREES(ACOS(I17))) -> 0 | N17: =C17 -> Belastning 10 | O17: =HLOOKUP($J$87,$AA$112:$AG$117,3) -> 0 | P17: Ð | Q17: =HLOOKUP($J$87,$AJ$112:$AP$117,3) -> 0 | R17: =HLOOKUP($J$87,$AA$112:$AG$117,4) -> 0 | S17: Ð | T17: =HLOOKUP($J$87,$AJ$112:$AP$117,4) -> -120 | U17: =HLOOKUP($J$87,$AA$112:$AG$117,5) -> 0 | V17: Ð | W17: =HLOOKUP($J$87,$AJ$112:$AP$117,5) -> 120 | X17: =HLOOKUP($J$87,$AA$112:$AG$117,6) -> 0 | Y17: Ð | Z17: =HLOOKUP($J$87,$AJ$112:$AP$117,6) -> 0
C18: Belastning 11 | F18: 0 | G18: =VLOOKUP(E91,B44:D46,3) -> [kW] | H18: =VLOOKUP(E91,M91:U93,J91+2) -> 0 | I18: 1 | K18: =IF(L91=1,-DEGREES(ACOS(I18)),DEGREES(ACOS(I18))) -> 0 | N18: =C18 -> Belastning 11 | O18: =HLOOKUP($J$91,$AA$119:$AG$124,3) -> 0 | P18: Ð | Q18: =HLOOKUP($J$91,$AJ$119:$AP$124,3) -> 0 | R18: =HLOOKUP($J$91,$AA$119:$AG$124,4) -> 0 | S18: Ð | T18: =HLOOKUP($J$91,$AJ$119:$AP$124,4) -> -120 | U18: =HLOOKUP($J$91,$AA$119:$AG$124,5) -> 0 | V18: Ð | W18: =HLOOKUP($J$91,$AJ$119:$AP$124,5) -> 120 | X18: =HLOOKUP($J$91,$AA$119:$AG$124,6) -> 0 | Y18: Ð | Z18: =HLOOKUP($J$91,$AJ$119:$AP$124,6) -> 0
C19: Belastning 12 | F19: 0 | G19: =VLOOKUP(E95,B44:D46,3) -> [kW] | H19: =VLOOKUP(E95,M95:U97,J95+2) -> 0 | I19: 1 | K19: =IF(L95=1,-DEGREES(ACOS(I19)),DEGREES(ACOS(I19))) -> 0 | N19: =C19 -> Belastning 12 | O19: =HLOOKUP($J$95,$AA$126:$AG$131,3) -> 0 | P19: Ð | Q19: =HLOOKUP($J$95,$AJ$126:$AP$131,3) -> 0 | R19: =HLOOKUP($J$95,$AA$126:$AG$131,4) -> 0 | S19: Ð | T19: =HLOOKUP($J$95,$AJ$126:$AP$131,4) -> -120 | U19: =HLOOKUP($J$95,$AA$126:$AG$131,5) -> 0 | V19: Ð | W19: =HLOOKUP($J$95,$AJ$126:$AP$131,5) -> 120 | X19: =HLOOKUP($J$95,$AA$126:$AG$131,6) -> 0 | Y19: Ð | Z19: =HLOOKUP($J$95,$AJ$126:$AP$131,6) -> 0
C20: Belastning 13 | F20: 0 | G20: =VLOOKUP(E99,B44:D46,3) -> [kW] | H20: =VLOOKUP(E99,M99:U101,J99+2) -> 0 | I20: 1 | K20: =IF(L99=1,-DEGREES(ACOS(I20)),DEGREES(ACOS(I20))) -> 0 | N20: =C20 -> Belastning 13 | O20: =HLOOKUP($J$99,$AA$133:$AG$138,3) -> 0 | P20: Ð | Q20: =HLOOKUP($J$99,$AJ$133:$AP$138,3) -> 0 | R20: =HLOOKUP($J$99,$AA$133:$AG$138,4) -> 0 | S20: Ð | T20: =HLOOKUP($J$99,$AJ$133:$AP$138,4) -> -120 | U20: =HLOOKUP($J$99,$AA$133:$AG$138,5) -> 0 | V20: Ð | W20: =HLOOKUP($J$99,$AJ$133:$AP$138,5) -> 120 | X20: =HLOOKUP($J$99,$AA$133:$AG$138,6) -> 0 | Y20: Ð | Z20: =HLOOKUP($J$99,$AJ$133:$AP$138,6) -> 0
C21: Belastning 14 | F21: 0 | G21: =VLOOKUP(E103,B44:D46,3) -> [kW] | H21: =VLOOKUP(E103,M103:U105,J103+2) -> 0 | I21: 1 | K21: =IF(L103=1,-DEGREES(ACOS(I21)),DEGREES(ACOS(I21))) -> 0 | N21: =C21 -> Belastning 14 | O21: =HLOOKUP($J$103,$AA$140:$AG$145,3) -> 0 | P21: Ð | Q21: =HLOOKUP($J$103,$AJ$140:$AP$145,3) -> 0 | R21: =HLOOKUP($J$103,$AA$140:$AG$145,4) -> 0 | S21: Ð | T21: =HLOOKUP($J$103,$AJ$140:$AP$145,4) -> -120 | U21: =HLOOKUP($J$103,$AA$140:$AG$145,5) -> 0 | V21: Ð | W21: =HLOOKUP($J$103,$AJ$140:$AP$145,5) -> 120 | X21: =HLOOKUP($J$103,$AA$140:$AG$145,6) -> 0 | Y21: Ð | Z21: =HLOOKUP($J$103,$AJ$140:$AP$145,6) -> 0
C22: Belastning 15 | F22: 0 | G22: =VLOOKUP(E107,B44:D46,3) -> [kW] | H22: =VLOOKUP(E107,M107:U109,J107+2) -> 0 | I22: 1 | K22: =IF(L107=1,-DEGREES(ACOS(I22)),DEGREES(ACOS(I22))) -> 0 | N22: =C22 -> Belastning 15 | O22: =HLOOKUP($J$107,$AA$147:$AG$152,3) -> 0 | P22: Ð | Q22: =HLOOKUP($J$107,$AJ$147:$AP$152,3) -> 0 | R22: =HLOOKUP($J$107,$AA$147:$AG$152,4) -> 0 | S22: Ð | T22: =HLOOKUP($J$107,$AJ$147:$AP$152,4) -> -120 | U22: =HLOOKUP($J$107,$AA$147:$AG$152,5) -> 0 | V22: Ð | W22: =HLOOKUP($J$107,$AJ$147:$AP$152,5) -> 120 | X22: =HLOOKUP($J$107,$AA$147:$AG$152,6) -> 0 | Y22: Ð | Z22: =HLOOKUP($J$107,$AJ$147:$AP$152,6) -> 0
N23: ∑Itil - Global | O23: =SQRT(E128^2+F128^2) -> 0 | P23: Ð | Q23: =IFERROR(DEGREES(ATAN(F128/E128)),0) -> 0 | R23: =SQRT(G128^2+H128^2) -> 0 | S23: Ð | T23: =IFERROR(-DEGREES(ATAN(G128/H128))-90,0) -> 0 | U23: =SQRT(I128^2+J128^2) -> 0 | V23: Ð | W23: =IFERROR(-DEGREES(ATAN(I128/J128))+90,0) -> 0 | X23: =IMABS(COMPLEX(C134+F134+I134,C135+F135+I135)) -> 0 | Y23: Ð | Z23: =IFERROR(DEGREES(IMARGUMENT(IMSUM(L135)))+180,0) -> 0
N24: ∑IB - Global | O24: =O23*Q3*T3 -> 0 | P24: Ð | Q24: =Q23 -> 0 | R24: =R23*Q3*T3 -> 0 | S24: Ð | T24: =T23 -> 0 | U24: =U23*Q3*T3 -> 0 | V24: Ð | W24: =W23 -> 0 | X24: =(X23)*Q3*T3 -> 0 | Y24: Ð | Z24: =Z23 -> 0
N25: ∑IB - Lokal | O25: =O24 -> 0 | P25: Ð | Q25: =Q23 -> 0 | R25: =R24 -> 0 | S25: Ð | T25: =T24+120 -> 120 | U25: =U24 -> 0 | V25: Ð | W25: =W24-120 -> -120 | X25: =(X24) -> 0 | Y25: Ð | Z25: =Z24 -> 0
N26: 3. harmoniske | O26: =IFERROR(((I5/3)/O24)*100,0) -> 0 | P26: % | R26: =IFERROR(((I5/3)/R24)*100,0) -> 0 | S26: % | U26: =IFERROR(((I5/3)/U24)*100,0) -> 0 | V26: %
K27: Tjek SB side 193
I39: 1 | J39: 3 - faser
I40: 2 | J40: L1 - N
I41: 3 | J41: L2 - N
I42: 4 | J42: L3 - N
I43: 5 | J43: L1 - L2 | AA43: 3-harmoniske
B44: 1 | C44: P [kW] | D44: [kW] | I44: 6 | J44: L2 - L3 | L44: Induktiv | Y44: 1 | Z44: IL1 | AB44: %
B45: 2 | C45: S [kVA] | D45: [kVA] | I45: 7 | J45: L1 - L3 | L45: Kapasativ | Y45: 2 | Z45: IL2 | AB45: %
B46: 3 | C46: I [A] | D46: [A] | Y46: 3 | Z46: IL3 | AB46: %
Y47: 4 | Z47: IN
E49: Output | AA49: 1 | AB49: 2 | AC49: 3 | AD49: 4 | AE49: 5 | AF49: 6 | AG49: 7 | AJ49: 1 | AK49: 2 | AL49: 3 | AM49: 4 | AN49: 5 | AO49: 6 | AP49: 7
O50: 3-faset | P50: L1-N | Q50: L2-N | R50: L3-N | S50: L1-L2 | T50: L2-L3 | U50: L1-L3 | AA50: 3-faset | AB50: L1-N | AC50: L2-N | AD50: L3-N | AE50: L1-L2 | AF50: L2-L3 | AG50: L1-L3 | AI50: Ðj Grader | AJ50: 3-faset | AK50: L1-N | AL50: L2-N | AM50: L3-N | AN50: L1-L2 | AO50: L2-L3 | AP50: L1-L3
C51: Belastning 1 | E51: 1 | J51: 1 | L51: 1 | M51: 1 | N51: P | O51: =(F8*1000)/($D$5*SQRT(3)*I8) -> 0 | P51: =($F$8*1000)/(($D$5/SQRT(3))*$I$8) -> 0 | Q51: =P51 -> 0 | R51: =P51 -> 0 | S51: =($F$8*1000)/($D$5*$I$8) -> 0 | T51: =S51 -> 0 | U51: =S51 -> 0 | Z51: IL1 | AA51: =H8 -> 0 | AB51: =AA51 -> 0 | AC51: 0 | AD51: 0 | AE51: =AA51 -> 0 | AF51: 0 | AG51: =AA51 -> 0 | AI51: IL1 | AJ51: =K8 -> 0 | AK51: =AJ51 -> 0 | AL51: 0 | AM51: 0 | AN51: =AJ51+30 -> 30 | AO51: 0 | AP51: =AJ51-30 -> -30
M52: 2 | N52: S | O52: =(F8*1000)/($D$5*SQRT(3)) -> 0 | P52: =($F$8*1000)/(($D$5/SQRT(3))) -> 0 | Q52: =P52 -> 0 | R52: =P52 -> 0 | S52: =($F$8*1000)/($D$5) -> 0 | T52: =S52 -> 0 | U52: =S52 -> 0 | Y52: 1 | Z52: IL2 | AA52: =AA51 -> 0 | AB52: 0 | AC52: =AA51 -> 0 | AD52: 0 | AE52: =AA51 -> 0 | AF52: =AA51 -> 0 | AG52: 0 | AI52: IL2 | AJ52: =AJ51-120 -> -120 | AK52: 0 | AL52: =AJ51-120 -> -120 | AM52: 0 | AN52: =AJ51-150 -> -150 | AO52: =AJ51-90 -> -90 | AP52: 0
M53: 3 | N53: I | O53: =F8 -> 0 | P53: =$F$8 -> 0 | Q53: =$F$8 -> 0 | R53: =$F$8 -> 0 | S53: =$F$8 -> 0 | T53: =$F$8 -> 0 | U53: =$F$8 -> 0 | Z53: IL3 | AA53: =AA51 -> 0 | AB53: 0 | AC53: 0 | AD53: =AA51 -> 0 | AE53: 0 | AF53: =AA51 -> 0 | AG53: =AA51 -> 0 | AI53: IL3 | AJ53: =AJ51+120 -> 120 | AK53: 0 | AL53: 0 | AM53: =AJ51+120 -> 120 | AN53: 0 | AO53: =AJ51+90 -> 90 | AP53: =AJ51+150 -> 150
...

Sheet Tavle +A15
C2: Eftersiddende tavle | H2: 15
P3: sf | Q3: 1 | S3: uf | T3: 1
N4: Selv skriv tavlenavn
C5: UL-L | D5: 400 | E5: [V] | F5: 3. harmoniske strømme | I5: 0 | J5: [A]
N6: Tavle +A15
F7: Værdi | H7: IB [A] | I7: cos ϕ | J7: Tilsluttet | K7: Ðj i Grader | L7: Ind./Kap. | N7: Belastning | P7: IL1 [A] | S7: IL2 [A] | V7: IL3 [A] | Y7: IN [A]
C8: Belastning 1 | F8: 0 | G8: =VLOOKUP(E51,B44:D46,3) -> [kW] | H8: =VLOOKUP(E51,M50:U53,J51+2) -> 0 | I8: 1 | K8: =IF(L51=1,-DEGREES(ACOS(I8)),DEGREES(ACOS(I8))) -> 0 | N8: =C8 -> Belastning 1 | O8: =HLOOKUP($J$51,$AA$49:$AG$54,3) -> 0 | P8: Ð | Q8: =HLOOKUP($J$51,$AJ$49:$AP$54,3) -> 0 | R8: =HLOOKUP($J$51,$AA$49:$AG$54,4) -> 0 | S8: Ð | T8: =HLOOKUP($J$51,$AJ$49:$AP$54,4) -> -120 | U8: =HLOOKUP($J$51,$AA$49:$AG$54,5) -> 0 | V8: Ð | W8: =HLOOKUP($J$51,$AJ$49:$AP$54,5) -> 120 | X8: =HLOOKUP($J$51,$AA$49:$AG$54,6) -> 0 | Y8: Ð | Z8: =HLOOKUP($J$51,$AJ$49:$AP$54,6) -> 0
C9: Belastning 2 | F9: 0 | G9: =VLOOKUP(E55,B44:D46,3) -> [kW] | H9: =VLOOKUP(E55,M55:U57,J55+2) -> 0 | I9: 1 | K9: =IF(L55=1,-DEGREES(ACOS(I9)),DEGREES(ACOS(I9))) -> 0 | L9: ½ | N9: =C9 -> Belastning 2 | O9: =HLOOKUP($J$55,$AA$56:$AG$61,3) -> 0 | P9: Ð | Q9: =HLOOKUP($J$55,$AJ$56:$AP$61,3) -> 0 | R9: =HLOOKUP($J$55,$AA$56:$AG$61,4) -> 0 | S9: Ð | T9: =HLOOKUP($J$55,$AJ$56:$AP$61,4) -> -120 | U9: =HLOOKUP($J$55,$AA$56:$AG$61,5) -> 0 | V9: Ð | W9: =HLOOKUP($J$55,$AJ$56:$AP$61,5) -> 120 | X9: =HLOOKUP($J$55,$AA$56:$AG$61,6) -> 0 | Y9: Ð | Z9: =HLOOKUP($J$55,$AJ$56:$AP$61,6) -> 0
C10: Belastning 3 | F10: 0 | G10: =VLOOKUP(E59,B44:D46,3) -> [kW] | H10: =VLOOKUP(E59,M59:U61,J59+2) -> 0 | I10: 1 | K10: =IF(L59=1,-DEGREES(ACOS(I10)),DEGREES(ACOS(I10))) -> 0 | N10: =C10 -> Belastning 3 | O10: =HLOOKUP($J$59,$AA$63:$AG468,3) -> 0 | P10: Ð | Q10: =HLOOKUP($J$59,$AJ$63:$AP$68,3) -> 0 | R10: =HLOOKUP($J$59,$AA$63:$AG468,4) -> 0 | S10: Ð | T10: =HLOOKUP($J$59,$AJ$63:$AP$68,4) -> -120 | U10: =HLOOKUP($J$59,$AA$63:$AG468,5) -> 0 | V10: Ð | W10: =HLOOKUP($J$59,$AJ$63:$AP$68,5) -> 120 | X10: =HLOOKUP($J$59,$AA$63:$AG468,6) -> 0 | Y10: Ð | Z10: =HLOOKUP($J$59,$AJ$63:$AP$68,6) -> 0
C11: Belastning 4 | F11: 0 | G11: =VLOOKUP(E63,B44:D46,3) -> [kW] | H11: =VLOOKUP(E63,M63:U65,J63+2) -> 0 | I11: 1 | K11: =IF(L63=1,-DEGREES(ACOS(I11)),DEGREES(ACOS(I11))) -> 0 | N11: =C11 -> Belastning 4 | O11: =HLOOKUP($J$63,$AA$70:$AG$75,3) -> 0 | P11: Ð | Q11: =HLOOKUP($J$63,$AJ$70:$AP$75,3) -> 0 | R11: =HLOOKUP($J$63,$AA$70:$AG$75,4) -> 0 | S11: Ð | T11: =HLOOKUP($J$63,$AJ$70:$AP$75,4) -> -120 | U11: =HLOOKUP($J$63,$AA$70:$AG$75,5) -> 0 | V11: Ð | W11: =HLOOKUP($J$63,$AJ$70:$AP$75,5) -> 120 | X11: =HLOOKUP($J$63,$AA$70:$AG$75,6) -> 0 | Y11: Ð | Z11: =HLOOKUP($J$63,$AJ$70:$AP$75,6) -> 0
C12: Belastning 5 | F12: 0 | G12: =VLOOKUP(E67,B44:D46,3) -> [kW] | H12: =VLOOKUP(E67,M67:U69,J67+2) -> 0 | I12: 1 | K12: =IF(L67=1,-DEGREES(ACOS(I12)),DEGREES(ACOS(I12))) -> 0 | N12: =C12 -> Belastning 5 | O12: =HLOOKUP($J$67,$AA$77:$AG$82,3) -> 0 | P12: Ð | Q12: =HLOOKUP($J$67,$AJ$77:$AP$82,3) -> 0 | R12: =HLOOKUP($J$67,$AA$77:$AG$82,4) -> 0 | S12: Ð | T12: =HLOOKUP($J$67,$AJ$77:$AP$82,4) -> -120 | U12: =HLOOKUP($J$67,$AA$77:$AG$82,5) -> 0 | V12: Ð | W12: =HLOOKUP($J$67,$AJ$77:$AP$82,5) -> 120 | X12: =HLOOKUP($J$67,$AA$77:$AG$82,6) -> 0 | Y12: Ð | Z12: =HLOOKUP($J$67,$AJ$77:$AP$82,6) -> 0
C13: Belastning 6 | F13: 0 | G13: =VLOOKUP(E71,B44:D46,3) -> [kW] | H13: =VLOOKUP(E71,M71:U73,J71+2) -> 0 | I13: 1 | K13: =IF(L71=1,-DEGREES(ACOS(I13)),DEGREES(ACOS(I13))) -> 0 | N13: =C13 -> Belastning 6 | O13: =HLOOKUP($J$71,$AA$84:$AG$89,3) -> 0 | P13: Ð | Q13: =HLOOKUP($J$71,$AJ$84:$AP$89,3) -> 0 | R13: =HLOOKUP($J$71,$AA$84:$AG$89,4) -> 0 | S13: Ð | T13: =HLOOKUP($J$71,$AJ$84:$AP$89,4) -> -120 | U13: =HLOOKUP($J$71,$AA$84:$AG$89,5) -> 0 | V13: Ð | W13: =HLOOKUP($J$71,$AJ$84:$AP$89,5) -> 120 | X13: =HLOOKUP($J$71,$AA$84:$AG$89,6) -> 0 | Y13: Ð | Z13: =HLOOKUP($J$71,$AJ$84:$AP$89,6) -> 0
C14: Belastning 7 | F14: 0 | G14: =VLOOKUP(E75,B44:D46,3) -> [kW] | H14: =VLOOKUP(E75,M75:U77,J75+2) -> 0 | I14: 1 | K14: =IF(L75=1,-DEGREES(ACOS(I14)),DEGREES(ACOS(I14))) -> 0 | N14: =C14 -> Belastning 7 | O14: =HLOOKUP($J$75,$AA$91:$AG$96,3) -> 0 | P14: Ð | Q14: =HLOOKUP($J$75,$AJ$91:$AP$96,3) -> 0 | R14: =HLOOKUP($J$75,$AA$91:$AG$96,4) -> 0 | S14: Ð | T14: =HLOOKUP($J$75,$AJ$91:$AP$96,4) -> -120 | U14: =HLOOKUP($J$75,$AA$91:$AG$96,5) -> 0 | V14: Ð | W14: =HLOOKUP($J$75,$AJ$91:$AP$96,5) -> 120 | X14: =HLOOKUP($J$75,$AA$91:$AG$96,6) -> 0 | Y14: Ð | Z14: =HLOOKUP($J$75,$AJ$91:$AP$96,6) -> 0
C15: Belastning 8 | F15: 0 | G15: =VLOOKUP(E79,B44:D46,3) -> [kW] | H15: =VLOOKUP(E79,M79:U81,J79+2) -> 0 | I15: 1 | K15: =IF(L79=1,-DEGREES(ACOS(I15)),DEGREES(ACOS(I15))) -> 0 | N15: =C15 -> Belastning 8 | O15: =HLOOKUP($J$79,$AA$98:$AG$103,3) -> 0 | P15: Ð | Q15: =HLOOKUP($J$79,$AJ$98:$AP$103,3) -> 0 | R15: =HLOOKUP($J$79,$AA$98:$AG$103,4) -> 0 | S15: Ð | T15: =HLOOKUP($J$79,$AJ$98:$AP$103,4) -> -120 | U15: =HLOOKUP($J$79,$AA$98:$AG$103,5) -> 0 | V15: Ð | W15: =HLOOKUP($J$79,$AJ$98:$AP$103,5) -> 120 | X15: =HLOOKUP($J$79,$AA$98:$AG$103,6) -> 0 | Y15: Ð | Z15: =HLOOKUP($J$79,$AJ$98:$AP$103,6) -> 0
C16: Belastning 9 | F16: 0 | G16: =VLOOKUP(E83,B44:D46,3) -> [kW] | H16: =VLOOKUP(E83,M83:U85,J83+2) -> 0 | I16: 1 | K16: =IF(L83=1,-DEGREES(ACOS(I16)),DEGREES(ACOS(I16))) -> 0 | N16: =C16 -> Belastning 9 | O16: =HLOOKUP($J$83,$AA$105:$AG$110,3) -> 0 | P16: Ð | Q16: =HLOOKUP($J$83,$AJ$105:$AP$110,3) -> 0 | R16: =HLOOKUP($J$83,$AA$105:$AG$110,4) -> 0 | S16: Ð | T16: =HLOOKUP($J$83,$AJ$105:$AP$110,4) -> -120 | U16: =HLOOKUP($J$83,$AA$105:$AG$110,5) -> 0 | V16: Ð | W16: =HLOOKUP($J$83,$AJ$105:$AP$110,5) -> 120 | X16: =HLOOKUP($J$83,$AA$105:$AG$110,6) -> 0 | Y16: Ð | Z16: =HLOOKUP($J$83,$AJ$105:$AP$110,6) -> 0
C17: Belastning 10 | F17: 0 | G17: =VLOOKUP(E87,B44:D46,3) -> [kW] | H17: =VLOOKUP(E87,M87:U89,J87+2) -> 0 | I17: 1 | K17: =IF(L87=1,-DEGREES(ACOS(I17)),DEGREES(ACOS(I17))) -> 0 | N17: =C17 -> Belastning 10 | O17: =HLOOKUP($J$87,$AA$112:$AG$117,3) -> 0 | P17: Ð | Q17: =HLOOKUP($J$87,$AJ$112:$AP$117,3) -> 0 | R17: =HLOOKUP($J$87,$AA$112:$AG$117,4) -> 0 | S17: Ð | T17: =HLOOKUP($J$87,$AJ$112:$AP$117,4) -> -120 | U17: =HLOOKUP($J$87,$AA$112:$AG$117,5) -> 0 | V17: Ð | W17: =HLOOKUP($J$87,$AJ$112:$AP$117,5) -> 120 | X17: =HLOOKUP($J$87,$AA$112:$AG$117,6) -> 0 | Y17: Ð | Z17: =HLOOKUP($J$87,$AJ$112:$AP$117,6) -> 0
C18: Belastning 11 | F18: 0 | G18: =VLOOKUP(E91,B44:D46,3) -> [kW] | H18: =VLOOKUP(E91,M91:U93,J91+2) -> 0 | I18: 1 | K18: =IF(L91=1,-DEGREES(ACOS(I18)),DEGREES(ACOS(I18))) -> 0 | N18: =C18 -> Belastning 11 | O18: =HLOOKUP($J$91,$AA$119:$AG$124,3) -> 0 | P18: Ð | Q18: =HLOOKUP($J$91,$AJ$119:$AP$124,3) -> 0 | R18: =HLOOKUP($J$91,$AA$119:$AG$124,4) -> 0 | S18: Ð | T18: =HLOOKUP($J$91,$AJ$119:$AP$124,4) -> -120 | U18: =HLOOKUP($J$91,$AA$119:$AG$124,5) -> 0 | V18: Ð | W18: =HLOOKUP($J$91,$AJ$119:$AP$124,5) -> 120 | X18: =HLOOKUP($J$91,$AA$119:$AG$124,6) -> 0 | Y18: Ð | Z18: =HLOOKUP($J$91,$AJ$119:$AP$124,6) -> 0
C19: Belastning 12 | F19: 0 | G19: =VLOOKUP(E95,B44:D46,3) -> [kW] | H19: =VLOOKUP(E95,M95:U97,J95+2) -> 0 | I19: 1 | K19: =IF(L95=1,-DEGREES(ACOS(I19)),DEGREES(ACOS(I19))) -> 0 | N19: =C19 -> Belastning 12 | O19: =HLOOKUP($J$95,$AA$126:$AG$131,3) -> 0 | P19: Ð | Q19: =HLOOKUP($J$95,$AJ$126:$AP$131,3) -> 0 | R19: =HLOOKUP($J$95,$AA$126:$AG$131,4) -> 0 | S19: Ð | T19: =HLOOKUP($J$95,$AJ$126:$AP$131,4) -> -120 | U19: =HLOOKUP($J$95,$AA$126:$AG$131,5) -> 0 | V19: Ð | W19: =HLOOKUP($J$95,$AJ$126:$AP$131,5) -> 120 | X19: =HLOOKUP($J$95,$AA$126:$AG$131,6) -> 0 | Y19: Ð | Z19: =HLOOKUP($J$95,$AJ$126:$AP$131,6) -> 0
C20: Belastning 13 | F20: 0 | G20: =VLOOKUP(E99,B44:D46,3) -> [kW] | H20: =VLOOKUP(E99,M99:U101,J99+2) -> 0 | I20: 1 | K20: =IF(L99=1,-DEGREES(ACOS(I20)),DEGREES(ACOS(I20))) -> 0 | N20: =C20 -> Belastning 13 | O20: =HLOOKUP($J$99,$AA$133:$AG$138,3) -> 0 | P20: Ð | Q20: =HLOOKUP($J$99,$AJ$133:$AP$138,3) -> 0 | R20: =HLOOKUP($J$99,$AA$133:$AG$138,4) -> 0 | S20: Ð | T20: =HLOOKUP($J$99,$AJ$133:$AP$138,4) -> -120 | U20: =HLOOKUP($J$99,$AA$133:$AG$138,5) -> 0 | V20: Ð | W20: =HLOOKUP($J$99,$AJ$133:$AP$138,5) -> 120 | X20: =HLOOKUP($J$99,$AA$133:$AG$138,6) -> 0 | Y20: Ð | Z20: =HLOOKUP($J$99,$AJ$133:$AP$138,6) -> 0
C21: Belastning 14 | F21: 0 | G21: =VLOOKUP(E103,B44:D46,3) -> [kW] | H21: =VLOOKUP(E103,M103:U105,J103+2) -> 0 | I21: 1 | K21: =IF(L103=1,-DEGREES(ACOS(I21)),DEGREES(ACOS(I21))) -> 0 | N21: =C21 -> Belastning 14 | O21: =HLOOKUP($J$103,$AA$140:$AG$145,3) -> 0 | P21: Ð | Q21: =HLOOKUP($J$103,$AJ$140:$AP$145,3) -> 0 | R21: =HLOOKUP($J$103,$AA$140:$AG$145,4) -> 0 | S21: Ð | T21: =HLOOKUP($J$103,$AJ$140:$AP$145,4) -> -120 | U21: =HLOOKUP($J$103,$AA$140:$AG$145,5) -> 0 | V21: Ð | W21: =HLOOKUP($J$103,$AJ$140:$AP$145,5) -> 120 | X21: =HLOOKUP($J$103,$AA$140:$AG$145,6) -> 0 | Y21: Ð | Z21: =HLOOKUP($J$103,$AJ$140:$AP$145,6) -> 0
