Workbook

Sheet Beregninger
B1: Belastningsberegninger
C3: Herfra og ned er de belastninger hvor strømmen er oplyst | O3: Input | P3: Beregning
C4: Beskrivelse | D4: Vælg belastede Fase/Faser | E4: Samtidighedsfaktor | F4: Antal | G4: - | H4: Strøm [A] | I4: Cos phi | J4: Resultat L1 Kompleks | K4: Resultat L2 Kompleks | L4: Resultat L3 Kompleks
D5: L1 | E5: 1 | F5: 1 | I5: 1 | J5: =IF(OR(D5="L1",D5="L1L2",D5="L3L1",D5="L1L2L3"),COMPLEX(E5*H5*F5*(COS(RADIANS(DEGREES(ACOS(I5))-IF(D5="L1L2",30,0)+IF(D5="L3L1",30,0)))),F5*E5*H5*(SIN(RADIANS(DEGREES(ACOS(I5))-IF(D5="L1L2",30,0)+IF(D5="L3L1",30,0)))),"i"),0) -> 0 | K5: =IF(OR(D5="L2",D5="L1L2",D5="L2L3",D5="L1L2L3"),COMPLEX(E5*H5*F5*(COS(RADIANS(DEGREES(ACOS(I5))-IF(D5="L2L3",30,0)+IF(D5="L1L2",30,0)))),F5*E5*H5*(SIN(RADIANS(DEGREES(ACOS(I5))-IF(D5="L2L3",30,0)+IF(D5="L1L2",30,0)))),"i"),0) -> 0 | L5: =IF(OR(D5="L3",D5="L3L1",D5="L2L3",D5="L1L2L3"),COMPLEX(E5*H5*F5*(COS(RADIANS(DEGREES(ACOS(I5))-IF(D5="L3L1",30,0)+IF(D5="L2L3",30,0)))),F5*E5*H5*(SIN(RADIANS(DEGREES(ACOS(I5))-IF(D5="L3L1",30,0)+IF(D5="L2L3",30,0)))),"i"),0) -> 0
D6: L2 | E6: 1 | F6: 1 | I6: 1 | J6: =IF(OR(D6="L1",D6="L1L2",D6="L3L1",D6="L1L2L3"),COMPLEX(E6*H6*F6*(COS(RADIANS(DEGREES(ACOS(I6))-IF(D6="L1L2",30,0)+IF(D6="L3L1",30,0)))),F6*E6*H6*(SIN(RADIANS(DEGREES(ACOS(I6))-IF(D6="L1L2",30,0)+IF(D6="L3L1",30,0)))),"i"),0) -> 0 | K6: =IF(OR(D6="L2",D6="L1L2",D6="L2L3",D6="L1L2L3"),COMPLEX(E6*H6*F6*(COS(RADIANS(DEGREES(ACOS(I6))-IF(D6="L2L3",30,0)+IF(D6="L1L2",30,0)))),F6*E6*H6*(SIN(RADIANS(DEGREES(ACOS(I6))-IF(D6="L2L3",30,0)+IF(D6="L1L2",30,0)))),"i"),0) -> 0 | L6: =IF(OR(D6="L3",D6="L3L1",D6="L2L3",D6="L1L2L3"),COMPLEX(E6*H6*F6*(COS(RADIANS(DEGREES(ACOS(I6))-IF(D6="L3L1",30,0)+IF(D6="L2L3",30,0)))),F6*E6*H6*(SIN(RADIANS(DEGREES(ACOS(I6))-IF(D6="L3L1",30,0)+IF(D6="L2L3",30,0)))),"i"),0) -> 0
D7: L3 | E7: 1 | F7: 1 | I7: 1 | J7: =IF(OR(D7="L1",D7="L1L2",D7="L3L1",D7="L1L2L3"),COMPLEX(E7*H7*F7*(COS(RADIANS(DEGREES(ACOS(I7))-IF(D7="L1L2",30,0)+IF(D7="L3L1",30,0)))),F7*E7*H7*(SIN(RADIANS(DEGREES(ACOS(I7))-IF(D7="L1L2",30,0)+IF(D7="L3L1",30,0)))),"i"),0) -> 0 | K7: =IF(OR(D7="L2",D7="L1L2",D7="L2L3",D7="L1L2L3"),COMPLEX(E7*H7*F7*(COS(RADIANS(DEGREES(ACOS(I7))-IF(D7="L2L3",30,0)+IF(D7="L1L2",30,0)))),F7*E7*H7*(SIN(RADIANS(DEGREES(ACOS(I7))-IF(D7="L2L3",30,0)+IF(D7="L1L2",30,0)))),"i"),0) -> 0 | L7: =IF(OR(D7="L3",D7="L3L1",D7="L2L3",D7="L1L2L3"),COMPLEX(E7*H7*F7*(COS(RADIANS(DEGREES(ACOS(I7))-IF(D7="L3L1",30,0)+IF(D7="L2L3",30,0)))),F7*E7*H7*(SIN(RADIANS(DEGREES(ACOS(I7))-IF(D7="L3L1",30,0)+IF(D7="L2L3",30,0)))),"i"),0) -> 0 | O7: Omregner vinkel ->Cos ϕ
D8: L1L2L3 | E8: 1 | F8: 1 | I8: 1 | J8: =IF(OR(D8="L1",D8="L1L2",D8="L3L1",D8="L1L2L3"),COMPLEX(E8*H8*F8*(COS(RADIANS(DEGREES(ACOS(I8))-IF(D8="L1L2",30,0)+IF(D8="L3L1",30,0)))),F8*E8*H8*(SIN(RADIANS(DEGREES(ACOS(I8))-IF(D8="L1L2",30,0)+IF(D8="L3L1",30,0)))),"i"),0) -> 0 | K8: =IF(OR(D8="L2",D8="L1L2",D8="L2L3",D8="L1L2L3"),COMPLEX(E8*H8*F8*(COS(RADIANS(DEGREES(ACOS(I8))-IF(D8="L2L3",30,0)+IF(D8="L1L2",30,0)))),F8*E8*H8*(SIN(RADIANS(DEGREES(ACOS(I8))-IF(D8="L2L3",30,0)+IF(D8="L1L2",30,0)))),"i"),0) -> 0 | L8: =IF(OR(D8="L3",D8="L3L1",D8="L2L3",D8="L1L2L3"),COMPLEX(E8*H8*F8*(COS(RADIANS(DEGREES(ACOS(I8))-IF(D8="L3L1",30,0)+IF(D8="L2L3",30,0)))),F8*E8*H8*(SIN(RADIANS(DEGREES(ACOS(I8))-IF(D8="L3L1",30,0)+IF(D8="L2L3",30,0)))),"i"),0) -> 0 | O8: Vinkel | P8: 73.3
D9: L2 | E9: 1 | F9: 1 | I9: 1 | J9: =IF(OR(D9="L1",D9="L1L2",D9="L3L1",D9="L1L2L3"),COMPLEX(E9*H9*F9*(COS(RADIANS(DEGREES(ACOS(I9))-IF(D9="L1L2",30,0)+IF(D9="L3L1",30,0)))),F9*E9*H9*(SIN(RADIANS(DEGREES(ACOS(I9))-IF(D9="L1L2",30,0)+IF(D9="L3L1",30,0)))),"i"),0) -> 0 | K9: =IF(OR(D9="L2",D9="L1L2",D9="L2L3",D9="L1L2L3"),COMPLEX(E9*H9*F9*(COS(RADIANS(DEGREES(ACOS(I9))-IF(D9="L2L3",30,0)+IF(D9="L1L2",30,0)))),F9*E9*H9*(SIN(RADIANS(DEGREES(ACOS(I9))-IF(D9="L2L3",30,0)+IF(D9="L1L2",30,0)))),"i"),0) -> 0 | L9: =IF(OR(D9="L3",D9="L3L1",D9="L2L3",D9="L1L2L3"),COMPLEX(E9*H9*F9*(COS(RADIANS(DEGREES(ACOS(I9))-IF(D9="L3L1",30,0)+IF(D9="L2L3",30,0)))),F9*E9*H9*(SIN(RADIANS(DEGREES(ACOS(I9))-IF(D9="L3L1",30,0)+IF(D9="L2L3",30,0)))),"i"),0) -> 0 | O9: Cos ϕ | P9: =COS(RADIANS(P8)) -> 0.28736052
D10: L1 | E10: 1 | F10: 1 | I10: 1 | J10: =IF(OR(D10="L1",D10="L1L2",D10="L3L1",D10="L1L2L3"),COMPLEX(E10*H10*F10*(COS(RADIANS(DEGREES(ACOS(I10))-IF(D10="L1L2",30,0)+IF(D10="L3L1",30,0)))),F10*E10*H10*(SIN(RADIANS(DEGREES(ACOS(I10))-IF(D10="L1L2",30,0)+IF(D10="L3L1",30,0)))),"i"),0) -> 0 | K10: =IF(OR(D10="L2",D10="L1L2",D10="L2L3",D10="L1L2L3"),COMPLEX(E10*H10*F10*(COS(RADIANS(DEGREES(ACOS(I10))-IF(D10="L2L3",30,0)+IF(D10="L1L2",30,0)))),F10*E10*H10*(SIN(RADIANS(DEGREES(ACOS(I10))-IF(D10="L2L3",30,0)+IF(D10="L1L2",30,0)))),"i"),0) -> 0 | L10: =IF(OR(D10="L3",D10="L3L1",D10="L2L3",D10="L1L2L3"),COMPLEX(E10*H10*F10*(COS(RADIANS(DEGREES(ACOS(I10))-IF(D10="L3L1",30,0)+IF(D10="L2L3",30,0)))),F10*E10*H10*(SIN(RADIANS(DEGREES(ACOS(I10))-IF(D10="L3L1",30,0)+IF(D10="L2L3",30,0)))),"i"),0) -> 0
D11: L1L2L3 | E11: 1 | F11: 1 | I11: 1 | J11: =IF(OR(D11="L1",D11="L1L2",D11="L3L1",D11="L1L2L3"),COMPLEX(E11*H11*F11*(COS(RADIANS(DEGREES(ACOS(I11))-IF(D11="L1L2",30,0)+IF(D11="L3L1",30,0)))),F11*E11*H11*(SIN(RADIANS(DEGREES(ACOS(I11))-IF(D11="L1L2",30,0)+IF(D11="L3L1",30,0)))),"i"),0) -> 0 | K11: =IF(OR(D11="L2",D11="L1L2",D11="L2L3",D11="L1L2L3"),COMPLEX(E11*H11*F11*(COS(RADIANS(DEGREES(ACOS(I11))-IF(D11="L2L3",30,0)+IF(D11="L1L2",30,0)))),F11*E11*H11*(SIN(RADIANS(DEGREES(ACOS(I11))-IF(D11="L2L3",30,0)+IF(D11="L1L2",30,0)))),"i"),0) -> 0 | L11: =IF(OR(D11="L3",D11="L3L1",D11="L2L3",D11="L1L2L3"),COMPLEX(E11*H11*F11*(COS(RADIANS(DEGREES(ACOS(I11))-IF(D11="L3L1",30,0)+IF(D11="L2L3",30,0)))),F11*E11*H11*(SIN(RADIANS(DEGREES(ACOS(I11))-IF(D11="L3L1",30,0)+IF(D11="L2L3",30,0)))),"i"),0) -> 0
D12: L1L2L3 | E12: 1 | F12: 1 | I12: 1 | J12: =IF(OR(D12="L1",D12="L1L2",D12="L3L1",D12="L1L2L3"),COMPLEX(E12*H12*F12*(COS(RADIANS(DEGREES(ACOS(I12))-IF(D12="L1L2",30,0)+IF(D12="L3L1",30,0)))),F12*E12*H12*(SIN(RADIANS(DEGREES(ACOS(I12))-IF(D12="L1L2",30,0)+IF(D12="L3L1",30,0)))),"i"),0) -> 0 | K12: =IF(OR(D12="L2",D12="L1L2",D12="L2L3",D12="L1L2L3"),COMPLEX(E12*H12*F12*(COS(RADIANS(DEGREES(ACOS(I12))-IF(D12="L2L3",30,0)+IF(D12="L1L2",30,0)))),F12*E12*H12*(SIN(RADIANS(DEGREES(ACOS(I12))-IF(D12="L2L3",30,0)+IF(D12="L1L2",30,0)))),"i"),0) -> 0 | L12: =IF(OR(D12="L3",D12="L3L1",D12="L2L3",D12="L1L2L3"),COMPLEX(E12*H12*F12*(COS(RADIANS(DEGREES(ACOS(I12))-IF(D12="L3L1",30,0)+IF(D12="L2L3",30,0)))),F12*E12*H12*(SIN(RADIANS(DEGREES(ACOS(I12))-IF(D12="L3L1",30,0)+IF(D12="L2L3",30,0)))),"i"),0) -> 0 | O12: Omregner P2 -> P1
D13: L1L2L3 | E13: 1 | F13: 1 | I13: 1 | J13: =IF(OR(D13="L1",D13="L1L2",D13="L3L1",D13="L1L2L3"),COMPLEX(E13*H13*F13*(COS(RADIANS(DEGREES(ACOS(I13))-IF(D13="L1L2",30,0)+IF(D13="L3L1",30,0)))),F13*E13*H13*(SIN(RADIANS(DEGREES(ACOS(I13))-IF(D13="L1L2",30,0)+IF(D13="L3L1",30,0)))),"i"),0) -> 0 | K13: =IF(OR(D13="L2",D13="L1L2",D13="L2L3",D13="L1L2L3"),COMPLEX(E13*H13*F13*(COS(RADIANS(DEGREES(ACOS(I13))-IF(D13="L2L3",30,0)+IF(D13="L1L2",30,0)))),F13*E13*H13*(SIN(RADIANS(DEGREES(ACOS(I13))-IF(D13="L2L3",30,0)+IF(D13="L1L2",30,0)))),"i"),0) -> 0 | L13: =IF(OR(D13="L3",D13="L3L1",D13="L2L3",D13="L1L2L3"),COMPLEX(E13*H13*F13*(COS(RADIANS(DEGREES(ACOS(I13))-IF(D13="L3L1",30,0)+IF(D13="L2L3",30,0)))),F13*E13*H13*(SIN(RADIANS(DEGREES(ACOS(I13))-IF(D13="L3L1",30,0)+IF(D13="L2L3",30,0)))),"i"),0) -> 0 | O13: P2 | P13: 18
D14: L1L2L3 | E14: 1 | F14: 1 | I14: 1 | J14: =IF(OR(D14="L1",D14="L1L2",D14="L3L1",D14="L1L2L3"),COMPLEX(E14*H14*F14*(COS(RADIANS(DEGREES(ACOS(I14))-IF(D14="L1L2",30,0)+IF(D14="L3L1",30,0)))),F14*E14*H14*(SIN(RADIANS(DEGREES(ACOS(I14))-IF(D14="L1L2",30,0)+IF(D14="L3L1",30,0)))),"i"),0) -> 0 | K14: =IF(OR(D14="L2",D14="L1L2",D14="L2L3",D14="L1L2L3"),COMPLEX(E14*H14*F14*(COS(RADIANS(DEGREES(ACOS(I14))-IF(D14="L2L3",30,0)+IF(D14="L1L2",30,0)))),F14*E14*H14*(SIN(RADIANS(DEGREES(ACOS(I14))-IF(D14="L2L3",30,0)+IF(D14="L1L2",30,0)))),"i"),0) -> 0 | L14: =IF(OR(D14="L3",D14="L3L1",D14="L2L3",D14="L1L2L3"),COMPLEX(E14*H14*F14*(COS(RADIANS(DEGREES(ACOS(I14))-IF(D14="L3L1",30,0)+IF(D14="L2L3",30,0)))),F14*E14*H14*(SIN(RADIANS(DEGREES(ACOS(I14))-IF(D14="L3L1",30,0)+IF(D14="L2L3",30,0)))),"i"),0) -> 0 | O14: Virkningsgrad η | P14: 0.8
D15: L1L2L3 | E15: 1 | F15: 1 | I15: 1 | J15: =IF(OR(D15="L1",D15="L1L2",D15="L3L1",D15="L1L2L3"),COMPLEX(E15*H15*F15*(COS(RADIANS(DEGREES(ACOS(I15))-IF(D15="L1L2",30,0)+IF(D15="L3L1",30,0)))),F15*E15*H15*(SIN(RADIANS(DEGREES(ACOS(I15))-IF(D15="L1L2",30,0)+IF(D15="L3L1",30,0)))),"i"),0) -> 0 | K15: =IF(OR(D15="L2",D15="L1L2",D15="L2L3",D15="L1L2L3"),COMPLEX(E15*H15*F15*(COS(RADIANS(DEGREES(ACOS(I15))-IF(D15="L2L3",30,0)+IF(D15="L1L2",30,0)))),F15*E15*H15*(SIN(RADIANS(DEGREES(ACOS(I15))-IF(D15="L2L3",30,0)+IF(D15="L1L2",30,0)))),"i"),0) -> 0 | L15: =IF(OR(D15="L3",D15="L3L1",D15="L2L3",D15="L1L2L3"),COMPLEX(E15*H15*F15*(COS(RADIANS(DEGREES(ACOS(I15))-IF(D15="L3L1",30,0)+IF(D15="L2L3",30,0)))),F15*E15*H15*(SIN(RADIANS(DEGREES(ACOS(I15))-IF(D15="L3L1",30,0)+IF(D15="L2L3",30,0)))),"i"),0) -> 0 | O15: P1 | P15: =P13/P14 -> 22.5
D16: L2 | E16: 1 | F16: 1 | I16: 1 | J16: =IF(OR(D16="L1",D16="L1L2",D16="L3L1",D16="L1L2L3"),COMPLEX(E16*H16*F16*(COS(RADIANS(DEGREES(ACOS(I16))-IF(D16="L1L2",30,0)+IF(D16="L3L1",30,0)))),F16*E16*H16*(SIN(RADIANS(DEGREES(ACOS(I16))-IF(D16="L1L2",30,0)+IF(D16="L3L1",30,0)))),"i"),0) -> 0 | K16: =IF(OR(D16="L2",D16="L1L2",D16="L2L3",D16="L1L2L3"),COMPLEX(E16*H16*F16*(COS(RADIANS(DEGREES(ACOS(I16))-IF(D16="L2L3",30,0)+IF(D16="L1L2",30,0)))),F16*E16*H16*(SIN(RADIANS(DEGREES(ACOS(I16))-IF(D16="L2L3",30,0)+IF(D16="L1L2",30,0)))),"i"),0) -> 0 | L16: =IF(OR(D16="L3",D16="L3L1",D16="L2L3",D16="L1L2L3"),COMPLEX(E16*H16*F16*(COS(RADIANS(DEGREES(ACOS(I16))-IF(D16="L3L1",30,0)+IF(D16="L2L3",30,0)))),F16*E16*H16*(SIN(RADIANS(DEGREES(ACOS(I16))-IF(D16="L3L1",30,0)+IF(D16="L2L3",30,0)))),"i"),0) -> 0
D17: L3 | E17: 1 | F17: 1 | I17: 1 | J17: =IF(OR(D17="L1",D17="L1L2",D17="L3L1",D17="L1L2L3"),COMPLEX(E17*H17*F17*(COS(RADIANS(DEGREES(ACOS(I17))-IF(D17="L1L2",30,0)+IF(D17="L3L1",30,0)))),F17*E17*H17*(SIN(RADIANS(DEGREES(ACOS(I17))-IF(D17="L1L2",30,0)+IF(D17="L3L1",30,0)))),"i"),0) -> 0 | K17: =IF(OR(D17="L2",D17="L1L2",D17="L2L3",D17="L1L2L3"),COMPLEX(E17*H17*F17*(COS(RADIANS(DEGREES(ACOS(I17))-IF(D17="L2L3",30,0)+IF(D17="L1L2",30,0)))),F17*E17*H17*(SIN(RADIANS(DEGREES(ACOS(I17))-IF(D17="L2L3",30,0)+IF(D17="L1L2",30,0)))),"i"),0) -> 0 | L17: =IF(OR(D17="L3",D17="L3L1",D17="L2L3",D17="L1L2L3"),COMPLEX(E17*H17*F17*(COS(RADIANS(DEGREES(ACOS(I17))-IF(D17="L3L1",30,0)+IF(D17="L2L3",30,0)))),F17*E17*H17*(SIN(RADIANS(DEGREES(ACOS(I17))-IF(D17="L3L1",30,0)+IF(D17="L2L3",30,0)))),"i"),0) -> 0
D18: L1 | E18: 1 | F18: 1 | I18: 1 | J18: =IF(OR(D18="L1",D18="L1L2",D18="L3L1",D18="L1L2L3"),COMPLEX(E18*H18*F18*(COS(RADIANS(DEGREES(ACOS(I18))-IF(D18="L1L2",30,0)+IF(D18="L3L1",30,0)))),F18*E18*H18*(SIN(RADIANS(DEGREES(ACOS(I18))-IF(D18="L1L2",30,0)+IF(D18="L3L1",30,0)))),"i"),0) -> 0 | K18: =IF(OR(D18="L2",D18="L1L2",D18="L2L3",D18="L1L2L3"),COMPLEX(E18*H18*F18*(COS(RADIANS(DEGREES(ACOS(I18))-IF(D18="L2L3",30,0)+IF(D18="L1L2",30,0)))),F18*E18*H18*(SIN(RADIANS(DEGREES(ACOS(I18))-IF(D18="L2L3",30,0)+IF(D18="L1L2",30,0)))),"i"),0) -> 0 | L18: =IF(OR(D18="L3",D18="L3L1",D18="L2L3",D18="L1L2L3"),COMPLEX(E18*H18*F18*(COS(RADIANS(DEGREES(ACOS(I18))-IF(D18="L3L1",30,0)+IF(D18="L2L3",30,0)))),F18*E18*H18*(SIN(RADIANS(DEGREES(ACOS(I18))-IF(D18="L3L1",30,0)+IF(D18="L2L3",30,0)))),"i"),0) -> 0 | O18: Omregn RX-forhold -> Vinkel
D19: L1L2L3 | E19: 1 | F19: 1 | I19: 1 | J19: =IF(OR(D19="L1",D19="L1L2",D19="L3L1",D19="L1L2L3"),COMPLEX(E19*H19*F19*(COS(RADIANS(DEGREES(ACOS(I19))-IF(D19="L1L2",30,0)+IF(D19="L3L1",30,0)))),F19*E19*H19*(SIN(RADIANS(DEGREES(ACOS(I19))-IF(D19="L1L2",30,0)+IF(D19="L3L1",30,0)))),"i"),0) -> 0 | K19: =IF(OR(D19="L2",D19="L1L2",D19="L2L3",D19="L1L2L3"),COMPLEX(E19*H19*F19*(COS(RADIANS(DEGREES(ACOS(I19))-IF(D19="L2L3",30,0)+IF(D19="L1L2",30,0)))),F19*E19*H19*(SIN(RADIANS(DEGREES(ACOS(I19))-IF(D19="L2L3",30,0)+IF(D19="L1L2",30,0)))),"i"),0) -> 0 | L19: =IF(OR(D19="L3",D19="L3L1",D19="L2L3",D19="L1L2L3"),COMPLEX(E19*H19*F19*(COS(RADIANS(DEGREES(ACOS(I19))-IF(D19="L3L1",30,0)+IF(D19="L2L3",30,0)))),F19*E19*H19*(SIN(RADIANS(DEGREES(ACOS(I19))-IF(D19="L3L1",30,0)+IF(D19="L2L3",30,0)))),"i"),0) -> 0 | O19: RX-forhold | P19: 0.3
E20: 1 | F20: 1 | I20: 1 | J20: =IF(OR(D20="L1",D20="L1L2",D20="L3L1",D20="L1L2L3"),COMPLEX(E20*H20*F20*(COS(RADIANS(DEGREES(ACOS(I20))-IF(D20="L1L2",30,0)+IF(D20="L3L1",30,0)))),F20*E20*H20*(SIN(RADIANS(DEGREES(ACOS(I20))-IF(D20="L1L2",30,0)+IF(D20="L3L1",30,0)))),"i"),0) -> 0 | K20: =IF(OR(D20="L2",D20="L1L2",D20="L2L3",D20="L1L2L3"),COMPLEX(E20*H20*F20*(COS(RADIANS(DEGREES(ACOS(I20))-IF(D20="L2L3",30,0)+IF(D20="L1L2",30,0)))),F20*E20*H20*(SIN(RADIANS(DEGREES(ACOS(I20))-IF(D20="L2L3",30,0)+IF(D20="L1L2",30,0)))),"i"),0) -> 0 | L20: =IF(OR(D20="L3",D20="L3L1",D20="L2L3",D20="L1L2L3"),COMPLEX(E20*H20*F20*(COS(RADIANS(DEGREES(ACOS(I20))-IF(D20="L3L1",30,0)+IF(D20="L2L3",30,0)))),F20*E20*H20*(SIN(RADIANS(DEGREES(ACOS(I20))-IF(D20="L3L1",30,0)+IF(D20="L2L3",30,0)))),"i"),0) -> 0 | O20: Vinkel | P20: =DEGREES(ATAN(1/P19)) -> 73.300756
E21: 1 | F21: 1 | I21: 1 | J21: =IF(OR(D21="L1",D21="L1L2",D21="L3L1",D21="L1L2L3"),COMPLEX(E21*H21*F21*(COS(RADIANS(DEGREES(ACOS(I21))-IF(D21="L1L2",30,0)+IF(D21="L3L1",30,0)))),F21*E21*H21*(SIN(RADIANS(DEGREES(ACOS(I21))-IF(D21="L1L2",30,0)+IF(D21="L3L1",30,0)))),"i"),0) -> 0 | K21: =IF(OR(D21="L2",D21="L1L2",D21="L2L3",D21="L1L2L3"),COMPLEX(E21*H21*F21*(COS(RADIANS(DEGREES(ACOS(I21))-IF(D21="L2L3",30,0)+IF(D21="L1L2",30,0)))),F21*E21*H21*(SIN(RADIANS(DEGREES(ACOS(I21))-IF(D21="L2L3",30,0)+IF(D21="L1L2",30,0)))),"i"),0) -> 0 | L21: =IF(OR(D21="L3",D21="L3L1",D21="L2L3",D21="L1L2L3"),COMPLEX(E21*H21*F21*(COS(RADIANS(DEGREES(ACOS(I21))-IF(D21="L3L1",30,0)+IF(D21="L2L3",30,0)))),F21*E21*H21*(SIN(RADIANS(DEGREES(ACOS(I21))-IF(D21="L3L1",30,0)+IF(D21="L2L3",30,0)))),"i"),0) -> 0
E22: 1 | F22: 1 | I22: 1 | J22: =IF(OR(D22="L1",D22="L1L2",D22="L3L1",D22="L1L2L3"),COMPLEX(E22*H22*F22*(COS(RADIANS(DEGREES(ACOS(I22))-IF(D22="L1L2",30,0)+IF(D22="L3L1",30,0)))),F22*E22*H22*(SIN(RADIANS(DEGREES(ACOS(I22))-IF(D22="L1L2",30,0)+IF(D22="L3L1",30,0)))),"i"),0) -> 0 | K22: =IF(OR(D22="L2",D22="L1L2",D22="L2L3",D22="L1L2L3"),COMPLEX(E22*H22*F22*(COS(RADIANS(DEGREES(ACOS(I22))-IF(D22="L2L3",30,0)+IF(D22="L1L2",30,0)))),F22*E22*H22*(SIN(RADIANS(DEGREES(ACOS(I22))-IF(D22="L2L3",30,0)+IF(D22="L1L2",30,0)))),"i"),0) -> 0 | L22: =IF(OR(D22="L3",D22="L3L1",D22="L2L3",D22="L1L2L3"),COMPLEX(E22*H22*F22*(COS(RADIANS(DEGREES(ACOS(I22))-IF(D22="L3L1",30,0)+IF(D22="L2L3",30,0)))),F22*E22*H22*(SIN(RADIANS(DEGREES(ACOS(I22))-IF(D22="L3L1",30,0)+IF(D22="L2L3",30,0)))),"i"),0) -> 0
E23: 1 | F23: 1 | I23: 1 | J23: =IF(OR(D23="L1",D23="L1L2",D23="L3L1",D23="L1L2L3"),COMPLEX(E23*H23*F23*(COS(RADIANS(DEGREES(ACOS(I23))-IF(D23="L1L2",30,0)+IF(D23="L3L1",30,0)))),F23*E23*H23*(SIN(RADIANS(DEGREES(ACOS(I23))-IF(D23="L1L2",30,0)+IF(D23="L3L1",30,0)))),"i"),0) -> 0 | K23: =IF(OR(D23="L2",D23="L1L2",D23="L2L3",D23="L1L2L3"),COMPLEX(E23*H23*F23*(COS(RADIANS(DEGREES(ACOS(I23))-IF(D23="L2L3",30,0)+IF(D23="L1L2",30,0)))),F23*E23*H23*(SIN(RADIANS(DEGREES(ACOS(I23))-IF(D23="L2L3",30,0)+IF(D23="L1L2",30,0)))),"i"),0) -> 0 | L23: =IF(OR(D23="L3",D23="L3L1",D23="L2L3",D23="L1L2L3"),COMPLEX(E23*H23*F23*(COS(RADIANS(DEGREES(ACOS(I23))-IF(D23="L3L1",30,0)+IF(D23="L2L3",30,0)))),F23*E23*H23*(SIN(RADIANS(DEGREES(ACOS(I23))-IF(D23="L3L1",30,0)+IF(D23="L2L3",30,0)))),"i"),0) -> 0
E24: 1 | F24: 1 | I24: 1 | J24: =IF(OR(D24="L1",D24="L1L2",D24="L3L1",D24="L1L2L3"),COMPLEX(E24*H24*F24*(COS(RADIANS(DEGREES(ACOS(I24))-IF(D24="L1L2",30,0)+IF(D24="L3L1",30,0)))),F24*E24*H24*(SIN(RADIANS(DEGREES(ACOS(I24))-IF(D24="L1L2",30,0)+IF(D24="L3L1",30,0)))),"i"),0) -> 0 | K24: =IF(OR(D24="L2",D24="L1L2",D24="L2L3",D24="L1L2L3"),COMPLEX(E24*H24*F24*(COS(RADIANS(DEGREES(ACOS(I24))-IF(D24="L2L3",30,0)+IF(D24="L1L2",30,0)))),F24*E24*H24*(SIN(RADIANS(DEGREES(ACOS(I24))-IF(D24="L2L3",30,0)+IF(D24="L1L2",30,0)))),"i"),0) -> 0 | L24: =IF(OR(D24="L3",D24="L3L1",D24="L2L3",D24="L1L2L3"),COMPLEX(E24*H24*F24*(COS(RADIANS(DEGREES(ACOS(I24))-IF(D24="L3L1",30,0)+IF(D24="L2L3",30,0)))),F24*E24*H24*(SIN(RADIANS(DEGREES(ACOS(I24))-IF(D24="L3L1",30,0)+IF(D24="L2L3",30,0)))),"i"),0) -> 0
E25: 1 | F25: 1 | I25: 1 | J25: =IF(OR(D25="L1",D25="L1L2",D25="L3L1",D25="L1L2L3"),COMPLEX(E25*H25*F25*(COS(RADIANS(DEGREES(ACOS(I25))-IF(D25="L1L2",30,0)+IF(D25="L3L1",30,0)))),F25*E25*H25*(SIN(RADIANS(DEGREES(ACOS(I25))-IF(D25="L1L2",30,0)+IF(D25="L3L1",30,0)))),"i"),0) -> 0 | K25: =IF(OR(D25="L2",D25="L1L2",D25="L2L3",D25="L1L2L3"),COMPLEX(E25*H25*F25*(COS(RADIANS(DEGREES(ACOS(I25))-IF(D25="L2L3",30,0)+IF(D25="L1L2",30,0)))),F25*E25*H25*(SIN(RADIANS(DEGREES(ACOS(I25))-IF(D25="L2L3",30,0)+IF(D25="L1L2",30,0)))),"i"),0) -> 0 | L25: =IF(OR(D25="L3",D25="L3L1",D25="L2L3",D25="L1L2L3"),COMPLEX(E25*H25*F25*(COS(RADIANS(DEGREES(ACOS(I25))-IF(D25="L3L1",30,0)+IF(D25="L2L3",30,0)))),F25*E25*H25*(SIN(RADIANS(DEGREES(ACOS(I25))-IF(D25="L3L1",30,0)+IF(D25="L2L3",30,0)))),"i"),0) -> 0
E26: 1 | F26: 1 | I26: 1 | J26: =IF(OR(D26="L1",D26="L1L2",D26="L3L1",D26="L1L2L3"),COMPLEX(E26*H26*F26*(COS(RADIANS(DEGREES(ACOS(I26))-IF(D26="L1L2",30,0)+IF(D26="L3L1",30,0)))),F26*E26*H26*(SIN(RADIANS(DEGREES(ACOS(I26))-IF(D26="L1L2",30,0)+IF(D26="L3L1",30,0)))),"i"),0) -> 0 | K26: =IF(OR(D26="L2",D26="L1L2",D26="L2L3",D26="L1L2L3"),COMPLEX(E26*H26*F26*(COS(RADIANS(DEGREES(ACOS(I26))-IF(D26="L2L3",30,0)+IF(D26="L1L2",30,0)))),F26*E26*H26*(SIN(RADIANS(DEGREES(ACOS(I26))-IF(D26="L2L3",30,0)+IF(D26="L1L2",30,0)))),"i"),0) -> 0 | L26: =IF(OR(D26="L3",D26="L3L1",D26="L2L3",D26="L1L2L3"),COMPLEX(E26*H26*F26*(COS(RADIANS(DEGREES(ACOS(I26))-IF(D26="L3L1",30,0)+IF(D26="L2L3",30,0)))),F26*E26*H26*(SIN(RADIANS(DEGREES(ACOS(I26))-IF(D26="L3L1",30,0)+IF(D26="L2L3",30,0)))),"i"),0) -> 0
E27: 1 | F27: 1 | I27: 1 | J27: =IF(OR(D27="L1",D27="L1L2",D27="L3L1",D27="L1L2L3"),COMPLEX(E27*H27*F27*(COS(RADIANS(DEGREES(ACOS(I27))-IF(D27="L1L2",30,0)+IF(D27="L3L1",30,0)))),F27*E27*H27*(SIN(RADIANS(DEGREES(ACOS(I27))-IF(D27="L1L2",30,0)+IF(D27="L3L1",30,0)))),"i"),0) -> 0 | K27: =IF(OR(D27="L2",D27="L1L2",D27="L2L3",D27="L1L2L3"),COMPLEX(E27*H27*F27*(COS(RADIANS(DEGREES(ACOS(I27))-IF(D27="L2L3",30,0)+IF(D27="L1L2",30,0)))),F27*E27*H27*(SIN(RADIANS(DEGREES(ACOS(I27))-IF(D27="L2L3",30,0)+IF(D27="L1L2",30,0)))),"i"),0) -> 0 | L27: =IF(OR(D27="L3",D27="L3L1",D27="L2L3",D27="L1L2L3"),COMPLEX(E27*H27*F27*(COS(RADIANS(DEGREES(ACOS(I27))-IF(D27="L3L1",30,0)+IF(D27="L2L3",30,0)))),F27*E27*H27*(SIN(RADIANS(DEGREES(ACOS(I27))-IF(D27="L3L1",30,0)+IF(D27="L2L3",30,0)))),"i"),0) -> 0
E28: 1 | F28: 1 | I28: 1 | J28: =IF(OR(D28="L1",D28="L1L2",D28="L3L1",D28="L1L2L3"),COMPLEX(E28*H28*F28*(COS(RADIANS(DEGREES(ACOS(I28))-IF(D28="L1L2",30,0)+IF(D28="L3L1",30,0)))),F28*E28*H28*(SIN(RADIANS(DEGREES(ACOS(I28))-IF(D28="L1L2",30,0)+IF(D28="L3L1",30,0)))),"i"),0) -> 0 | K28: =IF(OR(D28="L2",D28="L1L2",D28="L2L3",D28="L1L2L3"),COMPLEX(E28*H28*F28*(COS(RADIANS(DEGREES(ACOS(I28))-IF(D28="L2L3",30,0)+IF(D28="L1L2",30,0)))),F28*E28*H28*(SIN(RADIANS(DEGREES(ACOS(I28))-IF(D28="L2L3",30,0)+IF(D28="L1L2",30,0)))),"i"),0) -> 0 | L28: =IF(OR(D28="L3",D28="L3L1",D28="L2L3",D28="L1L2L3"),COMPLEX(E28*H28*F28*(COS(RADIANS(DEGREES(ACOS(I28))-IF(D28="L3L1",30,0)+IF(D28="L2L3",30,0)))),F28*E28*H28*(SIN(RADIANS(DEGREES(ACOS(I28))-IF(D28="L3L1",30,0)+IF(D28="L2L3",30,0)))),"i"),0) -> 0
C29: ©Lasse Klein - www.dokuteknik.dk
C30: Herfra og ned er de belastninger hvor effekten i kW er oplyst
C31: Beskrivelse | D31: Vælg belastede Fase/Faser | E31: Samtidighedsfaktor | F31: Antal | G31: Effekt [kW] | H31: Strøm [A] | I31: Cos phi | J31: Resultat L1 Kompleks | K31: Resultat L2 Kompleks | L31: Resultat L3 Kompleks
D32: L1L2 | E32: 1 | F32: 1 | H32: =(G32*1000)/_xlfn.IFS(D32="L1L2L3",(400*SQRT(3)*I32),OR(D32="L1",D32="L2",D32="L3"),(230*I32),OR(D32="L1L2",D32="L2L3",D32="L3L1"),(400*I32)) -> 0 | I32: 1 | J32: =IF(OR(D32="L1",D32="L1L2",D32="L3L1",D32="L1L2L3"),COMPLEX(E32*H32*F32*(COS(RADIANS(DEGREES(ACOS(I32))-IF(D32="L1L2",30,0)+IF(D32="L3L1",30,0)))),F32*E32*H32*(SIN(RADIANS(DEGREES(ACOS(I32))-IF(D32="L1L2",30,0)+IF(D32="L3L1",30,0)))),"i"),0) -> 0 | K32: =IF(OR(D32="L2",D32="L1L2",D32="L2L3",D32="L1L2L3"),COMPLEX(E32*H32*F32*(COS(RADIANS(DEGREES(ACOS(I32))-IF(D32="L2L3",30,0)+IF(D32="L1L2",30,0)))),F32*E32*H32*(SIN(RADIANS(DEGREES(ACOS(I32))-IF(D32="L2L3",30,0)+IF(D32="L1L2",30,0)))),"i"),0) -> 0 | L32: =IF(OR(D32="L3",D32="L3L1",D32="L2L3",D32="L1L2L3"),COMPLEX(E32*H32*F32*(COS(RADIANS(DEGREES(ACOS(I32))-IF(D32="L3L1",30,0)+IF(D32="L2L3",30,0)))),F32*E32*H32*(SIN(RADIANS(DEGREES(ACOS(I32))-IF(D32="L3L1",30,0)+IF(D32="L2L3",30,0)))),"i"),0) -> 0
D33: L1L2L3 | E33: 1 | F33: 1 | H33: =(G33*1000)/_xlfn.IFS(D33="L1L2L3",(400*SQRT(3)*I33),OR(D33="L1",D33="L2",D33="L3"),(230*I33),OR(D33="L1L2",D33="L2L3",D33="L3L1"),(400*I33)) -> 0 | I33: 1 | J33: =IF(OR(D33="L1",D33="L1L2",D33="L3L1",D33="L1L2L3"),COMPLEX(E33*H33*F33*(COS(RADIANS(DEGREES(ACOS(I33))-IF(D33="L1L2",30,0)+IF(D33="L3L1",30,0)))),F33*E33*H33*(SIN(RADIANS(DEGREES(ACOS(I33))-IF(D33="L1L2",30,0)+IF(D33="L3L1",30,0)))),"i"),0) -> 0 | K33: =IF(OR(D33="L2",D33="L1L2",D33="L2L3",D33="L1L2L3"),COMPLEX(E33*H33*F33*(COS(RADIANS(DEGREES(ACOS(I33))-IF(D33="L2L3",30,0)+IF(D33="L1L2",30,0)))),F33*E33*H33*(SIN(RADIANS(DEGREES(ACOS(I33))-IF(D33="L2L3",30,0)+IF(D33="L1L2",30,0)))),"i"),0) -> 0 | L33: =IF(OR(D33="L3",D33="L3L1",D33="L2L3",D33="L1L2L3"),COMPLEX(E33*H33*F33*(COS(RADIANS(DEGREES(ACOS(I33))-IF(D33="L3L1",30,0)+IF(D33="L2L3",30,0)))),F33*E33*H33*(SIN(RADIANS(DEGREES(ACOS(I33))-IF(D33="L3L1",30,0)+IF(D33="L2L3",30,0)))),"i"),0) -> 0
D34: L1L2L3 | E34: 1 | F34: 1 | H34: =(G34*1000)/_xlfn.IFS(D34="L1L2L3",(400*SQRT(3)*I34),OR(D34="L1",D34="L2",D34="L3"),(230*I34),OR(D34="L1L2",D34="L2L3",D34="L3L1"),(400*I34)) -> 0 | I34: 1 | J34: =IF(OR(D34="L1",D34="L1L2",D34="L3L1",D34="L1L2L3"),COMPLEX(E34*H34*F34*(COS(RADIANS(DEGREES(ACOS(I34))-IF(D34="L1L2",30,0)+IF(D34="L3L1",30,0)))),F34*E34*H34*(SIN(RADIANS(DEGREES(ACOS(I34))-IF(D34="L1L2",30,0)+IF(D34="L3L1",30,0)))),"i"),0) -> 0 | K34: =IF(OR(D34="L2",D34="L1L2",D34="L2L3",D34="L1L2L3"),COMPLEX(E34*H34*F34*(COS(RADIANS(DEGREES(ACOS(I34))-IF(D34="L2L3",30,0)+IF(D34="L1L2",30,0)))),F34*E34*H34*(SIN(RADIANS(DEGREES(ACOS(I34))-IF(D34="L2L3",30,0)+IF(D34="L1L2",30,0)))),"i"),0) -> 0 | L34: =IF(OR(D34="L3",D34="L3L1",D34="L2L3",D34="L1L2L3"),COMPLEX(E34*H34*F34*(COS(RADIANS(DEGREES(ACOS(I34))-IF(D34="L3L1",30,0)+IF(D34="L2L3",30,0)))),F34*E34*H34*(SIN(RADIANS(DEGREES(ACOS(I34))-IF(D34="L3L1",30,0)+IF(D34="L2L3",30,0)))),"i"),0) -> 0
D35: L1L2L3 | E35: 1 | F35: 1 | H35: =(G35*1000)/_xlfn.IFS(D35="L1L2L3",(400*SQRT(3)*I35),OR(D35="L1",D35="L2",D35="L3"),(230*I35),OR(D35="L1L2",D35="L2L3",D35="L3L1"),(400*I35)) -> 0 | I35: 1 | J35: =IF(OR(D35="L1",D35="L1L2",D35="L3L1",D35="L1L2L3"),COMPLEX(E35*H35*F35*(COS(RADIANS(DEGREES(ACOS(I35))-IF(D35="L1L2",30,0)+IF(D35="L3L1",30,0)))),F35*E35*H35*(SIN(RADIANS(DEGREES(ACOS(I35))-IF(D35="L1L2",30,0)+IF(D35="L3L1",30,0)))),"i"),0) -> 0 | K35: =IF(OR(D35="L2",D35="L1L2",D35="L2L3",D35="L1L2L3"),COMPLEX(E35*H35*F35*(COS(RADIANS(DEGREES(ACOS(I35))-IF(D35="L2L3",30,0)+IF(D35="L1L2",30,0)))),F35*E35*H35*(SIN(RADIANS(DEGREES(ACOS(I35))-IF(D35="L2L3",30,0)+IF(D35="L1L2",30,0)))),"i"),0) -> 0 | L35: =IF(OR(D35="L3",D35="L3L1",D35="L2L3",D35="L1L2L3"),COMPLEX(E35*H35*F35*(COS(RADIANS(DEGREES(ACOS(I35))-IF(D35="L3L1",30,0)+IF(D35="L2L3",30,0)))),F35*E35*H35*(SIN(RADIANS(DEGREES(ACOS(I35))-IF(D35="L3L1",30,0)+IF(D35="L2L3",30,0)))),"i"),0) -> 0
D36: L1L2L3 | E36: 1 | F36: 1 | H36: =(G36*1000)/_xlfn.IFS(D36="L1L2L3",(400*SQRT(3)*I36),OR(D36="L1",D36="L2",D36="L3"),(230*I36),OR(D36="L1L2",D36="L2L3",D36="L3L1"),(400*I36)) -> 0 | I36: 1 | J36: =IF(OR(D36="L1",D36="L1L2",D36="L3L1",D36="L1L2L3"),COMPLEX(E36*H36*F36*(COS(RADIANS(DEGREES(ACOS(I36))-IF(D36="L1L2",30,0)+IF(D36="L3L1",30,0)))),F36*E36*H36*(SIN(RADIANS(DEGREES(ACOS(I36))-IF(D36="L1L2",30,0)+IF(D36="L3L1",30,0)))),"i"),0) -> 0 | K36: =IF(OR(D36="L2",D36="L1L2",D36="L2L3",D36="L1L2L3"),COMPLEX(E36*H36*F36*(COS(RADIANS(DEGREES(ACOS(I36))-IF(D36="L2L3",30,0)+IF(D36="L1L2",30,0)))),F36*E36*H36*(SIN(RADIANS(DEGREES(ACOS(I36))-IF(D36="L2L3",30,0)+IF(D36="L1L2",30,0)))),"i"),0) -> 0 | L36: =IF(OR(D36="L3",D36="L3L1",D36="L2L3",D36="L1L2L3"),COMPLEX(E36*H36*F36*(COS(RADIANS(DEGREES(ACOS(I36))-IF(D36="L3L1",30,0)+IF(D36="L2L3",30,0)))),F36*E36*H36*(SIN(RADIANS(DEGREES(ACOS(I36))-IF(D36="L3L1",30,0)+IF(D36="L2L3",30,0)))),"i"),0) -> 0
D37: L1L2L3 | E37: 1 | F37: 1 | H37: =(G37*1000)/_xlfn.IFS(D37="L1L2L3",(400*SQRT(3)*I37),OR(D37="L1",D37="L2",D37="L3"),(230*I37),OR(D37="L1L2",D37="L2L3",D37="L3L1"),(400*I37)) -> 0 | I37: 1 | J37: =IF(OR(D37="L1",D37="L1L2",D37="L3L1",D37="L1L2L3"),COMPLEX(E37*H37*F37*(COS(RADIANS(DEGREES(ACOS(I37))-IF(D37="L1L2",30,0)+IF(D37="L3L1",30,0)))),F37*E37*H37*(SIN(RADIANS(DEGREES(ACOS(I37))-IF(D37="L1L2",30,0)+IF(D37="L3L1",30,0)))),"i"),0) -> 0 | K37: =IF(OR(D37="L2",D37="L1L2",D37="L2L3",D37="L1L2L3"),COMPLEX(E37*H37*F37*(COS(RADIANS(DEGREES(ACOS(I37))-IF(D37="L2L3",30,0)+IF(D37="L1L2",30,0)))),F37*E37*H37*(SIN(RADIANS(DEGREES(ACOS(I37))-IF(D37="L2L3",30,0)+IF(D37="L1L2",30,0)))),"i"),0) -> 0 | L37: =IF(OR(D37="L3",D37="L3L1",D37="L2L3",D37="L1L2L3"),COMPLEX(E37*H37*F37*(COS(RADIANS(DEGREES(ACOS(I37))-IF(D37="L3L1",30,0)+IF(D37="L2L3",30,0)))),F37*E37*H37*(SIN(RADIANS(DEGREES(ACOS(I37))-IF(D37="L3L1",30,0)+IF(D37="L2L3",30,0)))),"i"),0) -> 0
D38: L1L2L3 | E38: 1 | F38: 1 | H38: =(G38*1000)/_xlfn.IFS(D38="L1L2L3",(400*SQRT(3)*I38),OR(D38="L1",D38="L2",D38="L3"),(230*I38),OR(D38="L1L2",D38="L2L3",D38="L3L1"),(400*I38)) -> 0 | I38: 1 | J38: =IF(OR(D38="L1",D38="L1L2",D38="L3L1",D38="L1L2L3"),COMPLEX(E38*H38*F38*(COS(RADIANS(DEGREES(ACOS(I38))-IF(D38="L1L2",30,0)+IF(D38="L3L1",30,0)))),F38*E38*H38*(SIN(RADIANS(DEGREES(ACOS(I38))-IF(D38="L1L2",30,0)+IF(D38="L3L1",30,0)))),"i"),0) -> 0 | K38: =IF(OR(D38="L2",D38="L1L2",D38="L2L3",D38="L1L2L3"),COMPLEX(E38*H38*F38*(COS(RADIANS(DEGREES(ACOS(I38))-IF(D38="L2L3",30,0)+IF(D38="L1L2",30,0)))),F38*E38*H38*(SIN(RADIANS(DEGREES(ACOS(I38))-IF(D38="L2L3",30,0)+IF(D38="L1L2",30,0)))),"i"),0) -> 0 | L38: =IF(OR(D38="L3",D38="L3L1",D38="L2L3",D38="L1L2L3"),COMPLEX(E38*H38*F38*(COS(RADIANS(DEGREES(ACOS(I38))-IF(D38="L3L1",30,0)+IF(D38="L2L3",30,0)))),F38*E38*H38*(SIN(RADIANS(DEGREES(ACOS(I38))-IF(D38="L3L1",30,0)+IF(D38="L2L3",30,0)))),"i"),0) -> 0
C39: © Lasse Klein - www.dokuteknik.dk
C40: Herfra og ned er de belastninger hvor den tilsyneladende effekt i kVA er oplyst
C41: Beskrivelse | D41: Vælg belastede Fase/Faser | E41: Samtidighedsfaktor | F41: Antal | G41: Effekt [kVA] | H41: Strøm [A] | I41: Cos phi | J41: Resultat L1 Kompleks | K41: Resultat L2 Kompleks | L41: Resultat L3 Kompleks
...

Sheet Overblik
B2: Beskrivelse | C2: L1 | D2: L2 | E2: L3
B3: =IF(Beregninger!C5=0,"",Beregninger!C5) | C3: =IF(OR(Beregninger!H5=0,Beregninger!J5=0,Beregninger!F5=0),"",CONCATENATE(IMABS(Beregninger!J5),"A"," ∠",ROUND(DEGREES(-IMARGUMENT(Beregninger!J5)),2))) | D3: =IF(OR(Beregninger!H5=0,Beregninger!K5=0),"",CONCATENATE(IMABS(Beregninger!K5),"A"," ∠",ROUND(DEGREES(-IMARGUMENT(Beregninger!K5)),2))) | E3: =IF(OR(Beregninger!H5=0,Beregninger!L5=0),"",CONCATENATE(IMABS(Beregninger!L5),"A"," ∠",ROUND(DEGREES(-IMARGUMENT(Beregninger!L5)),2)))
B4: =IF(Beregninger!C6=0,"",Beregninger!C6) | C4: =IF(OR(Beregninger!H6=0,Beregninger!J6=0,Beregninger!F6=0),"",CONCATENATE(IMABS(Beregninger!J6),"A"," ∠",ROUND(DEGREES(-IMARGUMENT(Beregninger!J6)),2))) | D4: =IF(OR(Beregninger!H6=0,Beregninger!K6=0),"",CONCATENATE(IMABS(Beregninger!K6),"A"," ∠",ROUND(DEGREES(-IMARGUMENT(Beregninger!K6)),2))) | E4: =IF(OR(Beregninger!H6=0,Beregninger!L6=0),"",CONCATENATE(IMABS(Beregninger!L6),"A"," ∠",ROUND(DEGREES(-IMARGUMENT(Beregninger!L6)),2)))
B5: =IF(Beregninger!C7=0,"",Beregninger!C7) | C5: =IF(OR(Beregninger!H7=0,Beregninger!J7=0,Beregninger!F7=0),"",CONCATENATE(IMABS(Beregninger!J7),"A"," ∠",ROUND(DEGREES(-IMARGUMENT(Beregninger!J7)),2))) | D5: =IF(OR(Beregninger!H7=0,Beregninger!K7=0),"",CONCATENATE(IMABS(Beregninger!K7),"A"," ∠",ROUND(DEGREES(-IMARGUMENT(Beregninger!K7)),2))) | E5: =IF(OR(Beregninger!H7=0,Beregninger!L7=0),"",CONCATENATE(IMABS(Beregninger!L7),"A"," ∠",ROUND(DEGREES(-IMARGUMENT(Beregninger!L7)),2)))
B6: =IF(Beregninger!C8=0,"",Beregninger!C8) | C6: =IF(OR(Beregninger!H8=0,Beregninger!J8=0,Beregninger!F8=0),"",CONCATENATE(IMABS(Beregninger!J8),"A"," ∠",ROUND(DEGREES(-IMARGUMENT(Beregninger!J8)),2))) | D6: =IF(OR(Beregninger!H8=0,Beregninger!K8=0),"",CONCATENATE(IMABS(Beregninger!K8),"A"," ∠",ROUND(DEGREES(-IMARGUMENT(Beregninger!K8)),2))) | E6: =IF(OR(Beregninger!H8=0,Beregninger!L8=0),"",CONCATENATE(IMABS(Beregninger!L8),"A"," ∠",ROUND(DEGREES(-IMARGUMENT(Beregninger!L8)),2)))
B7: =IF(Beregninger!C9=0,"",Beregninger!C9) | C7: =IF(OR(Beregninger!H9=0,Beregninger!J9=0,Beregninger!F9=0),"",CONCATENATE(IMABS(Beregninger!J9),"A"," ∠",ROUND(DEGREES(-IMARGUMENT(Beregninger!J9)),2))) | D7: =IF(OR(Beregninger!H9=0,Beregninger!K9=0),"",CONCATENATE(IMABS(Beregninger!K9),"A"," ∠",ROUND(DEGREES(-IMARGUMENT(Beregninger!K9)),2))) | E7: =IF(OR(Beregninger!H9=0,Beregninger!L9=0),"",CONCATENATE(IMABS(Beregninger!L9),"A"," ∠",ROUND(DEGREES(-IMARGUMENT(Beregninger!L9)),2)))
B8: =IF(Beregninger!C10=0,"",Beregninger!C10) | C8: =IF(OR(Beregninger!H10=0,Beregninger!J10=0,Beregninger!F10=0),"",CONCATENATE(IMABS(Beregninger!J10),"A"," ∠",ROUND(DEGREES(-IMARGUMENT(Beregninger!J10)),2))) | D8: =IF(OR(Beregninger!H10=0,Beregninger!K10=0),"",CONCATENATE(IMABS(Beregninger!K10),"A"," ∠",ROUND(DEGREES(-IMARGUMENT(Beregninger!K10)),2))) | E8: =IF(OR(Beregninger!H10=0,Beregninger!L10=0),"",CONCATENATE(IMABS(Beregninger!L10),"A"," ∠",ROUND(DEGREES(-IMARGUMENT(Beregninger!L10)),2)))
B9: =IF(Beregninger!C11=0,"",Beregninger!C11) | C9: =IF(OR(Beregninger!H11=0,Beregninger!J11=0,Beregninger!F11=0),"",CONCATENATE(IMABS(Beregninger!J11),"A"," ∠",ROUND(DEGREES(-IMARGUMENT(Beregninger!J11)),2))) | D9: =IF(OR(Beregninger!H11=0,Beregninger!K11=0),"",CONCATENATE(IMABS(Beregninger!K11),"A"," ∠",ROUND(DEGREES(-IMARGUMENT(Beregninger!K11)),2))) | E9: =IF(OR(Beregninger!H11=0,Beregninger!L11=0),"",CONCATENATE(IMABS(Beregninger!L11),"A"," ∠",ROUND(DEGREES(-IMARGUMENT(Beregninger!L11)),2)))
B10: =IF(Beregninger!C12=0,"",Beregninger!C12) | C10: =IF(OR(Beregninger!H12=0,Beregninger!J12=0,Beregninger!F12=0),"",CONCATENATE(IMABS(Beregninger!J12),"A"," ∠",ROUND(DEGREES(-IMARGUMENT(Beregninger!J12)),2))) | D10: =IF(OR(Beregninger!H12=0,Beregninger!K12=0),"",CONCATENATE(IMABS(Beregninger!K12),"A"," ∠",ROUND(DEGREES(-IMARGUMENT(Beregninger!K12)),2))) | E10: =IF(OR(Beregninger!H12=0,Beregninger!L12=0),"",CONCATENATE(IMABS(Beregninger!L12),"A"," ∠",ROUND(DEGREES(-IMARGUMENT(Beregninger!L12)),2)))
B11: =IF(Beregninger!C13=0,"",Beregninger!C13) | C11: =IF(OR(Beregninger!H13=0,Beregninger!J13=0,Beregninger!F13=0),"",CONCATENATE(IMABS(Beregninger!J13),"A"," ∠",ROUND(DEGREES(-IMARGUMENT(Beregninger!J13)),2))) | D11: =IF(OR(Beregninger!H13=0,Beregninger!K13=0),"",CONCATENATE(IMABS(Beregninger!K13),"A"," ∠",ROUND(DEGREES(-IMARGUMENT(Beregninger!K13)),2))) | E11: =IF(OR(Beregninger!H13=0,Beregninger!L13=0),"",CONCATENATE(IMABS(Beregninger!L13),"A"," ∠",ROUND(DEGREES(-IMARGUMENT(Beregninger!L13)),2)))
B12: =IF(Beregninger!C14=0,"",Beregninger!C14) | C12: =IF(OR(Beregninger!H14=0,Beregninger!J14=0,Beregninger!F14=0),"",CONCATENATE(IMABS(Beregninger!J14),"A"," ∠",ROUND(DEGREES(-IMARGUMENT(Beregninger!J14)),2))) | D12: =IF(OR(Beregninger!H14=0,Beregninger!K14=0),"",CONCATENATE(IMABS(Beregninger!K14),"A"," ∠",ROUND(DEGREES(-IMARGUMENT(Beregninger!K14)),2))) | E12: =IF(OR(Beregninger!H14=0,Beregninger!L14=0),"",CONCATENATE(IMABS(Beregninger!L14),"A"," ∠",ROUND(DEGREES(-IMARGUMENT(Beregninger!L14)),2)))
B13: =IF(Beregninger!C15=0,"",Beregninger!C15) | C13: =IF(OR(Beregninger!H15=0,Beregninger!J15=0,Beregninger!F15=0),"",CONCATENATE(IMABS(Beregninger!J15),"A"," ∠",ROUND(DEGREES(-IMARGUMENT(Beregninger!J15)),2))) | D13: =IF(OR(Beregninger!H15=0,Beregninger!K15=0),"",CONCATENATE(IMABS(Beregninger!K15),"A"," ∠",ROUND(DEGREES(-IMARGUMENT(Beregninger!K15)),2))) | E13: =IF(OR(Beregninger!H15=0,Beregninger!L15=0),"",CONCATENATE(IMABS(Beregninger!L15),"A"," ∠",ROUND(DEGREES(-IMARGUMENT(Beregninger!L15)),2)))
B14: =IF(Beregninger!C16=0,"",Beregninger!C16) | C14: =IF(OR(Beregninger!H16=0,Beregninger!J16=0,Beregninger!F16=0),"",CONCATENATE(IMABS(Beregninger!J16),"A"," ∠",ROUND(DEGREES(-IMARGUMENT(Beregninger!J16)),2))) | D14: =IF(OR(Beregninger!H16=0,Beregninger!K16=0),"",CONCATENATE(IMABS(Beregninger!K16),"A"," ∠",ROUND(DEGREES(-IMARGUMENT(Beregninger!K16)),2))) | E14: =IF(OR(Beregninger!H16=0,Beregninger!L16=0),"",CONCATENATE(IMABS(Beregninger!L16),"A"," ∠",ROUND(DEGREES(-IMARGUMENT(Beregninger!L16)),2)))
... B26: =IF(Beregninger!C28=0,"",Beregninger!C28) | C26: =IF(OR(Beregninger!H28=0,Beregninger!J28=0,Beregninger!F28=0),"",CONCATENATE(IMABS(Beregninger!J28),"A"," ∠",ROUND(DEGREES(-IMARGUMENT(Beregninger!J28)),2))) | D26: =IF(OR(Beregninger!H28=0,Beregninger!K28=0),"",CONCATENATE(IMABS(Beregninger!K28),"A"," ∠",ROUND(DEGREES(-IMARGUMENT(Beregninger!K28)),2))) | E26: =IF(OR(Beregninger!H28=0,Beregninger!L28=0),"",CONCATENATE(IMABS(Beregninger!L28),"A"," ∠",ROUND(DEGREES(-IMARGUMENT(Beregninger!L28)),2)))
B27: =IF(Beregninger!C32=0,"",Beregninger!C32) | C27: =IF(OR(Beregninger!G32=0,Beregninger!J32=0,Beregninger!F32=0),"",CONCATENATE(ROUND(IMABS(Beregninger!J32),2),"A"," ∠",ROUND(DEGREES(-IMARGUMENT(Beregninger!J32)),2))) | D27: =IF(OR(Beregninger!G32=0,Beregninger!K32=0,Beregninger!F32=0),"",CONCATENATE(ROUND(IMABS(Beregninger!K32),2),"A"," ∠",ROUND(DEGREES(-IMARGUMENT(Beregninger!K32)),2))) | E27: =IF(OR(Beregninger!G32=0,Beregninger!L32=0,Beregninger!F32=0),"",CONCATENATE(ROUND(IMABS(Beregninger!L32),2),"A"," ∠",ROUND(DEGREES(-IMARGUMENT(Beregninger!L32)),2)))
B28: =IF(Beregninger!C33=0,"",Beregninger!C33) | C28: =IF(OR(Beregninger!G33=0,Beregninger!J33=0,Beregninger!F33=0),"",CONCATENATE(ROUND(IMABS(Beregninger!J33),2),"A"," ∠",ROUND(DEGREES(-IMARGUMENT(Beregninger!J33)),2))) | D28: =IF(OR(Beregninger!G33=0,Beregninger!K33=0,Beregninger!F33=0),"",CONCATENATE(ROUND(IMABS(Beregninger!K33),2),"A"," ∠",ROUND(DEGREES(-IMARGUMENT(Beregninger!K33)),2))) | E28: =IF(OR(Beregninger!G33=0,Beregninger!L33=0,Beregninger!F33=0),"",CONCATENATE(ROUND(IMABS(Beregninger!L33),2),"A"," ∠",ROUND(DEGREES(-IMARGUMENT(Beregninger!L33)),2)))
B29: =IF(Beregninger!C34=0,"",Beregninger!C34) | C29: =IF(OR(Beregninger!G34=0,Beregninger!J34=0,Beregninger!F34=0),"",CONCATENATE(ROUND(IMABS(Beregninger!J34),2),"A"," ∠",ROUND(DEGREES(-IMARGUMENT(Beregninger!J34)),2))) | D29: =IF(OR(Beregninger!G34=0,Beregninger!K34=0,Beregninger!F34=0),"",CONCATENATE(ROUND(IMABS(Beregninger!K34),2),"A"," ∠",ROUND(DEGREES(-IMARGUMENT(Beregninger!K34)),2))) | E29: =IF(OR(Beregninger!G34=0,Beregninger!L34=0,Beregninger!F34=0),"",CONCATENATE(ROUND(IMABS(Beregninger!L34),2),"A"," ∠",ROUND(DEGREES(-IMARGUMENT(Beregninger!L34)),2)))
B30: =IF(Beregninger!C35=0,"",Beregninger!C35) | C30: =IF(OR(Beregninger!G35=0,Beregninger!J35=0,Beregninger!F35=0),"",CONCATENATE(ROUND(IMABS(Beregninger!J35),2),"A"," ∠",ROUND(DEGREES(-IMARGUMENT(Beregninger!J35)),2))) | D30: =IF(OR(Beregninger!G35=0,Beregninger!K35=0,Beregninger!F35=0),"",CONCATENATE(ROUND(IMABS(Beregninger!K35),2),"A"," ∠",ROUND(DEGREES(-IMARGUMENT(Beregninger!K35)),2))) | E30: =IF(OR(Beregninger!G35=0,Beregninger!L35=0,Beregninger!F35=0),"",CONCATENATE(ROUND(IMABS(Beregninger!L35),2),"A"," ∠",ROUND(DEGREES(-IMARGUMENT(Beregninger!L35)),2)))
B31: =IF(Beregninger!C36=0,"",Beregninger!C36) | C31: =IF(OR(Beregninger!G36=0,Beregninger!J36=0,Beregninger!F36=0),"",CONCATENATE(ROUND(IMABS(Beregninger!J36),2),"A"," ∠",ROUND(DEGREES(-IMARGUMENT(Beregninger!J36)),2))) | D31: =IF(OR(Beregninger!G36=0,Beregninger!K36=0,Beregninger!F36=0),"",CONCATENATE(ROUND(IMABS(Beregninger!K36),2),"A"," ∠",ROUND(DEGREES(-IMARGUMENT(Beregninger!K36)),2))) | E31: =IF(OR(Beregninger!G36=0,Beregninger!L36=0,Beregninger!F36=0),"",CONCATENATE(ROUND(IMABS(Beregninger!L36),2),"A"," ∠",ROUND(DEGREES(-IMARGUMENT(Beregninger!L36)),2)))
B32: =IF(Beregninger!C37=0,"",Beregninger!C37) | C32: =IF(OR(Beregninger!G37=0,Beregninger!J37=0,Beregninger!F37=0),"",CONCATENATE(ROUND(IMABS(Beregninger!J37),2),"A"," ∠",ROUND(DEGREES(-IMARGUMENT(Beregninger!J37)),2))) | D32: =IF(OR(Beregninger!G37=0,Beregninger!K37=0,Beregninger!F37=0),"",CONCATENATE(ROUND(IMABS(Beregninger!K37),2),"A"," ∠",ROUND(DEGREES(-IMARGUMENT(Beregninger!K37)),2))) | E32: =IF(OR(Beregninger!G37=0,Beregninger!L37=0,Beregninger!F37=0),"",CONCATENATE(ROUND(IMABS(Beregninger!L37),2),"A"," ∠",ROUND(DEGREES(-IMARGUMENT(Beregninger!L37)),2)))
B33: =IF(Beregninger!C38=0,"",Beregninger!C38) | C33: =IF(OR(Beregninger!G38=0,Beregninger!J38=0,Beregninger!F38=0),"",CONCATENATE(ROUND(IMABS(Beregninger!J38),2),"A"," ∠",ROUND(DEGREES(-IMARGUMENT(Beregninger!J38)),2))) | D33: =IF(OR(Beregninger!G38=0,Beregninger!K38=0,Beregninger!F38=0),"",CONCATENATE(ROUND(IMABS(Beregninger!K38),2),"A"," ∠",ROUND(DEGREES(-IMARGUMENT(Beregninger!K38)),2))) | E33: =IF(OR(Beregninger!G38=0,Beregninger!L38=0,Beregninger!F38=0),"",CONCATENATE(ROUND(IMABS(Beregninger!L38),2),"A"," ∠",ROUND(DEGREES(-IMARGUMENT(Beregninger!L38)),2)))
B34: =IF(Beregninger!C42=0,"",Beregninger!C42) | C34: =IF(OR(Beregninger!G42=0,Beregninger!J42=0,Beregninger!F42=0),"",CONCATENATE(ROUND(IMABS(Beregninger!J42),2),"A"," ∠",ROUND(DEGREES(-IMARGUMENT(Beregninger!J42)),2))) | D34: =IF(OR(Beregninger!G42=0,Beregninger!K42=0,Beregninger!F42=0),"",CONCATENATE(ROUND(IMABS(Beregninger!K42),2),"A"," ∠",ROUND(DEGREES(-IMARGUMENT(Beregninger!K42)),2))) | E34: =IF(OR(Beregninger!G42=0,Beregninger!L42=0,Beregninger!F42=0),"",CONCATENATE(ROUND(IMABS(Beregninger!L42),2),"A"," ∠",ROUND(DEGREES(-IMARGUMENT(Beregninger!L42)),2)))
B35: =IF(Beregninger!C43=0,"",Beregninger!C43) | C35: =IF(OR(Beregninger!G43=0,Beregninger!J43=0,Beregninger!F43=0),"",CONCATENATE(ROUND(IMABS(Beregninger!J43),2),"A"," ∠",ROUND(DEGREES(-IMARGUMENT(Beregninger!J43)),2))) | D35: =IF(OR(Beregninger!G43=0,Beregninger!K43=0,Beregninger!F43=0),"",CONCATENATE(ROUND(IMABS(Beregninger!K43),2),"A"," ∠",ROUND(DEGREES(-IMARGUMENT(Beregninger!K43)),2))) | E35: =IF(OR(Beregninger!G43=0,Beregninger!L43=0,Beregninger!F43=0),"",CONCATENATE(ROUND(IMABS(Beregninger!L43),2),"A"," ∠",ROUND(DEGREES(-IMARGUMENT(Beregninger!L43)),2)))
B36: =IF(Beregninger!C44=0,"",Beregninger!C44) | C36: =IF(OR(Beregninger!G44=0,Beregninger!J44=0,Beregninger!F44=0),"",CONCATENATE(ROUND(IMABS(Beregninger!J44),2),"A"," ∠",ROUND(DEGREES(-IMARGUMENT(Beregninger!J44)),2))) | D36: =IF(OR(Beregninger!G44=0,Beregninger!K44=0,Beregninger!F44=0),"",CONCATENATE(ROUND(IMABS(Beregninger!K44),2),"A"," ∠",ROUND(DEGREES(-IMARGUMENT(Beregninger!K44)),2))) | E36: =IF(OR(Beregninger!G44=0,Beregninger!L44=0,Beregninger!F44=0),"",CONCATENATE(ROUND(IMABS(Beregninger!L44),2),"A"," ∠",ROUND(DEGREES(-IMARGUMENT(Beregninger!L44)),2)))
B37: =IF(Beregninger!C45=0,"",Beregninger!C45) | C37: =IF(OR(Beregninger!G45=0,Beregninger!J45=0,Beregninger!F45=0),"",CONCATENATE(ROUND(IMABS(Beregninger!J45),2),"A"," ∠",ROUND(DEGREES(-IMARGUMENT(Beregninger!J45)),2))) | D37: =IF(OR(Beregninger!G45=0,Beregninger!K45=0,Beregninger!F45=0),"",CONCATENATE(ROUND(IMABS(Beregninger!K45),2),"A"," ∠",ROUND(DEGREES(-IMARGUMENT(Beregninger!K45)),2))) | E37: =IF(OR(Beregninger!G45=0,Beregninger!L45=0,Beregninger!F45=0),"",CONCATENATE(ROUND(IMABS(Beregninger!L45),2),"A"," ∠",ROUND(DEGREES(-IMARGUMENT(Beregninger!L45)),2)))
B38: =IF(Beregninger!C46=0,"",Beregninger!C46) | C38: =IF(OR(Beregninger!G46=0,Beregninger!J46=0,Beregninger!F46=0),"",CONCATENATE(ROUND(IMABS(Beregninger!J46),2),"A"," ∠",ROUND(DEGREES(-IMARGUMENT(Beregninger!J46)),2))) | D38: =IF(OR(Beregninger!G46=0,Beregninger!K46=0,Beregninger!F46=0),"",CONCATENATE(ROUND(IMABS(Beregninger!K46),2),"A"," ∠",ROUND(DEGREES(-IMARGUMENT(Beregninger!K46)),2))) | E38: =IF(OR(Beregninger!G46=0,Beregninger!L46=0,Beregninger!F46=0),"",CONCATENATE(ROUND(IMABS(Beregninger!L46),2),"A"," ∠",ROUND(DEGREES(-IMARGUMENT(Beregninger!L46)),2)))
B39: =IF(Beregninger!C47=0,"",Beregninger!C47) | C39: =IF(OR(Beregninger!G47=0,Beregninger!J47=0,Beregninger!F47=0),"",CONCATENATE(ROUND(IMABS(Beregninger!J47),2),"A"," ∠",ROUND(DEGREES(-IMARGUMENT(Beregninger!J47)),2))) | D39: =IF(OR(Beregninger!G47=0,Beregninger!K47=0,Beregninger!F47=0),"",CONCATENATE(ROUND(IMABS(Beregninger!K47),2),"A"," ∠",ROUND(DEGREES(-IMARGUMENT(Beregninger!K47)),2))) | E39: =IF(OR(Beregninger!G47=0,Beregninger!L47=0,Beregninger!F47=0),"",CONCATENATE(ROUND(IMABS(Beregninger!L47),2),"A"," ∠",ROUND(DEGREES(-IMARGUMENT(Beregninger!L47)),2)))
B40: SUM (uden SF på tavle) | C40: =CONCATENATE(Beregninger!J52," ∠",Beregninger!J53) -> #DIV/0! | D40: =CONCATENATE(Beregninger!K52," ∠",Beregninger!K53) -> #DIV/0! | E40: =CONCATENATE(Beregninger!L52," ∠",Beregninger!L53) -> #DIV/0!
B41: =CONCATENATE("SUM (med SF på tavle) ",Beregninger!J54) -> SUM (med SF på tavle) 1 | C41: =CONCATENATE(Beregninger!J55," ∠",Beregninger!J53) -> #DIV/0! | D41: =CONCATENATE(Beregninger!K55," ∠",Beregninger!K53) -> #DIV/0! | E41: =CONCATENATE(Beregninger!L55," ∠",Beregninger!L53) -> #DIV/0!
B42: © Lasse Klein - www.dokuteknik.dk
