Workbook
Name MAfuld: 'Lister og genveje'!$D$1:$I$1
Name maksimal100: 'Lister og genveje'!$E$9:$E$17
Name maksimal100a: 'Lister og genveje'!$E$9:$E$17
Name maksimal100b: 'Lister og genveje'!$E$9:$E$17
Name maksimal160: 'Lister og genveje'!$F$9:$F$17
Name maksimal160a: 'Lister og genveje'!$F$9:$F$17
Name maksimal160b: 'Lister og genveje'!$F$9:$F$17
Name maksimal250a: 'Lister og genveje'!$G$9:$G$17
Name maksimal250b: 'Lister og genveje'!$H$9:$H$17
Name maksimal40: 'Lister og genveje'!$D$9:$D$17
Name maksimal400: 'Lister og genveje'!$I$9:$I$17
Name maksimal400a: 'Lister og genveje'!$I$9:$I$17
Name maksimal400b: 'Lister og genveje'!$I$9:$I$17
Name maksimal40a: 'Lister og genveje'!$D$9:$D$17
Name maksimal40b: 'Lister og genveje'!$D$9:$D$17
Name maksimal630: 'Lister og genveje'!$J$9:$J$17
Name maksimal630A: 'Lister og genveje'!$J$9:$J$17
Name maksimal630b: 'Lister og genveje'!$J$9:$J$17
Name MAlille: 'Lister og genveje'!$D$1:$H$1
Name NSX100MA: 'Maksimal afbryder'!#REF!
Name NSX160MA: 'Maksimal afbryder'!$M$41:$M$43
Name NSX250MA: 'Maksimal afbryder'!$M$44:$M$49
Name NSX400MA: 'Maksimal afbryder'!$M$50:$M$54
Name NSX630MA: 'Maksimal afbryder'!$M$55:$M$59
Name PE_: #REF!
Name R_: #REF!
Name TID_: #REF!
Name TID_: #REF!
Name Udsnitsværktøj_Antal_ledere: #N/A
Name Udsnitsværktøj_Automatsikring: #N/A
Name Udsnitsværktøj_Kabel_type: #N/A
Name Udsnitsværktøj_Kurve: #N/A
Name Udsnitsværktøj_Leder_type: #N/A
Name Udsnitsværktøj_mærkestrøm: #N/A
Name Udsnitsværktøj_Poler: #N/A
Name Udsnitsværktøj_Sikringens_størrelse___A: #N/A
Name Udsnitsværktøj_Sikrings_typen: #N/A
Name Udsnitsværktøj_Standart: #N/A
Name Udsnitsværktøj_Tværsnit: #N/A
Name X_: #REF!

Sheet Forside
B2: Valg af smeltesikringer | E2: Tavleoversigt
B5: Valg af Automatsikring | E5: Belastnings beregning
B8: Maksimal afbryder
E11: Lister og genveje

Sheet Maksimal afbryder
A2: =IF(D6<=40,40,"")&IF(AND(D6>40,D6<=100),100,"")&IF(AND(D6>100,D6<=160),160,"")&IF(AND(D6>160,D6<=250),250,"")&IF(AND(D6>250,D6<=400),400,"")&IF(AND(D6>400,D6<=630),630,"") -> 400 | B2: Trin 1 | K2: Kontrol af indstillinger
A3: 2 | B3: Vælg belastninger | R3: Maskimalafbryderens indstillinger
L4: Valgt maksimalafbryder plus indstillingere af Micrologix 2.2
S5: Valg af maksimalafbryder
C6: Ib | D6: 303.8 | E6: [ A ]
C7: I start | D7: 303.8 | E7: [ A ] | L7: ="NSX "&IF(A2<=100,100,LEFT($A$2,3)) -> NSX 400 | M7: =IF(AND(D8>0,D8<=35.99),"F","")&IF(AND(D8>36,D8<=49.99),"N","")&IF(AND(D8>50,D8<=69.99),"H","")&IF(AND(D8>70,D8<=99.99),"S","")&IF(AND(D8>100,D8<=150),"L","") -> F | O7: Icu | P7: =INDEX('Lister og genveje'!$D$2:$I$6,MATCH($L$7,'Lister og genveje'!$C$2:$C$6,FALSE),MATCH(M7,'Lister og genveje'!$D$1:$I$1,FALSE),1) -> 36 | Q7: [ kA ] | S7: ="valg af maksimalafbryder: "&L7&M7 -> valg af maksimalafbryder: NSX 400F | V7: Micrologic 2.2
C8: Ik max | D8: 12.1 | E8: [ kA ] | S8: ="In = "&P9&" A" -> In = 400 A | V8: ="In = "&P9&" A" -> In = 400 A
C9: Inrush | D9: 0 | E9: [ A ] | L9: Ib ≤ In | M9: = | N9: =D6 -> 303.8 | O9: ≤ | P9: =RIGHT(L7,3) -> 400 | Q9: =IF((LEFT(P9,3)-LEFT(N9,3))>=0,1,-1) -> 1 | S9: ="Icu = "&P7&" kA" -> Icu = 36 kA | V9: ="Ir = "&" ( "&IF($D$6<=40,'Lister og genveje'!$F$19,"")&IF(AND($D$6>=40,$D$6<=100),'Lister og genveje'!F20,"")&IF(AND($D$6>=100,$D$6<=160),'Lister og genveje'!F21,"")&IF(AND($D$6>=160,$D$6<=250,A3=1),'Lister og genveje'!F22,'Lister og genveje'!F23)&IF(AND($D$6>=250,$D$6<=400),'Lister og genveje'!F24,"")&IF(AND($D$6>=400,$D$6<=630),'Lister og genveje'!F25,"")&" - " -> Ir = ( 144 - | W9: =D6 -> 303.8 | X9: =" - "&IF($D$6<=40,'Lister og genveje'!$F$19,"")&IF(AND($D$6>=40,$D$6<=100),'Lister og genveje'!H20,"")&IF(AND($D$6>=100,$D$6<=160),'Lister og genveje'!H21,"")&IF(AND($D$6>=160,$D$6<=250),"",'Lister og genveje'!H23)&IF(AND($D$6>250,$D$6<=400),'Lister og genveje'!H24,'Lister og genveje'!H23)&IF(AND($D$6>=400,$D$6<=630),'Lister og genveje'!H25,"")&" )" -> - 250400 )
C10: Ik min | D10: 0 | E10: [ kA ] | S10: ="Ics = "&"Ics mangler" -> Ics = Ics mangler | V10: ="Isd = "&"( 1,5 - 10 ) x "&W9&" = " -> Isd = ( 1,5 - 10 ) x 303,8 =
L11: Ib ≤ I0 | M11: = | N11: =N9 -> 303.8 | O11: ≤ | P11: =C17 -> 320 | Q11: =IF((LEFT(P11,3)-LEFT(N11,3))>=0,1,-1) -> 1 | V11: ="Isd ="&" ( "&1.5*W9&" - " -> Isd = ( 455,7 - | W11: =E27*C27 -> 607.6 | X11: =" - "&10*C27&" ) A" -> - 3038 ) A
V12: ="Ii = "&R33&" kA" -> Ii = 4800 kA
B13: Trin 2 | L13: Istart ≤ Isd | M13: = | N13: =D7 -> 303.8 | O13: ≤ | P13: =$H$27&" / "&H28 -> 668,36 / 546,84 | Q13: =IF((H27-D7)>=0,1,-1) -> 1
B14: Indstill Io | Q14: =IF(H28-D7>=0,1,-1) -> 1
B16: Long-time protection [ Io] | L16: Ii ≤ Ikmax | M16: = | N16: =IF(LEFT(A2,3)="40",600,"")&IF(LEFT(A2,3)="100",1500,"")&IF(LEFT(A2,3)="160",2400,"")&IF(LEFT(A2,3)="250",3000,"")&IF(LEFT(A2,3)="400",4800,"")&IF(LEFT(A2,3)="630",9000,"") -> 4800 | O16: ≤ | P16: =D8*10^3 -> 12100 | Q16: =IF(P16-N16>=0,1,-1) -> 1
B17: I0 = | C17: 320 | F17: =IF('Lister og genveje'!F19=40,'Lister og genveje'!H19,"")
B18: Ir = | C18: =" ( "&IF($D$6<=40,'Lister og genveje'!$F$19,"")&IF(AND($D$6>=40,$D$6<=100),'Lister og genveje'!F20,"")&IF(AND($D$6>=100,$D$6<=160),'Lister og genveje'!F21,"")&IF(AND($D$6>=160,$D$6<=250,A3=1),'Lister og genveje'!F22,'Lister og genveje'!F23)&IF(AND($D$6>=250,$D$6<=400),'Lister og genveje'!F24,"")&IF(AND($D$6>=400,$D$6<=630),'Lister og genveje'!F25,"")&" - " -> ( 144 - | D18: =D6 -> 303.8 | E18: =" - "&IF($D$6<=40,'Lister og genveje'!$F$19,"")&IF(AND($D$6>=40,$D$6<=100),'Lister og genveje'!H20,"")&IF(AND($D$6>=100,$D$6<=160),'Lister og genveje'!H21,"")&IF(AND($D$6>160,$D$6<250),'Lister og genveje'!H22,'Lister og genveje'!H23)&IF(AND($D$6>=250,$D$6<=400),'Lister og genveje'!H24,"")&IF(AND($D$6>=400,$D$6<=630),'Lister og genveje'!H25,"")&" )" -> - 250400 ) | L18: Icu ≥ Ikmax | M18: = | N18: =LEFT(P7,3)*10^3 -> 36000 | O18: ≥ | P18: =D8*10^3 -> 12100 | Q18: =IF((P7*10^3)-D8>=0,1) -> 1
L20: Inrush < Ii | M20: = | N20: =D9 -> 0 | O20: < | P20: =N16 -> 4800 | Q20: =IF((P20-D9)>0,1,-1) -> 1
B22: Trin 3 | L22: Inrush ≤ Isd | M22: = | N22: =N20 -> 0 | O22: ≤ | P22: =$H$27&" / "&H28 -> 668,36 / 546,84 | Q22: =IF((H27-D9)>=0,1,-1) -> 1
B23: Indstill Isd | Q23: =IF((H28-N22)>=0,1,-1) -> 1
B25: Short-time protection whit fixed time delay [ Isd ] +/- 10% | K25: Ir [ Ib ] | M25: =C7 -> I start | O25: Isd | Q25: =C10 -> Ik min | S25: =C8 -> Ik max | U25: Icu
K26: =N9 -> 303.8 | L26: ≤ | M26: =D7 -> 303.8 | N26: ≤ | O26: =H28 -> 546.84 | P26: ≤ | Q26: =D10*10^3 -> 0 | R26: ≤ | S26: =D8*10^3 -> 12100 | T26: ≤ | U26: =P7*10^3 -> 36000 | V26: [ A ]
B27: Isd = | C27: =D6 -> 303.8 | D27: x | E27: 2 | F27: = | G27: =" + "&"10%" -> + 10% | H27: =ROUNDUP($C$27*$E$27*1.1,2) -> 668.36 | L27: =IF(K26<=M26,"","falsk") | N27: =IF(M26<=O26,"","falsk") | P27: =IF(O26<=Q26,"","falsk") -> falsk | R27: =IF(Q26<=S26,"","falsk") | T27: =IF(S26<=U26,"","falsk")
G28: =" - 10%" -> - 10% | H28: =ROUNDUP($C$27*$E$27*0.9,2) -> 546.84
B30: Isd = | C30: ="( 1,5 - "&ROUNDUP(IF(OR(E27=1.5,E27=10),"",E27),0)&IF(OR(E27=1.5,E27=10),""," - ")&"10 )" -> ( 1,5 - 2 - 10 )
W31: Tilbage til forsiden
R32: Ii
B33: Isd = | C33: ="( "&C17*1.5 -> ( 480 | D33: - | E33: =C27*E27 -> 607.6 | F33: - | G33: =10*C17&" ) " -> 3200 ) | R33: =N16 -> 4800

Sheet Tavle dim
A2: Un | B2: 400 | C2: V | K2: Samtidighedsfaktor | L2: 0
K3: Udvidelsesfaktorfaktor | L3: 0
A5: Tavle A09 | C5: Indtast værdi | D5: IB | E5: Cosj | F5: Tilsluttet | H5: Ðj i Grader | I5: SF | K5: Belastning | L5: IL1 | M5: Ðj | N5: IL2 | O5: Ðj | P5: IL3 | Q5: Ðj | R5: IN | S5: Ðj
A6: W09.1 - Søjleboremaskine | C6: 6.6 | D6: =CHOOSE(L36,C6*1000/Q36,C6*1000/Q36/E6,C6)*I6 -> 6.6 | E6: 0.95 | H6: =-DEGREES(ACOS(E6)) -> -18.194872 | I6: 1 | K6: =A6 -> W09.1 - Søjleboremaskine | L6: =ROUNDUP(IMABS(COMPLEX(M57,N57)),2) -> 6.6 | M6: =ROUNDUP(IFERROR(DEGREES(IMARGUMENT(COMPLEX(M57,N57))),0),2) -> -18.2 | N6: =ROUNDUP(IMABS(COMPLEX(O57,P57)),2) -> 0 | O6: =ROUNDUP(IFERROR(DEGREES(IMARGUMENT(COMPLEX(O57,P57))),0),2) -> 0 | P6: =ROUNDUP(IMABS(COMPLEX(Q57,R57)),2) -> 0 | Q6: =ROUNDUP(IFERROR(DEGREES(IMARGUMENT(COMPLEX(Q57,R57))),0),2) -> 0 | R6: =CHOOSE(M36,0,L6,N6,P6,0,0,0,0,0) -> 6.6
A7: W09.2 - Båndsav | C7: 8.6 | D7: =CHOOSE(L37,C7*1000/Q37,C7*1000/Q37/E7,C7)*I7 -> 8.6 | E7: 0.95 | H7: =-DEGREES(ACOS(E7)) -> -18.194872 | I7: 1 | K7: =A7 -> W09.2 - Båndsav | L7: =ROUNDUP(IMABS(COMPLEX(M58,N58)),2) -> 0 | M7: =ROUNDUP(IFERROR(DEGREES(IMARGUMENT(COMPLEX(M58,N58))),0),2) -> 0 | N7: =ROUNDUP(IMABS(COMPLEX(O58,P58)),2) -> 8.6 | O7: =ROUNDUP(IFERROR(DEGREES(IMARGUMENT(COMPLEX(O58,P58))),0),2) -> -18.2 | P7: =ROUNDUP(IMABS(COMPLEX(Q58,R58)),2) -> 0 | Q7: =ROUNDUP(IFERROR(DEGREES(IMARGUMENT(COMPLEX(Q58,R58))),0),2) -> 0 | R7: =CHOOSE(M37,0,L7,N7,P7,0,0,0,0,0) -> 8.6
A8: W09.3 - Skivepudsemaskine | C8: 6.6 | D8: =CHOOSE(L38,C8*1000/Q38,C8*1000/Q38/E8,C8)*I8 -> 6.6 | E8: 0.95 | H8: =-DEGREES(ACOS(E8)) -> -18.194872 | I8: 1 | K8: =A8 -> W09.3 - Skivepudsemaskine | L8: =ROUNDUP(IMABS(COMPLEX(M59,N59)),2) -> 0 | M8: =ROUNDUP(IFERROR(DEGREES(IMARGUMENT(COMPLEX(M59,N59))),0),2) -> 0 | N8: =ROUNDUP(IMABS(COMPLEX(O59,P59)),2) -> 0 | O8: =ROUNDUP(IFERROR(DEGREES(IMARGUMENT(COMPLEX(O59,P59))),0),2) -> 0 | P8: =ROUNDUP(IMABS(COMPLEX(Q59,R59)),2) -> 6.6 | Q8: =ROUNDUP(IFERROR(DEGREES(IMARGUMENT(COMPLEX(Q59,R59))),0),2) -> -18.2 | R8: =CHOOSE(M38,0,L8,N8,P8,0,0,0,0,0) -> 6.6
A9: W09.4 - Drejebænk | C9: 22 | D9: =CHOOSE(L39,C9*1000/Q39,C9*1000/Q39/E9,C9)*I9 -> 22 | E9: 0.9 | H9: =-DEGREES(ACOS(E9)) -> -25.841933 | I9: 1 | K9: =A9 -> W09.4 - Drejebænk | L9: =ROUNDUP(IMABS(COMPLEX(M60,N60)),2) -> 22 | M9: =ROUNDUP(IFERROR(DEGREES(IMARGUMENT(COMPLEX(M60,N60))),0),2) -> -25.85 | N9: =ROUNDUP(IMABS(COMPLEX(O60,P60)),2) -> 22 | O9: =ROUNDUP(IFERROR(DEGREES(IMARGUMENT(COMPLEX(O60,P60))),0),2) -> -25.85 | P9: =ROUNDUP(IMABS(COMPLEX(Q60,R60)),2) -> 22 | Q9: =ROUNDUP(IFERROR(DEGREES(IMARGUMENT(COMPLEX(Q60,R60))),0),2) -> -25.85 | R9: =CHOOSE(M39,0,L9,N9,P9,0,0,0,0,0) -> 0
A10: W09.5 - Afretter | C10: 8.6 | D10: =CHOOSE(L40,C10*1000/Q40,C10*1000/Q40/E10,C10)*I10 -> 8.6 | E10: 0.9 | G10: -14.38 | H10: =-DEGREES(ACOS(E10)) -> -25.841933 | I10: 1 | K10: =A10 -> W09.5 - Afretter | L10: =ROUNDUP(IMABS(COMPLEX(M61,N61)),2) -> 0 | M10: =ROUNDUP(IFERROR(DEGREES(IMARGUMENT(COMPLEX(M61,N61))),0),2) -> 0 | N10: =ROUNDUP(IMABS(COMPLEX(O61,P61)),2) -> 0 | O10: =ROUNDUP(IFERROR(DEGREES(IMARGUMENT(COMPLEX(O61,P61))),0),2) -> 0 | P10: =ROUNDUP(IMABS(COMPLEX(Q61,R61)),2) -> 8.6 | Q10: =ROUNDUP(IFERROR(DEGREES(IMARGUMENT(COMPLEX(Q61,R61))),0),2) -> -25.85 | R10: =CHOOSE(M40,0,L10,N10,P10,0,0,0,0,0) -> 8.6
A11: W09.6 - Overfræser | C11: 11.5 | D11: =CHOOSE(L41,C11*1000/Q41,C11*1000/Q41/E11,C11)*I11 -> 11.5 | E11: 0.95 | H11: =-DEGREES(ACOS(E11)) -> -18.194872 | I11: 1 | K11: =A11 -> W09.6 - Overfræser | L11: =ROUNDUP(IMABS(COMPLEX(M62,N62)),2) -> 11.5 | M11: =ROUNDUP(IFERROR(DEGREES(IMARGUMENT(COMPLEX(M62,N62))),0),2) -> -18.2 | N11: =ROUNDUP(IMABS(COMPLEX(O62,P62)),2) -> 0 | O11: =ROUNDUP(IFERROR(DEGREES(IMARGUMENT(COMPLEX(O62,P62))),0),2) -> 0 | P11: =ROUNDUP(IMABS(COMPLEX(Q62,R62)),2) -> 0 | Q11: =ROUNDUP(IFERROR(DEGREES(IMARGUMENT(COMPLEX(Q62,R62))),0),2) -> 0 | R11: =CHOOSE(M41,0,L11,N11,P11,0,0,0,0,0) -> 11.5
A12: W09.7 - Tykkelseshøvl | C12: 9 | D12: =CHOOSE(L42,C12*1000/Q42,C12*1000/Q42/E12,C12)*I12 -> 9 | E12: 0.9 | H12: =-DEGREES(ACOS(E12)) -> -25.841933 | I12: 1 | K12: =A12 -> W09.7 - Tykkelseshøvl | L12: =ROUNDUP(IMABS(COMPLEX(M63,N63)),2) -> 0 | M12: =ROUNDUP(IFERROR(DEGREES(IMARGUMENT(COMPLEX(M63,N63))),0),2) -> 0 | N12: =ROUNDUP(IMABS(COMPLEX(O63,P63)),2) -> 9 | O12: =ROUNDUP(IFERROR(DEGREES(IMARGUMENT(COMPLEX(O63,P63))),0),2) -> -25.85 | P12: =ROUNDUP(IMABS(COMPLEX(Q63,R63)),2) -> 0 | Q12: =ROUNDUP(IFERROR(DEGREES(IMARGUMENT(COMPLEX(Q63,R63))),0),2) -> 0 | R12: =CHOOSE(M42,0,L12,N12,P12,0,0,0,0,0) -> 9
A13: W09.8 - Langhulsboremaskine | C13: 5 | D13: =CHOOSE(L43,C13*1000/Q43,C13*1000/Q43/E13,C13)*I13 -> 5 | E13: 0.95 | H13: =-DEGREES(ACOS(E13)) -> -18.194872 | I13: 1 | K13: =A13 -> W09.8 - Langhulsboremaskine | L13: =ROUNDUP(IMABS(COMPLEX(M64,N64)),2) -> 5 | M13: =ROUNDUP(IFERROR(DEGREES(IMARGUMENT(COMPLEX(M64,N64))),0),2) -> -18.2 | N13: =ROUNDUP(IMABS(COMPLEX(O64,P64)),2) -> 0 | O13: =ROUNDUP(IFERROR(DEGREES(IMARGUMENT(COMPLEX(O64,P64))),0),2) -> 0 | P13: =ROUNDUP(IMABS(COMPLEX(Q64,R64)),2) -> 0 | Q13: =ROUNDUP(IFERROR(DEGREES(IMARGUMENT(COMPLEX(Q64,R64))),0),2) -> 0 | R13: =CHOOSE(M43,0,L13,N13,P13,0,0,0,0,0) -> 5
A14: W09.9 - Plasmaskærer | C14: 18.5 | D14: =CHOOSE(L44,C14*1000/Q44,C14*1000/Q44/E14,C14)*I14 -> 18.5 | E14: 0.81 | H14: =-DEGREES(ACOS(E14)) -> -35.904069 | I14: 1 | K14: =A14 -> W09.9 - Plasmaskærer | L14: =ROUNDUP(IMABS(COMPLEX(M65,N65)),2) -> 18.5 | M14: =ROUNDUP(IFERROR(DEGREES(IMARGUMENT(COMPLEX(M65,N65))),0),2) -> -35.91 | N14: =ROUNDUP(IMABS(COMPLEX(O65,P65)),2) -> 18.5 | O14: =ROUNDUP(IFERROR(DEGREES(IMARGUMENT(COMPLEX(O65,P65))),0),2) -> -35.91 | P14: =ROUNDUP(IMABS(COMPLEX(Q65,R65)),2) -> 18.5 | Q14: =ROUNDUP(IFERROR(DEGREES(IMARGUMENT(COMPLEX(Q65,R65))),0),2) -> -35.91 | R14: =CHOOSE(M44,0,L14,N14,P14,0,0,0,0,0) -> 0
A15: W09.10 - Fræser | C15: 19 | D15: =CHOOSE(L45,C15*1000/Q45,C15*1000/Q45/E15,C15)*I15 -> 19 | E15: 0.9 | H15: =-DEGREES(ACOS(E15)) -> -25.841933 | I15: 1 | K15: =A15 -> W09.10 - Fræser | L15: =ROUNDUP(IMABS(COMPLEX(M66,N66)),2) -> 19 | M15: =ROUNDUP(IFERROR(DEGREES(IMARGUMENT(COMPLEX(M66,N66))),0),2) -> -25.85 | N15: =ROUNDUP(IMABS(COMPLEX(O66,P66)),2) -> 19 | O15: =ROUNDUP(IFERROR(DEGREES(IMARGUMENT(COMPLEX(O66,P66))),0),2) -> -25.85 | P15: =ROUNDUP(IMABS(COMPLEX(Q66,R66)),2) -> 19 | Q15: =ROUNDUP(IFERROR(DEGREES(IMARGUMENT(COMPLEX(Q66,R66))),0),2) -> -25.85 | R15: =CHOOSE(M45,0,L15,N15,P15,0,0,0,0,0) -> 0
A16: W09.11 - Båndpudser | C16: 15.2 | D16: =CHOOSE(L46,C16*1000/Q46,C16*1000/Q46/E16,C16)*I16 -> 15.2 | E16: 0.9 | H16: =-DEGREES(ACOS(E16)) -> -25.841933 | I16: 1 | K16: =A16 -> W09.11 - Båndpudser | L16: =ROUNDUP(IMABS(COMPLEX(M67,N67)),2) -> 15.2 | M16: =ROUNDUP(IFERROR(DEGREES(IMARGUMENT(COMPLEX(M67,N67))),0),2) -> -25.85 | N16: =ROUNDUP(IMABS(COMPLEX(O67,P67)),2) -> 15.2 | O16: =ROUNDUP(IFERROR(DEGREES(IMARGUMENT(COMPLEX(O67,P67))),0),2) -> -25.85 | P16: =ROUNDUP(IMABS(COMPLEX(Q67,R67)),2) -> 15.2 | Q16: =ROUNDUP(IFERROR(DEGREES(IMARGUMENT(COMPLEX(Q67,R67))),0),2) -> -25.85 | R16: =CHOOSE(M46,0,L16,N16,P16,0,0,0,0,0) -> 0
A17: W09.12 - Rundsav | C17: 24 | D17: =CHOOSE(L47,C17*1000/Q47,C17*1000/Q47/E17,C17)*I17 -> 24 | E17: 0.95 | H17: =-DEGREES(ACOS(E17)) -> -18.194872 | I17: 1 | K17: =A17 -> W09.12 - Rundsav | L17: =ROUNDUP(IMABS(COMPLEX(M68,N68)),2) -> 24 | M17: =ROUNDUP(IFERROR(DEGREES(IMARGUMENT(COMPLEX(M68,N68))),0),2) -> -18.2 | N17: =ROUNDUP(IMABS(COMPLEX(O68,P68)),2) -> 24 | O17: =ROUNDUP(IFERROR(DEGREES(IMARGUMENT(COMPLEX(O68,P68))),0),2) -> -18.2 | P17: =ROUNDUP(IMABS(COMPLEX(Q68,R68)),2) -> 24 | Q17: =ROUNDUP(IFERROR(DEGREES(IMARGUMENT(COMPLEX(Q68,R68))),0),2) -> -18.2 | R17: =CHOOSE(M47,0,L17,N17,P17,0,0,0,0,0) -> 0
A18: W09.13 - Svejseværk | C18: 18 | D18: =CHOOSE(L48,C18*1000/Q48,C18*1000/Q48/E18,C18)*I18 -> 18 | E18: 0.8 | H18: =-DEGREES(ACOS(E18)) -> -36.869898 | I18: 1 | K18: =A18 -> W09.13 - Svejseværk | L18: =ROUNDUP(IMABS(COMPLEX(M69,N69)),2) -> 0 | M18: =ROUNDUP(IFERROR(DEGREES(IMARGUMENT(COMPLEX(M69,N69))),0),2) -> 0 | N18: =ROUNDUP(IMABS(COMPLEX(O69,P69)),2) -> 18 | O18: =ROUNDUP(IFERROR(DEGREES(IMARGUMENT(COMPLEX(O69,P69))),0),2) -> -6.87 | P18: =ROUNDUP(IMABS(COMPLEX(Q69,R69)),2) -> 18 | Q18: =ROUNDUP(IFERROR(DEGREES(IMARGUMENT(COMPLEX(Q69,R69))),0),2) -> -66.87 | R18: =CHOOSE(M48,0,L18,N18,P18,0,0,0,0,0) -> 0
A19: W09.14 - W09.20 -Stikk | C19: 40 | D19: =CHOOSE(L49,C19*1000/Q49,C19*1000/Q49/E19,C19)*I19 -> 20 | E19: 0.95 | H19: =-DEGREES(ACOS(E19)) -> -18.194872 | I19: 0.5 | K19: =A19 -> W09.14 - W09.20 -Stikk | L19: =ROUNDUP(IMABS(COMPLEX(M70,N70)),2) -> 20 | M19: =ROUNDUP(IFERROR(DEGREES(IMARGUMENT(COMPLEX(M70,N70))),0),2) -> -18.2 | N19: =ROUNDUP(IMABS(COMPLEX(O70,P70)),2) -> 0 | O19: =ROUNDUP(IFERROR(DEGREES(IMARGUMENT(COMPLEX(O70,P70))),0),2) -> 0 | P19: =ROUNDUP(IMABS(COMPLEX(Q70,R70)),2) -> 0 | Q19: =ROUNDUP(IFERROR(DEGREES(IMARGUMENT(COMPLEX(Q70,R70))),0),2) -> 0 | R19: =CHOOSE(M49,0,L19,N19,P19,0,0,0,0,0) -> 20
A20: W09.14 - W09.20 -Stikk | C20: 30 | D20: =CHOOSE(L50,C20*1000/Q50,C20*1000/Q50/E20,C20)*I20 -> 15 | E20: 0.95 | H20: =-DEGREES(ACOS(E20)) -> -18.194872 | I20: 0.5 | K20: =A20 -> W09.14 - W09.20 -Stikk | L20: =ROUNDUP(IMABS(COMPLEX(M71,N71)),2) -> 0 | M20: =ROUNDUP(IFERROR(DEGREES(IMARGUMENT(COMPLEX(M71,N71))),0),2) -> 0 | N20: =ROUNDUP(IMABS(COMPLEX(O71,P71)),2) -> 15 | O20: =ROUNDUP(IFERROR(DEGREES(IMARGUMENT(COMPLEX(O71,P71))),0),2) -> -18.2 | P20: =ROUNDUP(IMABS(COMPLEX(Q71,R71)),2) -> 0 | Q20: =ROUNDUP(IFERROR(DEGREES(IMARGUMENT(COMPLEX(Q71,R71))),0),2) -> 0 | R20: =CHOOSE(M50,0,L20,N20,P20,0,0,0,0,0) -> 15
A21: W09.14 - W09.20 -Stikk | C21: 30 | D21: =CHOOSE(L51,C21*1000/Q51,C21*1000/Q51/E21,C21)*I21 -> 15 | E21: 0.95 | H21: =-DEGREES(ACOS(E21)) -> -18.194872 | I21: 0.5 | K21: =A21 -> W09.14 - W09.20 -Stikk | L21: =ROUNDUP(IMABS(COMPLEX(M72,N72)),2) -> 0 | M21: =ROUNDUP(IFERROR(DEGREES(IMARGUMENT(COMPLEX(M72,N72))),0),2) -> 0 | N21: =ROUNDUP(IMABS(COMPLEX(O72,P72)),2) -> 0 | O21: =ROUNDUP(IFERROR(DEGREES(IMARGUMENT(COMPLEX(O72,P72))),0),2) -> 0 | P21: =ROUNDUP(IMABS(COMPLEX(Q72,R72)),2) -> 15 | Q21: =ROUNDUP(IFERROR(DEGREES(IMARGUMENT(COMPLEX(Q72,R72))),0),2) -> -18.2 | R21: =CHOOSE(M51,0,L21,N21,P21,0,0,0,0,0) -> 15
A22: W09.21 - W09.22 | C22: 64 | D22: =CHOOSE(L52,C22*1000/Q52,C22*1000/Q52/E22,C22)*I22 -> 32 | E22: 0.85 | H22: =-DEGREES(ACOS(E22)) -> -31.788331 | I22: 0.5 | K22: =A22 -> W09.21 - W09.22 | L22: =ROUNDUP(IMABS(COMPLEX(M73,N73)),2) -> 32 | M22: =ROUNDUP(IFERROR(DEGREES(IMARGUMENT(COMPLEX(M73,N73))),0),2) -> -31.79 | N22: =ROUNDUP(IMABS(COMPLEX(O73,P73)),2) -> 32 | O22: =ROUNDUP(IFERROR(DEGREES(IMARGUMENT(COMPLEX(O73,P73))),0),2) -> -31.79 | P22: =ROUNDUP(IMABS(COMPLEX(Q73,R73)),2) -> 32 | Q22: =ROUNDUP(IFERROR(DEGREES(IMARGUMENT(COMPLEX(Q73,R73))),0),2) -> -31.79 | R22: =CHOOSE(M52,0,L22,N22,P22,0,0,0,0,0) -> 0
A23: W09.23 - W09.25 | C23: 10 | D23: =CHOOSE(L53,C23*1000/Q53,C23*1000/Q53/E23,C23)*I23 -> 10 | E23: 1 | H23: =-DEGREES(ACOS(E23)) -> 0 | I23: 1 | K23: =A23 -> W09.23 - W09.25 | L23: =ROUNDUP(IMABS(COMPLEX(M74,N74)),2) -> 10 | M23: =ROUNDUP(IFERROR(DEGREES(IMARGUMENT(COMPLEX(M74,N74))),0),2) -> 0 | N23: =ROUNDUP(IMABS(COMPLEX(O74,P74)),2) -> 10 | O23: =ROUNDUP(IFERROR(DEGREES(IMARGUMENT(COMPLEX(O74,P74))),0),2) -> 0 | P23: =ROUNDUP(IMABS(COMPLEX(Q74,R74)),2) -> 10 | Q23: =ROUNDUP(IFERROR(DEGREES(IMARGUMENT(COMPLEX(Q74,R74))),0),2) -> 0 | R23: =CHOOSE(M53,0,L23,N23,P23,0,0,0,0,0) -> 0
D24: =CHOOSE(L54,C24*1000/Q54,C24*1000/Q54/E24,C24)*I24 -> 0 | E24: 1 | H24: =-DEGREES(ACOS(E24)) -> 0 | I24: 1 | K24: =A24 -> 0 | L24: =ROUNDUP(IMABS(COMPLEX(M75,N75)),2) -> 0 | M24: =ROUNDUP(IFERROR(DEGREES(IMARGUMENT(COMPLEX(M75,N75))),0),2) -> 0 | N24: =ROUNDUP(IMABS(COMPLEX(O75,P75)),2) -> 0 | O24: =ROUNDUP(IFERROR(DEGREES(IMARGUMENT(COMPLEX(O75,P75))),0),2) -> 0 | P24: =ROUNDUP(IMABS(COMPLEX(Q75,R75)),2) -> 0 | Q24: =ROUNDUP(IFERROR(DEGREES(IMARGUMENT(COMPLEX(Q75,R75))),0),2) -> 0 | R24: =CHOOSE(M54,0,L24,N24,P24,0,0,0,0,0) -> 0
K26: ∑ Itil | L26: =ROUNDUP(IMABS(COMPLEX(M76,N76)),2) -> 181.88 | M26: =ROUNDUP(IFERROR(DEGREES(IMARGUMENT(COMPLEX(M76,N76))),0),2) -> -23.72 | N26: =ROUNDUP(IMABS(COMPLEX(O76,P76)),2) -> 188.71 | O26: =ROUNDUP(IFERROR(DEGREES(IMARGUMENT(COMPLEX(O76,P76))),0),2) -> -22.81 | P26: =ROUNDUP(IMABS(COMPLEX(Q76,R76)),2) -> 182.79 | Q26: =ROUNDUP(IFERROR(DEGREES(IMARGUMENT(COMPLEX(Q76,R76))),0),2) -> -28.34 | R26: =ROUNDUP(IMABS(IMSUM(M85,O85,Q85)),2) -> 11.77 | S26: =ROUNDUP(IFERROR(DEGREES(IMARGUMENT(IMSUM(M85,O85,Q85)))+180,"%"),2) -> 157.4
K27: ∑ IB | L27: =L26*$L$2*$L$3 -> 0 | M27: =M26 -> -23.72 | N27: =N26*$L$2*$L$3 -> 0 | O27: =O26 -> -22.81 | P27: =P26*$L$2*$L$3 -> 0 | Q27: =Q26 -> -28.34 | R27: =R26*$L$2*$L$3 -> 0 | S27: =IFERROR(DEGREES(IMARGUMENT(IMSUM(M85,O85,Q85)))+180,"%") -> 157.39727
B30: Tilbage til forsiden
L31: Grader
L32: 0 | M32: -120 | N32: 120
L33: Radianer
L34: 0 | M34: -2.0943951 | N34: 2.0943951
L35: type | M35: spænding [OUT] | N35: Ðj i Radianer | O35: 30 | P35: -30 | Q35: Spænding
L36: 3 | M36: 2 | N36: =RADIANS(H6) -> -0.31756043 | O36: =RADIANS(O35) -> 0.52359878 | P36: =RADIANS(P35) -> -0.52359878 | Q36: =CHOOSE(M36,$B$2*SQRT(3),$B$2/SQRT(3),$B$2/SQRT(3),$B$2/SQRT(3),$B$2,$B$2,$B$2) -> 230.94011
L37: 3 | M37: 3 | N37: =RADIANS(H7) -> -0.31756043 | Q37: =CHOOSE(M37,$B$2*SQRT(3),$B$2/SQRT(3),$B$2/SQRT(3),$B$2/SQRT(3),$B$2,$B$2,$B$2) -> 230.94011
L38: 3 | M38: 4 | N38: =RADIANS(H8) -> -0.31756043 | Q38: =CHOOSE(M38,$B$2*SQRT(3),$B$2/SQRT(3),$B$2/SQRT(3),$B$2/SQRT(3),$B$2,$B$2,$B$2) -> 230.94011
L39: 3 | M39: 1 | N39: =RADIANS(H9) -> -0.45102681 | Q39: =CHOOSE(M39,$B$2*SQRT(3),$B$2/SQRT(3),$B$2/SQRT(3),$B$2/SQRT(3),$B$2,$B$2,$B$2) -> 692.82032
L40: 3 | M40: 4 | N40: =RADIANS(H10) -> -0.45102681 | Q40: =CHOOSE(M40,$B$2*SQRT(3),$B$2/SQRT(3),$B$2/SQRT(3),$B$2/SQRT(3),$B$2,$B$2,$B$2) -> 230.94011
L41: 3 | M41: 2 | N41: =RADIANS(H11) -> -0.31756043 | Q41: =CHOOSE(M41,$B$2*SQRT(3),$B$2/SQRT(3),$B$2/SQRT(3),$B$2/SQRT(3),$B$2,$B$2,$B$2) -> 230.94011
L42: 3 | M42: 3 | N42: =RADIANS(H12) -> -0.45102681 | Q42: =CHOOSE(M42,$B$2*SQRT(3),$B$2/SQRT(3),$B$2/SQRT(3),$B$2/SQRT(3),$B$2,$B$2,$B$2) -> 230.94011
L43: 3 | M43: 2 | N43: =RADIANS(H13) -> -0.31756043 | Q43: =CHOOSE(M43,$B$2*SQRT(3),$B$2/SQRT(3),$B$2/SQRT(3),$B$2/SQRT(3),$B$2,$B$2,$B$2) -> 230.94011
L44: 3 | M44: 1 | N44: =RADIANS(H14) -> -0.62664421 | Q44: =CHOOSE(M44,$B$2*SQRT(3),$B$2/SQRT(3),$B$2/SQRT(3),$B$2/SQRT(3),$B$2,$B$2,$B$2) -> 692.82032
L45: 3 | M45: 1 | N45: =RADIANS(H15) -> -0.45102681 | Q45: =CHOOSE(M45,$B$2*SQRT(3),$B$2/SQRT(3),$B$2/SQRT(3),$B$2/SQRT(3),$B$2,$B$2,$B$2) -> 692.82032
...

Sheet Sikringer
A13: ="Sikring valgt: "&'Lister og genveje'!AW2&" [A] "&'Lister og genveje'!AW1&IF('Lister og genveje'!AW2<=20,"+ ( HPFI 4 pol/40 [A] ifølge SB 6B, §4.4 siger at klasse II materiale IKKE behøver HPFI)","") -> Sikring valgt: 200 [A] NH 1
A14: ="Afbryder: "&'Lister og genveje'!AV6 -> Afbryder: INFD 250 | G14: ="Valgt automatsikring: "&'Lister og genveje'!AZ1 -> Valgt automatsikring: C60N | I14: ='Lister og genveje'!AZ3&'Lister og genveje'!AZ2&" A" -> B63 A
A15: ="Kortslutningsniveau: "&'Lister og genveje'!AV5 -> Kortslutningsniveau: 40 kA | G15: ="In = "&'Lister og genveje'!AZ2&" [ A ]" -> In = 63 [ A ] | I15: ="In = "&'Lister og genveje'!AZ2&" [A]" -> In = 63 [A]
G16: ="Icu = "&'Lister og genveje'!AY10&" [ kA ]" -> Icu = 10 [ kA ] | I16: ="Isd ="&'Lister og genveje'!AY8&" til "&'Lister og genveje'!AY7&" x "&'Lister og genveje'!AZ2&" In -> Isd ="&'Lister og genveje'!AZ2*'Lister og genveje'!AY8&" - "&'Lister og genveje'!AY7*'Lister og genveje'!AZ2&" [ A ]" -> Isd =3 til 5 x 63 In -> Isd =189 - 315 [ A ]
A17: ="Maks strøm i 5 sec. = "&'Lister og genveje'!AV7&" [ A ]" -> Maks strøm i 5 sec. = 1400 [ A ] | G17: ="Ics = "&'Lister og genveje'!AY9&" x Icu" -> Ics = 0,75 x Icu
G18: ="Ics = "&'Lister og genveje'!AY9&" x "&'Lister og genveje'!AY10&" [ kA ]"&" -> Ics = "&'Lister og genveje'!AY9*'Lister og genveje'!AY10&" [ kA ]" -> Ics = 0,75 x 10 [ kA ] -> Ics = 7,5 [ kA ]
G20: ="Valgt ud fra "&'Lister og genveje'!AY11 -> Valgt ud fra EN60898
C22: Tilbage til forsiden

Sheet Kabler
I5: H07RN-F
B27: ="S = "&'Lister og genveje'!BC4&" "&'Lister og genveje'!BC1&Kabler!MM2&" mm2 "&'Lister og genveje'!BC2 -> S = (Alle) (Alle) mm2 (Alle)
B28: ="r = "&'Lister og genveje'!BB7&" Ω/km" -> r = 0,1017 Ω/km
B29: ="x = "&'Lister og genveje'!BB8&" Ω/km" -> x = 0,077 Ω/km

Sheet Lister og genveje
A1: 230 | D1: B | E1: F | F1: N | G1: H | H1: S | I1: L | AV1: Sikrings typen | AW1: NH 1 | AY1: Automatsikring | AZ1: C60N | BB1: Tværsnit | BC1: (Alle)
A2: 1x400 | C2: NSX 100 | D2: 25 | E2: 36 | F2: 50 | G2: 70 | H2: 100 | I2: 150 | AV2: Sikringens størrelse [ A ] | AW2: 200 | AY2: mærkestrøm | AZ2: 63 | BB2: Kabel type | BC2: (Alle)
A3: 3x400 | C3: NSX 160 | D3: 25 | E3: 36 | F3: 50 | G3: 70 | H3: 100 | I3: 150 | AY3: Kurve | AZ3: B | BB3: Leder type | BC3: Kobber kabel
C4: NSX 250 | D4: 25 | E4: 36 | F4: 50 | G4: 70 | H4: 100 | I4: 150 | AV4: Rækkemærkater | AY4: Poler | AZ4: Flere poler | BB4: Antal ledere | BC4: (Alle)
C5: NSX 400 | E5: 36 | F5: 50 | G5: 70 | H5: 100 | I5: 150 | AV5: 40 kA
C6: NSX 630 | E6: 36 | F6: 50 | G6: 70 | H6: 100 | I6: 150 | Z6: Antal ledere | AA6: Leder type | AB6: Tværsnit | AC6: Kabel type | AD6: R | AE6: X | AV6: INFD 250 | AY6: Rækkenavne | BB6: Rækkemærkater | BC6: Antal af Antal ledere
Z7: 5 G | AA7: Kobber kabel | AB7: 1.5 | AC7: NOIKLX | AD7: =VLOOKUP(Tabel3[[#This Row],[Tværsnit]],'Lister og genveje'!$AQ$10:$AS$25,2,0) -> 12.1 | AE7: 0.113 | AV7: 1400 | AX7: Isd stor | AY7: 5 | BB7: 0.1017 | BC7: 2
C8: Io | D8: 40 | E8: 100 | F8: 160 | G8: 250 | H8: 250 B | I8: In = 400 [ A ] | J8: 630 | Z8: 5 G | AA8: Kobber kabel | AB8: 2.5 | AC8: NOIKLX | AD8: =VLOOKUP(Tabel3[[#This Row],[Tværsnit]],'Lister og genveje'!$AQ$10:$AS$25,2,0) -> 7.41 | AE8: 0.105 | AH8: NOIKLX | AI8: NOIKLX | AJ8: NOIKLX | AK8: Noik-AL-M | AL8: NOSP-AL | AM8: Noik-AL-M | AN8: NOSP-AL | AQ8: R | AV8: Hovedtotal | AX8: Isd lille | AY8: 3 | BB8: 0.077 | BC8: 1
A9: 1.5 | C9: 0.9 | D9: 18 | E9: 40 | F9: 63 | G9: 100 | H9: 70 | I9: 160 | J9: 250 | Z9: 5 G | AA9: Kobber kabel | AB9: 4 | AC9: NOIKLX | AD9: =VLOOKUP(Tabel3[[#This Row],[Tværsnit]],'Lister og genveje'!$AQ$10:$AS$25,2,0) -> 4.61 | AE9: 0.099 | AH9: NOIKX-FLEX | AI9: NOIKX-FLEX | AJ9: NOIKX-FLEX | AK9: Noik-Al-S | AQ9: tværsnit | AR9: Kobber | AS9: Alu | AX9: Ics | AY9: 0.75 | BB9: 0.082 | BC9: 1
A10: 2 | C10: 0.92 | D10: 18 | E10: 45 | F10: 70 | G10: 110 | H10: 100 | I10: 180 | J10: 280 | Z10: 5 G | AA10: Kobber kabel | AB10: 6 | AC10: NOIKLX | AD10: =VLOOKUP(Tabel3[[#This Row],[Tværsnit]],'Lister og genveje'!$AQ$10:$AS$25,2,0) -> 3.08 | AE10: 0.097 | AH10: 3 | AI10: 4 | AJ10: 5 | AK10: 4 | AL10: 4 | AM10: 5 | AN10: 3 | AQ10: 1.5 | AR10: 12.1 | AX10: Icu | AY10: 10 | BB10: 0.126 | BC10: 1
A11: 3 | C11: 0.93 | D11: 20 | E11: 50 | F11: 80 | G11: 125 | H11: 125 | I11: 200 | J11: 320 | Z11: 5 G | AA11: Kobber kabel | AB11: 10 | AC11: NOIKLX | AD11: =VLOOKUP(Tabel3[[#This Row],[Tværsnit]],'Lister og genveje'!$AQ$10:$AS$25,2,0) -> 1.83 | AE11: 0.092 | AG11: 1.5 | AH11: 0.103 | AI11: 0.11 | AJ11: 0.113 | AN11: 0.095 | AO11: 1.5 | AQ11: 2.5 | AR11: 7.41 | AX11: Standart | AY11: EN60898 | BB11: 0.084 | BC11: 1
A12: 4 | C12: 0.94 | D12: 23 | E12: 55 | F12: 90 | G12: 140 | H12: 140 | I12: 230 | J12: 350 | U12: Tilbage til forsiden | Z12: 5 G | AA12: Kobber kabel | AB12: 16 | AC12: NOIKLX | AD12: =VLOOKUP(Tabel3[[#This Row],[Tværsnit]],'Lister og genveje'!$AQ$10:$AS$25,2,0) -> 1.15 | AE12: 0.088 | AG12: 2.5 | AH12: 0.095 | AI12: 0.102 | AJ12: 0.105 | AN12: 0.089 | AO12: 2.5 | AQ12: 4 | AR12: 4.61 | AY12: Hovedtotal | BB12: 0.155 | BC12: 2
A13: 5 | C13: 0.95 | D13: 25 | E13: 63 | F13: 100 | G13: 160 | H13: 160 | I13: 250 | J13: 400 | Z13: 4 X | AA13: Kobber kabel | AB13: 4 | AC13: NOIKLX | AD13: =VLOOKUP(Tabel3[[#This Row],[Tværsnit]],'Lister og genveje'!$AQ$10:$AS$25,2,0) -> 4.61 | AE13: 0.096 | AG13: 4 | AH13: 0.089 | AI13: 0.096 | AJ13: 0.099 | AN13: 0.087 | AO13: 4 | AQ13: 6 | AR13: 3.08 | BB13: 0.077 | BC13: 1
A14: 6 | C14: 0.96 | D14: 28 | E14: 70 | F14: 110 | G14: 175 | H14: 175 | I14: 280 | J14: 450 | Z14: 4 X | AA14: Kobber kabel | AB14: 6 | AC14: NOIKLX | AD14: =VLOOKUP(Tabel3[[#This Row],[Tværsnit]],'Lister og genveje'!$AQ$10:$AS$25,2,0) -> 3.08 | AE14: 0.094 | AG14: 6 | AH14: 0.087 | AI14: 0.094 | AJ14: 0.097 | AN14: 0.082 | AO14: 6 | AQ14: 10 | AR14: 1.83 | BB14: 0.082 | BC14: 1
A15: 7 | C15: 0.97 | D15: 32 | E15: 80 | F15: 125 | G15: 200 | H15: 200 | I15: 320 | J15: 500 | Z15: 4 X | AA15: Kobber kabel | AB15: 10 | AC15: NOIKLX | AD15: =VLOOKUP(Tabel3[[#This Row],[Tværsnit]],'Lister og genveje'!$AQ$10:$AS$25,2,0) -> 1.83 | AE15: 0.089 | AG15: 10 | AH15: 0.082 | AI15: 0.089 | AJ15: 0.092 | AN15: 0.072 | AO15: 10 | AQ15: 16 | AR15: 1.15 | AS15: 1.91 | BB15: 0.194 | BC15: 2
A16: 8 | C16: 0.98 | D16: 36 | E16: 90 | F16: 150 | G16: 225 | H16: 225 | I16: 360 | J16: 570 | U16: 2 - 16 A | V16: D01 | W16: Gruppe afbryder | Z16: 4 X | AA16: Kobber kabel | AB16: 16 | AC16: NOIKLX | AD16: =VLOOKUP(Tabel3[[#This Row],[Tværsnit]],'Lister og genveje'!$AQ$10:$AS$25,2,0) -> 1.15 | AE16: 0.085 | AG16: 16 | AH16: 0.078 | AI16: 0.085 | AJ16: 0.088 | AK16: 0.088 | AM16: 0.072 | AN16: 0.077 | AO16: 16 | AQ16: 25 | AR16: 0.727 | AS16: 1.2 | BB16: 0.077 | BC16: 1
A17: 10 | C17: 1 | D17: 40 | E17: 100 | F17: 160 | G17: 250 | H17: 250 | I17: 400 | J17: 630 | U17: 20 - 63 A | V17: D02 | W17: Tytan afbryder ( 2 ) | Z17: 4 X | AA17: Kobber kabel | AB17: 6 | AC17: NOIKX-Flex | AD17: =VLOOKUP(Tabel3[[#This Row],[Tværsnit]],'Lister og genveje'!$AQ$10:$AS$25,2,0) -> 3.08 | AE17: 0.094 | AG17: 25 | AH17: 0.079 | AI17: 0.086 | AJ17: 0.089 | AK17: 0.089 | AM17: 0.087 | AN17: 0.07 | AO17: 25 | AQ17: 35 | AR17: 0.525 | AS17: 0.868 | BB17: 0.082 | BC17: 1
C18: =IF('Maksimal afbryder'!A2=250,'Lister og genveje'!C22,C21) -> maksimal400b | U18: 80 - 160 A | V18: NH 000 / 00 | W18: INFD 160 | Z18: 4 X | AA18: Kobber kabel | AB18: 10 | AC18: NOIKX-Flex | AD18: =VLOOKUP(Tabel3[[#This Row],[Tværsnit]],'Lister og genveje'!$AQ$10:$AS$25,2,0) -> 1.83 | AE18: 0.089 | AG18: 35 | AH18: 0.074 | AI18: 0.082 | AJ18: 0.085 | AK18: 0.085 | AN18: 0.074 | AO18: 35 | AQ18: 50 | AR18: 0.388 | AS18: 0.641 | BB18: 0.269 | BC18: 2
C19: ="NSX"&LEFT('Maksimal afbryder'!A2,3)&"MA" -> NSX400MA | E19: 40 | F19: =IF('Maksimal afbryder'!$N$9<40.000001,'Lister og genveje'!$D$9*0.9,"") | G19: ='Maksimal afbryder'!$C$17 -> 320 | H19: =IF('Maksimal afbryder'!$N$9<40.000001,E19,"") | U19: 200 -250 A | V19: NH 1 | W19: INFD 250 | Z19: 4 X | AA19: Kobber kabel | AB19: 16 | AC19: NOIKX-Flex | AD19: =VLOOKUP(Tabel3[[#This Row],[Tværsnit]],'Lister og genveje'!$AQ$10:$AS$25,2,0) -> 1.15 | AE19: 0.085 | AG19: 50 | AI19: 0.084 | AK19: 0.081 | AL19: 0.08 | AN19: 0.073 | AO19: 50 | AQ19: 70 | AR19: 0.269 | AS19: 0.444 | BB19: 0.079 | BC19: 1
C20: =IF(LEFT('Maksimal afbryder'!A2,3)<=250,"Mafuld","malille") -> malille | E20: 100 | F20: =IF(AND('Maksimal afbryder'!$N$9>=40.000001,'Maksimal afbryder'!$N$9<100),'Lister og genveje'!$E$9*0.9,"") | G20: ='Maksimal afbryder'!$C$17 -> 320 | H20: =IF(AND('Maksimal afbryder'!$N$9>=40.000001,'Maksimal afbryder'!$N$9<100),E20,"") | U20: 300 - 400 A | V20: NH 2 | W20: INFD 400 | Z20: 4 X | AA20: Kobber kabel | AB20: 25 | AC20: NOIKX-Flex | AD20: =VLOOKUP(Tabel3[[#This Row],[Tværsnit]],'Lister og genveje'!$AQ$10:$AS$25,2,0) -> 0.727 | AE20: 0.086 | AG20: 70 | AI20: 0.081 | AK20: 0.08 | AL20: 0.079 | AN20: 0.071 | AO20: 70 | AQ20: 95 | AR20: 0.194 | AS20: 0.321 | BB20: 0.081 | BC20: 1
C21: ="maksimal"&LEFT('Maksimal afbryder'!A2,3)&IF('Maksimal afbryder'!A3=2,"b","a") -> maksimal400b | E21: 160 | F21: =IF(AND('Maksimal afbryder'!$N$9>=100.001,'Maksimal afbryder'!$N$9<=160),0.9*'Lister og genveje'!$F$9,"") | G21: ='Maksimal afbryder'!$C$17 -> 320 | H21: =IF(AND('Maksimal afbryder'!$N$9>=100.001,'Maksimal afbryder'!$N$9<=160),E21,"") | U21: 425 - 630 A | V21: NH 3 | W21: INFD 630 | Z21: 4 X | AA21: Kobber kabel | AB21: 35 | AC21: NOIKX-Flex | AD21: =VLOOKUP(Tabel3[[#This Row],[Tværsnit]],'Lister og genveje'!$AQ$10:$AS$25,2,0) -> 0.525 | AE21: 0.082 | AG21: 95 | AI21: 0.082 | AK21: 0.078 | AL21: 0.077 | AN21: 0.07 | AO21: 95 | AQ21: 120 | AR21: 0.155 | AS21: 0.253 | BB21: 0.388 | BC21: 1
C22: ="maksimal"&LEFT('Maksimal afbryder'!A2,3) -> maksimal400 | E22: =IF('Maksimal afbryder'!A3=1,250,"") | F22: =IF(AND('Maksimal afbryder'!$N$9>=160.001,'Maksimal afbryder'!$N$9<250),0.9*'Lister og genveje'!$H$10,"") | G22: ='Maksimal afbryder'!$C$17 -> 320 | H22: 250 | Z22: 4 X | AA22: Kobber kabel | AB22: 50 | AC22: NOIKX-Flex | AD22: =VLOOKUP(Tabel3[[#This Row],[Tværsnit]],'Lister og genveje'!$AQ$10:$AS$25,2,0) -> 0.388 | AE22: 0.084 | AG22: 120 | AI22: 0.082 | AK22: 0.077 | AL22: 0.077 | AN22: 0.071 | AO22: 120 | AQ22: 150 | AR22: 0.126 | AS22: 0.207 | BB22: 0.084 | BC22: 1
E23: =IF('Maksimal afbryder'!A3=2,250,"") -> 250 | F23: =IF(AND('Maksimal afbryder'!$N$9>=160.001,'Maksimal afbryder'!$N$9<250),0.9*'Lister og genveje'!$F$10,"") | G23: ='Maksimal afbryder'!$C$17 -> 320 | H23: 250 | Z23: 4 X | AA23: Kobber kabel | AB23: 70 | AC23: NOIKX-Flex | AD23: =VLOOKUP(Tabel3[[#This Row],[Tværsnit]],'Lister og genveje'!$AQ$10:$AS$25,2,0) -> 0.269 | AE23: 0.081 | AG23: 150 | AI23: 0.084 | AK23: 0.078 | AL23: 0.077 | AN23: 0.071 | AO23: 150 | AQ23: 185 | AR23: 0.1017 | AS23: 0.166 | BB23: 0.525 | BC23: 2
E24: 400 | F24: =IF(AND('Maksimal afbryder'!$N$9>=250.001,'Maksimal afbryder'!$N$9<=400),0.9*'Lister og genveje'!$I$9,"") -> 144 | G24: ='Maksimal afbryder'!$C$17 -> 320 | H24: =IF(AND('Maksimal afbryder'!$N$9>=250.001,'Maksimal afbryder'!$N$9<=400),E24,"") -> 400 | Z24: 4 X | AA24: Kobber kabel | AB24: 95 | AC24: NOIKX-Flex | AD24: =VLOOKUP(Tabel3[[#This Row],[Tværsnit]],'Lister og genveje'!$AQ$10:$AS$25,2,0) -> 0.194 | AE24: 0.082 | AG24: 185 | AI24: 0.082 | AK24: 0.078 | AL24: 0.077 | AN24: 0.07 | AO24: 185 | AQ24: 240 | AR24: 0.0787 | AS24: 0.127 | BB24: 0.082 | BC24: 1
E25: 630 | F25: =IF(AND('Maksimal afbryder'!$N$9>=400.001,'Maksimal afbryder'!$N$9<=6300),0.9*'Lister og genveje'!$J$9,"") | G25: ='Maksimal afbryder'!$C$17 -> 320 | H25: =IF(AND('Maksimal afbryder'!$N$9>=400.001,'Maksimal afbryder'!$N$9<=6300),E25,"") | Z25: 4 X | AA25: Kobber kabel | AB25: 120 | AC25: NOIKX-Flex | AD25: =VLOOKUP(Tabel3[[#This Row],[Tværsnit]],'Lister og genveje'!$AQ$10:$AS$25,2,0) -> 0.155 | AE25: 0.082 | AG25: 240 | AI25: 0.083 | AK25: 0.077 | AL25: 0.077 | AO25: 240 | AQ25: 300 | AS25: 0.103 | BB25: 0.085 | BC25: 1
L26: Standart | M26: Automatsikring | N26: mærkestrøm | O26: Kurve | P26: Poler | Q26: Icu [ kA ] | R26: Isd min | S26: Isd max | T26: Ics | Z26: 4 X | AA26: Kobber kabel | AB26: 150 | AC26: NOIKX-Flex | AD26: =VLOOKUP(Tabel3[[#This Row],[Tværsnit]],'Lister og genveje'!$AQ$10:$AS$25,2,0) -> 0.126 | AE26: 0.084 | BB26: 0.727 | BC26: 2
L27: IEC 947-2 | M27: ='Lister og genveje'!$D$39 -> C60N | N27: 0.5 | O27: B | P27: ='Lister og genveje'!$F$38 -> 1 Pol | Q27: =INDEX('Lister og genveje'!$E$39:$I$46,MATCH(M27,'Lister og genveje'!$D$39:$D$46,0),MATCH(P27,'Lister og genveje'!$E$38:$I$38,0),1) -> 3 | R27: =HLOOKUP(O27,'Lister og genveje'!$E$50:$G$52,2,0) -> 3.2 | S27: =HLOOKUP(O27,'Lister og genveje'!$E$50:$G$52,3,0) -> 4.8 | T27: =VLOOKUP(M27,'Lister og genveje'!$D$39:$J$46,7,0) -> 0.75 | Z27: 4 X | AA27: Kobber kabel | AB27: 185 | AC27: NOIKX-Flex | AD27: =VLOOKUP(Tabel3[[#This Row],[Tværsnit]],'Lister og genveje'!$AQ$10:$AS$25,2,0) -> 0.1017 | AE27: 0.082 | BB27: 0.086 | BC27: 1
L28: =$L$27 -> IEC 947-2 | M28: ='Lister og genveje'!$D$39 -> C60N | N28: 1 | O28: B | P28: ='Lister og genveje'!$F$38 -> 1 Pol | Q28: =INDEX('Lister og genveje'!$E$39:$I$46,MATCH(M28,'Lister og genveje'!$D$39:$D$46,0),MATCH(P28,'Lister og genveje'!$E$38:$I$38,0),1) -> 3 | R28: =HLOOKUP(O28,'Lister og genveje'!$E$50:$G$52,2,0) -> 3.2 | S28: =HLOOKUP(O28,'Lister og genveje'!$E$50:$G$52,3,0) -> 4.8 | T28: =VLOOKUP(M28,'Lister og genveje'!$D$39:$J$46,7,0) -> 0.75 | Z28: 4 X | AA28: Kobber kabel | AB28: 240 | AC28: NOIKX-Flex | AD28: =VLOOKUP(Tabel3[[#This Row],[Tværsnit]],'Lister og genveje'!$AQ$10:$AS$25,2,0) -> 0.0787 | AE28: 0.083 | BB28: 0.089 | BC28: 1
L29: =$L$27 -> IEC 947-2 | M29: ='Lister og genveje'!$D$39 -> C60N | N29: 2 | O29: B | P29: ='Lister og genveje'!$F$38 -> 1 Pol | Q29: =INDEX('Lister og genveje'!$E$39:$I$46,MATCH(M29,'Lister og genveje'!$D$39:$D$46,0),MATCH(P29,'Lister og genveje'!$E$38:$I$38,0),1) -> 3 | R29: =HLOOKUP(O29,'Lister og genveje'!$E$50:$G$52,2,0) -> 3.2 | S29: =HLOOKUP(O29,'Lister og genveje'!$E$50:$G$52,3,0) -> 4.8 | T29: =VLOOKUP(M29,'Lister og genveje'!$D$39:$J$46,7,0) -> 0.75 | Z29: 5 G | AA29: Kobber kabel | AB29: 6 | AC29: NOIKX-Flex | AD29: =VLOOKUP(Tabel3[[#This Row],[Tværsnit]],'Lister og genveje'!$AQ$10:$AS$25,2,0) -> 3.08 | AE29: 0.097 | BB29: 1.15 | BC29: 4
H30: S [ kVA ] | L30: =$L$27 -> IEC 947-2 | M30: ='Lister og genveje'!$D$39 -> C60N | N30: 3 | O30: B | P30: ='Lister og genveje'!$F$38 -> 1 Pol | Q30: =INDEX('Lister og genveje'!$E$39:$I$46,MATCH(M30,'Lister og genveje'!$D$39:$D$46,0),MATCH(P30,'Lister og genveje'!$E$38:$I$38,0),1) -> 3 | R30: =HLOOKUP(O30,'Lister og genveje'!$E$50:$G$52,2,0) -> 3.2 | S30: =HLOOKUP(O30,'Lister og genveje'!$E$50:$G$52,3,0) -> 4.8 | T30: =VLOOKUP(M30,'Lister og genveje'!$D$39:$J$46,7,0) -> 0.75 | Z30: 5 G | AA30: Kobber kabel | AB30: 10 | AC30: NOIKX-Flex | AD30: =VLOOKUP(Tabel3[[#This Row],[Tværsnit]],'Lister og genveje'!$AQ$10:$AS$25,2,0) -> 1.83 | AE30: 0.092 | BB30: 0.085 | BC30: 2
A31: Tilbage til forsiden | H31: I [ A ] | L31: =$L$27 -> IEC 947-2 | M31: ='Lister og genveje'!$D$39 -> C60N | N31: 4 | O31: B | P31: ='Lister og genveje'!$F$38 -> 1 Pol | Q31: =INDEX('Lister og genveje'!$E$39:$I$46,MATCH(M31,'Lister og genveje'!$D$39:$D$46,0),MATCH(P31,'Lister og genveje'!$E$38:$I$38,0),1) -> 3 | R31: =HLOOKUP(O31,'Lister og genveje'!$E$50:$G$52,2,0) -> 3.2 | S31: =HLOOKUP(O31,'Lister og genveje'!$E$50:$G$52,3,0) -> 4.8 | T31: =VLOOKUP(M31,'Lister og genveje'!$D$39:$J$46,7,0) -> 0.75 | Z31: 5 G | AA31: Kobber kabel | AB31: 16 | AC31: NOIKX-Flex | AD31: =VLOOKUP(Tabel3[[#This Row],[Tværsnit]],'Lister og genveje'!$AQ$10:$AS$25,2,0) -> 1.15 | AE31: 0.088 | BB31: 0.088 | BC31: 2
H32: P [ W ] | L32: =$L$27 -> IEC 947-2 | M32: ='Lister og genveje'!$D$39 -> C60N | N32: 6 | O32: B | P32: ='Lister og genveje'!$F$38 -> 1 Pol | Q32: =INDEX('Lister og genveje'!$E$39:$I$46,MATCH(M32,'Lister og genveje'!$D$39:$D$46,0),MATCH(P32,'Lister og genveje'!$E$38:$I$38,0),1) -> 3 | R32: =HLOOKUP(O32,'Lister og genveje'!$E$50:$G$52,2,0) -> 3.2 | S32: =HLOOKUP(O32,'Lister og genveje'!$E$50:$G$52,3,0) -> 4.8 | T32: =VLOOKUP(M32,'Lister og genveje'!$D$39:$J$46,7,0) -> 0.75 | Z32: 5 G | AA32: Kobber kabel | AB32: 25 | AC32: NOIKX-Flex | AD32: =VLOOKUP(Tabel3[[#This Row],[Tværsnit]],'Lister og genveje'!$AQ$10:$AS$25,2,0) -> 0.727 | AE32: 0.089 | BB32: 1.83 | BC32: 4
L33: =$L$27 -> IEC 947-2 | M33: ='Lister og genveje'!$D$39 -> C60N | N33: 10 | O33: B | P33: ='Lister og genveje'!$F$38 -> 1 Pol | Q33: =INDEX('Lister og genveje'!$E$39:$I$46,MATCH(M33,'Lister og genveje'!$D$39:$D$46,0),MATCH(P33,'Lister og genveje'!$E$38:$I$38,0),1) -> 3 | R33: =HLOOKUP(O33,'Lister og genveje'!$E$50:$G$52,2,0) -> 3.2 | S33: =HLOOKUP(O33,'Lister og genveje'!$E$50:$G$52,3,0) -> 4.8 | T33: =VLOOKUP(M33,'Lister og genveje'!$D$39:$J$46,7,0) -> 0.75 | Z33: 5 G | AA33: Kobber kabel | AB33: 35 | AC33: NOIKX-Flex | AD33: =VLOOKUP(Tabel3[[#This Row],[Tværsnit]],'Lister og genveje'!$AQ$10:$AS$25,2,0) -> 0.525 | AE33: 0.085 | BB33: 0.089 | BC33: 2
L34: =$L$27 -> IEC 947-2 | M34: ='Lister og genveje'!$D$39 -> C60N | N34: 13 | O34: B | P34: ='Lister og genveje'!$F$38 -> 1 Pol | Q34: =INDEX('Lister og genveje'!$E$39:$I$46,MATCH(M34,'Lister og genveje'!$D$39:$D$46,0),MATCH(P34,'Lister og genveje'!$E$38:$I$38,0),1) -> 3 | R34: =HLOOKUP(O34,'Lister og genveje'!$E$50:$G$52,2,0) -> 3.2 | S34: =HLOOKUP(O34,'Lister og genveje'!$E$50:$G$52,3,0) -> 4.8 | T34: =VLOOKUP(M34,'Lister og genveje'!$D$39:$J$46,7,0) -> 0.75 | Z34: 3 X | AA34: Kobber kabel | AB34: 70 + 35 | AC34: NOSP-CU | AD34: ='Lister og genveje'!AR19 -> 0.269 | AE34: 0.079 | BB34: 0.092 | BC34: 2
L35: =$L$27 -> IEC 947-2 | M35: ='Lister og genveje'!$D$39 -> C60N | N35: 16 | O35: B | P35: ='Lister og genveje'!$F$38 -> 1 Pol | Q35: =INDEX('Lister og genveje'!$E$39:$I$46,MATCH(M35,'Lister og genveje'!$D$39:$D$46,0),MATCH(P35,'Lister og genveje'!$E$38:$I$38,0),1) -> 3 | R35: =HLOOKUP(O35,'Lister og genveje'!$E$50:$G$52,2,0) -> 3.2 | S35: =HLOOKUP(O35,'Lister og genveje'!$E$50:$G$52,3,0) -> 4.8 | T35: =VLOOKUP(M35,'Lister og genveje'!$D$39:$J$46,7,0) -> 0.75 | Z35: 3 X | AA35: Kobber kabel | AB35: 95 + 50 | AC35: NOSP-CU | AD35: ='Lister og genveje'!AR20 -> 0.194 | AE35: 0.077 | BB35: 3.08 | BC35: 4
L36: =$L$27 -> IEC 947-2 | M36: ='Lister og genveje'!$D$39 -> C60N | N36: 20 | O36: B | P36: ='Lister og genveje'!$F$38 -> 1 Pol | Q36: =INDEX('Lister og genveje'!$E$39:$I$46,MATCH(M36,'Lister og genveje'!$D$39:$D$46,0),MATCH(P36,'Lister og genveje'!$E$38:$I$38,0),1) -> 3 | R36: =HLOOKUP(O36,'Lister og genveje'!$E$50:$G$52,2,0) -> 3.2 | S36: =HLOOKUP(O36,'Lister og genveje'!$E$50:$G$52,3,0) -> 4.8 | T36: =VLOOKUP(M36,'Lister og genveje'!$D$39:$J$46,7,0) -> 0.75 | Z36: 3 X | AA36: Kobber kabel | AB36: 120 + 70 | AC36: NOSP-CU | AD36: ='Lister og genveje'!AR21 -> 0.155 | AE36: 0.077 | BB36: 0.094 | BC36: 2
L37: =$L$27 -> IEC 947-2 | M37: ='Lister og genveje'!$D$39 -> C60N | N37: 25 | O37: B | P37: ='Lister og genveje'!$F$38 -> 1 Pol | Q37: =INDEX('Lister og genveje'!$E$39:$I$46,MATCH(M37,'Lister og genveje'!$D$39:$D$46,0),MATCH(P37,'Lister og genveje'!$E$38:$I$38,0),1) -> 3 | R37: =HLOOKUP(O37,'Lister og genveje'!$E$50:$G$52,2,0) -> 3.2 | S37: =HLOOKUP(O37,'Lister og genveje'!$E$50:$G$52,3,0) -> 4.8 | T37: =VLOOKUP(M37,'Lister og genveje'!$D$39:$J$46,7,0) -> 0.75 | Z37: 3 X | AA37: Kobber kabel | AB37: 185 + 95 | AC37: NOSP-CU | AD37: ='Lister og genveje'!AR23 -> 0.1017 | AE37: 0.077 | BB37: 0.097 | BC37: 2
D38: Automatsikring | E38: kurve | F38: 1 Pol | G38: Flere poler | H38: MIN [ A ] | I38: MAX [ A ] | J38: Ics | L38: =$L$27 -> IEC 947-2 | M38: ='Lister og genveje'!$D$39 -> C60N | N38: 32 | O38: B | P38: ='Lister og genveje'!$F$38 -> 1 Pol | Q38: =INDEX('Lister og genveje'!$E$39:$I$46,MATCH(M38,'Lister og genveje'!$D$39:$D$46,0),MATCH(P38,'Lister og genveje'!$E$38:$I$38,0),1) -> 3 | R38: =HLOOKUP(O38,'Lister og genveje'!$E$50:$G$52,2,0) -> 3.2 | S38: =HLOOKUP(O38,'Lister og genveje'!$E$50:$G$52,3,0) -> 4.8 | T38: =VLOOKUP(M38,'Lister og genveje'!$D$39:$J$46,7,0) -> 0.75 | Z38: 4 X | AA38: Aluminium kabel | AB38: 16 | AC38: NOIK-AL-M | AD38: =VLOOKUP(Tabel3[[#This Row],[Tværsnit]],'Lister og genveje'!$AQ$10:$AS$25,3,1) -> 1.91 | AE38: 0.069 | BB38: 4.61 | BC38: 2
D39: C60N | F39: 3 | G39: 10 | H39: 1 | I39: 63 | J39: 0.75 | L39: =$L$27 -> IEC 947-2 | M39: ='Lister og genveje'!$D$39 -> C60N | N39: 40 | O39: B | P39: ='Lister og genveje'!$F$38 -> 1 Pol | Q39: =INDEX('Lister og genveje'!$E$39:$I$46,MATCH(M39,'Lister og genveje'!$D$39:$D$46,0),MATCH(P39,'Lister og genveje'!$E$38:$I$38,0),1) -> 3 | R39: =HLOOKUP(O39,'Lister og genveje'!$E$50:$G$52,2,0) -> 3.2 | S39: =HLOOKUP(O39,'Lister og genveje'!$E$50:$G$52,3,0) -> 4.8 | T39: =VLOOKUP(M39,'Lister og genveje'!$D$39:$J$46,7,0) -> 0.75 | Z39: 4 X | AA39: Aluminium kabel | AB39: 25 | AC39: NOIK-AL-M | AD39: =VLOOKUP(Tabel3[[#This Row],[Tværsnit]],'Lister og genveje'!$AQ$10:$AS$25,3,1) -> 1.2 | AE39: 0.084 | BB39: 0.096 | BC39: 1
D40: C60H | F40: 3 | G40: 15 | H40: 1 | I40: 63 | J40: 0.5 | L40: =$L$27 -> IEC 947-2 | M40: ='Lister og genveje'!$D$39 -> C60N | N40: 50 | O40: B | P40: ='Lister og genveje'!$F$38 -> 1 Pol | Q40: =INDEX('Lister og genveje'!$E$39:$I$46,MATCH(M40,'Lister og genveje'!$D$39:$D$46,0),MATCH(P40,'Lister og genveje'!$E$38:$I$38,0),1) -> 3 | R40: =HLOOKUP(O40,'Lister og genveje'!$E$50:$G$52,2,0) -> 3.2 | S40: =HLOOKUP(O40,'Lister og genveje'!$E$50:$G$52,3,0) -> 4.8 | T40: =VLOOKUP(M40,'Lister og genveje'!$D$39:$J$46,7,0) -> 0.75 | Z40: 4 X | AA40: Aluminium kabel | AB40: 50 | AC40: NOIK-AL-M | AD40: =VLOOKUP(Tabel3[[#This Row],[Tværsnit]],'Lister og genveje'!$AQ$10:$AS$25,3,1) -> 0.641 | AE40: 0.081 | BB40: 0.099 | BC40: 1
...
