Workbook

Sheet Dimensionering
D4: Stikledning
D6: Oplægningsmetode | E6: IB | F6: IN | G6: Grader | H6: Antal kabler | I6: Anneks A | J6: Anneks B | K6: Tabel | L6: Termisk Modstand | M6: KT | N6: KS | O6: Iz nødvedig | P6: Strømværdi kabel CU | Q6: Strømværdi kabel AL
D7: kabelstige (transformer) | E7: 144 A | F7: 144 | G7: 20 | H7: 2 | I7: 34 | J7: E | K7: B.52.12 | M7: 1.08 | N7: 0.87 | O7: =$F$7/(N7*M7) -> 153.2567 | P7: 50mm2 192A | Q7: 70mm2 187A
D8: direkte i jord | E8: 144 A | F8: 144 | G8: 20 | H8: 1 | I8: 72 | J8: D2 | K8: B.52.5 | L8: 1.5 | M8: 1 | N8: 0.8 | O8: =$F$7/(N8*M8*L8) -> 120 | P8: 50mm2 153A
D9: Rør i fundament | E9: 144 A | F9: 144 | G9: 20 | H9: 1 | I9: 60 | J9: B2 | K9: B.52.5 | L9: 1.5 | M9: 1 | N9: 1 | O9: =$F$7/(N9*M9*L9) -> 96 | P9: 35mm2 128A
D10: Bygningshulrum (Tavle) | E10: 144 A | F10: 144 | G10: 30 | H10: 1 | I10: 40 | J10: B1 | K10: B.52.5 | L10: 1 | M10: 1.04 | N10: 1 | O10: =$F$7/(N10*M10*L10) -> 138.46154 | P10: 50mm2 175A
D15: Gruppeledning Kværn
D17: Oplægningsmetode | E17: IB | F17: IN | G17: Grader | H17: Antal kabler | I17: Anneks A | J17: Anneks B | K17: Tabel | L17: Termisk Modstand | M17: KT | N17: KS | O17: Iz nødvedig | P17: Strømværdi kabel CU | Q17: Strømværdi kabel AL
D18: Kabelfelt | E18: 28 | F18: 32 | G18: 30 | H18: 5 | I18: 40 | J18: B2 | K18: B.52.5 kol. 5 | L18: 1 | M18: 1 | N18: 0.6 | O18: =$F$18/(N18*M18*L18) -> 53.333333 | P18: 10 mm2 60
D19: Kabelstige | E19: 28 | F19: 32 | G19: 25 | H19: 5 | I19: 34 | J19: E/F | K19: B.52.12 | L19: 1 | M19: 1.04 | N19: 0.6 | O19: =$F$18/(N19*M19*L19) -> 51.282051 | P19: 6 mm2 54
D20: Gitterbakke | E20: 28 | F20: 32 | G20: 25 | H20: 5 | I20: 32 | J20: E/F | K20: B.52.12 | L20: 1 | M20: 1.04 | N20: 0.73 | O20: =$F$18/(N20*M20*L20) -> 42.149631 | P20: 6 mm2 54
D21: Rør på væg | E21: 28 | F21: 32 | G21: 25 | H21: 1 | I21: 5 | J21: B2 | K21: B.52.5 kol. 5 | L21: 1 | M21: 1.04 | N21: 1 | O21: =$F$18/(N21*M21*L21) -> 30.769231 | P21: 4 mm2 35
D23: Gruppeledning Lys/udendørs
D25: Oplægningsmetode | E25: IB | F25: IN | G25: Grader | H25: Antal kabler | I25: Anneks A | J25: Anneks B | K25: Tabel | L25: Termisk Modstand | M25: KT | N25: KS | O25: Iz nødvedig | P25: Strømværdi kabel CU | Q25: Strømværdi kabel AL
D26: Gitterbakke | E26: 1.85 | F26: 6 | G26: 25 | H26: 5 | I26: 32 | J26: E/F | K26: B.52.12 | L26: 1 | M26: 1.04 | N26: 0.96 | O26: 7,9A | P26: 1,5mm^2 26A
D27: kabelstige | E27: 1.85 | F27: 6 | G27: 25 | H27: 5 | I27: 34 | J27: F | K27: B.52.12 | L27: 1 | M27: 1.04 | N27: 1 | O27: 5,77A | P27: 1,5mm^2 26A
D28: kabelfelt | E28: 1.85 | F28: 6 | G28: 30 | H28: 5 | I28: 40 | J28: B1 | K28: B.52.5 | L28: 1 | M28: 1 | N28: 0.6 | O28: 10A | P28: 1,5mm^2 20A
D29: Rør på væg | E29: 1.85 | F29: 6 | G29: 25 | H29: 1 | I29: 5 | J29: B2 | K29: B.52.3 | L29: 1 | M29: 1.04 | N29: 1 | O29: 5,8A | P29: 1,5mm^2 22A
D34: Gruppeledning Horse trainer
D36: Oplægningsmetode | E36: IB | F36: IN | G36: Grader | H36: Antal kabler | I36: Anneks A | J36: Anneks B | K36: Tabel | L36: Termisk Modstand | M36: KT | N36: KS | O36: Iz nødvedig | P36: Strømværdi kabel CU | Q36: Strømværdi kabel AL
D37: Gitterbakke | E37: 16 | F37: 16 | G37: 25 | H37: 5 | I37: 32 | J37: E/F | K37: B.52.12 | L37: 1 | M37: 1.04 | N37: 0.96 | O37: 16,03A | P37: 2,5mm^2 36A
D38: Kabelstige | E38: 16 | F38: 16 | G38: 25 | H38: 5 | I38: 34 | J38: F | K38: B.52.12 | L38: 1 | M38: 1.04 | N38: 1 | O38: 15,4A | P38: 1,5mm^2 23A
D39: kabelfelt | E39: 16 | F39: 16 | G39: 30 | H39: 5 | I39: 40 | J39: B1 | K39: B.52.5 | L39: 1 | M39: 1 | N39: 0.6 | O39: 26,6A | P39: 2,5mm^2 28A
D41: Tilledning
D43: Oplægningsmetode | E43: IB | F43: IN | G43: Grader | H43: Antal kabler | I43: Anneks A | J43: Anneks B | K43: Tabel | L43: Termisk Modstand | M43: KT | N43: KS | O43: Iz nødvedig | P43: Strømværdi kabel CU | Q43: Strømværdi kabel AL
D44: Fri luft | E44: 16 | F44: 16 | G44: 25 | H44: 1 | I44: 22 | J44: E | K44: B.52.12 | L44: 1 | M44: 1.04 | N44: 1 | O44: 15,4A | P44: 1,5mm^2 23A
D47: Gruppeledning Ventilation
D49: Oplægningsmetode | E49: IB | F49: IN | G49: Grader | H49: Antal kabler | I49: Anneks A | J49: Anneks B | K49: Tabel | L49: Termisk Modstand | M49: KT | N49: KS | O49: Iz nødvedig | P49: Strømværdi kabel CU | Q49: Strømværdi kabel AL
D50: kabelfelt | E50: 8.24 | F50: 10 | G50: 30 | H50: 5 | I50: 40 | J50: B1 | K50: B.52.5 | L50: 1 | M50: 1 | N50: 0.6 | O50: 16,7A | P50: 1,5mm^2 20A
D51: Kabelstige | E51: 8.24 | F51: 10 | G51: 25 | H51: 5 | I51: 34 | J51: F | K51: B.52.12 | L51: 1 | M51: 1.04 | N51: 1 | O51: 9,6A | P51: 1,5mm^2 23A
D52: Gitterbakke | E52: 8.24 | F52: 10 | G52: 25 | H52: 5 | I52: 32 | J52: E/F | K52: B.52.12 | L52: 1 | M52: 1.04 | N52: 0.96 | O52: 10A | P52: 1,5mm^2 23A
D53: Rør på væg | E53: 8.24 | F53: 10 | G53: 25 | H53: 1 | I53: 5 | J53: B2 | K53: B.52.3 | L53: 1 | M53: 1.04 | N53: 1 | O53: 9,6A | P53: 1,5mm^2 22A
D59: Byggestrøm Drejebænk
D61: Oplægningsmetode | E61: IB | F61: IN | G61: Grader | H61: Antal kabler | I61: Anneks A | J61: Anneks B | K61: Tabel | L61: Termisk Modstand | M61: KT | N61: KS | O61: Iz nødvedig | P61: Strømværdi kabel CU | Q61: Strømværdi kabel AL
D62: kabelfelt | E62: 25 | F62: 25 | G62: 20 | H62: 3 | I62: 40 | J62: B1 | K62: B.52.5 | L62: 1 | M62: 1.08 | N62: 0.7 | O62: =F62/(N62*M62*L62) -> 33.068783 | P62: 4 mm2 37 A
D63: Kabelstige | E63: 25 | F63: 25 | G63: 20 | H63: 2 | I63: 34 | J63: E/F | K63: B.52.12 | L63: 1 | M63: 1.08 | N63: 0.87 | O63: =F63/(N63*M63*L63) -> 26.607067 | P63: 2,5 mm2 32 A
D64: ophængt på kabelspyd | E64: 25 | F64: 25 | G64: 20 | H64: 2 | I64: 35 | J64: E/F | K64: B.52.12 | L64: 1 | M64: 1.08 | N64: 0.87 | O64: =F64/(N64*M64*L64) -> 26.607067 | P64: 2,5 mm2 32 A
D68: Byggestrøm til tavle 1
D70: Oplægningsmetode | E70: IB | F70: IN | G70: Grader | H70: Antal kabler | I70: Anneks A | J70: Anneks B | K70: Tabel | L70: Termisk Modstand | M70: KT | N70: KS | O70: Iz nødvedig | P70: Strømværdi kabel CU | Q70: Strømværdi kabel AL
D71: kabelfelt | E71: 57.6 | F71: 63 | G71: 20 | H71: 3 | I71: 40 | J71: B1 | K71: B.52.5 | L71: 1 | M71: 1.08 | N71: 0.7 | O71: =F71/(N71*M71*L71) -> 83.333333 | P71: 16 mm2 88 A
...

Sheet Spændingsfald (UdeLys)
A1: Stikledning | B1: Spænding | C1: b | D1: Længde | E1: kvadrat og ledertype | F1: Rtabel | G1: ρ-værdi | H1: cosȹ | I1: IN | J1: delta U | K1: delta U% | Q1: Enhed | R1: pris pr meter listepris | S1: pris
B2: 400 | C2: =VLOOKUP(B2,'Spændingsfald (UdeLys)'!$C$18:$D$21,2) -> 1 | D2: 55 | E2: 50 | F2: =VLOOKUP(E2,$A$19:$B$66,2,FALSE) -> 0.389 | G2: 1.28 | H2: 0.929 | I2: 144 | J2: =C2*D2*(F2*G2*H2)*I2/1000 -> 3.663536 | K2: =J2*SQRT(3)/400 -> 0.015863576 | M2: Rulleliste (vælg værdi) | N2: Indtast værdi | O2: Faste værdier | Q2: pris 4x95AL | R2: 275 | S2: =D2*R2 -> 15125
M3: OBS SE HER OVER!!!!!!!
A4: Hovedledning 1 | C4: b | D4: Længde | E4: kvadrat og ledertype | F4: Rtabel | G4: ρ-værdi | H4: cosȹ | I4: IN | J4: delta U | K4: delta U%
B5: 400 | C5: =VLOOKUP(B5,'Spændingsfald (UdeLys)'!$C$19:$D$21,2) -> 1 | D5: 60 | E5: 1.5 | F5: 7.41 | G5: 1.28 | H5: 0.8 | I5: 1.83 | J5: =C5*D5*(F5*G5*H5)*I5/1000 -> 0.83314483 | K5: =J5*SQRT(3)/400 -> 0.0036076229
Q6: 5g16 | R6: 285 | S6: =D5*R6 -> 17100
A8: HL 2 | C8: b | D8: Længde | E8: kvadrat og ledertype | F8: Rtabel | G8: ρ-værdi | H8: cosȹ | I8: IN | J8: delta U | K8: delta U%
B9: 400 | C9: =VLOOKUP(B9,C20:D21,2) -> 1 | D9: 0 | E9: 35 | F9: =VLOOKUP(E9,$A$19:$B$66,2,FALSE) -> 0.525 | G9: 1.28 | H9: 0.92 | I9: 20 | J9: =C9*D9*(F9*G9*H9)*I9/1000 -> 0 | K9: =J9*SQRT(3)/400 -> 0 | Q9: 5g10 | R9: 209 | S9: =R9*D9 -> 0
Q10: 5g6 | R10: 110 | S10: =R10*D9 -> 0
A12: Gruppekabel | C12: b | D12: Længde | E12: kvadrat og ledertype | F12: Rtabel | G12: ρ-værdi | H12: cosȹ | I12: IN | J12: delta U | K12: delta U%
B13: 400 | C13: 1 | D13: 0 | E13: 2.5 | F13: 7.41 | G13: 1.28 | H13: 0.8 | I13: 16 | J13: =C13*D13*(F13*G13*H13)*I13/1000 -> 0 | K13: =J13*SQRT(3)/400 -> 0 | Q13: 3g2,5 | R13: 28.43 | S13: =R13*D13 -> 0
Q14: 3g1,5 | R14: 16.33 | S14: =R14*D13 -> 0
J15: total | K15: =J2+J5+J9+J13 -> 4.4966809
J16: total % | K16: =(J2+J5+J9+J13)*SQRT(3)/400 -> 0.019471199
A18: tværsnit | B18: kobblerleder ohm/km | C18: Kolonne1 | D18: Kolonne2
A19: 0.5 | C19: Spænding | D19: værdi
A20: 0.75 | C20: 230 | D20: 2
A21: 1 | C21: 400 | D21: 1
A22: 1.5 | B22: 12.1
A23: 2.5 | B23: 7.41
A24: 4 | B24: 4.61
A25: 6 | B25: 3.08
A26: 10 | B26: 1.83
A27: 16 | B27: 1.15
A28: 25 | B28: 0.728
A29: 35 | B29: 0.525
A30: 50 | B30: 0.389
A31: 70 | B31: 0.27
A32: 95 | B32: 0.195
A33: 120 | B33: 0.155
... A37: 300 | B37: 0.0642
B38: Alu
A39: al16 | B39: 1.91
A40: al25 | B40: 1.2
A41: al35 | B41: 0.868
A42: al50 | B42: 0.841
A43: al70 | B43: 0.443
A44: al95 | B44: 0.32
A45: al120 | B45: 0.254
A46: al150 | B46: 0.208
...

Sheet Spændingsfald(HTwater)
A1: Stikledning | B1: Spænding | C1: b | D1: Længde | E1: kvadrat og ledertype | F1: Rtabel | G1: ρ-værdi | H1: cosȹ | I1: IN | J1: delta U | K1: delta U% | Q1: Enhed | R1: pris pr meter listepris | S1: pris
B2: 400 | C2: =VLOOKUP(B2,'Spændingsfald(HTwater)'!$C$18:$D$21,2) -> 1 | D2: 55 | E2: 50 | F2: =VLOOKUP(E2,$A$19:$B$66,2,FALSE) -> 0.389 | G2: 1.28 | H2: 0.92 | I2: 144 | J2: =C2*D2*(F2*G2*H2)*I2/1000 -> 3.6280443 | K2: =J2*SQRT(3)/400 -> 0.015709893 | M2: Rulleliste (vælg værdi) | N2: Indtast værdi | O2: Faste værdier | Q2: 4x95AL | R2: 275 | S2: =D2*R2 -> 15125
M3: OBS SE HER OVER!!!!!!!
A4: Hovedledning 1 | C4: b | D4: Længde | E4: kvadrat og ledertype | F4: Rtabel | G4: ρ-værdi | H4: cosȹ | I4: IN | J4: delta U | K4: delta U%
B5: 400 | C5: =VLOOKUP(B5,'Spændingsfald(HTwater)'!$C$19:$D$21,2) -> 1 | D5: 15 | E5: 2.5 | F5: =VLOOKUP(E5,$A$19:$B$66,2,FALSE) -> 7.41 | G5: 1.28 | H5: 0.8 | I5: 16 | J5: =C5*D5*(F5*G5*H5)*I5/1000 -> 1.8210816 | K5: =J5*SQRT(3)/400 -> 0.0078855146
Q6: 5g16 | R6: 285 | S6: =D5*R6 -> 4275
A8: HL 2 | C8: b | D8: Længde | E8: kvadrat og ledertype | F8: Rtabel | G8: ρ-værdi | H8: cosȹ | I8: IN | J8: delta U | K8: delta U%
B9: 400 | C9: =VLOOKUP(B9,C20:D21,2) -> 1 | E9: 6 | F9: =VLOOKUP(E9,$A$19:$B$66,2,FALSE) -> 3.08 | G9: 1.28 | H9: 0.92 | I9: 0 | J9: =C9*D9*(F9*G9*H9)*I9/1000 -> 0 | K9: =J9*SQRT(3)/400 -> 0 | Q9: 5g10 | R9: 209 | S9: =R9*D9 -> 0
Q10: 5g6 | R10: 110 | S10: =R10*D9 -> 0
A12: Gruppekabel | C12: b | D12: Længde | E12: kvadrat og ledertype | F12: Rtabel | G12: ρ-værdi | H12: cosȹ | I12: IN | J12: delta U | K12: delta U%
B13: 230 | C13: =VLOOKUP(B13,C20:D21,2) -> 2 | E13: 1.5 | F13: =VLOOKUP(E13,$A$19:$B$66,2,FALSE) -> 12.1 | G13: 1.28 | H13: 0.92 | I13: 0 | J13: =C13*D13*(F13*G13*H13)*I13/1000 -> 0 | K13: =J13*SQRT(3)/400 -> 0 | Q13: 3g2,5 | R13: 28.43 | S13: =R13*D13 -> 0
Q14: 3g1,5 | R14: 16.33 | S14: =R14*D13 -> 0
J15: total | K15: =J2+J5+J9+J13 -> 5.4491259
J16: total % | K16: =(J2+J5+J9+J13)*SQRT(3)/400 -> 0.023595407
A18: tværsnit | B18: kobblerleder ohm/km | C18: Kolonne1 | D18: Kolonne2
A19: 0.5 | C19: Spænding | D19: værdi
A20: 0.75 | C20: 230 | D20: 2
A21: 1 | C21: 400 | D21: 1
A22: 1.5 | B22: 12.1
A23: 2.5 | B23: 7.41
A24: 4 | B24: 4.61
A25: 6 | B25: 3.08
A26: 10 | B26: 1.83
A27: 16 | B27: 1.15
A28: 25 | B28: 0.728
A29: 35 | B29: 0.525
A30: 50 | B30: 0.389
A31: 70 | B31: 0.27
A32: 95 | B32: 0.195
A33: 120 | B33: 0.155
... A37: 300 | B37: 0.0642
B38: Alu
A39: al16 | B39: 1.91
A40: al25 | B40: 1.2
A41: al35 | B41: 0.868
A42: al50 | B42: 0.841
A43: al70 | B43: 0.443
A44: al95 | B44: 0.32
A45: al120 | B45: 0.254
A46: al150 | B46: 0.208
...

Sheet Spændingsf. Ventilation
A2: Stikledning | B2: Spænding | C2: b | D2: Længde | E2: kvadrat og ledertype | F2: Rtabel | G2: ρ-værdi | H2: cosȹ | I2: Ib | J2: delta U | K2: delta U% | Q2: Enhed | R2: pris pr meter listepris | S2: pris
B3: 400 | C3: =VLOOKUP(B3,'Spændingsf. Ventilation'!$C$19:$D$22,2) -> 1 | D3: 55 | E3: 50 | F3: =VLOOKUP(E3,$A$20:$B$67,2,FALSE) -> 0.389 | G3: 1.28 | H3: 0.97 | I3: 116 | J3: =C3*D3*(F3*G3*H3)*I3/1000 -> 3.0814277 | K3: =J3*SQRT(3)/400 -> 0.013342973 | M3: Rulleliste (vælg værdi) | N3: Indtast værdi | O3: Faste værdier | Q3: pris 4x95AL | R3: 275 | S3: =D3*R3 -> 15125
M4: OBS SE HER OVER!!!!!!!
A5: Gruppekabel | C5: b | D5: Længde | E5: kvadrat og ledertype | F5: Rtabel | G5: ρ-værdi | H5: cosȹ | I5: IN | J5: delta U | K5: delta U%
B6: 230 | C6: =VLOOKUP(B6,'Spændingsf. Ventilation'!$C$20:$D$22,2) -> 2 | D6: 15 | E6: 2.5 | F6: =VLOOKUP(E6,$A$20:$B$67,2,FALSE) -> 7.41 | G6: 1.28 | H6: 0.97 | I6: 13 | J6: =C6*D6*(F6*G6*H6)*I6/1000 -> 3.5880998 | K6: =J6*SQRT(3)/400 -> 0.015536928
Q7: 5g16 | R7: 285 | S7: =D6*R7 -> 4275
A9: HL 2 | C9: b | D9: Længde | E9: kvadrat og ledertype | F9: Rtabel | G9: ρ-værdi | H9: cosȹ | I9: IN | J9: delta U | K9: delta U%
B10: 230 | C10: =VLOOKUP(B10,C21:D22,2) -> 2 | D10: 0 | E10: 4 | F10: =VLOOKUP(E10,$A$20:$B$67,2,FALSE) -> 4.61 | G10: 1.28 | H10: 0.97 | I10: 13 | J10: =C10*D10*(F10*G10*H10)*I10/1000 -> 0 | K10: =J10*SQRT(3)/400 -> 0 | Q10: 5g10 | R10: 209 | S10: =R10*D10 -> 0
Q11: 5g6 | R11: 110 | S11: =R11*D10 -> 0
A13: Gruppekabel | C13: b | D13: Længde | E13: kvadrat og ledertype | F13: Rtabel | G13: ρ-værdi | H13: cosȹ | I13: IN | J13: delta U | K13: delta U%
B14: 230 | C14: =VLOOKUP(B14,C21:D22,2) -> 2 | D14: 60 | E14: 2.5 | F14: 7.41 | G14: 1.28 | H14: 0.8 | I14: 6 | J14: =C14*D14*(F14*G14*H14)*I14/1000 -> 5.4632448 | K14: =J14*SQRT(3)/400 -> 0.023656544 | Q14: 3g2,5 | R14: 28.43 | S14: =R14*D14 -> 1705.8
Q15: 3g1,5 | R15: 16.33 | S15: =R15*D14 -> 979.8
J16: total | K16: =J3+J6+J10+J14 -> 12.132772
J17: total % | K17: =(J3+J6+J10+J14)*SQRT(3)/400 -> 0.052536445
A19: tværsnit | B19: kobblerleder ohm/km | C19: Kolonne1 | D19: Kolonne2
A20: 0.5 | C20: Spænding | D20: værdi
A21: 0.75 | C21: 230 | D21: 2
A22: 1 | C22: 400 | D22: 1
A23: 1.5 | B23: 12.1
A24: 2.5 | B24: 7.41
A25: 4 | B25: 4.61
A26: 6 | B26: 3.08
A27: 10 | B27: 1.83
A28: 16 | B28: 1.15
A29: 25 | B29: 0.728
A30: 35 | B30: 0.525
A31: 50 | B31: 0.389
A32: 70 | B32: 0.27
A33: 95 | B33: 0.195
A34: 120 | B34: 0.155
... A38: 300 | B38: 0.0642
B39: Alu
A40: al16 | B40: 1.91
A41: al25 | B41: 1.2
A42: al35 | B42: 0.868
A43: al50 | B43: 0.841
A44: al70 | B44: 0.443
A45: al95 | B45: 0.32
A46: al120 | B46: 0.254
A47: al150 | B47: 0.208
...

Sheet Fællesinstallationer
A2: Belastningsoversigt
B4: Titel | C4: L1 | D4: L2 | E4: L3 | F4: Tavlekomponent | G4: RCD'er
A5: Gr 1 | B5: VM1 | C5: 9.1 | F5: d01 10A (1P+N)
A6: Gr 2 | B6: VM2 | D6: 9.1 | F6: d01 10A (1P+N)
A7: Gr 3 | B7: TT1 | E7: 5.4 | F7: d01 10A (1P+N)
A8: Gr 4 | B8: TT2 | E8: 5.4 | F8: d01 10A (1P+N)
A9: Gr 5 | B9: ST.RULLE | C9: 4.3 | D9: 4.3 | E9: 4.3 | F9: d01 10A (3P+N)
A10: Gr 6 | B10: VENT1 | C10: 13 | F10: d01 13A (1P+N)
A11: Gr 7 | B11: VENT2 | D11: 13 | F11: d01 13A (1P+N)
A12: Gr 8 | B12: KLD+LOFT LYS1 | C12: 3.5 | F12: d01 10A (1P+N)
A13: Gr 9 | B13: KLD+LOFT LYS2 | D13: 3.5 | F13: d01 10A (1P+N)
A14: Gr 10 | B14: KLD STIKK | E14: 10 | F14: d01 10A (1P+N)
A15: Gr 11 | B15: UDE LYS | D15: 10 | F15: d01 10A (1P+N)
A16: Gr 12 | B16: UDE STIKK | E16: 10 | F16: d01 10A (1P+N) | G16: RCD 1
A17: Gr 13 | B17: LYS1 OPG 5+7 | C17: 1.04 | F17: d01 6A (1P+N)
A18: Gr 14 | B18: LYS2 OPG 5+7 | D18: 1.04 | F18: d01 6A (1P+N)
A19: Gr 15 | B19: GASFYR | C19: 4.5 | F19: d01 10A (1P+N)
A20: Gr 16
A21: Gr 17
A22: Gr 18
A23: Gr 19
A24: Gr 20
A25: Gr 21
A26: Gr 22
A27: Gr 23
A28: Gr 24
A29: Gr 25
A30: Belastning | B30: IB | C30: =SUM(C5:C29) -> 35.44 | D30: =SUM(D5:D29) -> 40.94 | E30: =SUM(E5:E29) -> 35.1 | F30: ="Antal grupper "&COUNTA(F5:F29) -> Antal grupper 15 | G30: Antal RCD: 1
A31: Korrigeret belastning | B31: IB [A] | C31: =C30*IF(VALUE($B$33)>0,$B$33,$B$32) -> 28.352 | D31: =D30*IF(VALUE($B$33)>0,$B$33,$B$32) -> 32.752 | E31: =E30*IF(VALUE($B$33)>0,$B$33,$B$32) -> 28.08
A32: Samtidsfaktor (61439-3) | B32: =IF(COUNTA(B5:B20)>4,0.6,0.7) -> 0.6
A33: Samtidsfaktor (bestemt) | B33: 0.8
