Workbook

Sheet Forside
A1: KVALITETSLEDELSESSYSTEM · KLS
A2: Ifølge Sikkerhedsstyrelsen · BEK nr. 725 / 724 / 722 af 12. juni 2024
A4: ℹ️ VEJLEDNING · FORSIDE · Stamoplysninger
A5: 📌 HVAD ER DETTE ARK?
A6: Forsiden er KLS-systemets identitetskort. Den udfyldes én gang og holdes ajour. Informationerne her bruges af Dashboard og Tilsyn-arket til automatiske beregninger — forkerte oplysninger her smitter af på hele systemet.
A8: FELTERNES BETYDNING — udfyld fra top til bund
A9: 🏢 Virksomhedsnavn | C9: Skal matche præcis det navn, der er registreret på cvr.dk — brug Ctrl+C fra cvr.dk for at undgå stavefejl.
A10: 🔢 CVR-nummer | C10: 8-cifret. Er din autorisation tilknyttet et personligt CVR, skrives det her og ikke firmaCVR.
A11: ⚡ Autorisationstype | C11: Vælg fra rullemenuen. Har virksomheden el OG VVS-autorisation, vælg den primære og skriv den anden i parentes i feltet til højre.
A12: 🏛️ Kontrolinstans | C12: Normalt VALIDAN ApS. Skift kun hvis I bytter kontrolinstans — og opdater da straks også Tilsyn-arket.
A13: 📅 KLS godkendt dato + udløbsdato | C13: Udfyldes første gang KLS godkendes. Udløb = altid præcis 2 år frem. Når I fornyer, opdateres begge datoer. Dashboard viser automatisk advarsel ved udløb.
A15: ⚠️ VIGTIGT LOVKRAV: KLS SKAL fornyes inden 2-årsperiodens udløb. Udløber autorisationen mister I retten til at udføre lovpligtigt arbejde — der er ingen grace-periode.
A17: VIRKSOMHEDENS STAMOPLYSNINGER — udfyld alle felter
A18: Virksomhedsnavn:
A19: CVR-nummer:
A20: Adresse:
A21: Postnr. & By:
A22: Telefon:
A23: E-mail:
A24: Autorisationstype: | C24: El / VVS / Kloak / Gas / Asbest
A25: Autorisationsnummer:
A26: Fagligt ansvarlig:
A27: Kontrolinstans: | C27: VALIDAN ApS
A28: KLS godkendt dato:
A29: KLS udløbsdato:
A30: Version: | C30: 1.0
A31: Revideret dato: | C31: 02-06-2026
A34: SYSTEMINDHOLD — 14 ark dækker alle krav
A35: 1 | B35: Forside | C35: Stamoplysninger og systemindhold | G35: —
A36: 2 | B36: Kvalitetspolitik | C36: Virksomhedens kvalitetsmål og lovgrundlag | G36: Ledelse
A37: 3 | B37: Organisation | C37: Roller, ansvar og medarbejderkompetencer | G37: Ledelse
A38: 4 | B38: Procedurer | C38: 14 arbejdsprocedurer med versionsstyring | G38: KLS-ansvarlig
A39: 5 | B39: Slutkontrol EL | C39: Verifikationslog for el-installationer | G39: FA el
A40: 6 | B40: Slutkontrol VVS | C40: Verifikationslog for VVS-arbejder | G40: FA vvs
A41: 7 | B41: Slutkontrol Kloak | C41: Verifikationslog for kloakinstallationer | G41: FA kloak
A42: 8 | B42: Afvigelsesrapport | C42: Registrering og opfølgning på afvigelser | G42: FA / Ledelse
A43: 9 | B43: Intern Efterprøvning | C43: Ledelsens evaluering (min. 1 × om året) | G43: Ledelse
A44: 10 | B44: Kompetenceskema | C44: Medarbejderkvalifikationer og kursusplan | G44: Ledelse
A45: 11 | B45: Måleudstyr | C45: Kalibrering og kontrol af instrumenter | G45: FA el
A46: 12 | B46: Tilsyn | C46: Log over kontrolinstans-besøg og godkendelser | G46: Ledelse
...

Sheet Kvalitetspolitik
A1: KVALITETSPOLITIK
A2: Virksomhedens overordnede mål og forpligtelse til kvalitet
A4: ℹ️ VEJLEDNING · KVALITETSPOLITIK
A5: 📌 HVAD ER DETTE ARK?
A6: Kvalitetspolitikken er det dokument der viser at virksomheden har taget et aktivt ledelsesansvar for kvalitet. Kontrolinstansen læser den og spørger: Er den underskrevet? Er målene konkrete? Er den implementeret i hverdagen?
A8: KVALITETSMÅL · Erstat eksempel-målene med jeres egne
A9: 🎯 Hvad er et godt kvalitetsmål? | C9: Det skal være konkret og målbart — ikke en from hensigtserklæring. Tænk: Kan vi dokumentere om vi nåede målet? Hvis ikke, er det for vagt.
A10: EKSEMPEL · Skiv SÅDAN:
A11: ✗ UNDGÅ: 'Vi leverer god kvalitet til kunderne.'
A12: ✓ SKRIV: 'Vi måler kundetilfredshed via opfølgningssnak senest 14 dage efter hvert afleveret projekt. Mål: min. 90 % tilfredse kunder i 2025.'
A14: LOVGRUNDLAG · Tabellen er preudfyldt — hold versioner ajour
A15: 📜 Bekendtgørelser | C15: De 4 BEK'er i tabellen er dem der gælder per 12. juni 2024. Hvis Sikkerhedsstyrelsen udsender nye, opdater versionsnummer og dato her.
A17: ANSVARSMATRIX · Brug navne, ikke kun stillinger
A18: 👤 Ansvarsmatrix | C18: Skriv de konkrete personers navne ved siden af rollen. 'Faglig ansvarlig: Henrik Nielsen' er langt bedre end bare 'Faglig ansvarlig'.
A19: ⚠️ VIGTIGT LOVKRAV: Underskrift i bunden af arket er OBLIGATORISK. Uden daglig leders underskrift er kvalitetspolitikken ikke gyldig ved audit. Skriv dato for underskrift.
A22: KVALITETSMÅL
A23: Mål 1 | B23: Vi udfører alle installationer iht. gældende lovgivning og standarder.
A24: Mål 2 | B24: Vi sikrer løbende kompetenceudvikling af alle medarbejdere.
A25: Mål 3 | B25: Vi registrerer og følger op på alle afvigelser for at undgå gentagelse.
A26: Mål 4 | B26: Vi gennemfører ledelsens evaluering minimum én gang om året.
A27: Mål 5 | B27: Vi vedligeholder og kalibrerer vores måleinstrumenter regelmæssigt.
A29: LOVGRUNDLAG
A30: BEK 725/2024 | B30: Kvalitetsledelsessystemer — el, vvs og kloak (Sikkerhedsstyrelsen)
A31: BEK 724/2024 | B31: VVS-installationsområdet
A32: BEK 722/2024 | B32: Kloakinstallationsområdet
A33: Autorisationsloven | B33: Lov om autorisation af elinstallatørvirksomheder m.v.
A35: GODKENDELSE — daglig leders underskrift
A36: Navn:
A37: Dato:
A38: Underskrift:

Sheet Organisation
A1: ORGANISATION · ROLLER OG ANSVAR
A3: ℹ️ VEJLEDNING · ORGANISATION
A4: 📌 HVAD ER DETTE ARK?
A5: Her dokumenterer I hvem der er ansat, hvad de kan, og hvem der bærer de specifikke KLS-roller. Kontrolinstansen ser på om antallet af autoriserede medarbejdere matcher virksomhedens arbejdsomfang.
A7: MEDARBEJDERTABEL · Øverste del
A8: 👷 Hvem skal med? | C8: Alle der udfører autoriseret arbejde under virksomhedens autorisation — fastansatte, deltidsansatte og faste vikarer. Ikke rengøring og administration.
A9: 🎓 Faglig kompetence | C9: Angiv uddannelsesniveau og år — fx 'Elektrikersvend 2019' eller 'VVS-lærling 3. år'. Jo mere præcist, jo nemmere ved audit.
A10: EKSEMPEL · Skiv SÅDAN:
A11: ✗ UNDGÅ: 'Montør'
A12: ✓ SKRIV: 'Autoriseret el-installatør · EUC Syd 2019 · Certifikat nr. EL-XXXX'
A14: FAGLIG ANSVARLIGE · Nederste del
A15: 🔑 Autorisationsnummer | C15: Hentes fra Sikkerhedsstyrelsens godkendelsesbrev. Kun den fagligt ansvarlige med gyldigt autorisationsnummer må godkende slutkontroller.
A16: ⚠️ VIGTIGT LOVKRAV: Udløber en faglig ansvarlig persons certifikat, mister virksomheden sin autorisation for det pågældende fagområde øjeblikkeligt. Sæt reminder 3 måneder inden udløb.
A19: Navn | B19: Stilling | C19: Faglig kompetence | D19: KLS-ansvar | E19: Autoriseret | F19: Telefon | G19: E-mail | H19: Ansættelsesdato | I19: Bemærkninger
A37: FAGLIGT ANSVARLIGE
A38: Faglig ansvarlig | B38: Fagområde | C38: Autorisationsnummer | D38: Udstedt dato | E38: Udløber | F38: Status

Sheet Procedurer
A1: ARBEJDSPROCEDURER OG INSTRUKTIONER
A3: ℹ️ VEJLEDNING · PROCEDURER
A4: 📌 HVAD ER DETTE ARK?
A5: Procedureoversigten dokumenterer at virksomheden har planlagt og beskrevet alle sine arbejdsgange skriftligt. Det er beviset på at KLS-systemet er implementeret i praksis — ikke bare et dokument der samler støv.
A7: KOLONNEFORKLARING
A8: 🏷️ Gælder for | C8: Angiv kun de fagområder I er autoriseret til. Har I kun el, sæt VVS/Kloak-procedurerne til 'Udgået'.
A9: 📅 Godkendt dato | C9: Dato for hvornår ledelsen sidst gennemgik og godkendte proceduren. Nye procedurer godkendes ved oprettelse.
A10: 🔢 Revision | C10: Start på 1.0. Hæv til 1.1 ved mindre rettelser. Hæv til 2.0 ved store ændringer i selve indholdet.
A11: 📁 Link / Reference | C11: Indsæt filsti eller URL til det faktiske Word/PDF-dokument. Jo lettere det er at finde, jo bedre går auditen.
A12: 🟢 Status: Aktiv / Under revision / Udgået | C12: 'Udgået' bruges for procedurer der ikke er relevante — men SLET dem aldrig. Kontrolinstansen kan bede om historik op til 5 år tilbage.
A14: ⚠️ VIGTIGT LOVKRAV: Proceduren skal faktisk EKSISTERE som et dokument et sted. En linje i denne liste uden et tilknyttet dokument tæller ikke ved audit.
A17: Nr. | B17: Procedure titel | C17: Gælder for | D17: Ansvarlig | E17: Godkendt dato | F17: Rev. | G17: Status | H17: Link / Reference
A18: P-01 | B18: Indgåelse af arbejdsaftale og kundedokumentation | C18: El, VVS, Kloak, Gas | D18: Faglig ansvarlig | F18: 1.0 | G18: Aktiv
A19: P-02 | B19: Projektgennemgang og risikovurdering | C19: El, VVS, Kloak, Gas | D19: Faglig ansvarlig | F19: 1.0 | G19: Aktiv
A20: P-03 | B20: Udførelse af installation | C20: El, VVS, Kloak, Gas | D20: Installatør | F20: 1.0 | G20: Aktiv
A21: P-04 | B21: Slutkontrol og verifikation — el | C21: El | D21: FA el | F21: 1.0 | G21: Aktiv
A22: P-05 | B22: Slutkontrol — VVS-installationer | C22: VVS | D22: FA vvs | F22: 1.0 | G22: Aktiv
A23: P-06 | B23: Slutkontrol — kloakinstallationer | C23: Kloak | D23: FA kloak | F23: 1.0 | G23: Aktiv
A24: P-07 | B24: Afvigelseshåndtering | C24: Alle | D24: Faglig ansvarlig | F24: 1.0 | G24: Aktiv
A25: P-08 | B25: Intern efterprøvning (ledelsens evaluering) | C25: Alle | D25: Ledelse | F25: 1.0 | G25: Aktiv
A26: P-09 | B26: Kompetencevurdering og kursusplanlægning | C26: Alle | D26: Ledelse | F26: 1.0 | G26: Aktiv
A27: P-10 | B27: Kalibrering og kontrol af måleudstyr | C27: El | D27: FA el | F27: 1.0 | G27: Aktiv
A28: P-11 | B28: Underleverandørstyring | C28: Alle | D28: Faglig ansvarlig | F28: 1.0 | G28: Aktiv
A29: P-12 | B29: Kundeklager og reklamationer | C29: Alle | D29: Ledelse | F29: 1.0 | G29: Aktiv
... A31: P-14 | B31: Beredskabsplan ved ulykker | C31: Alle | D31: Ledelse | F31: 1.0 | G31: Aktiv

Sheet Slutkontrol EL
A1: SLUTKONTROL OG VERIFIKATIONSLOG · EL-INSTALLATIONER
A2: Jf. DS/HD 60364-6 og BEK nr. 725 af 12. juni 2024
A4: ℹ️ VEJLEDNING · SLUTKONTROL EL · Verifikationslog
A5: 📌 HVAD ER DETTE ARK?
A6: Hvert el-arbejde der kræver autorisation skal dokumenteres her. Arket er jeres bevis over for kontrolinstansen og kommunen på at installationerne er korrekt afprøvet og godkendt inden aflevering.
A8: ⚠️ VIGTIGT LOVKRAV: Udfyld STRAKS efter installationen — aldrig bagudrettet. En slutkontrol skrevet 3 uger senere er ubrugelig som dokumentation ved tvister.
A10: KOLONNEFORKLARING · Udfyld fra venstre mod højre
A11: 🔢 Sagsnr. | C11: Brug et konsekvent system, fx ÅR-LØBENUMMER: '2025-001', '2025-002'... Nummeret skal matche din faktura og arbejdsseddel til kunden.
A12: ⚡ Installationstype (vælg fra rullemenuen) | C12: Nyinstallation og Udvidelse kræver ALTID fuld verifikation iht. DS/HD 60364-6. Fejlafhjælpning kræver verifikation af den berørte del.
A13: 🔌 Isolationsmodstand (MΩ) | C13: Angiv den laveste målte værdi. Krav: min. 1 MΩ for 230V installationer. Lavere end 1 MΩ = afvigelse → opret straks i Afvigelsesrapport-arket.
A14: EKSEMPEL · Skiv SÅDAN:
A15: ✗ UNDGÅ: 'OK' (vagt og udokumenteret)
A16: ✓ SKRIV: '1,8 MΩ' (præcis målt værdi — bevis der holder ved tvister)
A17: ✅ Jordingstest + HPFI/HFI test | C17: Vælg OK eller Ikke OK. Ved Ikke OK: opret STRAKS en afvigelse. Sæt N/A kun hvis testen reelt ikke er relevant for denne type installation.
A18: 🖊️ Godkendt af (FA) | C18: KUN den fagligt ansvarlige må godkende. Skriv fulde navn — ikke initialer. Initialer er ikke juridisk tilstrækkelig signatur.
A19: 🟢 Status (automatisk farve) | C19: Godkendt = grøn · Afvigelse = rød · Under behandling = orange. Afvigelse kræver at en post oprettes i Afvigelsesrapport-arket samme dag.
A22: Dato | B22: Sagsnr. | C22: Adresse / Projekt | D22: Installationstype | E22: Isolationsmodstand (MΩ) | F22: Jordingstest OK | G22: HPFI test OK | H22: Fejlstrøm (mA) | I22: Udført af | J22: Godkendt af (FA) | K22: Status | M22: STATISTIK
M23: Godkendte: | N23: =COUNTIF(K23:K72,"Godkendt") -> 0
M24: Afvigelser: | N24: =COUNTIF(K23:K72,"Afvigelse") -> 0
M25: Rate: | N25: =IFERROR(COUNTIF(K23:K72,"Godkendt")/(COUNTIF(K23:K72,"Godkendt")+COUNTIF(K23:K72,"Afvigelse")),"N/A") -> N/A

Sheet Slutkontrol VVS
A1: SLUTKONTROL OG ARBEJDSRAPPORT · VVS-INSTALLATIONER
A3: ℹ️ VEJLEDNING · SLUTKONTROL VVS · Arbejdsrapport
A4: 📌 HVAD ER DETTE ARK?
A5: Dokumenterer at VVS-installationer er afprøvet og kontrolleret inden aflevering. Krav følger af BEK nr. 724 og gælder for alle nyinstallationer, udvidelser og ændringer under VVS-autorisation.
A6: ⚠️ VIGTIGT LOVKRAV: Udfyld INDEN aflevering til kunden — aldrig bagudrettet. Samme princip som el-arket.
A8: KOLONNEFORKLARING
A9: 💧 Trykprøve OK | C9: Varmtvandsinstallationer trykprøves til 1,5 × driftstryk. Notér det faktiske prøvetryk i Bemærkninger hvis det afviger.
A10: 🔒 Tæthedsprøve OK | C10: Bruges primært på gasinstallationer (BEK nr. 30). Gasspecifikke krav — sørg for at FA kender de præcise procedurer.
A11: 🌡️ Temperaturkontrol | C11: Angiv målt temperatur på varmt vand: min. 60°C ved varmtvandsbeholder, max. 50°C ved udtag. Forebygger legionella og er et sundhedskrav.
A12: EKSEMPEL · Skiv SÅDAN:
A13: ✗ UNDGÅ: 'Temp. OK'
A14: ✓ SKRIV: '62°C ved beholder · 48°C ved håndvask (begge inden for krav)'
A15: 🖊️ Godkendt af (FA) | C15: Kun autoriseret VVS-installatør med gyldig VVS-autorisation må godkende.
A18: Dato | B18: Sagsnr. | C18: Adresse / Projekt | D18: Arbejdstype | E18: Trykprøve OK | F18: Tæthedsprøve OK | G18: Temperaturkontrol | H18: Udført af | I18: Godkendt af (FA) | J18: Status

Sheet Slutkontrol Kloak
A1: SLUTKONTROL OG ARBEJDSRAPPORT · KLOAKINSTALLATIONER
A3: ℹ️ VEJLEDNING · SLUTKONTROL KLOAK · Arbejdsrapport
A4: 📌 HVAD ER DETTE ARK?
A5: Dokumenterer at kloakinstallationer overholder DS 432 og er godkendt inden tildækning eller aflevering. Krav følger BEK nr. 722. Manglende dokumentation kan føre til at kommunen kræver opgravning.
A6: ⚠️ VIGTIGT LOVKRAV: VIGTIGST AF ALT: Slutkontrol skal udfyldes INDEN tildækning af ledninger. Efterfølgende dokumentation accepteres ikke ved kommunalt tilsyn.
A8: KOLONNEFORKLARING
A9: 📹 TV-inspektion | C9: Kræves typisk ved afløbsledninger > DN110 eller ved renovering. Vedhæft inspektionsrapporten som fil og notér filnavn i sagsnr.-feltet.
A10: 💨 Tæthedsprøve OK | C10: Udføres iht. DS 432 med lufttryk: normalt 50 mbar, 5 minutters holdetid. Angiv faktisk prøvetryk og holdetid i Bemærkninger-kolonnen.
A11: 📐 Fald kontrolleret | C11: Minimum 10‰ fald for afløbsledninger (DS 432). For lavt fald giver stående vand og tilstopningsrisiko — skal registreres som afvigelse.
A12: EKSEMPEL · Skiv SÅDAN:
A13: ✗ UNDGÅ: 'Fald OK'
A14: ✓ SKRIV: 'Målt fald: 15‰ (krav min. 10‰) — tæthedsprøve 50 mbar, holdt 5 min.'
A15: 🏛️ Arbejdstype 'Separering' | C15: Kræver ALTID kommunal godkendelse inden arbejdet påbegyndes. Notér kommunens sagsnummer i sagsnr.-kolonnen.
A18: Dato | B18: Sagsnr. | C18: Adresse / Projekt | D18: Arbejdstype | E18: TV-inspektion | F18: Tæthedsprøve OK | G18: Fald kontrolleret | H18: Udført af | I18: Godkendt af (FA) | J18: Status

Sheet Afvigelsesrapport
A1: AFVIGELSESRAPPORT OG KORRIGERENDE HANDLINGER
A2: Alle afvigelser registreres, analyseres og følges op — ingen undtagelser
A4: ℹ️ VEJLEDNING · AFVIGELSESRAPPORT · Det vigtigste dokument ved audit
A5: 📌 HVAD ER DETTE ARK?
A6: Kontrolinstansen kigger ALTID grundigt her. De ser på tre ting: (1) Er alle afvigelser registreret? (2) Er der lavet årsagsanalyse? (3) Er der fulgt op med konkret handling?
A7: ⚠️ VIGTIGT LOVKRAV: Et TOMT afvigelsesark tolkes som at KLS-systemet ikke er implementeret i praksis. Det er bedre at have 10 afvigelser og lukke dem, end slet ingen — det viser at systemet virker.
A9: HVORNÅR OPRETTES EN AFVIGELSE?
A10: 🔴 Opret STRAKS ved: | C10: Fejl i installation · Kundeklage · Manglende slutkontrol · Udstyr der ikke virker · Afvigelse fra procedure · Lovkrav der ikke er overholdt
A12: KOLONNEFORKLARING · Udfyld alle felter
A13: 🔢 Afv.nr. | C13: Genereres automatisk: AFV-001, AFV-002... Ændr det IKKE — det er en unik reference.
A14: 📝 Beskrivelse af afvigelse | C14: Vær konkret og faktabaseret. Brug tal og målinger hvor det er muligt.
A15: EKSEMPEL · Skiv SÅDAN:
A16: ✗ UNDGÅ: 'Installation var dårlig.'
A17: ✓ SKRIV: 'Isolationsmodstand målt til 0,3 MΩ på kurs XXX — krav er min. 1 MΩ. Sag 2025-014, adresse XYZ.'
A18: 🔍 Årsagsanalyse (rodårsag, ikke symptom) | C18: Stil 5× 'Hvorfor?' Fx: Forkert kabel → valgt fra lager → lager ikke opdateret → indkøbsprocedure mangler specifikation → ingen ansvarlig for lageropdatering.
A19: 🛠️ Korrigerende handling | C19: Beskriv BÅDE hvad der rettes nu OG hvad der forhindrer gentagelse. De to ting er ikke det samme — begge dele skal med.
A20: 📅 Frist | C20: Sæt en realistisk dato og overhold den. Gentagne overskredet frister er i sig selv en afvigelse ved næste audit.
A21: 🟢 Status: Afsluttet | C21: Sæt IKKE 'Afsluttet' når handlingen er udført — sæt det når I har verificeret at handlingen faktisk virker og fejlen ikke er gentaget.
A24: Afv.nr. | B24: Dato opdaget | C24: Opdaget af | D24: Sagsnr. | E24: Beskrivelse af afvigelse | F24: Årsagsanalyse | G24: Korrigerende handling | H24: Ansvarlig | I24: Frist | J24: Afsluttet | K24: Status | M24: STAT.
A25: =IFERROR("AFV-"&TEXT(ROW()-24,"000"),"") -> AFV-001 | M25: Åbne: | N25: =COUNTIF(K25:K74,"Åben") -> 0
A26: =IFERROR("AFV-"&TEXT(ROW()-24,"000"),"") -> AFV-002 | M26: Igangsat: | N26: =COUNTIF(K25:K74,"Under behandling") -> 0
A27: =IFERROR("AFV-"&TEXT(ROW()-24,"000"),"") -> AFV-003 | M27: Afsluttet: | N27: =COUNTIF(K25:K74,"Afsluttet") -> 0
A28: =IFERROR("AFV-"&TEXT(ROW()-24,"000"),"") -> AFV-004 | M28: Total: | N28: =COUNTA(B25:B74) -> 0
A29: =IFERROR("AFV-"&TEXT(ROW()-24,"000"),"") -> AFV-005
A30: =IFERROR("AFV-"&TEXT(ROW()-24,"000"),"") -> AFV-006
A31: =IFERROR("AFV-"&TEXT(ROW()-24,"000"),"") -> AFV-007
A32: =IFERROR("AFV-"&TEXT(ROW()-24,"000"),"") -> AFV-008
A33: =IFERROR("AFV-"&TEXT(ROW()-24,"000"),"") -> AFV-009
A34: =IFERROR("AFV-"&TEXT(ROW()-24,"000"),"") -> AFV-010
A35: =IFERROR("AFV-"&TEXT(ROW()-24,"000"),"") -> AFV-011
A36: =IFERROR("AFV-"&TEXT(ROW()-24,"000"),"") -> AFV-012
A37: =IFERROR("AFV-"&TEXT(ROW()-24,"000"),"") -> AFV-013
A38: =IFERROR("AFV-"&TEXT(ROW()-24,"000"),"") -> AFV-014
A39: =IFERROR("AFV-"&TEXT(ROW()-24,"000"),"") -> AFV-015
A40: =IFERROR("AFV-"&TEXT(ROW()-24,"000"),"") -> AFV-016
... A74: =IFERROR("AFV-"&TEXT(ROW()-24,"000"),"") -> AFV-050

Sheet Intern Efterprøvning
A1: LEDELSENS EVALUERING · INTERN EFTERPRØVNING
A2: Lovkrav: Min. én gang om året — max. 12 måneders interval · BEK nr. 725 §8
A4: ℹ️ VEJLEDNING · INTERN EFTERPRØVNING · Ledelsens evaluering
A5: 📌 HVAD ER DETTE ARK?
A6: Ledelsens evaluering er et direkte lovkrav. Kontrolinstansen kontrollerer specifikt om det er gennemført inden for de seneste 12 måneder. Er dokumentationen ikke der, er det en kritisk afvigelse der kan koste autorisationen.
A7: ⚠️ VIGTIGT LOVKRAV: Mangler dokumentation for ledelsens evaluering = kritisk afvigelse ved audit. Sæt en fast dato i virksomhedens kalender hvert år — det er nemmere end at jage den.
A9: TRIN FOR TRIN · Sådan gennemføres evalueringen
A10: 1️⃣ Indkald møde | C10: Sæt dato i kalenderen. Deltagere: daglig leder + faglig ansvarlig(e). Minimum 1 time afsat. Dokumentér hvem der deltog.
A11: 2️⃣ Gå igennem alle 12 punkter | C11: Spring INGEN over. 'Ikke relevant' bruges kun for fagområder I ikke er autoriseret til. Alle andre punkter kommenteres.
A12: 3️⃣ Skriv konkrete beslutninger | C12: Ikke bare 'alt er OK'. Skriv hvad I besluttede at gøre, hvem der er ansvarlig, og hvornår.
A13: EKSEMPEL · Skiv SÅDAN:
A14: ✗ UNDGÅ: 'Evaluering gennemgået. Alt tilfredsstillende.'
A15: ✓ SKRIV: 'Punkt 4 (afvigelser): 2 åbne afvigelser lukkes inden 1. marts af Henrik. Punkt 5 (kompetencer): Brian starter DS 60364-6 kursus i april.'
A16: 4️⃣ Underskrift | C16: Daglig leder underskriver i bunden. Gem kopi som PDF i KLS-mappen. Uden underskrift er dokumentet ikke gyldigt.
A17: 5️⃣ Sæt dato for næste evaluering | C17: Gør det MENS I er samlet. Max 12 måneder frem. Notér det i virksomhedens kalender med reminder 1 måned forinden.
A20: EVALUERINGSOPLYSNINGER
A21: Evalueringsperiode (fx '1. jan 2025 – 31. dec 2025'):
A22: Mødedato:
A23: Deltagere (fulde navne):
A24: Næste evaluering planlagt til:
A26: EVALUERINGSPUNKTER — Gennemgå alle 12 · Ingen må springes over
A27: Nr. | B27: Evalueringspunkt | C27: Vurdering | D27: Handling krævet | E27: Ansvarlig | F27: Frist | G27: Status
A28: 1 | B28: Opfølgning fra forrige evaluering
A29: 2 | B29: KLS-dokumentation er opdateret og tilgængelig
A30: 3 | B30: Antal udførte installationer og slutkontroller
A31: 4 | B31: Afvigelser registreret og afsluttet
A32: 5 | B32: Medarbejderkompetencer og uddannelse
A33: 6 | B33: Tilstand og kalibrering af måleudstyr
A34: 7 | B34: Kundeklager og reklamationer
A35: 8 | B35: Underleverandørers præstation
A36: 9 | B36: Lovgivningsændringer siden sidst
A37: 10 | B37: Forbedringsforslag fra medarbejdere
A38: 11 | B38: Ressourcebehov og kapacitet
A39: 12 | B39: KLS systemets samlede effektivitet
A41: SAMLET KONKLUSION OG BESLUTNINGER
A42: Konklusioner:
A43: Forbedringspunkter:
A44: Beslutninger taget:
A46: UNDERSKRIFT — Ledelsens evaluering er gennemført
A47: Daglig leder — navn:
...

Sheet Kompetenceskema
A1: KOMPETENCEVURDERING OG KURSUSPLAN
A3: ℹ️ VEJLEDNING · KOMPETENCESKEMA
A4: 📌 HVAD ER DETTE ARK?
A5: Dokumenterer at alle ansatte har de nødvendige kvalifikationer. Kontrolinstansen spørger direkte: 'Kan I dokumentere at jeres folk er kompetente?' Dette skema er jeres svar.
A7: KOLONNEFORKLARING
A8: 🎓 Grunduddannelse | C8: Angiv uddannelsens fulde navn + år + skole. Fx 'Elektrikersvend, EUC Syd, 2019' eller 'VVS-installatør, Erhvervsskolen Nordsjælland, 2021'.
A9: 📜 Certifikater (El / VVS / Kloak) | C9: Vælg Ja / Nej / Under uddannelse. 'Ja' kræver at certifikatnummer og udstedelsesdato kan fremvises. Gem scannede kopier i KLS-mappen.
A10: 🦺 Arbejdsmiljø | C10: Alle ansatte skal have gennemført grundlæggende arbejdsmiljøuddannelse (32 timer). Asbest, tagarbejde og stilladser kræver yderligere certifikater.
A11: EKSEMPEL · Skiv SÅDAN:
A12: ✗ UNDGÅ: 'Kursus: Arbejdsmiljø'
A13: ✓ SKRIV: 'AMU Grundlæggende arbejdsmiljø, 32 timer, Teknisk Skole Aarhus, marts 2024 · Cert.nr. AM-2024-1234'
A14: 📅 Næste kursus | C14: Planlæg kompetenceløft FREMAD — ikke kun bag ud. Sæt konkrete kursusnavne, ikke bare 'diverse kurser'.
A15: ⚠️ VIGTIGT LOVKRAV: Opdater skemaet ved ansættelse af ny medarbejder og ved gennemførelse af kurser. Forældet data er værre end intet data.
A18: Navn | B18: Stilling | C18: Grunduddannelse | D18: El-cert. | E18: VVS-cert. | F18: Kloak-cert. | G18: Arbejdsmiljø | H18: Kursus / Kompetenceløft | I18: Kursusdato | J18: Næste kursus | K18: Niveau | L18: Bem.

Sheet Måleudstyr
A1: REGISTRERING OG KALIBRERING AF MÅLEUDSTYR
A3: ℹ️ VEJLEDNING · MÅLEUDSTYR · Kalibrering og kontrol
A4: 📌 HVAD ER DETTE ARK?
A5: Dokumenterer at alle instrumenter der bruges til verifikationsmålinger er i korrekt stand og kalibreret. Et HPFI-test med ukalibreret udstyr er retlig set ugyldig og kan give problemer ved forsikringssager.
A6: ⚠️ VIGTIGT LOVKRAV: Et instrument med udløbet kalibrering MÅ IKKE bruges til godkendelsesprøvninger. Brug i stedet reserveudstyr eller lej kalibreret udstyr midlertidigt.
A8: KOLONNEFORKLARING
A9: 🔢 Inv.nr. | C9: De første 8 rækker er preudfyldt med typiske instrumenter. Tilret fabrikat og serienummer. Tilføj ALT udstyr til verifikation — håndtermometre, trykmålere, kameraer mv.
A10: 📜 Kalibreret dato + Kalibreret af | C10: Angiv dato og firmanavn. Gem kalibreringsattesten — den skal fremvises ved audit. 'Intern kalibrering' er kun acceptabelt for simpelt mekanisk udstyr.
A11: EKSEMPEL · Skiv SÅDAN:
A12: ✗ UNDGÅ: 'Kalibreret: OK'
A13: ✓ SKRIV: 'Kalibreret: Fluke Nordic A/S · 15. jan 2025 · Cert.nr. KAL-2025-0042 · Næste: jan 2026'
A14: 📐 Tolerancegrænse | C14: Angiv hvad instrumentet er kalibreret til — fx '±2% ved 10 MΩ' eller '±0,5°C'. Bruges til at vurdere om en måling er valid.
A15: 📅 Næste kalibrering | C15: Typisk 1 år for elektriske instrumenter, 2 år for mekaniske. Sæt datoen i virksomhedskalenderen med 30-dages forvarsel.
A18: Inv.nr. | B18: Instrument | C18: Fabrikat / Model | D18: Serienr. | E18: Kalibreret dato | F18: Kalibreret af | G18: Næste kalibrering | H18: Tolerancegrænse | I18: Kontrolleret OK | J18: Status
A19: INV-001 | B19: Installationstester / HPFI-tester
A20: INV-002 | B20: Multimeter
A21: INV-003 | B21: Jordingsmåler
A22: INV-004 | B22: Lekkagestrøms-amperemeter
A23: INV-005 | B23: Isolationstester (Megger)
A24: INV-006 | B24: Termostat-kalibreringsinstrument
A25: INV-007 | B25: Manometer (trykprøve VVS)
A26: INV-008 | B26: Rørinspektionskamera (Kloak)

Sheet Tilsyn
A1: TILSYNSLOG · KONTROLINSTANS OG SIKKERHEDSSTYRELSEN
A3: ℹ️ VEJLEDNING · TILSYN · Godkendelsescyklus og log
A4: 📌 HVAD ER DETTE ARK?
A5: Tilsynsloggen registrerer alle besøg og godkendelser fra kontrolinstansen og Sikkerhedsstyrelsen. Det er jeres historik over KLS-godkendelsesstatus og kan bruges som bevis ved tvister eller forsikringssager.
A7: KLS-GODKENDELSESCYKLUSSEN · Kend den udenad
A8: 1️⃣ Fase 1 — Præaudit (dokumentgennemgang) | C8: Kontrolinstansen gennemgår KLS-dokumentationen. Foregår typisk som videoopkald eller ved besøg. Her opdager I 'huller' inden den rigtige audit.
A9: 2️⃣ Fase 2 — Godkendelse (fysisk besøg) | C9: Kontrolinstansen besøger virksomheden, taler med personalet og gennemgår konkrete sager. Resulterer i: Godkendt / Betinget godkendt / Ikke godkendt.
A10: 🔄 Gengodkendelse — Inden 2 år | C10: Kontakt kontrolinstansen min. 3 måneder inden udløb — de har ventetider. Udløbet KLS = øjeblikkelig suspension af autorisation.
A11: ⚠️ Betinget godkendt — Hvad nu? | C11: Alle afvigelser i auditrapporterne SKAL lukkes inden aftalt frist. Opret dem STRAKS i Afvigelsesrapport-arket med reference til auditrapporten.
A12: 📄 Rapport modtaget | C12: I har ret til at modtage den skriftlige auditrapport. Kræv den hvis den ikke kommer inden for 14 dage efter besøget.
A14: ⚠️ VIGTIGT LOVKRAV: Sikkerhedsstyrelsen kan til enhver tid foretage uanmeldt tilsyn. Hele KLS-systemet inkl. dette ark skal til enhver tid kunne fremvises.
A17: Dato | B17: Besøgstype | C17: Kontrolinstans | D17: Auditor | E17: Afvigelser fundet | F17: Krav om handling | G17: Rapport modtaget | H17: Status
A39: KLS GODKENDELSESHISTORIK
A40: Godkendt dato | B40: Udløber | C40: Kontrolinstans | D40: Certifikatnr. | E40: Fornyelse søgt | F40: Status

Sheet Dokumentstyring
A1: DOKUMENTSTYRING · AKTIVE KLS-DOKUMENTER
A3: ℹ️ VEJLEDNING · DOKUMENTSTYRING · Master-liste
A4: 📌 HVAD ER DETTE ARK?
A5: Dette er master-listen over alle KLS-dokumenter. Kontrolinstansen bruger den til at verificere at systemet er komplet og at versionsstyringen fungerer. Et dokument der ikke er på listen, er ikke en del af KLS-systemet.
A7: VERSIONSSTYRING · Sådan fungerer det
A8: 🔢 Versionnumre: 1.0 / 1.1 / 2.0 | C8: 1.0 → 1.1: Mindre rettelser (stavefejl, præcisering af formulering). 1.0 → 2.0: Væsentlig ændring af selve indholdet eller proceduren.
A9: EKSEMPEL · Skiv SÅDAN:
A10: ✗ UNDGÅ: Slette et dokument fra listen når det ikke bruges mere.
A11: ✓ SKRIV: Sæt status til 'Udgået' og bevar dokumentet på listen. Kontrolinstansen kan bede om historik op til 5 år tilbage.
A13: KOLONNEFORKLARING
A14: 🔗 Placering / Link | C14: Indsæt fuld filsti eller URL. Brug UNC-stier på netværk: \\server\KLS\DOK-001.docx — virker fra alle computere.
A15: 📅 Næste revision | C15: Sæt revisionsdato på alle dokumenter — typisk 1-2 år frem. Dokumenter uden revisionsdato er per definition forældet.
A16: 🟢 Status | C16: Aktiv: Gældende version. Under revision: I gang med at opdatere. Udgået: Erstattet af ny version — beholdes på listen.
A17: ⚠️ VIGTIGT LOVKRAV: Gennemgå denne liste ved den årlige ledelsesgennemgang — opdater revisionsdatoer og verificer at alle links stadig virker.
A20: Dok.nr. | B20: Dokumenttitel | C20: Ansvarlig | D20: Ver. | E20: Godkendt dato | F20: Næste revision | G20: Placering / Link | H20: Status
A21: DOK-001 | B21: KLS Håndbog (hoveddokument) | C21: Ledelse | D21: 1.0 | H21: Aktiv
A22: DOK-002 | B22: Kvalitetspolitik | C22: Ledelse | D22: 1.0 | H22: Aktiv
A23: DOK-003 | B23: Organisationsdiagram og roller | C23: Ledelse | D23: 1.0 | H23: Aktiv
A24: DOK-004 | B24: Procedurer P-01 til P-14 | C24: KLS-ansvarlig | D24: 1.0 | H24: Aktiv
A25: DOK-005 | B25: Slutkontrolskema EL | C25: FA el | D25: 1.0 | H25: Aktiv
A26: DOK-006 | B26: Slutkontrolskema VVS | C26: FA vvs | D26: 1.0 | H26: Aktiv
A27: DOK-007 | B27: Slutkontrolskema Kloak | C27: FA kloak | D27: 1.0 | H27: Aktiv
A28: DOK-008 | B28: Afvigelsesrapport skabelon | C28: KLS-ansvarlig | D28: 1.0 | H28: Aktiv
A29: DOK-009 | B29: Kompetencevurderingsskema | C29: Ledelse | D29: 1.0 | H29: Aktiv
A30: DOK-010 | B30: Måleudstyrsliste og kalibrering | C30: FA el | D30: 1.0 | H30: Aktiv
A31: DOK-011 | B31: Ledelsens evalueringsrapport | C31: Ledelse | D31: 1.0 | H31: Aktiv
A32: DOK-012 | B32: Kundeklage procedure | C32: Ledelse | D32: 1.0 | H32: Aktiv
... A34: DOK-014 | B34: Beredskabsplan | C34: Ledelse | D34: 1.0 | H34: Aktiv

Sheet Dashboard
A1: KLS DASHBOARD · STATUS OVERBLIK
A2: Alle nøgletal hentes automatisk · Opdateret: 02-06-2026
A4: ℹ️ VEJLEDNING · DASHBOARD · Jeres KLS-cockpit
A5: 📌 HVAD ER DETTE ARK?
A6: Dashboard-arket opdateres automatisk baseret på data i de øvrige ark. Start altid her når I åbner systemet — et hurtigt kig fortæller jer om alt er grønt, eller om noget kræver opmærksomhed.
A8: BRUGSGUIDE · 3 ting I skal tjekke
A9: 📊 Nøgletal (opdateres automatisk) | C9: Tallene hentes live fra Slutkontrol EL, Afvigelsesrapport og Dokumentstyring. I behøver ikke gøre noget manuelt her — bare hold de øvrige ark ajour.
A10: 📅 KLS udløbsdato (kritisk at holde øje med) | C10: Hentes fra Forsiden. Er udløbsdatoen inden for 3 måneder: kontakt STRAKS kontrolinstansen for at booke gengodkendelse.
A11: ☑️ Årlig tjekliste (eneste manuelle del) | C11: Gennemgå de 8 spørgsmål én gang om året — helst i forbindelse med ledelsens evaluering. 'Nej' på et punkt er et signal om at noget mangler.
A14: EL · SLUTKONTROLLER | F14: AFVIGELSESLOG · STATUS | K14: DOK. STATUS
A15: Godkendte: | D15: =COUNTIF('Slutkontrol EL'!K23:K72,"Godkendt") -> 0 | F15: Åbne afvigelser: | I15: =COUNTIF(Afvigelsesrapport!K25:K74,"Åben") -> 0 | K15: Aktive: | L15: =COUNTIF(Dokumentstyring!H21:H40,"Aktiv") -> 14
A16: Afvigelser: | D16: =COUNTIF('Slutkontrol EL'!K23:K72,"Afvigelse") -> 0 | F16: Under behandling: | I16: =COUNTIF(Afvigelsesrapport!K25:K74,"Under behandling") -> 0 | K16: Udgåede: | L16: =COUNTIF(Dokumentstyring!H21:H40,"Udgået") -> 0
A17: Godkendelsesprocent: | D17: =IFERROR(COUNTIF('Slutkontrol EL'!K23:K72,"Godkendt")/(COUNTIF('Slutkontrol EL'!K23:K72,"Godkendt")+COUNTIF('Slutkontrol EL'!K23:K72,"Afvigelse")),"N/A") -> N/A | F17: Afsluttede: | I17: =COUNTIF(Afvigelsesrapport!K25:K74,"Afsluttet") -> 0 | K17: Under rev.: | L17: =COUNTIF(Dokumentstyring!H21:H40,"Under revision") -> 0
A19: ⚠️ KLS UDLØBSDATO · Hold øje med denne
A20: KLS godkendt dato (fra Forside): | H20: =Forside!C13 -> Udfyldes første gang KLS godkendes. Udløb = altid præcis 2 år frem. Når I fornyer, opdateres begge datoer. Dashboard viser automatisk advarsel ved udløb.
A21: KLS udløber (fra Forside): | H21: =Forside!C14 -> 0
A23: ☑️ ÅRLIG KLS TJEKLISTE · Gennemgås ved ledelsens evaluering
A24: Er ledelsens evaluering gennemført inden for de seneste 12 måneder? | J24: LOVKRAV
A25: Er alle slutkontroller dokumenteret og arkiveret for perioden? | J25: LOVKRAV
A26: Er alle afvigelsesrapporter oprettet og fulgt op? | J26: LOVKRAV
A27: Er medarbejdernes certifikater og kompetencer gyldige? | J27: VIGTIGT
A28: Er alt måleudstyr kalibreret og kontrolleret inden for fristen? | J28: LOVKRAV
A29: Er KLS-dokumentationen opdateret med korrekte versioner? | J29: VIGTIGT
A30: Er kontrolinstansen kontaktet for gengodkendelse (inden 2 år)? | J30: LOVKRAV
A31: Er ændringer i lovgivning implementeret i KLS-systemet? | J31: VIGTIGT
