Workbook

Sheet 0. START HERE
A1: QI INTELLIGENCE PLATFORM v9 - choose-only, fully integrated
A2: Graphical - AI-assisted - every sheet linked. You only ever pick from dropdowns.
B4: HOW IT WORKS
B5: 1 | C5: Open '1. MASTER_ENTRY' and fill ONE row by clicking the dropdown arrows (yellow cells only).
B6: 2 | C6: RPN, timing, health and an AI recommendation calculate instantly.
B7: 3 | C7: That single case auto-creates a PM task, scored risk, FMEA line, PDCA cycle, action-log entry and Gantt bar.
B8: 4 | C8: Open 'DASHBOARD' for live KPIs & charts (change the chart with the D13 dropdown).
B9: 5 | C9: Open 'AI_ASSISTANT' for a ranked action queue and a Lean playbook advisor.
C10: ALL sheets are locked so you can only choose - never mistype. (Review > Unprotect Sheet to edit structure.)
B11: NAVIGATION
C12: > 1. MASTER_ENTRY
C13: > 2. PM_TASKS
C14: > 3. RISK_REGISTER
C15: > 4. FMEA
C16: > 5. PDCA
C17: > 6. ACTION_LOG
C18: > 7. TIMELINE
C19: > 8. SIX_SIGMA
C20: > DASHBOARD
C21: > AI_ASSISTANT

Sheet 1. MASTER_ENTRY
A1: CHOOSE-ONLY MASTER ENTRY - click dropdowns in the YELLOW columns
A2: Nothing here can be typed. Pick from the lists. GREEN columns auto-calc. Each row drives PM Tasks, Risk, FMEA, PDCA, Action Log, Timeline, Dashboard & AI.
A3: CASE ID (auto) | B3: DATE LOGGED | C3: PROBLEM / CHALLENGE STATEMENT | D3: CATEGORY | E3: PRIORITY | F3: SEV 1-10 | G3: OCC 1-10 | H3: DET 1-10 | I3: RPN (auto) | J3: RPN BAND (auto) | K3: ROOT CAUSE HYPOTHESIS | L3: LEAN METHOD | M3: OWNER | N3: TARGET OUTCOME (MEASURABLE) | O3: START DATE | P3: EST. DAYS (auto) | Q3: EST. END (auto) | R3: STATUS | S3: % DONE | T3: HEALTH (auto) | U3: AI RECOMMENDED ACTION (auto-generated)
A4: =IF($C4="","",TEXT(1,"\C\A\S\E-000")) | B4: 46157 | C4: Delivery targets missed 20% consistently | D4: Delivery / Schedule | E4: 1-CRITICAL | F4: 8 | G4: 7 | H4: 6 | I4: =IF($C4="","",IF(COUNT(F4,G4,H4)=3,F4*G4*H4,"")) | J4: =IF($I4="","",IF($I4>=200,"1-CRITICAL",IF($I4>=100,"2-HIGH",IF($I4>=50,"3-MEDIUM","4-LOW")))) | K4: Handoff delays invisible; no WIP limits | L4: Value Stream Mapping | M4: PM | N4: On-time delivery >95% in 8 weeks | O4: 46174 | P4: =IF($C4="","",ROUND(IF($E4="1-CRITICAL",7,IF($E4="2-HIGH",14,IF($E4="3-MEDIUM",30,45)))*(1+IF($I4="",0,$I4)/400),0)) | Q4: =IF(OR($C4="",$O4=""),"",$O4+$P4) | R4: IN PROGRESS | S4: 0.2 | T4: =IF($C4="","",IF($R4="CLOSED","Closed",IF($R4="RESOLVED","Resolved",IF($R4="BLOCKED","BLOCKED",IF($I4>=200,"CRITICAL",IF($I4>=100,"High",IF($E4="1-CRITICAL","High","On track"))))))) | U4: =IF($C4="","",IF($R4="CLOSED","Closed - capture lessons learned in PDCA Act phase.",IF($I4>=200,"CRITICAL (RPN "&$I4&"): Escalate today. Open FMEA action + daily PDCA. Owner "&IF($M4="","?",$M4)&". Apply "&IF($L4="","a Lean method",$L4)&". Close by "&IF($Q4="","ASAP",TEXT($Q4,"dd-mmm"))&".",IF($I4>=100,"HIGH (RPN "&$I4&"): Add to current sprint. Mitigate via "&IF($L4="","Standard Work",$L4)&". Review weekly with "&IF($M4="","owner",$M4)&".",IF(OR($E4="1-CRITICAL",$E4="2-HIGH"),"Priority case: schedule "&IF($L4="","a Lean workshop",$L4)&" within 2 weeks. Track to "&IF($N4="","target",$N4)&".","Monitor: apply "&IF($L4="","standard cadence",$L4)&". Re-score if conditions change."))))) | V4: =IF($C4="","",IF($I4="",0,$I4)+ROW()/100000)
A5: =IF($C5="","",TEXT(2,"\C\A\S\E-000")) | B5: 46157 | C5: Defect rate at 12% - customers complaining | D5: Quality / Defects | E5: 1-CRITICAL | F5: 8 | G5: 7 | H5: 6 | I5: =IF($C5="","",IF(COUNT(F5,G5,H5)=3,F5*G5*H5,"")) | J5: =IF($I5="","",IF($I5>=200,"1-CRITICAL",IF($I5>=100,"2-HIGH",IF($I5>=50,"3-MEDIUM","4-LOW")))) | K5: No quality check at source | L5: PDCA | M5: PM | N5: Zero defect escapes within 4 weeks | O5: 46174 | P5: =IF($C5="","",ROUND(IF($E5="1-CRITICAL",7,IF($E5="2-HIGH",14,IF($E5="3-MEDIUM",30,45)))*(1+IF($I5="",0,$I5)/400),0)) | Q5: =IF(OR($C5="",$O5=""),"",$O5+$P5) | R5: OPEN | S5: 0 | T5: =IF($C5="","",IF($R5="CLOSED","Closed",IF($R5="RESOLVED","Resolved",IF($R5="BLOCKED","BLOCKED",IF($I5>=200,"CRITICAL",IF($I5>=100,"High",IF($E5="1-CRITICAL","High","On track"))))))) | U5: =IF($C5="","",IF($R5="CLOSED","Closed - capture lessons learned in PDCA Act phase.",IF($I5>=200,"CRITICAL (RPN "&$I5&"): Escalate today. Open FMEA action + daily PDCA. Owner "&IF($M5="","?",$M5)&". Apply "&IF($L5="","a Lean method",$L5)&". Close by "&IF($Q5="","ASAP",TEXT($Q5,"dd-mmm"))&".",IF($I5>=100,"HIGH (RPN "&$I5&"): Add to current sprint. Mitigate via "&IF($L5="","Standard Work",$L5)&". Review weekly with "&IF($M5="","owner",$M5)&".",IF(OR($E5="1-CRITICAL",$E5="2-HIGH"),"Priority case: schedule "&IF($L5="","a Lean workshop",$L5)&" within 2 weeks. Track to "&IF($N5="","target",$N5)&".","Monitor: apply "&IF($L5="","standard cadence",$L5)&". Re-score if conditions change."))))) | V5: =IF($C5="","",IF($I5="",0,$I5)+ROW()/100000)
A6: =IF($C6="","",TEXT(3,"\C\A\S\E-000")) | B6: 46157 | C6: Team overwhelmed, parallel tasks >8 each | D6: Process / Flow | E6: 2-HIGH | F6: 7 | G6: 6 | H6: 5 | I6: =IF($C6="","",IF(COUNT(F6,G6,H6)=3,F6*G6*H6,"")) | J6: =IF($I6="","",IF($I6>=200,"1-CRITICAL",IF($I6>=100,"2-HIGH",IF($I6>=50,"3-MEDIUM","4-LOW")))) | K6: No WIP limits; everything is priority 1 | L6: Kanban | M6: PM | N6: Max 3 active tasks per person | O6: 46174 | P6: =IF($C6="","",ROUND(IF($E6="1-CRITICAL",7,IF($E6="2-HIGH",14,IF($E6="3-MEDIUM",30,45)))*(1+IF($I6="",0,$I6)/400),0)) | Q6: =IF(OR($C6="",$O6=""),"",$O6+$P6) | R6: OPEN | S6: 0 | T6: =IF($C6="","",IF($R6="CLOSED","Closed",IF($R6="RESOLVED","Resolved",IF($R6="BLOCKED","BLOCKED",IF($I6>=200,"CRITICAL",IF($I6>=100,"High",IF($E6="1-CRITICAL","High","On track"))))))) | U6: =IF($C6="","",IF($R6="CLOSED","Closed - capture lessons learned in PDCA Act phase.",IF($I6>=200,"CRITICAL (RPN "&$I6&"): Escalate today. Open FMEA action + daily PDCA. Owner "&IF($M6="","?",$M6)&". Apply "&IF($L6="","a Lean method",$L6)&". Close by "&IF($Q6="","ASAP",TEXT($Q6,"dd-mmm"))&".",IF($I6>=100,"HIGH (RPN "&$I6&"): Add to current sprint. Mitigate via "&IF($L6="","Standard Work",$L6)&". Review weekly with "&IF($M6="","owner",$M6)&".",IF(OR($E6="1-CRITICAL",$E6="2-HIGH"),"Priority case: schedule "&IF($L6="","a Lean workshop",$L6)&" within 2 weeks. Track to "&IF($N6="","target",$N6)&".","Monitor: apply "&IF($L6="","standard cadence",$L6)&". Re-score if conditions change."))))) | V6: =IF($C6="","",IF($I6="",0,$I6)+ROW()/100000)
A7: =IF($C7="","",TEXT(4,"\C\A\S\E-000")) | B7: 46157 | C7: Approval bottleneck adds 2.3 days per case | D7: Process / Flow | E7: 2-HIGH | F7: 7 | G7: 6 | H7: 5 | I7: =IF($C7="","",IF(COUNT(F7,G7,H7)=3,F7*G7*H7,"")) | J7: =IF($I7="","",IF($I7>=200,"1-CRITICAL",IF($I7>=100,"2-HIGH",IF($I7>=50,"3-MEDIUM","4-LOW")))) | K7: Wrong routing; unclear decision authority | L7: Standard Work | M7: PM | N7: Approval time <4 hours | O7: 46174 | P7: =IF($C7="","",ROUND(IF($E7="1-CRITICAL",7,IF($E7="2-HIGH",14,IF($E7="3-MEDIUM",30,45)))*(1+IF($I7="",0,$I7)/400),0)) | Q7: =IF(OR($C7="",$O7=""),"",$O7+$P7) | R7: OPEN | S7: 0 | T7: =IF($C7="","",IF($R7="CLOSED","Closed",IF($R7="RESOLVED","Resolved",IF($R7="BLOCKED","BLOCKED",IF($I7>=200,"CRITICAL",IF($I7>=100,"High",IF($E7="1-CRITICAL","High","On track"))))))) | U7: =IF($C7="","",IF($R7="CLOSED","Closed - capture lessons learned in PDCA Act phase.",IF($I7>=200,"CRITICAL (RPN "&$I7&"): Escalate today. Open FMEA action + daily PDCA. Owner "&IF($M7="","?",$M7)&". Apply "&IF($L7="","a Lean method",$L7)&". Close by "&IF($Q7="","ASAP",TEXT($Q7,"dd-mmm"))&".",IF($I7>=100,"HIGH (RPN "&$I7&"): Add to current sprint. Mitigate via "&IF($L7="","Standard Work",$L7)&". Review weekly with "&IF($M7="","owner",$M7)&".",IF(OR($E7="1-CRITICAL",$E7="2-HIGH"),"Priority case: schedule "&IF($L7="","a Lean workshop",$L7)&" within 2 weeks. Track to "&IF($N7="","target",$N7)&".","Monitor: apply "&IF($L7="","standard cadence",$L7)&". Re-score if conditions change."))))) | V7: =IF($C7="","",IF($I7="",0,$I7)+ROW()/100000)
A8: =IF($C8="","",TEXT(5,"\C\A\S\E-000")) | B8: 46157 | C8: New hire onboarding takes 6 weeks | D8: Process / Flow | E8: 3-MEDIUM | F8: 6 | G8: 5 | H8: 5 | I8: =IF($C8="","",IF(COUNT(F8,G8,H8)=3,F8*G8*H8,"")) | J8: =IF($I8="","",IF($I8>=200,"1-CRITICAL",IF($I8>=100,"2-HIGH",IF($I8>=50,"3-MEDIUM","4-LOW")))) | K8: No documented process; tribal knowledge | L8: Standard Work | M8: PM | N8: Onboard in 2 weeks, consistent quality | O8: 46174 | P8: =IF($C8="","",ROUND(IF($E8="1-CRITICAL",7,IF($E8="2-HIGH",14,IF($E8="3-MEDIUM",30,45)))*(1+IF($I8="",0,$I8)/400),0)) | Q8: =IF(OR($C8="",$O8=""),"",$O8+$P8) | R8: OPEN | S8: 0 | T8: =IF($C8="","",IF($R8="CLOSED","Closed",IF($R8="RESOLVED","Resolved",IF($R8="BLOCKED","BLOCKED",IF($I8>=200,"CRITICAL",IF($I8>=100,"High",IF($E8="1-CRITICAL","High","On track"))))))) | U8: =IF($C8="","",IF($R8="CLOSED","Closed - capture lessons learned in PDCA Act phase.",IF($I8>=200,"CRITICAL (RPN "&$I8&"): Escalate today. Open FMEA action + daily PDCA. Owner "&IF($M8="","?",$M8)&". Apply "&IF($L8="","a Lean method",$L8)&". Close by "&IF($Q8="","ASAP",TEXT($Q8,"dd-mmm"))&".",IF($I8>=100,"HIGH (RPN "&$I8&"): Add to current sprint. Mitigate via "&IF($L8="","Standard Work",$L8)&". Review weekly with "&IF($M8="","owner",$M8)&".",IF(OR($E8="1-CRITICAL",$E8="2-HIGH"),"Priority case: schedule "&IF($L8="","a Lean workshop",$L8)&" within 2 weeks. Track to "&IF($N8="","target",$N8)&".","Monitor: apply "&IF($L8="","standard cadence",$L8)&". Re-score if conditions change."))))) | V8: =IF($C8="","",IF($I8="",0,$I8)+ROW()/100000)
A9: =IF($C9="","",TEXT(6,"\C\A\S\E-000")) | B9: 46157 | C9: Leader not visible to frontline team | D9: Process / Flow | E9: 2-HIGH | F9: 7 | G9: 6 | H9: 5 | I9: =IF($C9="","",IF(COUNT(F9,G9,H9)=3,F9*G9*H9,"")) | J9: =IF($I9="","",IF($I9>=200,"1-CRITICAL",IF($I9>=100,"2-HIGH",IF($I9>=50,"3-MEDIUM","4-LOW")))) | K9: No structured Gemba cadence in place | L9: Gemba Walk | M9: PM | N9: Weekly Gemba walk every leader, every week | O9: 46174 | P9: =IF($C9="","",ROUND(IF($E9="1-CRITICAL",7,IF($E9="2-HIGH",14,IF($E9="3-MEDIUM",30,45)))*(1+IF($I9="",0,$I9)/400),0)) | Q9: =IF(OR($C9="",$O9=""),"",$O9+$P9) | R9: IN PROGRESS | S9: 0.2 | T9: =IF($C9="","",IF($R9="CLOSED","Closed",IF($R9="RESOLVED","Resolved",IF($R9="BLOCKED","BLOCKED",IF($I9>=200,"CRITICAL",IF($I9>=100,"High",IF($E9="1-CRITICAL","High","On track"))))))) | U9: =IF($C9="","",IF($R9="CLOSED","Closed - capture lessons learned in PDCA Act phase.",IF($I9>=200,"CRITICAL (RPN "&$I9&"): Escalate today. Open FMEA action + daily PDCA. Owner "&IF($M9="","?",$M9)&". Apply "&IF($L9="","a Lean method",$L9)&". Close by "&IF($Q9="","ASAP",TEXT($Q9,"dd-mmm"))&".",IF($I9>=100,"HIGH (RPN "&$I9&"): Add to current sprint. Mitigate via "&IF($L9="","Standard Work",$L9)&". Review weekly with "&IF($M9="","owner",$M9)&".",IF(OR($E9="1-CRITICAL",$E9="2-HIGH"),"Priority case: schedule "&IF($L9="","a Lean workshop",$L9)&" within 2 weeks. Track to "&IF($N9="","target",$N9)&".","Monitor: apply "&IF($L9="","standard cadence",$L9)&". Re-score if conditions change."))))) | V9: =IF($C9="","",IF($I9="",0,$I9)+ROW()/100000)
A10: =IF($C10="","",TEXT(7,"\C\A\S\E-000")) | I10: =IF($C10="","",IF(COUNT(F10,G10,H10)=3,F10*G10*H10,"")) | J10: =IF($I10="","",IF($I10>=200,"1-CRITICAL",IF($I10>=100,"2-HIGH",IF($I10>=50,"3-MEDIUM","4-LOW")))) | P10: =IF($C10="","",ROUND(IF($E10="1-CRITICAL",7,IF($E10="2-HIGH",14,IF($E10="3-MEDIUM",30,45)))*(1+IF($I10="",0,$I10)/400),0)) | Q10: =IF(OR($C10="",$O10=""),"",$O10+$P10) | T10: =IF($C10="","",IF($R10="CLOSED","Closed",IF($R10="RESOLVED","Resolved",IF($R10="BLOCKED","BLOCKED",IF($I10>=200,"CRITICAL",IF($I10>=100,"High",IF($E10="1-CRITICAL","High","On track"))))))) | U10: =IF($C10="","",IF($R10="CLOSED","Closed - capture lessons learned in PDCA Act phase.",IF($I10>=200,"CRITICAL (RPN "&$I10&"): Escalate today. Open FMEA action + daily PDCA. Owner "&IF($M10="","?",$M10)&". Apply "&IF($L10="","a Lean method",$L10)&". Close by "&IF($Q10="","ASAP",TEXT($Q10,"dd-mmm"))&".",IF($I10>=100,"HIGH (RPN "&$I10&"): Add to current sprint. Mitigate via "&IF($L10="","Standard Work",$L10)&". Review weekly with "&IF($M10="","owner",$M10)&".",IF(OR($E10="1-CRITICAL",$E10="2-HIGH"),"Priority case: schedule "&IF($L10="","a Lean workshop",$L10)&" within 2 weeks. Track to "&IF($N10="","target",$N10)&".","Monitor: apply "&IF($L10="","standard cadence",$L10)&". Re-score if conditions change."))))) | V10: =IF($C10="","",IF($I10="",0,$I10)+ROW()/100000)
A11: =IF($C11="","",TEXT(8,"\C\A\S\E-000")) | I11: =IF($C11="","",IF(COUNT(F11,G11,H11)=3,F11*G11*H11,"")) | J11: =IF($I11="","",IF($I11>=200,"1-CRITICAL",IF($I11>=100,"2-HIGH",IF($I11>=50,"3-MEDIUM","4-LOW")))) | P11: =IF($C11="","",ROUND(IF($E11="1-CRITICAL",7,IF($E11="2-HIGH",14,IF($E11="3-MEDIUM",30,45)))*(1+IF($I11="",0,$I11)/400),0)) | Q11: =IF(OR($C11="",$O11=""),"",$O11+$P11) | T11: =IF($C11="","",IF($R11="CLOSED","Closed",IF($R11="RESOLVED","Resolved",IF($R11="BLOCKED","BLOCKED",IF($I11>=200,"CRITICAL",IF($I11>=100,"High",IF($E11="1-CRITICAL","High","On track"))))))) | U11: =IF($C11="","",IF($R11="CLOSED","Closed - capture lessons learned in PDCA Act phase.",IF($I11>=200,"CRITICAL (RPN "&$I11&"): Escalate today. Open FMEA action + daily PDCA. Owner "&IF($M11="","?",$M11)&". Apply "&IF($L11="","a Lean method",$L11)&". Close by "&IF($Q11="","ASAP",TEXT($Q11,"dd-mmm"))&".",IF($I11>=100,"HIGH (RPN "&$I11&"): Add to current sprint. Mitigate via "&IF($L11="","Standard Work",$L11)&". Review weekly with "&IF($M11="","owner",$M11)&".",IF(OR($E11="1-CRITICAL",$E11="2-HIGH"),"Priority case: schedule "&IF($L11="","a Lean workshop",$L11)&" within 2 weeks. Track to "&IF($N11="","target",$N11)&".","Monitor: apply "&IF($L11="","standard cadence",$L11)&". Re-score if conditions change."))))) | V11: =IF($C11="","",IF($I11="",0,$I11)+ROW()/100000)
A12: =IF($C12="","",TEXT(9,"\C\A\S\E-000")) | I12: =IF($C12="","",IF(COUNT(F12,G12,H12)=3,F12*G12*H12,"")) | J12: =IF($I12="","",IF($I12>=200,"1-CRITICAL",IF($I12>=100,"2-HIGH",IF($I12>=50,"3-MEDIUM","4-LOW")))) | P12: =IF($C12="","",ROUND(IF($E12="1-CRITICAL",7,IF($E12="2-HIGH",14,IF($E12="3-MEDIUM",30,45)))*(1+IF($I12="",0,$I12)/400),0)) | Q12: =IF(OR($C12="",$O12=""),"",$O12+$P12) | T12: =IF($C12="","",IF($R12="CLOSED","Closed",IF($R12="RESOLVED","Resolved",IF($R12="BLOCKED","BLOCKED",IF($I12>=200,"CRITICAL",IF($I12>=100,"High",IF($E12="1-CRITICAL","High","On track"))))))) | U12: =IF($C12="","",IF($R12="CLOSED","Closed - capture lessons learned in PDCA Act phase.",IF($I12>=200,"CRITICAL (RPN "&$I12&"): Escalate today. Open FMEA action + daily PDCA. Owner "&IF($M12="","?",$M12)&". Apply "&IF($L12="","a Lean method",$L12)&". Close by "&IF($Q12="","ASAP",TEXT($Q12,"dd-mmm"))&".",IF($I12>=100,"HIGH (RPN "&$I12&"): Add to current sprint. Mitigate via "&IF($L12="","Standard Work",$L12)&". Review weekly with "&IF($M12="","owner",$M12)&".",IF(OR($E12="1-CRITICAL",$E12="2-HIGH"),"Priority case: schedule "&IF($L12="","a Lean workshop",$L12)&" within 2 weeks. Track to "&IF($N12="","target",$N12)&".","Monitor: apply "&IF($L12="","standard cadence",$L12)&". Re-score if conditions change."))))) | V12: =IF($C12="","",IF($I12="",0,$I12)+ROW()/100000)
A13: =IF($C13="","",TEXT(10,"\C\A\S\E-000")) | I13: =IF($C13="","",IF(COUNT(F13,G13,H13)=3,F13*G13*H13,"")) | J13: =IF($I13="","",IF($I13>=200,"1-CRITICAL",IF($I13>=100,"2-HIGH",IF($I13>=50,"3-MEDIUM","4-LOW")))) | P13: =IF($C13="","",ROUND(IF($E13="1-CRITICAL",7,IF($E13="2-HIGH",14,IF($E13="3-MEDIUM",30,45)))*(1+IF($I13="",0,$I13)/400),0)) | Q13: =IF(OR($C13="",$O13=""),"",$O13+$P13) | T13: =IF($C13="","",IF($R13="CLOSED","Closed",IF($R13="RESOLVED","Resolved",IF($R13="BLOCKED","BLOCKED",IF($I13>=200,"CRITICAL",IF($I13>=100,"High",IF($E13="1-CRITICAL","High","On track"))))))) | U13: =IF($C13="","",IF($R13="CLOSED","Closed - capture lessons learned in PDCA Act phase.",IF($I13>=200,"CRITICAL (RPN "&$I13&"): Escalate today. Open FMEA action + daily PDCA. Owner "&IF($M13="","?",$M13)&". Apply "&IF($L13="","a Lean method",$L13)&". Close by "&IF($Q13="","ASAP",TEXT($Q13,"dd-mmm"))&".",IF($I13>=100,"HIGH (RPN "&$I13&"): Add to current sprint. Mitigate via "&IF($L13="","Standard Work",$L13)&". Review weekly with "&IF($M13="","owner",$M13)&".",IF(OR($E13="1-CRITICAL",$E13="2-HIGH"),"Priority case: schedule "&IF($L13="","a Lean workshop",$L13)&" within 2 weeks. Track to "&IF($N13="","target",$N13)&".","Monitor: apply "&IF($L13="","standard cadence",$L13)&". Re-score if conditions change."))))) | V13: =IF($C13="","",IF($I13="",0,$I13)+ROW()/100000)
A14: =IF($C14="","",TEXT(11,"\C\A\S\E-000")) | I14: =IF($C14="","",IF(COUNT(F14,G14,H14)=3,F14*G14*H14,"")) | J14: =IF($I14="","",IF($I14>=200,"1-CRITICAL",IF($I14>=100,"2-HIGH",IF($I14>=50,"3-MEDIUM","4-LOW")))) | P14: =IF($C14="","",ROUND(IF($E14="1-CRITICAL",7,IF($E14="2-HIGH",14,IF($E14="3-MEDIUM",30,45)))*(1+IF($I14="",0,$I14)/400),0)) | Q14: =IF(OR($C14="",$O14=""),"",$O14+$P14) | T14: =IF($C14="","",IF($R14="CLOSED","Closed",IF($R14="RESOLVED","Resolved",IF($R14="BLOCKED","BLOCKED",IF($I14>=200,"CRITICAL",IF($I14>=100,"High",IF($E14="1-CRITICAL","High","On track"))))))) | U14: =IF($C14="","",IF($R14="CLOSED","Closed - capture lessons learned in PDCA Act phase.",IF($I14>=200,"CRITICAL (RPN "&$I14&"): Escalate today. Open FMEA action + daily PDCA. Owner "&IF($M14="","?",$M14)&". Apply "&IF($L14="","a Lean method",$L14)&". Close by "&IF($Q14="","ASAP",TEXT($Q14,"dd-mmm"))&".",IF($I14>=100,"HIGH (RPN "&$I14&"): Add to current sprint. Mitigate via "&IF($L14="","Standard Work",$L14)&". Review weekly with "&IF($M14="","owner",$M14)&".",IF(OR($E14="1-CRITICAL",$E14="2-HIGH"),"Priority case: schedule "&IF($L14="","a Lean workshop",$L14)&" within 2 weeks. Track to "&IF($N14="","target",$N14)&".","Monitor: apply "&IF($L14="","standard cadence",$L14)&". Re-score if conditions change."))))) | V14: =IF($C14="","",IF($I14="",0,$I14)+ROW()/100000)
A15: =IF($C15="","",TEXT(12,"\C\A\S\E-000")) | I15: =IF($C15="","",IF(COUNT(F15,G15,H15)=3,F15*G15*H15,"")) | J15: =IF($I15="","",IF($I15>=200,"1-CRITICAL",IF($I15>=100,"2-HIGH",IF($I15>=50,"3-MEDIUM","4-LOW")))) | P15: =IF($C15="","",ROUND(IF($E15="1-CRITICAL",7,IF($E15="2-HIGH",14,IF($E15="3-MEDIUM",30,45)))*(1+IF($I15="",0,$I15)/400),0)) | Q15: =IF(OR($C15="",$O15=""),"",$O15+$P15) | T15: =IF($C15="","",IF($R15="CLOSED","Closed",IF($R15="RESOLVED","Resolved",IF($R15="BLOCKED","BLOCKED",IF($I15>=200,"CRITICAL",IF($I15>=100,"High",IF($E15="1-CRITICAL","High","On track"))))))) | U15: =IF($C15="","",IF($R15="CLOSED","Closed - capture lessons learned in PDCA Act phase.",IF($I15>=200,"CRITICAL (RPN "&$I15&"): Escalate today. Open FMEA action + daily PDCA. Owner "&IF($M15="","?",$M15)&". Apply "&IF($L15="","a Lean method",$L15)&". Close by "&IF($Q15="","ASAP",TEXT($Q15,"dd-mmm"))&".",IF($I15>=100,"HIGH (RPN "&$I15&"): Add to current sprint. Mitigate via "&IF($L15="","Standard Work",$L15)&". Review weekly with "&IF($M15="","owner",$M15)&".",IF(OR($E15="1-CRITICAL",$E15="2-HIGH"),"Priority case: schedule "&IF($L15="","a Lean workshop",$L15)&" within 2 weeks. Track to "&IF($N15="","target",$N15)&".","Monitor: apply "&IF($L15="","standard cadence",$L15)&". Re-score if conditions change."))))) | V15: =IF($C15="","",IF($I15="",0,$I15)+ROW()/100000)
A16: =IF($C16="","",TEXT(13,"\C\A\S\E-000")) | I16: =IF($C16="","",IF(COUNT(F16,G16,H16)=3,F16*G16*H16,"")) | J16: =IF($I16="","",IF($I16>=200,"1-CRITICAL",IF($I16>=100,"2-HIGH",IF($I16>=50,"3-MEDIUM","4-LOW")))) | P16: =IF($C16="","",ROUND(IF($E16="1-CRITICAL",7,IF($E16="2-HIGH",14,IF($E16="3-MEDIUM",30,45)))*(1+IF($I16="",0,$I16)/400),0)) | Q16: =IF(OR($C16="",$O16=""),"",$O16+$P16) | T16: =IF($C16="","",IF($R16="CLOSED","Closed",IF($R16="RESOLVED","Resolved",IF($R16="BLOCKED","BLOCKED",IF($I16>=200,"CRITICAL",IF($I16>=100,"High",IF($E16="1-CRITICAL","High","On track"))))))) | U16: =IF($C16="","",IF($R16="CLOSED","Closed - capture lessons learned in PDCA Act phase.",IF($I16>=200,"CRITICAL (RPN "&$I16&"): Escalate today. Open FMEA action + daily PDCA. Owner "&IF($M16="","?",$M16)&". Apply "&IF($L16="","a Lean method",$L16)&". Close by "&IF($Q16="","ASAP",TEXT($Q16,"dd-mmm"))&".",IF($I16>=100,"HIGH (RPN "&$I16&"): Add to current sprint. Mitigate via "&IF($L16="","Standard Work",$L16)&". Review weekly with "&IF($M16="","owner",$M16)&".",IF(OR($E16="1-CRITICAL",$E16="2-HIGH"),"Priority case: schedule "&IF($L16="","a Lean workshop",$L16)&" within 2 weeks. Track to "&IF($N16="","target",$N16)&".","Monitor: apply "&IF($L16="","standard cadence",$L16)&". Re-score if conditions change."))))) | V16: =IF($C16="","",IF($I16="",0,$I16)+ROW()/100000)
A17: =IF($C17="","",TEXT(14,"\C\A\S\E-000")) | I17: =IF($C17="","",IF(COUNT(F17,G17,H17)=3,F17*G17*H17,"")) | J17: =IF($I17="","",IF($I17>=200,"1-CRITICAL",IF($I17>=100,"2-HIGH",IF($I17>=50,"3-MEDIUM","4-LOW")))) | P17: =IF($C17="","",ROUND(IF($E17="1-CRITICAL",7,IF($E17="2-HIGH",14,IF($E17="3-MEDIUM",30,45)))*(1+IF($I17="",0,$I17)/400),0)) | Q17: =IF(OR($C17="",$O17=""),"",$O17+$P17) | T17: =IF($C17="","",IF($R17="CLOSED","Closed",IF($R17="RESOLVED","Resolved",IF($R17="BLOCKED","BLOCKED",IF($I17>=200,"CRITICAL",IF($I17>=100,"High",IF($E17="1-CRITICAL","High","On track"))))))) | U17: =IF($C17="","",IF($R17="CLOSED","Closed - capture lessons learned in PDCA Act phase.",IF($I17>=200,"CRITICAL (RPN "&$I17&"): Escalate today. Open FMEA action + daily PDCA. Owner "&IF($M17="","?",$M17)&". Apply "&IF($L17="","a Lean method",$L17)&". Close by "&IF($Q17="","ASAP",TEXT($Q17,"dd-mmm"))&".",IF($I17>=100,"HIGH (RPN "&$I17&"): Add to current sprint. Mitigate via "&IF($L17="","Standard Work",$L17)&". Review weekly with "&IF($M17="","owner",$M17)&".",IF(OR($E17="1-CRITICAL",$E17="2-HIGH"),"Priority case: schedule "&IF($L17="","a Lean workshop",$L17)&" within 2 weeks. Track to "&IF($N17="","target",$N17)&".","Monitor: apply "&IF($L17="","standard cadence",$L17)&". Re-score if conditions change."))))) | V17: =IF($C17="","",IF($I17="",0,$I17)+ROW()/100000)
A18: =IF($C18="","",TEXT(15,"\C\A\S\E-000")) | I18: =IF($C18="","",IF(COUNT(F18,G18,H18)=3,F18*G18*H18,"")) | J18: =IF($I18="","",IF($I18>=200,"1-CRITICAL",IF($I18>=100,"2-HIGH",IF($I18>=50,"3-MEDIUM","4-LOW")))) | P18: =IF($C18="","",ROUND(IF($E18="1-CRITICAL",7,IF($E18="2-HIGH",14,IF($E18="3-MEDIUM",30,45)))*(1+IF($I18="",0,$I18)/400),0)) | Q18: =IF(OR($C18="",$O18=""),"",$O18+$P18) | T18: =IF($C18="","",IF($R18="CLOSED","Closed",IF($R18="RESOLVED","Resolved",IF($R18="BLOCKED","BLOCKED",IF($I18>=200,"CRITICAL",IF($I18>=100,"High",IF($E18="1-CRITICAL","High","On track"))))))) | U18: =IF($C18="","",IF($R18="CLOSED","Closed - capture lessons learned in PDCA Act phase.",IF($I18>=200,"CRITICAL (RPN "&$I18&"): Escalate today. Open FMEA action + daily PDCA. Owner "&IF($M18="","?",$M18)&". Apply "&IF($L18="","a Lean method",$L18)&". Close by "&IF($Q18="","ASAP",TEXT($Q18,"dd-mmm"))&".",IF($I18>=100,"HIGH (RPN "&$I18&"): Add to current sprint. Mitigate via "&IF($L18="","Standard Work",$L18)&". Review weekly with "&IF($M18="","owner",$M18)&".",IF(OR($E18="1-CRITICAL",$E18="2-HIGH"),"Priority case: schedule "&IF($L18="","a Lean workshop",$L18)&" within 2 weeks. Track to "&IF($N18="","target",$N18)&".","Monitor: apply "&IF($L18="","standard cadence",$L18)&". Re-score if conditions change."))))) | V18: =IF($C18="","",IF($I18="",0,$I18)+ROW()/100000)
A19: =IF($C19="","",TEXT(16,"\C\A\S\E-000")) | I19: =IF($C19="","",IF(COUNT(F19,G19,H19)=3,F19*G19*H19,"")) | J19: =IF($I19="","",IF($I19>=200,"1-CRITICAL",IF($I19>=100,"2-HIGH",IF($I19>=50,"3-MEDIUM","4-LOW")))) | P19: =IF($C19="","",ROUND(IF($E19="1-CRITICAL",7,IF($E19="2-HIGH",14,IF($E19="3-MEDIUM",30,45)))*(1+IF($I19="",0,$I19)/400),0)) | Q19: =IF(OR($C19="",$O19=""),"",$O19+$P19) | T19: =IF($C19="","",IF($R19="CLOSED","Closed",IF($R19="RESOLVED","Resolved",IF($R19="BLOCKED","BLOCKED",IF($I19>=200,"CRITICAL",IF($I19>=100,"High",IF($E19="1-CRITICAL","High","On track"))))))) | U19: =IF($C19="","",IF($R19="CLOSED","Closed - capture lessons learned in PDCA Act phase.",IF($I19>=200,"CRITICAL (RPN "&$I19&"): Escalate today. Open FMEA action + daily PDCA. Owner "&IF($M19="","?",$M19)&". Apply "&IF($L19="","a Lean method",$L19)&". Close by "&IF($Q19="","ASAP",TEXT($Q19,"dd-mmm"))&".",IF($I19>=100,"HIGH (RPN "&$I19&"): Add to current sprint. Mitigate via "&IF($L19="","Standard Work",$L19)&". Review weekly with "&IF($M19="","owner",$M19)&".",IF(OR($E19="1-CRITICAL",$E19="2-HIGH"),"Priority case: schedule "&IF($L19="","a Lean workshop",$L19)&" within 2 weeks. Track to "&IF($N19="","target",$N19)&".","Monitor: apply "&IF($L19="","standard cadence",$L19)&". Re-score if conditions change."))))) | V19: =IF($C19="","",IF($I19="",0,$I19)+ROW()/100000)
A20: =IF($C20="","",TEXT(17,"\C\A\S\E-000")) | I20: =IF($C20="","",IF(COUNT(F20,G20,H20)=3,F20*G20*H20,"")) | J20: =IF($I20="","",IF($I20>=200,"1-CRITICAL",IF($I20>=100,"2-HIGH",IF($I20>=50,"3-MEDIUM","4-LOW")))) | P20: =IF($C20="","",ROUND(IF($E20="1-CRITICAL",7,IF($E20="2-HIGH",14,IF($E20="3-MEDIUM",30,45)))*(1+IF($I20="",0,$I20)/400),0)) | Q20: =IF(OR($C20="",$O20=""),"",$O20+$P20) | T20: =IF($C20="","",IF($R20="CLOSED","Closed",IF($R20="RESOLVED","Resolved",IF($R20="BLOCKED","BLOCKED",IF($I20>=200,"CRITICAL",IF($I20>=100,"High",IF($E20="1-CRITICAL","High","On track"))))))) | U20: =IF($C20="","",IF($R20="CLOSED","Closed - capture lessons learned in PDCA Act phase.",IF($I20>=200,"CRITICAL (RPN "&$I20&"): Escalate today. Open FMEA action + daily PDCA. Owner "&IF($M20="","?",$M20)&". Apply "&IF($L20="","a Lean method",$L20)&". Close by "&IF($Q20="","ASAP",TEXT($Q20,"dd-mmm"))&".",IF($I20>=100,"HIGH (RPN "&$I20&"): Add to current sprint. Mitigate via "&IF($L20="","Standard Work",$L20)&". Review weekly with "&IF($M20="","owner",$M20)&".",IF(OR($E20="1-CRITICAL",$E20="2-HIGH"),"Priority case: schedule "&IF($L20="","a Lean workshop",$L20)&" within 2 weeks. Track to "&IF($N20="","target",$N20)&".","Monitor: apply "&IF($L20="","standard cadence",$L20)&". Re-score if conditions change."))))) | V20: =IF($C20="","",IF($I20="",0,$I20)+ROW()/100000)
A21: =IF($C21="","",TEXT(18,"\C\A\S\E-000")) | I21: =IF($C21="","",IF(COUNT(F21,G21,H21)=3,F21*G21*H21,"")) | J21: =IF($I21="","",IF($I21>=200,"1-CRITICAL",IF($I21>=100,"2-HIGH",IF($I21>=50,"3-MEDIUM","4-LOW")))) | P21: =IF($C21="","",ROUND(IF($E21="1-CRITICAL",7,IF($E21="2-HIGH",14,IF($E21="3-MEDIUM",30,45)))*(1+IF($I21="",0,$I21)/400),0)) | Q21: =IF(OR($C21="",$O21=""),"",$O21+$P21) | T21: =IF($C21="","",IF($R21="CLOSED","Closed",IF($R21="RESOLVED","Resolved",IF($R21="BLOCKED","BLOCKED",IF($I21>=200,"CRITICAL",IF($I21>=100,"High",IF($E21="1-CRITICAL","High","On track"))))))) | U21: =IF($C21="","",IF($R21="CLOSED","Closed - capture lessons learned in PDCA Act phase.",IF($I21>=200,"CRITICAL (RPN "&$I21&"): Escalate today. Open FMEA action + daily PDCA. Owner "&IF($M21="","?",$M21)&". Apply "&IF($L21="","a Lean method",$L21)&". Close by "&IF($Q21="","ASAP",TEXT($Q21,"dd-mmm"))&".",IF($I21>=100,"HIGH (RPN "&$I21&"): Add to current sprint. Mitigate via "&IF($L21="","Standard Work",$L21)&". Review weekly with "&IF($M21="","owner",$M21)&".",IF(OR($E21="1-CRITICAL",$E21="2-HIGH"),"Priority case: schedule "&IF($L21="","a Lean workshop",$L21)&" within 2 weeks. Track to "&IF($N21="","target",$N21)&".","Monitor: apply "&IF($L21="","standard cadence",$L21)&". Re-score if conditions change."))))) | V21: =IF($C21="","",IF($I21="",0,$I21)+ROW()/100000)
A22: =IF($C22="","",TEXT(19,"\C\A\S\E-000")) | I22: =IF($C22="","",IF(COUNT(F22,G22,H22)=3,F22*G22*H22,"")) | J22: =IF($I22="","",IF($I22>=200,"1-CRITICAL",IF($I22>=100,"2-HIGH",IF($I22>=50,"3-MEDIUM","4-LOW")))) | P22: =IF($C22="","",ROUND(IF($E22="1-CRITICAL",7,IF($E22="2-HIGH",14,IF($E22="3-MEDIUM",30,45)))*(1+IF($I22="",0,$I22)/400),0)) | Q22: =IF(OR($C22="",$O22=""),"",$O22+$P22) | T22: =IF($C22="","",IF($R22="CLOSED","Closed",IF($R22="RESOLVED","Resolved",IF($R22="BLOCKED","BLOCKED",IF($I22>=200,"CRITICAL",IF($I22>=100,"High",IF($E22="1-CRITICAL","High","On track"))))))) | U22: =IF($C22="","",IF($R22="CLOSED","Closed - capture lessons learned in PDCA Act phase.",IF($I22>=200,"CRITICAL (RPN "&$I22&"): Escalate today. Open FMEA action + daily PDCA. Owner "&IF($M22="","?",$M22)&". Apply "&IF($L22="","a Lean method",$L22)&". Close by "&IF($Q22="","ASAP",TEXT($Q22,"dd-mmm"))&".",IF($I22>=100,"HIGH (RPN "&$I22&"): Add to current sprint. Mitigate via "&IF($L22="","Standard Work",$L22)&". Review weekly with "&IF($M22="","owner",$M22)&".",IF(OR($E22="1-CRITICAL",$E22="2-HIGH"),"Priority case: schedule "&IF($L22="","a Lean workshop",$L22)&" within 2 weeks. Track to "&IF($N22="","target",$N22)&".","Monitor: apply "&IF($L22="","standard cadence",$L22)&". Re-score if conditions change."))))) | V22: =IF($C22="","",IF($I22="",0,$I22)+ROW()/100000)
A23: =IF($C23="","",TEXT(20,"\C\A\S\E-000")) | I23: =IF($C23="","",IF(COUNT(F23,G23,H23)=3,F23*G23*H23,"")) | J23: =IF($I23="","",IF($I23>=200,"1-CRITICAL",IF($I23>=100,"2-HIGH",IF($I23>=50,"3-MEDIUM","4-LOW")))) | P23: =IF($C23="","",ROUND(IF($E23="1-CRITICAL",7,IF($E23="2-HIGH",14,IF($E23="3-MEDIUM",30,45)))*(1+IF($I23="",0,$I23)/400),0)) | Q23: =IF(OR($C23="",$O23=""),"",$O23+$P23) | T23: =IF($C23="","",IF($R23="CLOSED","Closed",IF($R23="RESOLVED","Resolved",IF($R23="BLOCKED","BLOCKED",IF($I23>=200,"CRITICAL",IF($I23>=100,"High",IF($E23="1-CRITICAL","High","On track"))))))) | U23: =IF($C23="","",IF($R23="CLOSED","Closed - capture lessons learned in PDCA Act phase.",IF($I23>=200,"CRITICAL (RPN "&$I23&"): Escalate today. Open FMEA action + daily PDCA. Owner "&IF($M23="","?",$M23)&". Apply "&IF($L23="","a Lean method",$L23)&". Close by "&IF($Q23="","ASAP",TEXT($Q23,"dd-mmm"))&".",IF($I23>=100,"HIGH (RPN "&$I23&"): Add to current sprint. Mitigate via "&IF($L23="","Standard Work",$L23)&". Review weekly with "&IF($M23="","owner",$M23)&".",IF(OR($E23="1-CRITICAL",$E23="2-HIGH"),"Priority case: schedule "&IF($L23="","a Lean workshop",$L23)&" within 2 weeks. Track to "&IF($N23="","target",$N23)&".","Monitor: apply "&IF($L23="","standard cadence",$L23)&". Re-score if conditions change."))))) | V23: =IF($C23="","",IF($I23="",0,$I23)+ROW()/100000)
A24: =IF($C24="","",TEXT(21,"\C\A\S\E-000")) | I24: =IF($C24="","",IF(COUNT(F24,G24,H24)=3,F24*G24*H24,"")) | J24: =IF($I24="","",IF($I24>=200,"1-CRITICAL",IF($I24>=100,"2-HIGH",IF($I24>=50,"3-MEDIUM","4-LOW")))) | P24: =IF($C24="","",ROUND(IF($E24="1-CRITICAL",7,IF($E24="2-HIGH",14,IF($E24="3-MEDIUM",30,45)))*(1+IF($I24="",0,$I24)/400),0)) | Q24: =IF(OR($C24="",$O24=""),"",$O24+$P24) | T24: =IF($C24="","",IF($R24="CLOSED","Closed",IF($R24="RESOLVED","Resolved",IF($R24="BLOCKED","BLOCKED",IF($I24>=200,"CRITICAL",IF($I24>=100,"High",IF($E24="1-CRITICAL","High","On track"))))))) | U24: =IF($C24="","",IF($R24="CLOSED","Closed - capture lessons learned in PDCA Act phase.",IF($I24>=200,"CRITICAL (RPN "&$I24&"): Escalate today. Open FMEA action + daily PDCA. Owner "&IF($M24="","?",$M24)&". Apply "&IF($L24="","a Lean method",$L24)&". Close by "&IF($Q24="","ASAP",TEXT($Q24,"dd-mmm"))&".",IF($I24>=100,"HIGH (RPN "&$I24&"): Add to current sprint. Mitigate via "&IF($L24="","Standard Work",$L24)&". Review weekly with "&IF($M24="","owner",$M24)&".",IF(OR($E24="1-CRITICAL",$E24="2-HIGH"),"Priority case: schedule "&IF($L24="","a Lean workshop",$L24)&" within 2 weeks. Track to "&IF($N24="","target",$N24)&".","Monitor: apply "&IF($L24="","standard cadence",$L24)&". Re-score if conditions change."))))) | V24: =IF($C24="","",IF($I24="",0,$I24)+ROW()/100000)
A25: =IF($C25="","",TEXT(22,"\C\A\S\E-000")) | I25: =IF($C25="","",IF(COUNT(F25,G25,H25)=3,F25*G25*H25,"")) | J25: =IF($I25="","",IF($I25>=200,"1-CRITICAL",IF($I25>=100,"2-HIGH",IF($I25>=50,"3-MEDIUM","4-LOW")))) | P25: =IF($C25="","",ROUND(IF($E25="1-CRITICAL",7,IF($E25="2-HIGH",14,IF($E25="3-MEDIUM",30,45)))*(1+IF($I25="",0,$I25)/400),0)) | Q25: =IF(OR($C25="",$O25=""),"",$O25+$P25) | T25: =IF($C25="","",IF($R25="CLOSED","Closed",IF($R25="RESOLVED","Resolved",IF($R25="BLOCKED","BLOCKED",IF($I25>=200,"CRITICAL",IF($I25>=100,"High",IF($E25="1-CRITICAL","High","On track"))))))) | U25: =IF($C25="","",IF($R25="CLOSED","Closed - capture lessons learned in PDCA Act phase.",IF($I25>=200,"CRITICAL (RPN "&$I25&"): Escalate today. Open FMEA action + daily PDCA. Owner "&IF($M25="","?",$M25)&". Apply "&IF($L25="","a Lean method",$L25)&". Close by "&IF($Q25="","ASAP",TEXT($Q25,"dd-mmm"))&".",IF($I25>=100,"HIGH (RPN "&$I25&"): Add to current sprint. Mitigate via "&IF($L25="","Standard Work",$L25)&". Review weekly with "&IF($M25="","owner",$M25)&".",IF(OR($E25="1-CRITICAL",$E25="2-HIGH"),"Priority case: schedule "&IF($L25="","a Lean workshop",$L25)&" within 2 weeks. Track to "&IF($N25="","target",$N25)&".","Monitor: apply "&IF($L25="","standard cadence",$L25)&". Re-score if conditions change."))))) | V25: =IF($C25="","",IF($I25="",0,$I25)+ROW()/100000)
A26: =IF($C26="","",TEXT(23,"\C\A\S\E-000")) | I26: =IF($C26="","",IF(COUNT(F26,G26,H26)=3,F26*G26*H26,"")) | J26: =IF($I26="","",IF($I26>=200,"1-CRITICAL",IF($I26>=100,"2-HIGH",IF($I26>=50,"3-MEDIUM","4-LOW")))) | P26: =IF($C26="","",ROUND(IF($E26="1-CRITICAL",7,IF($E26="2-HIGH",14,IF($E26="3-MEDIUM",30,45)))*(1+IF($I26="",0,$I26)/400),0)) | Q26: =IF(OR($C26="",$O26=""),"",$O26+$P26) | T26: =IF($C26="","",IF($R26="CLOSED","Closed",IF($R26="RESOLVED","Resolved",IF($R26="BLOCKED","BLOCKED",IF($I26>=200,"CRITICAL",IF($I26>=100,"High",IF($E26="1-CRITICAL","High","On track"))))))) | U26: =IF($C26="","",IF($R26="CLOSED","Closed - capture lessons learned in PDCA Act phase.",IF($I26>=200,"CRITICAL (RPN "&$I26&"): Escalate today. Open FMEA action + daily PDCA. Owner "&IF($M26="","?",$M26)&". Apply "&IF($L26="","a Lean method",$L26)&". Close by "&IF($Q26="","ASAP",TEXT($Q26,"dd-mmm"))&".",IF($I26>=100,"HIGH (RPN "&$I26&"): Add to current sprint. Mitigate via "&IF($L26="","Standard Work",$L26)&". Review weekly with "&IF($M26="","owner",$M26)&".",IF(OR($E26="1-CRITICAL",$E26="2-HIGH"),"Priority case: schedule "&IF($L26="","a Lean workshop",$L26)&" within 2 weeks. Track to "&IF($N26="","target",$N26)&".","Monitor: apply "&IF($L26="","standard cadence",$L26)&". Re-score if conditions change."))))) | V26: =IF($C26="","",IF($I26="",0,$I26)+ROW()/100000)
A27: =IF($C27="","",TEXT(24,"\C\A\S\E-000")) | I27: =IF($C27="","",IF(COUNT(F27,G27,H27)=3,F27*G27*H27,"")) | J27: =IF($I27="","",IF($I27>=200,"1-CRITICAL",IF($I27>=100,"2-HIGH",IF($I27>=50,"3-MEDIUM","4-LOW")))) | P27: =IF($C27="","",ROUND(IF($E27="1-CRITICAL",7,IF($E27="2-HIGH",14,IF($E27="3-MEDIUM",30,45)))*(1+IF($I27="",0,$I27)/400),0)) | Q27: =IF(OR($C27="",$O27=""),"",$O27+$P27) | T27: =IF($C27="","",IF($R27="CLOSED","Closed",IF($R27="RESOLVED","Resolved",IF($R27="BLOCKED","BLOCKED",IF($I27>=200,"CRITICAL",IF($I27>=100,"High",IF($E27="1-CRITICAL","High","On track"))))))) | U27: =IF($C27="","",IF($R27="CLOSED","Closed - capture lessons learned in PDCA Act phase.",IF($I27>=200,"CRITICAL (RPN "&$I27&"): Escalate today. Open FMEA action + daily PDCA. Owner "&IF($M27="","?",$M27)&". Apply "&IF($L27="","a Lean method",$L27)&". Close by "&IF($Q27="","ASAP",TEXT($Q27,"dd-mmm"))&".",IF($I27>=100,"HIGH (RPN "&$I27&"): Add to current sprint. Mitigate via "&IF($L27="","Standard Work",$L27)&". Review weekly with "&IF($M27="","owner",$M27)&".",IF(OR($E27="1-CRITICAL",$E27="2-HIGH"),"Priority case: schedule "&IF($L27="","a Lean workshop",$L27)&" within 2 weeks. Track to "&IF($N27="","target",$N27)&".","Monitor: apply "&IF($L27="","standard cadence",$L27)&". Re-score if conditions change."))))) | V27: =IF($C27="","",IF($I27="",0,$I27)+ROW()/100000)
A28: =IF($C28="","",TEXT(25,"\C\A\S\E-000")) | I28: =IF($C28="","",IF(COUNT(F28,G28,H28)=3,F28*G28*H28,"")) | J28: =IF($I28="","",IF($I28>=200,"1-CRITICAL",IF($I28>=100,"2-HIGH",IF($I28>=50,"3-MEDIUM","4-LOW")))) | P28: =IF($C28="","",ROUND(IF($E28="1-CRITICAL",7,IF($E28="2-HIGH",14,IF($E28="3-MEDIUM",30,45)))*(1+IF($I28="",0,$I28)/400),0)) | Q28: =IF(OR($C28="",$O28=""),"",$O28+$P28) | T28: =IF($C28="","",IF($R28="CLOSED","Closed",IF($R28="RESOLVED","Resolved",IF($R28="BLOCKED","BLOCKED",IF($I28>=200,"CRITICAL",IF($I28>=100,"High",IF($E28="1-CRITICAL","High","On track"))))))) | U28: =IF($C28="","",IF($R28="CLOSED","Closed - capture lessons learned in PDCA Act phase.",IF($I28>=200,"CRITICAL (RPN "&$I28&"): Escalate today. Open FMEA action + daily PDCA. Owner "&IF($M28="","?",$M28)&". Apply "&IF($L28="","a Lean method",$L28)&". Close by "&IF($Q28="","ASAP",TEXT($Q28,"dd-mmm"))&".",IF($I28>=100,"HIGH (RPN "&$I28&"): Add to current sprint. Mitigate via "&IF($L28="","Standard Work",$L28)&". Review weekly with "&IF($M28="","owner",$M28)&".",IF(OR($E28="1-CRITICAL",$E28="2-HIGH"),"Priority case: schedule "&IF($L28="","a Lean workshop",$L28)&" within 2 weeks. Track to "&IF($N28="","target",$N28)&".","Monitor: apply "&IF($L28="","standard cadence",$L28)&". Re-score if conditions change."))))) | V28: =IF($C28="","",IF($I28="",0,$I28)+ROW()/100000)
A29: =IF($C29="","",TEXT(26,"\C\A\S\E-000")) | I29: =IF($C29="","",IF(COUNT(F29,G29,H29)=3,F29*G29*H29,"")) | J29: =IF($I29="","",IF($I29>=200,"1-CRITICAL",IF($I29>=100,"2-HIGH",IF($I29>=50,"3-MEDIUM","4-LOW")))) | P29: =IF($C29="","",ROUND(IF($E29="1-CRITICAL",7,IF($E29="2-HIGH",14,IF($E29="3-MEDIUM",30,45)))*(1+IF($I29="",0,$I29)/400),0)) | Q29: =IF(OR($C29="",$O29=""),"",$O29+$P29) | T29: =IF($C29="","",IF($R29="CLOSED","Closed",IF($R29="RESOLVED","Resolved",IF($R29="BLOCKED","BLOCKED",IF($I29>=200,"CRITICAL",IF($I29>=100,"High",IF($E29="1-CRITICAL","High","On track"))))))) | U29: =IF($C29="","",IF($R29="CLOSED","Closed - capture lessons learned in PDCA Act phase.",IF($I29>=200,"CRITICAL (RPN "&$I29&"): Escalate today. Open FMEA action + daily PDCA. Owner "&IF($M29="","?",$M29)&". Apply "&IF($L29="","a Lean method",$L29)&". Close by "&IF($Q29="","ASAP",TEXT($Q29,"dd-mmm"))&".",IF($I29>=100,"HIGH (RPN "&$I29&"): Add to current sprint. Mitigate via "&IF($L29="","Standard Work",$L29)&". Review weekly with "&IF($M29="","owner",$M29)&".",IF(OR($E29="1-CRITICAL",$E29="2-HIGH"),"Priority case: schedule "&IF($L29="","a Lean workshop",$L29)&" within 2 weeks. Track to "&IF($N29="","target",$N29)&".","Monitor: apply "&IF($L29="","standard cadence",$L29)&". Re-score if conditions change."))))) | V29: =IF($C29="","",IF($I29="",0,$I29)+ROW()/100000)
A30: =IF($C30="","",TEXT(27,"\C\A\S\E-000")) | I30: =IF($C30="","",IF(COUNT(F30,G30,H30)=3,F30*G30*H30,"")) | J30: =IF($I30="","",IF($I30>=200,"1-CRITICAL",IF($I30>=100,"2-HIGH",IF($I30>=50,"3-MEDIUM","4-LOW")))) | P30: =IF($C30="","",ROUND(IF($E30="1-CRITICAL",7,IF($E30="2-HIGH",14,IF($E30="3-MEDIUM",30,45)))*(1+IF($I30="",0,$I30)/400),0)) | Q30: =IF(OR($C30="",$O30=""),"",$O30+$P30) | T30: =IF($C30="","",IF($R30="CLOSED","Closed",IF($R30="RESOLVED","Resolved",IF($R30="BLOCKED","BLOCKED",IF($I30>=200,"CRITICAL",IF($I30>=100,"High",IF($E30="1-CRITICAL","High","On track"))))))) | U30: =IF($C30="","",IF($R30="CLOSED","Closed - capture lessons learned in PDCA Act phase.",IF($I30>=200,"CRITICAL (RPN "&$I30&"): Escalate today. Open FMEA action + daily PDCA. Owner "&IF($M30="","?",$M30)&". Apply "&IF($L30="","a Lean method",$L30)&". Close by "&IF($Q30="","ASAP",TEXT($Q30,"dd-mmm"))&".",IF($I30>=100,"HIGH (RPN "&$I30&"): Add to current sprint. Mitigate via "&IF($L30="","Standard Work",$L30)&". Review weekly with "&IF($M30="","owner",$M30)&".",IF(OR($E30="1-CRITICAL",$E30="2-HIGH"),"Priority case: schedule "&IF($L30="","a Lean workshop",$L30)&" within 2 weeks. Track to "&IF($N30="","target",$N30)&".","Monitor: apply "&IF($L30="","standard cadence",$L30)&". Re-score if conditions change."))))) | V30: =IF($C30="","",IF($I30="",0,$I30)+ROW()/100000)
A31: =IF($C31="","",TEXT(28,"\C\A\S\E-000")) | I31: =IF($C31="","",IF(COUNT(F31,G31,H31)=3,F31*G31*H31,"")) | J31: =IF($I31="","",IF($I31>=200,"1-CRITICAL",IF($I31>=100,"2-HIGH",IF($I31>=50,"3-MEDIUM","4-LOW")))) | P31: =IF($C31="","",ROUND(IF($E31="1-CRITICAL",7,IF($E31="2-HIGH",14,IF($E31="3-MEDIUM",30,45)))*(1+IF($I31="",0,$I31)/400),0)) | Q31: =IF(OR($C31="",$O31=""),"",$O31+$P31) | T31: =IF($C31="","",IF($R31="CLOSED","Closed",IF($R31="RESOLVED","Resolved",IF($R31="BLOCKED","BLOCKED",IF($I31>=200,"CRITICAL",IF($I31>=100,"High",IF($E31="1-CRITICAL","High","On track"))))))) | U31: =IF($C31="","",IF($R31="CLOSED","Closed - capture lessons learned in PDCA Act phase.",IF($I31>=200,"CRITICAL (RPN "&$I31&"): Escalate today. Open FMEA action + daily PDCA. Owner "&IF($M31="","?",$M31)&". Apply "&IF($L31="","a Lean method",$L31)&". Close by "&IF($Q31="","ASAP",TEXT($Q31,"dd-mmm"))&".",IF($I31>=100,"HIGH (RPN "&$I31&"): Add to current sprint. Mitigate via "&IF($L31="","Standard Work",$L31)&". Review weekly with "&IF($M31="","owner",$M31)&".",IF(OR($E31="1-CRITICAL",$E31="2-HIGH"),"Priority case: schedule "&IF($L31="","a Lean workshop",$L31)&" within 2 weeks. Track to "&IF($N31="","target",$N31)&".","Monitor: apply "&IF($L31="","standard cadence",$L31)&". Re-score if conditions change."))))) | V31: =IF($C31="","",IF($I31="",0,$I31)+ROW()/100000)
A32: =IF($C32="","",TEXT(29,"\C\A\S\E-000")) | I32: =IF($C32="","",IF(COUNT(F32,G32,H32)=3,F32*G32*H32,"")) | J32: =IF($I32="","",IF($I32>=200,"1-CRITICAL",IF($I32>=100,"2-HIGH",IF($I32>=50,"3-MEDIUM","4-LOW")))) | P32: =IF($C32="","",ROUND(IF($E32="1-CRITICAL",7,IF($E32="2-HIGH",14,IF($E32="3-MEDIUM",30,45)))*(1+IF($I32="",0,$I32)/400),0)) | Q32: =IF(OR($C32="",$O32=""),"",$O32+$P32) | T32: =IF($C32="","",IF($R32="CLOSED","Closed",IF($R32="RESOLVED","Resolved",IF($R32="BLOCKED","BLOCKED",IF($I32>=200,"CRITICAL",IF($I32>=100,"High",IF($E32="1-CRITICAL","High","On track"))))))) | U32: =IF($C32="","",IF($R32="CLOSED","Closed - capture lessons learned in PDCA Act phase.",IF($I32>=200,"CRITICAL (RPN "&$I32&"): Escalate today. Open FMEA action + daily PDCA. Owner "&IF($M32="","?",$M32)&". Apply "&IF($L32="","a Lean method",$L32)&". Close by "&IF($Q32="","ASAP",TEXT($Q32,"dd-mmm"))&".",IF($I32>=100,"HIGH (RPN "&$I32&"): Add to current sprint. Mitigate via "&IF($L32="","Standard Work",$L32)&". Review weekly with "&IF($M32="","owner",$M32)&".",IF(OR($E32="1-CRITICAL",$E32="2-HIGH"),"Priority case: schedule "&IF($L32="","a Lean workshop",$L32)&" within 2 weeks. Track to "&IF($N32="","target",$N32)&".","Monitor: apply "&IF($L32="","standard cadence",$L32)&". Re-score if conditions change."))))) | V32: =IF($C32="","",IF($I32="",0,$I32)+ROW()/100000)
A33: =IF($C33="","",TEXT(30,"\C\A\S\E-000")) | I33: =IF($C33="","",IF(COUNT(F33,G33,H33)=3,F33*G33*H33,"")) | J33: =IF($I33="","",IF($I33>=200,"1-CRITICAL",IF($I33>=100,"2-HIGH",IF($I33>=50,"3-MEDIUM","4-LOW")))) | P33: =IF($C33="","",ROUND(IF($E33="1-CRITICAL",7,IF($E33="2-HIGH",14,IF($E33="3-MEDIUM",30,45)))*(1+IF($I33="",0,$I33)/400),0)) | Q33: =IF(OR($C33="",$O33=""),"",$O33+$P33) | T33: =IF($C33="","",IF($R33="CLOSED","Closed",IF($R33="RESOLVED","Resolved",IF($R33="BLOCKED","BLOCKED",IF($I33>=200,"CRITICAL",IF($I33>=100,"High",IF($E33="1-CRITICAL","High","On track"))))))) | U33: =IF($C33="","",IF($R33="CLOSED","Closed - capture lessons learned in PDCA Act phase.",IF($I33>=200,"CRITICAL (RPN "&$I33&"): Escalate today. Open FMEA action + daily PDCA. Owner "&IF($M33="","?",$M33)&". Apply "&IF($L33="","a Lean method",$L33)&". Close by "&IF($Q33="","ASAP",TEXT($Q33,"dd-mmm"))&".",IF($I33>=100,"HIGH (RPN "&$I33&"): Add to current sprint. Mitigate via "&IF($L33="","Standard Work",$L33)&". Review weekly with "&IF($M33="","owner",$M33)&".",IF(OR($E33="1-CRITICAL",$E33="2-HIGH"),"Priority case: schedule "&IF($L33="","a Lean workshop",$L33)&" within 2 weeks. Track to "&IF($N33="","target",$N33)&".","Monitor: apply "&IF($L33="","standard cadence",$L33)&". Re-score if conditions change."))))) | V33: =IF($C33="","",IF($I33="",0,$I33)+ROW()/100000)
A34: =IF($C34="","",TEXT(31,"\C\A\S\E-000")) | I34: =IF($C34="","",IF(COUNT(F34,G34,H34)=3,F34*G34*H34,"")) | J34: =IF($I34="","",IF($I34>=200,"1-CRITICAL",IF($I34>=100,"2-HIGH",IF($I34>=50,"3-MEDIUM","4-LOW")))) | P34: =IF($C34="","",ROUND(IF($E34="1-CRITICAL",7,IF($E34="2-HIGH",14,IF($E34="3-MEDIUM",30,45)))*(1+IF($I34="",0,$I34)/400),0)) | Q34: =IF(OR($C34="",$O34=""),"",$O34+$P34) | T34: =IF($C34="","",IF($R34="CLOSED","Closed",IF($R34="RESOLVED","Resolved",IF($R34="BLOCKED","BLOCKED",IF($I34>=200,"CRITICAL",IF($I34>=100,"High",IF($E34="1-CRITICAL","High","On track"))))))) | U34: =IF($C34="","",IF($R34="CLOSED","Closed - capture lessons learned in PDCA Act phase.",IF($I34>=200,"CRITICAL (RPN "&$I34&"): Escalate today. Open FMEA action + daily PDCA. Owner "&IF($M34="","?",$M34)&". Apply "&IF($L34="","a Lean method",$L34)&". Close by "&IF($Q34="","ASAP",TEXT($Q34,"dd-mmm"))&".",IF($I34>=100,"HIGH (RPN "&$I34&"): Add to current sprint. Mitigate via "&IF($L34="","Standard Work",$L34)&". Review weekly with "&IF($M34="","owner",$M34)&".",IF(OR($E34="1-CRITICAL",$E34="2-HIGH"),"Priority case: schedule "&IF($L34="","a Lean workshop",$L34)&" within 2 weeks. Track to "&IF($N34="","target",$N34)&".","Monitor: apply "&IF($L34="","standard cadence",$L34)&". Re-score if conditions change."))))) | V34: =IF($C34="","",IF($I34="",0,$I34)+ROW()/100000)
A35: =IF($C35="","",TEXT(32,"\C\A\S\E-000")) | I35: =IF($C35="","",IF(COUNT(F35,G35,H35)=3,F35*G35*H35,"")) | J35: =IF($I35="","",IF($I35>=200,"1-CRITICAL",IF($I35>=100,"2-HIGH",IF($I35>=50,"3-MEDIUM","4-LOW")))) | P35: =IF($C35="","",ROUND(IF($E35="1-CRITICAL",7,IF($E35="2-HIGH",14,IF($E35="3-MEDIUM",30,45)))*(1+IF($I35="",0,$I35)/400),0)) | Q35: =IF(OR($C35="",$O35=""),"",$O35+$P35) | T35: =IF($C35="","",IF($R35="CLOSED","Closed",IF($R35="RESOLVED","Resolved",IF($R35="BLOCKED","BLOCKED",IF($I35>=200,"CRITICAL",IF($I35>=100,"High",IF($E35="1-CRITICAL","High","On track"))))))) | U35: =IF($C35="","",IF($R35="CLOSED","Closed - capture lessons learned in PDCA Act phase.",IF($I35>=200,"CRITICAL (RPN "&$I35&"): Escalate today. Open FMEA action + daily PDCA. Owner "&IF($M35="","?",$M35)&". Apply "&IF($L35="","a Lean method",$L35)&". Close by "&IF($Q35="","ASAP",TEXT($Q35,"dd-mmm"))&".",IF($I35>=100,"HIGH (RPN "&$I35&"): Add to current sprint. Mitigate via "&IF($L35="","Standard Work",$L35)&". Review weekly with "&IF($M35="","owner",$M35)&".",IF(OR($E35="1-CRITICAL",$E35="2-HIGH"),"Priority case: schedule "&IF($L35="","a Lean workshop",$L35)&" within 2 weeks. Track to "&IF($N35="","target",$N35)&".","Monitor: apply "&IF($L35="","standard cadence",$L35)&". Re-score if conditions change."))))) | V35: =IF($C35="","",IF($I35="",0,$I35)+ROW()/100000)
A36: =IF($C36="","",TEXT(33,"\C\A\S\E-000")) | I36: =IF($C36="","",IF(COUNT(F36,G36,H36)=3,F36*G36*H36,"")) | J36: =IF($I36="","",IF($I36>=200,"1-CRITICAL",IF($I36>=100,"2-HIGH",IF($I36>=50,"3-MEDIUM","4-LOW")))) | P36: =IF($C36="","",ROUND(IF($E36="1-CRITICAL",7,IF($E36="2-HIGH",14,IF($E36="3-MEDIUM",30,45)))*(1+IF($I36="",0,$I36)/400),0)) | Q36: =IF(OR($C36="",$O36=""),"",$O36+$P36) | T36: =IF($C36="","",IF($R36="CLOSED","Closed",IF($R36="RESOLVED","Resolved",IF($R36="BLOCKED","BLOCKED",IF($I36>=200,"CRITICAL",IF($I36>=100,"High",IF($E36="1-CRITICAL","High","On track"))))))) | U36: =IF($C36="","",IF($R36="CLOSED","Closed - capture lessons learned in PDCA Act phase.",IF($I36>=200,"CRITICAL (RPN "&$I36&"): Escalate today. Open FMEA action + daily PDCA. Owner "&IF($M36="","?",$M36)&". Apply "&IF($L36="","a Lean method",$L36)&". Close by "&IF($Q36="","ASAP",TEXT($Q36,"dd-mmm"))&".",IF($I36>=100,"HIGH (RPN "&$I36&"): Add to current sprint. Mitigate via "&IF($L36="","Standard Work",$L36)&". Review weekly with "&IF($M36="","owner",$M36)&".",IF(OR($E36="1-CRITICAL",$E36="2-HIGH"),"Priority case: schedule "&IF($L36="","a Lean workshop",$L36)&" within 2 weeks. Track to "&IF($N36="","target",$N36)&".","Monitor: apply "&IF($L36="","standard cadence",$L36)&". Re-score if conditions change."))))) | V36: =IF($C36="","",IF($I36="",0,$I36)+ROW()/100000)
A37: =IF($C37="","",TEXT(34,"\C\A\S\E-000")) | I37: =IF($C37="","",IF(COUNT(F37,G37,H37)=3,F37*G37*H37,"")) | J37: =IF($I37="","",IF($I37>=200,"1-CRITICAL",IF($I37>=100,"2-HIGH",IF($I37>=50,"3-MEDIUM","4-LOW")))) | P37: =IF($C37="","",ROUND(IF($E37="1-CRITICAL",7,IF($E37="2-HIGH",14,IF($E37="3-MEDIUM",30,45)))*(1+IF($I37="",0,$I37)/400),0)) | Q37: =IF(OR($C37="",$O37=""),"",$O37+$P37) | T37: =IF($C37="","",IF($R37="CLOSED","Closed",IF($R37="RESOLVED","Resolved",IF($R37="BLOCKED","BLOCKED",IF($I37>=200,"CRITICAL",IF($I37>=100,"High",IF($E37="1-CRITICAL","High","On track"))))))) | U37: =IF($C37="","",IF($R37="CLOSED","Closed - capture lessons learned in PDCA Act phase.",IF($I37>=200,"CRITICAL (RPN "&$I37&"): Escalate today. Open FMEA action + daily PDCA. Owner "&IF($M37="","?",$M37)&". Apply "&IF($L37="","a Lean method",$L37)&". Close by "&IF($Q37="","ASAP",TEXT($Q37,"dd-mmm"))&".",IF($I37>=100,"HIGH (RPN "&$I37&"): Add to current sprint. Mitigate via "&IF($L37="","Standard Work",$L37)&". Review weekly with "&IF($M37="","owner",$M37)&".",IF(OR($E37="1-CRITICAL",$E37="2-HIGH"),"Priority case: schedule "&IF($L37="","a Lean workshop",$L37)&" within 2 weeks. Track to "&IF($N37="","target",$N37)&".","Monitor: apply "&IF($L37="","standard cadence",$L37)&". Re-score if conditions change."))))) | V37: =IF($C37="","",IF($I37="",0,$I37)+ROW()/100000)
A38: =IF($C38="","",TEXT(35,"\C\A\S\E-000")) | I38: =IF($C38="","",IF(COUNT(F38,G38,H38)=3,F38*G38*H38,"")) | J38: =IF($I38="","",IF($I38>=200,"1-CRITICAL",IF($I38>=100,"2-HIGH",IF($I38>=50,"3-MEDIUM","4-LOW")))) | P38: =IF($C38="","",ROUND(IF($E38="1-CRITICAL",7,IF($E38="2-HIGH",14,IF($E38="3-MEDIUM",30,45)))*(1+IF($I38="",0,$I38)/400),0)) | Q38: =IF(OR($C38="",$O38=""),"",$O38+$P38) | T38: =IF($C38="","",IF($R38="CLOSED","Closed",IF($R38="RESOLVED","Resolved",IF($R38="BLOCKED","BLOCKED",IF($I38>=200,"CRITICAL",IF($I38>=100,"High",IF($E38="1-CRITICAL","High","On track"))))))) | U38: =IF($C38="","",IF($R38="CLOSED","Closed - capture lessons learned in PDCA Act phase.",IF($I38>=200,"CRITICAL (RPN "&$I38&"): Escalate today. Open FMEA action + daily PDCA. Owner "&IF($M38="","?",$M38)&". Apply "&IF($L38="","a Lean method",$L38)&". Close by "&IF($Q38="","ASAP",TEXT($Q38,"dd-mmm"))&".",IF($I38>=100,"HIGH (RPN "&$I38&"): Add to current sprint. Mitigate via "&IF($L38="","Standard Work",$L38)&". Review weekly with "&IF($M38="","owner",$M38)&".",IF(OR($E38="1-CRITICAL",$E38="2-HIGH"),"Priority case: schedule "&IF($L38="","a Lean workshop",$L38)&" within 2 weeks. Track to "&IF($N38="","target",$N38)&".","Monitor: apply "&IF($L38="","standard cadence",$L38)&". Re-score if conditions change."))))) | V38: =IF($C38="","",IF($I38="",0,$I38)+ROW()/100000)
A39: =IF($C39="","",TEXT(36,"\C\A\S\E-000")) | I39: =IF($C39="","",IF(COUNT(F39,G39,H39)=3,F39*G39*H39,"")) | J39: =IF($I39="","",IF($I39>=200,"1-CRITICAL",IF($I39>=100,"2-HIGH",IF($I39>=50,"3-MEDIUM","4-LOW")))) | P39: =IF($C39="","",ROUND(IF($E39="1-CRITICAL",7,IF($E39="2-HIGH",14,IF($E39="3-MEDIUM",30,45)))*(1+IF($I39="",0,$I39)/400),0)) | Q39: =IF(OR($C39="",$O39=""),"",$O39+$P39) | T39: =IF($C39="","",IF($R39="CLOSED","Closed",IF($R39="RESOLVED","Resolved",IF($R39="BLOCKED","BLOCKED",IF($I39>=200,"CRITICAL",IF($I39>=100,"High",IF($E39="1-CRITICAL","High","On track"))))))) | U39: =IF($C39="","",IF($R39="CLOSED","Closed - capture lessons learned in PDCA Act phase.",IF($I39>=200,"CRITICAL (RPN "&$I39&"): Escalate today. Open FMEA action + daily PDCA. Owner "&IF($M39="","?",$M39)&". Apply "&IF($L39="","a Lean method",$L39)&". Close by "&IF($Q39="","ASAP",TEXT($Q39,"dd-mmm"))&".",IF($I39>=100,"HIGH (RPN "&$I39&"): Add to current sprint. Mitigate via "&IF($L39="","Standard Work",$L39)&". Review weekly with "&IF($M39="","owner",$M39)&".",IF(OR($E39="1-CRITICAL",$E39="2-HIGH"),"Priority case: schedule "&IF($L39="","a Lean workshop",$L39)&" within 2 weeks. Track to "&IF($N39="","target",$N39)&".","Monitor: apply "&IF($L39="","standard cadence",$L39)&". Re-score if conditions change."))))) | V39: =IF($C39="","",IF($I39="",0,$I39)+ROW()/100000)
A40: =IF($C40="","",TEXT(37,"\C\A\S\E-000")) | I40: =IF($C40="","",IF(COUNT(F40,G40,H40)=3,F40*G40*H40,"")) | J40: =IF($I40="","",IF($I40>=200,"1-CRITICAL",IF($I40>=100,"2-HIGH",IF($I40>=50,"3-MEDIUM","4-LOW")))) | P40: =IF($C40="","",ROUND(IF($E40="1-CRITICAL",7,IF($E40="2-HIGH",14,IF($E40="3-MEDIUM",30,45)))*(1+IF($I40="",0,$I40)/400),0)) | Q40: =IF(OR($C40="",$O40=""),"",$O40+$P40) | T40: =IF($C40="","",IF($R40="CLOSED","Closed",IF($R40="RESOLVED","Resolved",IF($R40="BLOCKED","BLOCKED",IF($I40>=200,"CRITICAL",IF($I40>=100,"High",IF($E40="1-CRITICAL","High","On track"))))))) | U40: =IF($C40="","",IF($R40="CLOSED","Closed - capture lessons learned in PDCA Act phase.",IF($I40>=200,"CRITICAL (RPN "&$I40&"): Escalate today. Open FMEA action + daily PDCA. Owner "&IF($M40="","?",$M40)&". Apply "&IF($L40="","a Lean method",$L40)&". Close by "&IF($Q40="","ASAP",TEXT($Q40,"dd-mmm"))&".",IF($I40>=100,"HIGH (RPN "&$I40&"): Add to current sprint. Mitigate via "&IF($L40="","Standard Work",$L40)&". Review weekly with "&IF($M40="","owner",$M40)&".",IF(OR($E40="1-CRITICAL",$E40="2-HIGH"),"Priority case: schedule "&IF($L40="","a Lean workshop",$L40)&" within 2 weeks. Track to "&IF($N40="","target",$N40)&".","Monitor: apply "&IF($L40="","standard cadence",$L40)&". Re-score if conditions change."))))) | V40: =IF($C40="","",IF($I40="",0,$I40)+ROW()/100000)
...

Sheet 2. PM_TASKS
A1: PM TASK TRACKER - auto-built from every registered case
A2: Read-only. Each task mirrors a MASTER case. Edit on MASTER_ENTRY; this updates instantly.
A3: TASK ID | B3: TASK / DELIVERABLE | C3: OWNER | D3: PRIORITY | E3: START | F3: DUE | G3: EST DAYS | H3: % DONE | I3: STATUS | J3: HEALTH
A4: =IF('1. MASTER_ENTRY'!$C4="","",'1. MASTER_ENTRY'!$A4) | B4: =IF('1. MASTER_ENTRY'!$C4="","",'1. MASTER_ENTRY'!$C4) | C4: =IF('1. MASTER_ENTRY'!$C4="","",'1. MASTER_ENTRY'!$M4) | D4: =IF('1. MASTER_ENTRY'!$C4="","",'1. MASTER_ENTRY'!$E4) | E4: =IF('1. MASTER_ENTRY'!$C4="","",'1. MASTER_ENTRY'!$O4) | F4: =IF('1. MASTER_ENTRY'!$C4="","",'1. MASTER_ENTRY'!$Q4) | G4: =IF('1. MASTER_ENTRY'!$C4="","",'1. MASTER_ENTRY'!$P4) | H4: =IF('1. MASTER_ENTRY'!$C4="","",'1. MASTER_ENTRY'!$S4) | I4: =IF('1. MASTER_ENTRY'!$C4="","",'1. MASTER_ENTRY'!$R4) | J4: =IF('1. MASTER_ENTRY'!$C4="","",'1. MASTER_ENTRY'!$T4)
A5: =IF('1. MASTER_ENTRY'!$C5="","",'1. MASTER_ENTRY'!$A5) | B5: =IF('1. MASTER_ENTRY'!$C5="","",'1. MASTER_ENTRY'!$C5) | C5: =IF('1. MASTER_ENTRY'!$C5="","",'1. MASTER_ENTRY'!$M5) | D5: =IF('1. MASTER_ENTRY'!$C5="","",'1. MASTER_ENTRY'!$E5) | E5: =IF('1. MASTER_ENTRY'!$C5="","",'1. MASTER_ENTRY'!$O5) | F5: =IF('1. MASTER_ENTRY'!$C5="","",'1. MASTER_ENTRY'!$Q5) | G5: =IF('1. MASTER_ENTRY'!$C5="","",'1. MASTER_ENTRY'!$P5) | H5: =IF('1. MASTER_ENTRY'!$C5="","",'1. MASTER_ENTRY'!$S5) | I5: =IF('1. MASTER_ENTRY'!$C5="","",'1. MASTER_ENTRY'!$R5) | J5: =IF('1. MASTER_ENTRY'!$C5="","",'1. MASTER_ENTRY'!$T5)
A6: =IF('1. MASTER_ENTRY'!$C6="","",'1. MASTER_ENTRY'!$A6) | B6: =IF('1. MASTER_ENTRY'!$C6="","",'1. MASTER_ENTRY'!$C6) | C6: =IF('1. MASTER_ENTRY'!$C6="","",'1. MASTER_ENTRY'!$M6) | D6: =IF('1. MASTER_ENTRY'!$C6="","",'1. MASTER_ENTRY'!$E6) | E6: =IF('1. MASTER_ENTRY'!$C6="","",'1. MASTER_ENTRY'!$O6) | F6: =IF('1. MASTER_ENTRY'!$C6="","",'1. MASTER_ENTRY'!$Q6) | G6: =IF('1. MASTER_ENTRY'!$C6="","",'1. MASTER_ENTRY'!$P6) | H6: =IF('1. MASTER_ENTRY'!$C6="","",'1. MASTER_ENTRY'!$S6) | I6: =IF('1. MASTER_ENTRY'!$C6="","",'1. MASTER_ENTRY'!$R6) | J6: =IF('1. MASTER_ENTRY'!$C6="","",'1. MASTER_ENTRY'!$T6)
A7: =IF('1. MASTER_ENTRY'!$C7="","",'1. MASTER_ENTRY'!$A7) | B7: =IF('1. MASTER_ENTRY'!$C7="","",'1. MASTER_ENTRY'!$C7) | C7: =IF('1. MASTER_ENTRY'!$C7="","",'1. MASTER_ENTRY'!$M7) | D7: =IF('1. MASTER_ENTRY'!$C7="","",'1. MASTER_ENTRY'!$E7) | E7: =IF('1. MASTER_ENTRY'!$C7="","",'1. MASTER_ENTRY'!$O7) | F7: =IF('1. MASTER_ENTRY'!$C7="","",'1. MASTER_ENTRY'!$Q7) | G7: =IF('1. MASTER_ENTRY'!$C7="","",'1. MASTER_ENTRY'!$P7) | H7: =IF('1. MASTER_ENTRY'!$C7="","",'1. MASTER_ENTRY'!$S7) | I7: =IF('1. MASTER_ENTRY'!$C7="","",'1. MASTER_ENTRY'!$R7) | J7: =IF('1. MASTER_ENTRY'!$C7="","",'1. MASTER_ENTRY'!$T7)
A8: =IF('1. MASTER_ENTRY'!$C8="","",'1. MASTER_ENTRY'!$A8) | B8: =IF('1. MASTER_ENTRY'!$C8="","",'1. MASTER_ENTRY'!$C8) | C8: =IF('1. MASTER_ENTRY'!$C8="","",'1. MASTER_ENTRY'!$M8) | D8: =IF('1. MASTER_ENTRY'!$C8="","",'1. MASTER_ENTRY'!$E8) | E8: =IF('1. MASTER_ENTRY'!$C8="","",'1. MASTER_ENTRY'!$O8) | F8: =IF('1. MASTER_ENTRY'!$C8="","",'1. MASTER_ENTRY'!$Q8) | G8: =IF('1. MASTER_ENTRY'!$C8="","",'1. MASTER_ENTRY'!$P8) | H8: =IF('1. MASTER_ENTRY'!$C8="","",'1. MASTER_ENTRY'!$S8) | I8: =IF('1. MASTER_ENTRY'!$C8="","",'1. MASTER_ENTRY'!$R8) | J8: =IF('1. MASTER_ENTRY'!$C8="","",'1. MASTER_ENTRY'!$T8)
A9: =IF('1. MASTER_ENTRY'!$C9="","",'1. MASTER_ENTRY'!$A9) | B9: =IF('1. MASTER_ENTRY'!$C9="","",'1. MASTER_ENTRY'!$C9) | C9: =IF('1. MASTER_ENTRY'!$C9="","",'1. MASTER_ENTRY'!$M9) | D9: =IF('1. MASTER_ENTRY'!$C9="","",'1. MASTER_ENTRY'!$E9) | E9: =IF('1. MASTER_ENTRY'!$C9="","",'1. MASTER_ENTRY'!$O9) | F9: =IF('1. MASTER_ENTRY'!$C9="","",'1. MASTER_ENTRY'!$Q9) | G9: =IF('1. MASTER_ENTRY'!$C9="","",'1. MASTER_ENTRY'!$P9) | H9: =IF('1. MASTER_ENTRY'!$C9="","",'1. MASTER_ENTRY'!$S9) | I9: =IF('1. MASTER_ENTRY'!$C9="","",'1. MASTER_ENTRY'!$R9) | J9: =IF('1. MASTER_ENTRY'!$C9="","",'1. MASTER_ENTRY'!$T9)
A10: =IF('1. MASTER_ENTRY'!$C10="","",'1. MASTER_ENTRY'!$A10) | B10: =IF('1. MASTER_ENTRY'!$C10="","",'1. MASTER_ENTRY'!$C10) | C10: =IF('1. MASTER_ENTRY'!$C10="","",'1. MASTER_ENTRY'!$M10) | D10: =IF('1. MASTER_ENTRY'!$C10="","",'1. MASTER_ENTRY'!$E10) | E10: =IF('1. MASTER_ENTRY'!$C10="","",'1. MASTER_ENTRY'!$O10) | F10: =IF('1. MASTER_ENTRY'!$C10="","",'1. MASTER_ENTRY'!$Q10) | G10: =IF('1. MASTER_ENTRY'!$C10="","",'1. MASTER_ENTRY'!$P10) | H10: =IF('1. MASTER_ENTRY'!$C10="","",'1. MASTER_ENTRY'!$S10) | I10: =IF('1. MASTER_ENTRY'!$C10="","",'1. MASTER_ENTRY'!$R10) | J10: =IF('1. MASTER_ENTRY'!$C10="","",'1. MASTER_ENTRY'!$T10)
A11: =IF('1. MASTER_ENTRY'!$C11="","",'1. MASTER_ENTRY'!$A11) | B11: =IF('1. MASTER_ENTRY'!$C11="","",'1. MASTER_ENTRY'!$C11) | C11: =IF('1. MASTER_ENTRY'!$C11="","",'1. MASTER_ENTRY'!$M11) | D11: =IF('1. MASTER_ENTRY'!$C11="","",'1. MASTER_ENTRY'!$E11) | E11: =IF('1. MASTER_ENTRY'!$C11="","",'1. MASTER_ENTRY'!$O11) | F11: =IF('1. MASTER_ENTRY'!$C11="","",'1. MASTER_ENTRY'!$Q11) | G11: =IF('1. MASTER_ENTRY'!$C11="","",'1. MASTER_ENTRY'!$P11) | H11: =IF('1. MASTER_ENTRY'!$C11="","",'1. MASTER_ENTRY'!$S11) | I11: =IF('1. MASTER_ENTRY'!$C11="","",'1. MASTER_ENTRY'!$R11) | J11: =IF('1. MASTER_ENTRY'!$C11="","",'1. MASTER_ENTRY'!$T11)
A12: =IF('1. MASTER_ENTRY'!$C12="","",'1. MASTER_ENTRY'!$A12) | B12: =IF('1. MASTER_ENTRY'!$C12="","",'1. MASTER_ENTRY'!$C12) | C12: =IF('1. MASTER_ENTRY'!$C12="","",'1. MASTER_ENTRY'!$M12) | D12: =IF('1. MASTER_ENTRY'!$C12="","",'1. MASTER_ENTRY'!$E12) | E12: =IF('1. MASTER_ENTRY'!$C12="","",'1. MASTER_ENTRY'!$O12) | F12: =IF('1. MASTER_ENTRY'!$C12="","",'1. MASTER_ENTRY'!$Q12) | G12: =IF('1. MASTER_ENTRY'!$C12="","",'1. MASTER_ENTRY'!$P12) | H12: =IF('1. MASTER_ENTRY'!$C12="","",'1. MASTER_ENTRY'!$S12) | I12: =IF('1. MASTER_ENTRY'!$C12="","",'1. MASTER_ENTRY'!$R12) | J12: =IF('1. MASTER_ENTRY'!$C12="","",'1. MASTER_ENTRY'!$T12)
A13: =IF('1. MASTER_ENTRY'!$C13="","",'1. MASTER_ENTRY'!$A13) | B13: =IF('1. MASTER_ENTRY'!$C13="","",'1. MASTER_ENTRY'!$C13) | C13: =IF('1. MASTER_ENTRY'!$C13="","",'1. MASTER_ENTRY'!$M13) | D13: =IF('1. MASTER_ENTRY'!$C13="","",'1. MASTER_ENTRY'!$E13) | E13: =IF('1. MASTER_ENTRY'!$C13="","",'1. MASTER_ENTRY'!$O13) | F13: =IF('1. MASTER_ENTRY'!$C13="","",'1. MASTER_ENTRY'!$Q13) | G13: =IF('1. MASTER_ENTRY'!$C13="","",'1. MASTER_ENTRY'!$P13) | H13: =IF('1. MASTER_ENTRY'!$C13="","",'1. MASTER_ENTRY'!$S13) | I13: =IF('1. MASTER_ENTRY'!$C13="","",'1. MASTER_ENTRY'!$R13) | J13: =IF('1. MASTER_ENTRY'!$C13="","",'1. MASTER_ENTRY'!$T13)
